<?xml version="1.0" ?>
<robot name="partnet_ad6bd7e24e5bc25f3593835fe348a036">
	<link name="base"/>
	<link name="link_0">
		<visual name="frame-2">
			<origin xyz="0 0 0"/>
			<geometry>
				<mesh filename="textured_objs/new-0.obj"/>
			</geometry>
		</visual>
		<collision>
			<origin xyz="0 0 0"/>
			<geometry>
				<mesh filename="textured_objs/new-0.obj"/>
			</geometry>
		</collision>
	</link>
	<joint name="joint_0" type="fixed">
		<origin rpy="1.570796326794897 0 -1.570796326794897" xyz="0 0 0"/>
		<child link="link_0"/>
		<parent link="base"/>
	</joint>
	<link name="link_1">
		<visual name="door_frame-4">
			<origin xyz="0.2841406049282753 -0.9260130000000002 -0.28576689270347044"/>
			<geometry>
				<mesh filename="textured_objs/original-2.obj"/>
			</geometry>
		</visual>
		<visual name="door_frame-4">
			<origin xyz="0.2841406049282753 -0.9260130000000002 -0.28576689270347044"/>
			<geometry>
				<mesh filename="textured_objs/original-3.obj"/>
			</geometry>
		</visual>
		<visual name="door_frame-4">
			<origin xyz="0.2841406049282753 -0.9260130000000002 -0.28576689270347044"/>
			<geometry>
				<mesh filename="textured_objs/original-5.obj"/>
			</geometry>
		</visual>
		<visual name="door_frame-4">
			<origin xyz="0.2841406049282753 -0.9260130000000002 -0.28576689270347044"/>
			<geometry>
				<mesh filename="textured_objs/original-6.obj"/>
			</geometry>
		</visual>
		<visual name="door_frame-4">
			<origin xyz="0.2841406049282753 -0.9260130000000002 -0.28576689270347044"/>
			<geometry>
				<mesh filename="textured_objs/original-7.obj"/>
			</geometry>
		</visual>
		<visual name="door_frame-4">
			<origin xyz="0.2841406049282753 -0.9260130000000002 -0.28576689270347044"/>
			<geometry>
				<mesh filename="textured_objs/original-8.obj"/>
			</geometry>
		</visual>
		<visual name="door_frame-4">
			<origin xyz="0.2841406049282753 -0.9260130000000002 -0.28576689270347044"/>
			<geometry>
				<mesh filename="textured_objs/original-9.obj"/>
			</geometry>
		</visual>
		<visual name="door_frame-4">
			<origin xyz="0.2841406049282753 -0.9260130000000002 -0.28576689270347044"/>
			<geometry>
				<mesh filename="textured_objs/original-10.obj"/>
			</geometry>
		</visual>
		<visual name="door_frame-4">
			<origin xyz="0.2841406049282753 -0.9260130000000002 -0.28576689270347044"/>
			<geometry>
				<mesh filename="textured_objs/new-2.obj"/>
			</geometry>
		</visual>
		<visual name="door_frame-4">
			<origin xyz="0.2841406049282753 -0.9260130000000002 -0.28576689270347044"/>
			<geometry>
				<mesh filename="textured_objs/original-11.obj"/>
			</geometry>
		</visual>
		<visual name="door_frame-4">
			<origin xyz="0.2841406049282753 -0.9260130000000002 -0.28576689270347044"/>
			<geometry>
				<mesh filename="textured_objs/original-12.obj"/>
			</geometry>
		</visual>
		<visual name="handle-5">
			<origin xyz="0.2841406049282753 -0.9260130000000002 -0.28576689270347044"/>
			<geometry>
				<mesh filename="textured_objs/new-1.obj"/>
			</geometry>
		</visual>
		<collision>
			<origin xyz="0.2841406049282753 -0.9260130000000002 -0.28576689270347044"/>
			<geometry>
				<mesh filename="textured_objs/original-2.obj"/>
			</geometry>
		</collision>
		<collision>
			<origin xyz="0.2841406049282753 -0.9260130000000002 -0.28576689270347044"/>
			<geometry>
				<mesh filename="textured_objs/original-3.obj"/>
			</geometry>
		</collision>
		<collision>
			<origin xyz="0.2841406049282753 -0.9260130000000002 -0.28576689270347044"/>
			<geometry>
				<mesh filename="textured_objs/original-5.obj"/>
			</geometry>
		</collision>
		<collision>
			<origin xyz="0.2841406049282753 -0.9260130000000002 -0.28576689270347044"/>
			<geometry>
				<mesh filename="textured_objs/original-6.obj"/>
			</geometry>
		</collision>
		<collision>
			<origin xyz="0.2841406049282753 -0.9260130000000002 -0.28576689270347044"/>
			<geometry>
				<mesh filename="textured_objs/original-7.obj"/>
			</geometry>
		</collision>
		<collision>
			<origin xyz="0.2841406049282753 -0.9260130000000002 -0.28576689270347044"/>
			<geometry>
				<mesh filename="textured_objs/original-8.obj"/>
			</geometry>
		</collision>
		<collision>
			<origin xyz="0.2841406049282753 -0.9260130000000002 -0.28576689270347044"/>
			<geometry>
				<mesh filename="textured_objs/original-9.obj"/>
			</geometry>
		</collision>
		<collision>
			<origin xyz="0.2841406049282753 -0.9260130000000002 -0.28576689270347044"/>
			<geometry>
				<mesh filename="textured_objs/original-10.obj"/>
			</geometry>
		</collision>
		<collision>
			<origin xyz="0.2841406049282753 -0.9260130000000002 -0.28576689270347044"/>
			<geometry>
				<mesh filename="textured_objs/new-2.obj"/>
			</geometry>
		</collision>
		<collision>
			<origin xyz="0.2841406049282753 -0.9260130000000002 -0.28576689270347044"/>
			<geometry>
				<mesh filename="textured_objs/original-11.obj"/>
			</geometry>
		</collision>
		<collision>
			<origin xyz="0.2841406049282753 -0.9260130000000002 -0.28576689270347044"/>
			<geometry>
				<mesh filename="textured_objs/original-12.obj"/>
			</geometry>
		</collision>
		<collision>
			<origin xyz="0.2841406049282753 -0.9260130000000002 -0.28576689270347044"/>
			<geometry>
				<mesh filename="textured_objs/new-1.obj"/>
			</geometry>
		</collision>
	</link>
	<joint name="joint_1" type="revolute">
		<origin xyz="-0.2841406049282753 0.9260130000000002 0.28576689270347044"/>
		<axis xyz="0 -0.9999999999999999 0"/>
		<child link="link_1"/>
		<parent link="link_0"/>
		<limit lower="0.0" upper="3.141592653589793"/>
	</joint>
</robot>
