<?xml version="1.0" ?>
<robot name="partnet_12c3e644bc371f30366648d52e38fd70">
	<link name="base"/>
	<link name="link_0">
		<visual name="button-4">
			<origin xyz="-0.37744141282687205 0.361968114812975 -0.620633891790364"/>
			<geometry>
				<mesh filename="textured_objs/original-4.obj"/>
			</geometry>
		</visual>
		<collision>
			<origin xyz="-0.37744141282687205 0.361968114812975 -0.620633891790364"/>
			<geometry>
				<mesh filename="textured_objs/original-4.obj"/>
			</geometry>
		</collision>
	</link>
	<joint name="joint_0" type="prismatic">
		<origin xyz="0.37744141282687205 -0.361968114812975 0.620633891790364"/>
		<axis xyz="0.041060981347366084 -0.6702268736185778 -0.7410195231505431"/>
		<child link="link_0"/>
		<parent link="link_4"/>
		<limit lower="0" upper="0.02400000000000002"/>
	</joint>
	<link name="link_1">
		<visual name="button-5">
			<origin xyz="-0.37744141282687205 0.361968114812975 -0.620633891790364"/>
			<geometry>
				<mesh filename="textured_objs/original-3.obj"/>
			</geometry>
		</visual>
		<collision>
			<origin xyz="-0.37744141282687205 0.361968114812975 -0.620633891790364"/>
			<geometry>
				<mesh filename="textured_objs/original-3.obj"/>
			</geometry>
		</collision>
	</link>
	<joint name="joint_1" type="prismatic">
		<origin xyz="0.37744141282687205 -0.361968114812975 0.620633891790364"/>
		<axis xyz="0.041060981347366084 -0.6702268736185778 -0.7410195231505431"/>
		<child link="link_1"/>
		<parent link="link_4"/>
		<limit lower="0" upper="0.005"/>
	</joint>
	<link name="link_2">
		<visual name="button-6">
			<origin xyz="-0.37744141282687205 0.361968114812975 -0.620633891790364"/>
			<geometry>
				<mesh filename="textured_objs/original-2.obj"/>
			</geometry>
		</visual>
		<collision>
			<origin xyz="-0.37744141282687205 0.361968114812975 -0.620633891790364"/>
			<geometry>
				<mesh filename="textured_objs/original-2.obj"/>
			</geometry>
		</collision>
	</link>
	<joint name="joint_2" type="prismatic">
		<origin xyz="0.37744141282687205 -0.361968114812975 0.620633891790364"/>
		<axis xyz="0.041060981347366084 -0.6702268736185778 -0.7410195231505431"/>
		<child link="link_2"/>
		<parent link="link_4"/>
		<limit lower="0" upper="0.005"/>
	</joint>
	<link name="link_3">
		<visual name="button-7">
			<origin xyz="-0.37744141282687205 0.361968114812975 -0.620633891790364"/>
			<geometry>
				<mesh filename="textured_objs/original-1.obj"/>
			</geometry>
		</visual>
		<collision>
			<origin xyz="-0.37744141282687205 0.361968114812975 -0.620633891790364"/>
			<geometry>
				<mesh filename="textured_objs/original-1.obj"/>
			</geometry>
		</collision>
	</link>
	<joint name="joint_3" type="prismatic">
		<origin xyz="0.37744141282687205 -0.361968114812975 0.620633891790364"/>
		<axis xyz="0.041060981347366084 -0.6702268736185778 -0.7410195231505431"/>
		<child link="link_3"/>
		<parent link="link_4"/>
		<limit lower="0" upper="0.005"/>
	</joint>
	<link name="link_4">
		<visual name="frame-2">
			<origin xyz="0 0 0"/>
			<geometry>
				<mesh filename="textured_objs/new-1.obj"/>
			</geometry>
		</visual>
		<visual name="screen-3">
			<origin xyz="0 0 0"/>
			<geometry>
				<mesh filename="textured_objs/original-5.obj"/>
			</geometry>
		</visual>
		<visual name="screen-3">
			<origin xyz="0 0 0"/>
			<geometry>
				<mesh filename="textured_objs/new-0.obj"/>
			</geometry>
		</visual>
		<collision>
			<origin xyz="0 0 0"/>
			<geometry>
				<mesh filename="textured_objs/new-1.obj"/>
			</geometry>
		</collision>
		<collision>
			<origin xyz="0 0 0"/>
			<geometry>
				<mesh filename="textured_objs/original-5.obj"/>
			</geometry>
		</collision>
		<collision>
			<origin xyz="0 0 0"/>
			<geometry>
				<mesh filename="textured_objs/new-0.obj"/>
			</geometry>
		</collision>
	</link>
	<joint name="joint_4" type="fixed">
		<origin rpy="1.570796326794897 0 -1.570796326794897" xyz="0 0 0"/>
		<child link="link_4"/>
		<parent link="base"/>
	</joint>
</robot>
