<?xml version="1.0" ?>
<robot name="partnet_1bcc781e46ae8d3a8a5a55f9e4159d1">
	<link name="base"/>
	<link name="link_0">
		<visual name="outside_frame-1">
			<origin xyz="0 0 0"/>
			<geometry>
				<mesh filename="textured_objs/original-1.obj"/>
			</geometry>
		</visual>
		<visual name="outside_frame-1">
			<origin xyz="0 0 0"/>
			<geometry>
				<mesh filename="textured_objs/original-2.obj"/>
			</geometry>
		</visual>
		<collision>
			<origin xyz="0 0 0"/>
			<geometry>
				<mesh filename="textured_objs/original-1.obj"/>
			</geometry>
		</collision>
		<collision>
			<origin xyz="0 0 0"/>
			<geometry>
				<mesh filename="textured_objs/original-2.obj"/>
			</geometry>
		</collision>
	</link>
	<joint name="joint_0" type="fixed">
		<origin rpy="1.570796326794897 0 -1.570796326794897" xyz="0 0 0"/>
		<child link="link_0"/>
		<parent link="base"/>
	</joint>
	<link name="link_1">
		<visual name="fixed_part-11">
			<origin xyz="0.5031069626410286 -0.8463550209999084 0.06656380173772726"/>
			<geometry>
				<mesh filename="textured_objs/original-7.obj"/>
			</geometry>
		</visual>
		<visual name="fixed_part-11">
			<origin xyz="0.5031069626410286 -0.8463550209999084 0.06656380173772726"/>
			<geometry>
				<mesh filename="textured_objs/original-5.obj"/>
			</geometry>
		</visual>
		<visual name="surface_board-12">
			<origin xyz="0.5031069626410286 -0.8463550209999084 0.06656380173772726"/>
			<geometry>
				<mesh filename="textured_objs/original-4.obj"/>
			</geometry>
		</visual>
		<collision>
			<origin xyz="0.5031069626410286 -0.8463550209999084 0.06656380173772726"/>
			<geometry>
				<mesh filename="textured_objs/original-7.obj"/>
			</geometry>
		</collision>
		<collision>
			<origin xyz="0.5031069626410286 -0.8463550209999084 0.06656380173772726"/>
			<geometry>
				<mesh filename="textured_objs/original-5.obj"/>
			</geometry>
		</collision>
		<collision>
			<origin xyz="0.5031069626410286 -0.8463550209999084 0.06656380173772726"/>
			<geometry>
				<mesh filename="textured_objs/original-4.obj"/>
			</geometry>
		</collision>
	</link>
	<joint name="joint_1" type="revolute">
		<origin xyz="-0.5031069626410286 0.8463550209999084 -0.06656380173772726"/>
		<axis xyz="0 -1 0"/>
		<child link="link_1"/>
		<parent link="link_0"/>
		<limit lower="-0.5026548245743669" upper="1.193805208364121"/>
	</joint>
	<link name="link_2">
		<visual name="fixed_part-10">
			<origin xyz="-0.4965788093925727 -0.8463550209999084 0.05746366017555979"/>
			<geometry>
				<mesh filename="textured_objs/original-11.obj"/>
			</geometry>
		</visual>
		<visual name="fixed_part-10">
			<origin xyz="-0.4965788093925727 -0.8463550209999084 0.05746366017555979"/>
			<geometry>
				<mesh filename="textured_objs/original-13.obj"/>
			</geometry>
		</visual>
		<visual name="surface_board-13">
			<origin xyz="-0.4965788093925727 -0.8463550209999084 0.05746366017555979"/>
			<geometry>
				<mesh filename="textured_objs/original-10.obj"/>
			</geometry>
		</visual>
		<collision>
			<origin xyz="-0.4965788093925727 -0.8463550209999084 0.05746366017555979"/>
			<geometry>
				<mesh filename="textured_objs/original-11.obj"/>
			</geometry>
		</collision>
		<collision>
			<origin xyz="-0.4965788093925727 -0.8463550209999084 0.05746366017555979"/>
			<geometry>
				<mesh filename="textured_objs/original-13.obj"/>
			</geometry>
		</collision>
		<collision>
			<origin xyz="-0.4965788093925727 -0.8463550209999084 0.05746366017555979"/>
			<geometry>
				<mesh filename="textured_objs/original-10.obj"/>
			</geometry>
		</collision>
	</link>
	<joint name="joint_2" type="revolute">
		<origin xyz="0.4965788093925727 0.8463550209999084 -0.05746366017555979"/>
		<axis xyz="0 1 0"/>
		<child link="link_2"/>
		<parent link="link_0"/>
		<limit lower="-0.251327412287184" upper="1.6336281798666925"/>
	</joint>
</robot>
