<?xml version="1.0" ?>
<robot name="partnet_52356ccfc05934f2a41386d23d519c74">
	<link name="base"/>
	<link name="link_0">
		<visual name="frame-7">
			<origin xyz="0 0 0"/>
			<geometry>
				<mesh filename="textured_objs/new-6.obj"/>
			</geometry>
		</visual>
		<visual name="frame-7">
			<origin xyz="0 0 0"/>
			<geometry>
				<mesh filename="textured_objs/new-11.obj"/>
			</geometry>
		</visual>
		<collision>
			<origin xyz="0 0 0"/>
			<geometry>
				<mesh filename="textured_objs/new-6.obj"/>
			</geometry>
		</collision>
		<collision>
			<origin xyz="0 0 0"/>
			<geometry>
				<mesh filename="textured_objs/new-11.obj"/>
			</geometry>
		</collision>
	</link>
	<joint name="joint_0" type="fixed">
		<origin rpy="1.570796326794897 0 -1.570796326794897" xyz="0 0 0"/>
		<child link="link_0"/>
		<parent link="base"/>
	</joint>
	<link name="link_1">
		<visual name="door_frame-12">
			<origin xyz="-0.5018334931065915 -0.8400639999999999 -0.18692712456529925"/>
			<geometry>
				<mesh filename="textured_objs/new-8.obj"/>
			</geometry>
		</visual>
		<visual name="handle-13">
			<origin xyz="-0.5018334931065915 -0.8400639999999999 -0.18692712456529925"/>
			<geometry>
				<mesh filename="textured_objs/new-7.obj"/>
			</geometry>
		</visual>
		<collision>
			<origin xyz="-0.5018334931065915 -0.8400639999999999 -0.18692712456529925"/>
			<geometry>
				<mesh filename="textured_objs/new-8.obj"/>
			</geometry>
		</collision>
		<collision>
			<origin xyz="-0.5018334931065915 -0.8400639999999999 -0.18692712456529925"/>
			<geometry>
				<mesh filename="textured_objs/new-7.obj"/>
			</geometry>
		</collision>
	</link>
	<joint name="joint_1" type="revolute">
		<origin xyz="0.5018334931065915 0.8400639999999999 0.18692712456529925"/>
		<axis xyz="0 1 0"/>
		<child link="link_1"/>
		<parent link="link_0"/>
		<limit lower="-0.0" upper="3.141592653589793"/>
	</joint>
	<link name="link_2">
		<visual name="control_panel-16">
			<origin xyz="0.5103242329668447 -0.8400639999999999 -0.19646803644768696"/>
			<geometry>
				<mesh filename="textured_objs/original-7.obj"/>
			</geometry>
		</visual>
		<visual name="control_panel-16">
			<origin xyz="0.5103242329668447 -0.8400639999999999 -0.19646803644768696"/>
			<geometry>
				<mesh filename="textured_objs/original-8.obj"/>
			</geometry>
		</visual>
		<visual name="control_panel-16">
			<origin xyz="0.5103242329668447 -0.8400639999999999 -0.19646803644768696"/>
			<geometry>
				<mesh filename="textured_objs/original-5.obj"/>
			</geometry>
		</visual>
		<visual name="control_panel-16">
			<origin xyz="0.5103242329668447 -0.8400639999999999 -0.19646803644768696"/>
			<geometry>
				<mesh filename="textured_objs/original-3.obj"/>
			</geometry>
		</visual>
		<visual name="control_panel-16">
			<origin xyz="0.5103242329668447 -0.8400639999999999 -0.19646803644768696"/>
			<geometry>
				<mesh filename="textured_objs/original-4.obj"/>
			</geometry>
		</visual>
		<visual name="control_panel-16">
			<origin xyz="0.5103242329668447 -0.8400639999999999 -0.19646803644768696"/>
			<geometry>
				<mesh filename="textured_objs/new-9.obj"/>
			</geometry>
		</visual>
		<visual name="control_panel-16">
			<origin xyz="0.5103242329668447 -0.8400639999999999 -0.19646803644768696"/>
			<geometry>
				<mesh filename="textured_objs/original-6.obj"/>
			</geometry>
		</visual>
		<visual name="door_frame-10">
			<origin xyz="0.5103242329668447 -0.8400639999999999 -0.19646803644768696"/>
			<geometry>
				<mesh filename="textured_objs/new-10.obj"/>
			</geometry>
		</visual>
		<visual name="handle-11">
			<origin xyz="0.5103242329668447 -0.8400639999999999 -0.19646803644768696"/>
			<geometry>
				<mesh filename="textured_objs/original-2.obj"/>
			</geometry>
		</visual>
		<collision>
			<origin xyz="0.5103242329668447 -0.8400639999999999 -0.19646803644768696"/>
			<geometry>
				<mesh filename="textured_objs/original-7.obj"/>
			</geometry>
		</collision>
		<collision>
			<origin xyz="0.5103242329668447 -0.8400639999999999 -0.19646803644768696"/>
			<geometry>
				<mesh filename="textured_objs/original-8.obj"/>
			</geometry>
		</collision>
		<collision>
			<origin xyz="0.5103242329668447 -0.8400639999999999 -0.19646803644768696"/>
			<geometry>
				<mesh filename="textured_objs/original-5.obj"/>
			</geometry>
		</collision>
		<collision>
			<origin xyz="0.5103242329668447 -0.8400639999999999 -0.19646803644768696"/>
			<geometry>
				<mesh filename="textured_objs/original-3.obj"/>
			</geometry>
		</collision>
		<collision>
			<origin xyz="0.5103242329668447 -0.8400639999999999 -0.19646803644768696"/>
			<geometry>
				<mesh filename="textured_objs/original-4.obj"/>
			</geometry>
		</collision>
		<collision>
			<origin xyz="0.5103242329668447 -0.8400639999999999 -0.19646803644768696"/>
			<geometry>
				<mesh filename="textured_objs/new-9.obj"/>
			</geometry>
		</collision>
		<collision>
			<origin xyz="0.5103242329668447 -0.8400639999999999 -0.19646803644768696"/>
			<geometry>
				<mesh filename="textured_objs/original-6.obj"/>
			</geometry>
		</collision>
		<collision>
			<origin xyz="0.5103242329668447 -0.8400639999999999 -0.19646803644768696"/>
			<geometry>
				<mesh filename="textured_objs/new-10.obj"/>
			</geometry>
		</collision>
		<collision>
			<origin xyz="0.5103242329668447 -0.8400639999999999 -0.19646803644768696"/>
			<geometry>
				<mesh filename="textured_objs/original-2.obj"/>
			</geometry>
		</collision>
	</link>
	<joint name="joint_2" type="revolute">
		<origin xyz="-0.5103242329668447 0.8400639999999999 0.19646803644768696"/>
		<axis xyz="0 -1 0"/>
		<child link="link_2"/>
		<parent link="link_0"/>
		<limit lower="0.0" upper="3.141592653589793"/>
	</joint>
</robot>
