<?xml version="1.0" ?>
<robot name="partnet_dd8cebcb4d0564059352b002a7d38daa">
	<link name="base"/>
	<link name="link_0">
		<visual name="button-8">
			<origin xyz="-0.0016310887362587234 0.3833000928301903 -0.5079890000000007"/>
			<geometry>
				<mesh filename="textured_objs/original-6.obj"/>
			</geometry>
		</visual>
		<collision>
			<origin xyz="-0.0016310887362587234 0.3833000928301903 -0.5079890000000007"/>
			<geometry>
				<mesh filename="textured_objs/original-6.obj"/>
			</geometry>
		</collision>
	</link>
	<joint name="joint_0" type="prismatic">
		<origin xyz="0.0016310887362587234 -0.3833000928301903 0.5079890000000007"/>
		<axis xyz="0 0 -1"/>
		<child link="link_0"/>
		<parent link="link_3"/>
		<limit lower="0" upper="0.012"/>
	</joint>
	<link name="link_1">
		<visual name="button-9">
			<origin xyz="-0.0016310887362587234 0.3833000928301903 -0.5079890000000007"/>
			<geometry>
				<mesh filename="textured_objs/original-5.obj"/>
			</geometry>
		</visual>
		<collision>
			<origin xyz="-0.0016310887362587234 0.3833000928301903 -0.5079890000000007"/>
			<geometry>
				<mesh filename="textured_objs/original-5.obj"/>
			</geometry>
		</collision>
	</link>
	<joint name="joint_1" type="prismatic">
		<origin xyz="0.0016310887362587234 -0.3833000928301903 0.5079890000000007"/>
		<axis xyz="0 0 -1"/>
		<child link="link_1"/>
		<parent link="link_3"/>
		<limit lower="0" upper="0.012"/>
	</joint>
	<link name="link_2">
		<visual name="button-10">
			<origin xyz="-0.0016310887362587234 0.3833000928301903 -0.5079890000000007"/>
			<geometry>
				<mesh filename="textured_objs/original-8.obj"/>
			</geometry>
		</visual>
		<collision>
			<origin xyz="-0.0016310887362587234 0.3833000928301903 -0.5079890000000007"/>
			<geometry>
				<mesh filename="textured_objs/original-8.obj"/>
			</geometry>
		</collision>
	</link>
	<joint name="joint_2" type="prismatic">
		<origin xyz="0.0016310887362587234 -0.3833000928301903 0.5079890000000007"/>
		<axis xyz="0 0 -1"/>
		<child link="link_2"/>
		<parent link="link_3"/>
		<limit lower="0" upper="0.04"/>
	</joint>
	<link name="link_3">
		<visual name="frame-6">
			<origin xyz="0 0 0"/>
			<geometry>
				<mesh filename="textured_objs/original-9.obj"/>
			</geometry>
		</visual>
		<visual name="frame-6">
			<origin xyz="0 0 0"/>
			<geometry>
				<mesh filename="textured_objs/original-3.obj"/>
			</geometry>
		</visual>
		<visual name="screen-7">
			<origin xyz="0 0 0"/>
			<geometry>
				<mesh filename="textured_objs/original-1.obj"/>
			</geometry>
		</visual>
		<visual name="base_support-4">
			<origin xyz="0 0 0"/>
			<geometry>
				<mesh filename="textured_objs/original-4.obj"/>
			</geometry>
		</visual>
		<visual name="surface-5">
			<origin xyz="0 0 0"/>
			<geometry>
				<mesh filename="textured_objs/original-10.obj"/>
			</geometry>
		</visual>
		<collision>
			<origin xyz="0 0 0"/>
			<geometry>
				<mesh filename="textured_objs/original-9.obj"/>
			</geometry>
		</collision>
		<collision>
			<origin xyz="0 0 0"/>
			<geometry>
				<mesh filename="textured_objs/original-3.obj"/>
			</geometry>
		</collision>
		<collision>
			<origin xyz="0 0 0"/>
			<geometry>
				<mesh filename="textured_objs/original-1.obj"/>
			</geometry>
		</collision>
		<collision>
			<origin xyz="0 0 0"/>
			<geometry>
				<mesh filename="textured_objs/original-4.obj"/>
			</geometry>
		</collision>
		<collision>
			<origin xyz="0 0 0"/>
			<geometry>
				<mesh filename="textured_objs/original-10.obj"/>
			</geometry>
		</collision>
	</link>
	<joint name="joint_3" type="fixed">
		<origin rpy="1.570796326794897 0 -1.570796326794897" xyz="0 0 0"/>
		<child link="link_3"/>
		<parent link="base"/>
	</joint>
</robot>
