<?xml version="1.0" ?>
<robot name="partnet_492fec23e4c64c524a2f4691c3504a20">
	<link name="base"/>
	<link name="link_0">
		<visual name="blade-14">
			<origin xyz="-0.7828294736009814 -0.014026025454442426 0.08830536924611698"/>
			<geometry>
				<mesh filename="textured_objs/new-7.obj"/>
			</geometry>
		</visual>
		<visual name="handle-15">
			<origin xyz="-0.7828294736009814 -0.014026025454442426 0.08830536924611698"/>
			<geometry>
				<mesh filename="textured_objs/new-6.obj"/>
			</geometry>
		</visual>
		<visual name="handle-15">
			<origin xyz="-0.7828294736009814 -0.014026025454442426 0.08830536924611698"/>
			<geometry>
				<mesh filename="textured_objs/new-0.obj"/>
			</geometry>
		</visual>
		<collision>
			<origin xyz="-0.7828294736009814 -0.014026025454442426 0.08830536924611698"/>
			<geometry>
				<mesh filename="textured_objs/new-7.obj"/>
			</geometry>
		</collision>
		<collision>
			<origin xyz="-0.7828294736009814 -0.014026025454442426 0.08830536924611698"/>
			<geometry>
				<mesh filename="textured_objs/new-6.obj"/>
			</geometry>
		</collision>
		<collision>
			<origin xyz="-0.7828294736009814 -0.014026025454442426 0.08830536924611698"/>
			<geometry>
				<mesh filename="textured_objs/new-0.obj"/>
			</geometry>
		</collision>
	</link>
	<joint name="joint_0" type="revolute">
		<origin xyz="0.7828294736009814 0.014026025454442426 -0.08830536924611698"/>
		<axis xyz="0 -1 0"/>
		<child link="link_0"/>
		<parent link="link_1"/>
		<limit lower="-0.20734511513692636" upper="0.35185837720205726"/>
	</joint>
	<link name="link_1">
		<visual name="blade-12">
			<origin xyz="0 0 0"/>
			<geometry>
				<mesh filename="textured_objs/new-5.obj"/>
			</geometry>
		</visual>
		<visual name="handle-13">
			<origin xyz="0 0 0"/>
			<geometry>
				<mesh filename="textured_objs/new-4.obj"/>
			</geometry>
		</visual>
		<visual name="handle-13">
			<origin xyz="0 0 0"/>
			<geometry>
				<mesh filename="textured_objs/new-2.obj"/>
			</geometry>
		</visual>
		<collision>
			<origin xyz="0 0 0"/>
			<geometry>
				<mesh filename="textured_objs/new-5.obj"/>
			</geometry>
		</collision>
		<collision>
			<origin xyz="0 0 0"/>
			<geometry>
				<mesh filename="textured_objs/new-4.obj"/>
			</geometry>
		</collision>
		<collision>
			<origin xyz="0 0 0"/>
			<geometry>
				<mesh filename="textured_objs/new-2.obj"/>
			</geometry>
		</collision>
	</link>
	<joint name="joint_1" type="fixed">
		<origin rpy="1.570796326794897 0 -1.570796326794897" xyz="0 0 0"/>
		<child link="link_1"/>
		<parent link="base"/>
	</joint>
</robot>
