<?xml version="1.0" ?>
<robot name="partnet_34dc6c4e022b380cf91663a74ccd2338">
	<link name="base"/>
	<link name="link_0">
		<visual name="wheel-37">
			<origin xyz="-0.5168257392119482 0.7590451924053613 -0.13398070870341763"/>
			<geometry>
				<mesh filename="textured_objs/original-36.obj"/>
			</geometry>
		</visual>
		<visual name="wheel-37">
			<origin xyz="-0.5168257392119482 0.7590451924053613 -0.13398070870341763"/>
			<geometry>
				<mesh filename="textured_objs/original-37.obj"/>
			</geometry>
		</visual>
		<visual name="wheel-37">
			<origin xyz="-0.5168257392119482 0.7590451924053613 -0.13398070870341763"/>
			<geometry>
				<mesh filename="textured_objs/original-38.obj"/>
			</geometry>
		</visual>
		<collision>
			<origin xyz="-0.5168257392119482 0.7590451924053613 -0.13398070870341763"/>
			<geometry>
				<mesh filename="textured_objs/original-36.obj"/>
			</geometry>
		</collision>
		<collision>
			<origin xyz="-0.5168257392119482 0.7590451924053613 -0.13398070870341763"/>
			<geometry>
				<mesh filename="textured_objs/original-37.obj"/>
			</geometry>
		</collision>
		<collision>
			<origin xyz="-0.5168257392119482 0.7590451924053613 -0.13398070870341763"/>
			<geometry>
				<mesh filename="textured_objs/original-38.obj"/>
			</geometry>
		</collision>
	</link>
	<joint name="joint_0" type="continuous">
		<origin xyz="-0.018249785369767735 -0.7590451924053613 -0.06454791084797498"/>
		<axis xyz="-0.25778559697560666 -0.004979292778086137 0.9661893151113607"/>
		<child link="link_0"/>
		<parent link="link_12"/>
	</joint>
	<link name="link_1">
		<visual name="wheel-38">
			<origin xyz="-0.5168257392119482 0.7590451924053613 -0.13398070870341763"/>
			<geometry>
				<mesh filename="textured_objs/original-26.obj"/>
			</geometry>
		</visual>
		<visual name="wheel-38">
			<origin xyz="-0.5168257392119482 0.7590451924053613 -0.13398070870341763"/>
			<geometry>
				<mesh filename="textured_objs/original-49.obj"/>
			</geometry>
		</visual>
		<visual name="wheel-38">
			<origin xyz="-0.5168257392119482 0.7590451924053613 -0.13398070870341763"/>
			<geometry>
				<mesh filename="textured_objs/original-44.obj"/>
			</geometry>
		</visual>
		<collision>
			<origin xyz="-0.5168257392119482 0.7590451924053613 -0.13398070870341763"/>
			<geometry>
				<mesh filename="textured_objs/original-26.obj"/>
			</geometry>
		</collision>
		<collision>
			<origin xyz="-0.5168257392119482 0.7590451924053613 -0.13398070870341763"/>
			<geometry>
				<mesh filename="textured_objs/original-49.obj"/>
			</geometry>
		</collision>
		<collision>
			<origin xyz="-0.5168257392119482 0.7590451924053613 -0.13398070870341763"/>
			<geometry>
				<mesh filename="textured_objs/original-44.obj"/>
			</geometry>
		</collision>
	</link>
	<joint name="joint_1" type="continuous">
		<origin xyz="-0.018249785369767735 -0.7590451924053613 -0.06454791084797498"/>
		<axis xyz="-0.25778559697560666 -0.004979292778086137 0.9661893151113607"/>
		<child link="link_1"/>
		<parent link="link_12"/>
	</joint>
	<link name="link_2">
		<visual name="wheel-33">
			<origin xyz="-0.028673532125386748 0.7603782394812434 -0.5657908578579166"/>
			<geometry>
				<mesh filename="textured_objs/original-25.obj"/>
			</geometry>
		</visual>
		<visual name="wheel-33">
			<origin xyz="-0.028673532125386748 0.7603782394812434 -0.5657908578579166"/>
			<geometry>
				<mesh filename="textured_objs/original-34.obj"/>
			</geometry>
		</visual>
		<visual name="wheel-33">
			<origin xyz="-0.028673532125386748 0.7603782394812434 -0.5657908578579166"/>
			<geometry>
				<mesh filename="textured_objs/original-35.obj"/>
			</geometry>
		</visual>
		<collision>
			<origin xyz="-0.028673532125386748 0.7603782394812434 -0.5657908578579166"/>
			<geometry>
				<mesh filename="textured_objs/original-25.obj"/>
			</geometry>
		</collision>
		<collision>
			<origin xyz="-0.028673532125386748 0.7603782394812434 -0.5657908578579166"/>
			<geometry>
				<mesh filename="textured_objs/original-34.obj"/>
			</geometry>
		</collision>
		<collision>
			<origin xyz="-0.028673532125386748 0.7603782394812434 -0.5657908578579166"/>
			<geometry>
				<mesh filename="textured_objs/original-35.obj"/>
			</geometry>
		</collision>
	</link>
	<joint name="joint_2" type="continuous">
		<origin xyz="-0.011102120017844528 -0.7603782394812434 -0.03346113073937962"/>
		<axis xyz="-0.9985696765565794 0.002097258654447217 0.05342473741465594"/>
		<child link="link_2"/>
		<parent link="link_13"/>
	</joint>
	<link name="link_3">
		<visual name="wheel-34">
			<origin xyz="-0.028673532125386748 0.7603782394812434 -0.5657908578579166"/>
			<geometry>
				<mesh filename="textured_objs/original-31.obj"/>
			</geometry>
		</visual>
		<visual name="wheel-34">
			<origin xyz="-0.028673532125386748 0.7603782394812434 -0.5657908578579166"/>
			<geometry>
				<mesh filename="textured_objs/original-23.obj"/>
			</geometry>
		</visual>
		<visual name="wheel-34">
			<origin xyz="-0.028673532125386748 0.7603782394812434 -0.5657908578579166"/>
			<geometry>
				<mesh filename="textured_objs/original-33.obj"/>
			</geometry>
		</visual>
		<collision>
			<origin xyz="-0.028673532125386748 0.7603782394812434 -0.5657908578579166"/>
			<geometry>
				<mesh filename="textured_objs/original-31.obj"/>
			</geometry>
		</collision>
		<collision>
			<origin xyz="-0.028673532125386748 0.7603782394812434 -0.5657908578579166"/>
			<geometry>
				<mesh filename="textured_objs/original-23.obj"/>
			</geometry>
		</collision>
		<collision>
			<origin xyz="-0.028673532125386748 0.7603782394812434 -0.5657908578579166"/>
			<geometry>
				<mesh filename="textured_objs/original-33.obj"/>
			</geometry>
		</collision>
	</link>
	<joint name="joint_3" type="continuous">
		<origin xyz="-0.011102120017844528 -0.7603782394812434 -0.03346113073937962"/>
		<axis xyz="-0.9985696765565794 0.002097258654447217 0.05342473741465594"/>
		<child link="link_3"/>
		<parent link="link_13"/>
	</joint>
	<link name="link_4">
		<visual name="wheel-29">
			<origin xyz="0.4852918711986985 0.7569110656227171 -0.18178004081092514"/>
			<geometry>
				<mesh filename="textured_objs/original-53.obj"/>
			</geometry>
		</visual>
		<visual name="wheel-29">
			<origin xyz="0.4852918711986985 0.7569110656227171 -0.18178004081092514"/>
			<geometry>
				<mesh filename="textured_objs/original-56.obj"/>
			</geometry>
		</visual>
		<visual name="wheel-29">
			<origin xyz="0.4852918711986985 0.7569110656227171 -0.18178004081092514"/>
			<geometry>
				<mesh filename="textured_objs/original-52.obj"/>
			</geometry>
		</visual>
		<collision>
			<origin xyz="0.4852918711986985 0.7569110656227171 -0.18178004081092514"/>
			<geometry>
				<mesh filename="textured_objs/original-53.obj"/>
			</geometry>
		</collision>
		<collision>
			<origin xyz="0.4852918711986985 0.7569110656227171 -0.18178004081092514"/>
			<geometry>
				<mesh filename="textured_objs/original-56.obj"/>
			</geometry>
		</collision>
		<collision>
			<origin xyz="0.4852918711986985 0.7569110656227171 -0.18178004081092514"/>
			<geometry>
				<mesh filename="textured_objs/original-52.obj"/>
			</geometry>
		</collision>
	</link>
	<joint name="joint_4" type="continuous">
		<origin xyz="0.009244917389541696 -0.7569110656227171 -0.07012190432127441"/>
		<axis xyz="0.35936094811647146 -0.006291248278804359 0.9331774371275409"/>
		<child link="link_4"/>
		<parent link="link_14"/>
	</joint>
	<link name="link_5">
		<visual name="wheel-30">
			<origin xyz="0.4852918711986985 0.7569110656227171 -0.18178004081092514"/>
			<geometry>
				<mesh filename="textured_objs/original-43.obj"/>
			</geometry>
		</visual>
		<visual name="wheel-30">
			<origin xyz="0.4852918711986985 0.7569110656227171 -0.18178004081092514"/>
			<geometry>
				<mesh filename="textured_objs/original-41.obj"/>
			</geometry>
		</visual>
		<visual name="wheel-30">
			<origin xyz="0.4852918711986985 0.7569110656227171 -0.18178004081092514"/>
			<geometry>
				<mesh filename="textured_objs/original-42.obj"/>
			</geometry>
		</visual>
		<collision>
			<origin xyz="0.4852918711986985 0.7569110656227171 -0.18178004081092514"/>
			<geometry>
				<mesh filename="textured_objs/original-43.obj"/>
			</geometry>
		</collision>
		<collision>
			<origin xyz="0.4852918711986985 0.7569110656227171 -0.18178004081092514"/>
			<geometry>
				<mesh filename="textured_objs/original-41.obj"/>
			</geometry>
		</collision>
		<collision>
			<origin xyz="0.4852918711986985 0.7569110656227171 -0.18178004081092514"/>
			<geometry>
				<mesh filename="textured_objs/original-42.obj"/>
			</geometry>
		</collision>
	</link>
	<joint name="joint_5" type="continuous">
		<origin xyz="0.009244917389541696 -0.7569110656227171 -0.07012190432127441"/>
		<axis xyz="0.35936094811647146 -0.006291248278804359 0.9331774371275409"/>
		<child link="link_5"/>
		<parent link="link_14"/>
	</joint>
	<link name="link_6">
		<visual name="wheel-25">
			<origin xyz="0.2861112838270263 0.7542747014476247 0.3546861544212182"/>
			<geometry>
				<mesh filename="textured_objs/original-27.obj"/>
			</geometry>
		</visual>
		<visual name="wheel-25">
			<origin xyz="0.2861112838270263 0.7542747014476247 0.3546861544212182"/>
			<geometry>
				<mesh filename="textured_objs/original-51.obj"/>
			</geometry>
		</visual>
		<visual name="wheel-25">
			<origin xyz="0.2861112838270263 0.7542747014476247 0.3546861544212182"/>
			<geometry>
				<mesh filename="textured_objs/original-55.obj"/>
			</geometry>
		</visual>
		<collision>
			<origin xyz="0.2861112838270263 0.7542747014476247 0.3546861544212182"/>
			<geometry>
				<mesh filename="textured_objs/original-27.obj"/>
			</geometry>
		</collision>
		<collision>
			<origin xyz="0.2861112838270263 0.7542747014476247 0.3546861544212182"/>
			<geometry>
				<mesh filename="textured_objs/original-51.obj"/>
			</geometry>
		</collision>
		<collision>
			<origin xyz="0.2861112838270263 0.7542747014476247 0.3546861544212182"/>
			<geometry>
				<mesh filename="textured_objs/original-55.obj"/>
			</geometry>
		</collision>
	</link>
	<joint name="joint_6" type="continuous">
		<origin xyz="0.043198878504279004 -0.7542747014476247 0.008670027738291564"/>
		<axis xyz="-0.7764609821235829 -0.001797429372505803 0.6301627666621791"/>
		<child link="link_6"/>
		<parent link="link_15"/>
	</joint>
	<link name="link_7">
		<visual name="wheel-26">
			<origin xyz="0.2861112838270263 0.7542747014476247 0.3546861544212182"/>
			<geometry>
				<mesh filename="textured_objs/original-48.obj"/>
			</geometry>
		</visual>
		<visual name="wheel-26">
			<origin xyz="0.2861112838270263 0.7542747014476247 0.3546861544212182"/>
			<geometry>
				<mesh filename="textured_objs/original-54.obj"/>
			</geometry>
		</visual>
		<visual name="wheel-26">
			<origin xyz="0.2861112838270263 0.7542747014476247 0.3546861544212182"/>
			<geometry>
				<mesh filename="textured_objs/original-50.obj"/>
			</geometry>
		</visual>
		<collision>
			<origin xyz="0.2861112838270263 0.7542747014476247 0.3546861544212182"/>
			<geometry>
				<mesh filename="textured_objs/original-48.obj"/>
			</geometry>
		</collision>
		<collision>
			<origin xyz="0.2861112838270263 0.7542747014476247 0.3546861544212182"/>
			<geometry>
				<mesh filename="textured_objs/original-54.obj"/>
			</geometry>
		</collision>
		<collision>
			<origin xyz="0.2861112838270263 0.7542747014476247 0.3546861544212182"/>
			<geometry>
				<mesh filename="textured_objs/original-50.obj"/>
			</geometry>
		</collision>
	</link>
	<joint name="joint_7" type="continuous">
		<origin xyz="0.043198878504279004 -0.7542747014476247 0.008670027738291564"/>
		<axis xyz="-0.7764609821235829 -0.001797429372505803 0.6301627666621791"/>
		<child link="link_7"/>
		<parent link="link_15"/>
	</joint>
	<link name="link_8">
		<visual name="wheel-20">
			<origin xyz="-0.2497708133999873 0.7553415202031197 0.39272606779490293"/>
			<geometry>
				<mesh filename="textured_objs/original-45.obj"/>
			</geometry>
		</visual>
		<visual name="wheel-20">
			<origin xyz="-0.2497708133999873 0.7553415202031197 0.39272606779490293"/>
			<geometry>
				<mesh filename="textured_objs/original-46.obj"/>
			</geometry>
		</visual>
		<visual name="wheel-20">
			<origin xyz="-0.2497708133999873 0.7553415202031197 0.39272606779490293"/>
			<geometry>
				<mesh filename="textured_objs/original-47.obj"/>
			</geometry>
		</visual>
		<collision>
			<origin xyz="-0.2497708133999873 0.7553415202031197 0.39272606779490293"/>
			<geometry>
				<mesh filename="textured_objs/original-45.obj"/>
			</geometry>
		</collision>
		<collision>
			<origin xyz="-0.2497708133999873 0.7553415202031197 0.39272606779490293"/>
			<geometry>
				<mesh filename="textured_objs/original-46.obj"/>
			</geometry>
		</collision>
		<collision>
			<origin xyz="-0.2497708133999873 0.7553415202031197 0.39272606779490293"/>
			<geometry>
				<mesh filename="textured_objs/original-47.obj"/>
			</geometry>
		</collision>
	</link>
	<joint name="joint_8" type="continuous">
		<origin xyz="-0.05708981281814707 -0.7553415202031197 0.0035298088718096476"/>
		<axis xyz="0.8392482734267239 -0.005182759840040722 0.5437237115950557"/>
		<child link="link_8"/>
		<parent link="link_16"/>
	</joint>
	<link name="link_9">
		<visual name="wheel-21">
			<origin xyz="-0.2497708133999873 0.7553415202031197 0.39272606779490293"/>
			<geometry>
				<mesh filename="textured_objs/original-24.obj"/>
			</geometry>
		</visual>
		<visual name="wheel-21">
			<origin xyz="-0.2497708133999873 0.7553415202031197 0.39272606779490293"/>
			<geometry>
				<mesh filename="textured_objs/original-39.obj"/>
			</geometry>
		</visual>
		<visual name="wheel-21">
			<origin xyz="-0.2497708133999873 0.7553415202031197 0.39272606779490293"/>
			<geometry>
				<mesh filename="textured_objs/original-40.obj"/>
			</geometry>
		</visual>
		<collision>
			<origin xyz="-0.2497708133999873 0.7553415202031197 0.39272606779490293"/>
			<geometry>
				<mesh filename="textured_objs/original-24.obj"/>
			</geometry>
		</collision>
		<collision>
			<origin xyz="-0.2497708133999873 0.7553415202031197 0.39272606779490293"/>
			<geometry>
				<mesh filename="textured_objs/original-39.obj"/>
			</geometry>
		</collision>
		<collision>
			<origin xyz="-0.2497708133999873 0.7553415202031197 0.39272606779490293"/>
			<geometry>
				<mesh filename="textured_objs/original-40.obj"/>
			</geometry>
		</collision>
	</link>
	<joint name="joint_9" type="continuous">
		<origin xyz="-0.05708981281814707 -0.7553415202031197 0.0035298088718096476"/>
		<axis xyz="0.8392482734267239 -0.005182759840040722 0.5437237115950557"/>
		<child link="link_9"/>
		<parent link="link_16"/>
	</joint>
	<link name="link_10">
		<visual name="back_soft_surface-46">
			<origin xyz="-0.013638851921841371 0 -0.05874068116031517"/>
			<geometry>
				<mesh filename="textured_objs/original-12.obj"/>
			</geometry>
		</visual>
		<visual name="back_soft_surface-46">
			<origin xyz="-0.013638851921841371 0 -0.05874068116031517"/>
			<geometry>
				<mesh filename="textured_objs/original-21.obj"/>
			</geometry>
		</visual>
		<visual name="back_soft_surface-46">
			<origin xyz="-0.013638851921841371 0 -0.05874068116031517"/>
			<geometry>
				<mesh filename="textured_objs/original-11.obj"/>
			</geometry>
		</visual>
		<visual name="back_support-44">
			<origin xyz="-0.013638851921841371 0 -0.05874068116031517"/>
			<geometry>
				<mesh filename="textured_objs/original-22.obj"/>
			</geometry>
		</visual>
		<visual name="back_support-44">
			<origin xyz="-0.013638851921841371 0 -0.05874068116031517"/>
			<geometry>
				<mesh filename="textured_objs/original-5.obj"/>
			</geometry>
		</visual>
		<visual name="back_support-44">
			<origin xyz="-0.013638851921841371 0 -0.05874068116031517"/>
			<geometry>
				<mesh filename="textured_objs/original-7.obj"/>
			</geometry>
		</visual>
		<visual name="back_support-44">
			<origin xyz="-0.013638851921841371 0 -0.05874068116031517"/>
			<geometry>
				<mesh filename="textured_objs/original-8.obj"/>
			</geometry>
		</visual>
		<visual name="back_support-44">
			<origin xyz="-0.013638851921841371 0 -0.05874068116031517"/>
			<geometry>
				<mesh filename="textured_objs/original-6.obj"/>
			</geometry>
		</visual>
		<visual name="back_support-44">
			<origin xyz="-0.013638851921841371 0 -0.05874068116031517"/>
			<geometry>
				<mesh filename="textured_objs/original-10.obj"/>
			</geometry>
		</visual>
		<visual name="back_support-44">
			<origin xyz="-0.013638851921841371 0 -0.05874068116031517"/>
			<geometry>
				<mesh filename="textured_objs/original-9.obj"/>
			</geometry>
		</visual>
		<visual name="back_connector-45">
			<origin xyz="-0.013638851921841371 0 -0.05874068116031517"/>
			<geometry>
				<mesh filename="textured_objs/original-20.obj"/>
			</geometry>
		</visual>
		<visual name="seat_soft_surface-42">
			<origin xyz="-0.013638851921841371 0 -0.05874068116031517"/>
			<geometry>
				<mesh filename="textured_objs/original-2.obj"/>
			</geometry>
		</visual>
		<visual name="seat_soft_surface-42">
			<origin xyz="-0.013638851921841371 0 -0.05874068116031517"/>
			<geometry>
				<mesh filename="textured_objs/original-3.obj"/>
			</geometry>
		</visual>
		<visual name="seat_support-40">
			<origin xyz="-0.013638851921841371 0 -0.05874068116031517"/>
			<geometry>
				<mesh filename="textured_objs/original-18.obj"/>
			</geometry>
		</visual>
		<visual name="seat_support-40">
			<origin xyz="-0.013638851921841371 0 -0.05874068116031517"/>
			<geometry>
				<mesh filename="textured_objs/original-17.obj"/>
			</geometry>
		</visual>
		<visual name="central_support-7">
			<origin xyz="-0.013638851921841371 0 -0.05874068116031517"/>
			<geometry>
				<mesh filename="textured_objs/original-64.obj"/>
			</geometry>
		</visual>
		<visual name="seat_connector-41">
			<origin xyz="-0.013638851921841371 0 -0.05874068116031517"/>
			<geometry>
				<mesh filename="textured_objs/original-14.obj"/>
			</geometry>
		</visual>
		<visual name="seat_connector-41">
			<origin xyz="-0.013638851921841371 0 -0.05874068116031517"/>
			<geometry>
				<mesh filename="textured_objs/original-15.obj"/>
			</geometry>
		</visual>
		<collision>
			<origin xyz="-0.013638851921841371 0 -0.05874068116031517"/>
			<geometry>
				<mesh filename="textured_objs/original-12.obj"/>
			</geometry>
		</collision>
		<collision>
			<origin xyz="-0.013638851921841371 0 -0.05874068116031517"/>
			<geometry>
				<mesh filename="textured_objs/original-21.obj"/>
			</geometry>
		</collision>
		<collision>
			<origin xyz="-0.013638851921841371 0 -0.05874068116031517"/>
			<geometry>
				<mesh filename="textured_objs/original-11.obj"/>
			</geometry>
		</collision>
		<collision>
			<origin xyz="-0.013638851921841371 0 -0.05874068116031517"/>
			<geometry>
				<mesh filename="textured_objs/original-22.obj"/>
			</geometry>
		</collision>
		<collision>
			<origin xyz="-0.013638851921841371 0 -0.05874068116031517"/>
			<geometry>
				<mesh filename="textured_objs/original-5.obj"/>
			</geometry>
		</collision>
		<collision>
			<origin xyz="-0.013638851921841371 0 -0.05874068116031517"/>
			<geometry>
				<mesh filename="textured_objs/original-7.obj"/>
			</geometry>
		</collision>
		<collision>
			<origin xyz="-0.013638851921841371 0 -0.05874068116031517"/>
			<geometry>
				<mesh filename="textured_objs/original-8.obj"/>
			</geometry>
		</collision>
		<collision>
			<origin xyz="-0.013638851921841371 0 -0.05874068116031517"/>
			<geometry>
				<mesh filename="textured_objs/original-6.obj"/>
			</geometry>
		</collision>
		<collision>
			<origin xyz="-0.013638851921841371 0 -0.05874068116031517"/>
			<geometry>
				<mesh filename="textured_objs/original-10.obj"/>
			</geometry>
		</collision>
		<collision>
			<origin xyz="-0.013638851921841371 0 -0.05874068116031517"/>
			<geometry>
				<mesh filename="textured_objs/original-9.obj"/>
			</geometry>
		</collision>
		<collision>
			<origin xyz="-0.013638851921841371 0 -0.05874068116031517"/>
			<geometry>
				<mesh filename="textured_objs/original-20.obj"/>
			</geometry>
		</collision>
		<collision>
			<origin xyz="-0.013638851921841371 0 -0.05874068116031517"/>
			<geometry>
				<mesh filename="textured_objs/original-2.obj"/>
			</geometry>
		</collision>
		<collision>
			<origin xyz="-0.013638851921841371 0 -0.05874068116031517"/>
			<geometry>
				<mesh filename="textured_objs/original-3.obj"/>
			</geometry>
		</collision>
		<collision>
			<origin xyz="-0.013638851921841371 0 -0.05874068116031517"/>
			<geometry>
				<mesh filename="textured_objs/original-18.obj"/>
			</geometry>
		</collision>
		<collision>
			<origin xyz="-0.013638851921841371 0 -0.05874068116031517"/>
			<geometry>
				<mesh filename="textured_objs/original-17.obj"/>
			</geometry>
		</collision>
		<collision>
			<origin xyz="-0.013638851921841371 0 -0.05874068116031517"/>
			<geometry>
				<mesh filename="textured_objs/original-64.obj"/>
			</geometry>
		</collision>
		<collision>
			<origin xyz="-0.013638851921841371 0 -0.05874068116031517"/>
			<geometry>
				<mesh filename="textured_objs/original-14.obj"/>
			</geometry>
		</collision>
		<collision>
			<origin xyz="-0.013638851921841371 0 -0.05874068116031517"/>
			<geometry>
				<mesh filename="textured_objs/original-15.obj"/>
			</geometry>
		</collision>
	</link>
	<joint name="joint_10" type="continuous">
		<origin xyz="0.0 0 0.0"/>
		<axis xyz="0 1 0"/>
		<child link="link_10"/>
		<parent link="link_10_helper"/>
	</joint>
	<link name="link_11">
		<visual name="central_support-5">
			<origin xyz="0 0 0"/>
			<geometry>
				<mesh filename="textured_objs/original-63.obj"/>
			</geometry>
		</visual>
		<visual name="central_support-6">
			<origin xyz="0 0 0"/>
			<geometry>
				<mesh filename="textured_objs/original-65.obj"/>
			</geometry>
		</visual>
		<visual name="central_support-6">
			<origin xyz="0 0 0"/>
			<geometry>
				<mesh filename="textured_objs/original-29.obj"/>
			</geometry>
		</visual>
		<visual name="central_support-6">
			<origin xyz="0 0 0"/>
			<geometry>
				<mesh filename="textured_objs/original-66.obj"/>
			</geometry>
		</visual>
		<visual name="leg-9">
			<origin xyz="0 0 0"/>
			<geometry>
				<mesh filename="textured_objs/new-4.obj"/>
			</geometry>
		</visual>
		<visual name="leg-10">
			<origin xyz="0 0 0"/>
			<geometry>
				<mesh filename="textured_objs/new-3.obj"/>
			</geometry>
		</visual>
		<visual name="leg-11">
			<origin xyz="0 0 0"/>
			<geometry>
				<mesh filename="textured_objs/new-2.obj"/>
			</geometry>
		</visual>
		<visual name="leg-12">
			<origin xyz="0 0 0"/>
			<geometry>
				<mesh filename="textured_objs/new-1.obj"/>
			</geometry>
		</visual>
		<visual name="leg-13">
			<origin xyz="0 0 0"/>
			<geometry>
				<mesh filename="textured_objs/new-0.obj"/>
			</geometry>
		</visual>
		<collision>
			<origin xyz="0 0 0"/>
			<geometry>
				<mesh filename="textured_objs/original-63.obj"/>
			</geometry>
		</collision>
		<collision>
			<origin xyz="0 0 0"/>
			<geometry>
				<mesh filename="textured_objs/original-65.obj"/>
			</geometry>
		</collision>
		<collision>
			<origin xyz="0 0 0"/>
			<geometry>
				<mesh filename="textured_objs/original-29.obj"/>
			</geometry>
		</collision>
		<collision>
			<origin xyz="0 0 0"/>
			<geometry>
				<mesh filename="textured_objs/original-66.obj"/>
			</geometry>
		</collision>
		<collision>
			<origin xyz="0 0 0"/>
			<geometry>
				<mesh filename="textured_objs/new-4.obj"/>
			</geometry>
		</collision>
		<collision>
			<origin xyz="0 0 0"/>
			<geometry>
				<mesh filename="textured_objs/new-3.obj"/>
			</geometry>
		</collision>
		<collision>
			<origin xyz="0 0 0"/>
			<geometry>
				<mesh filename="textured_objs/new-2.obj"/>
			</geometry>
		</collision>
		<collision>
			<origin xyz="0 0 0"/>
			<geometry>
				<mesh filename="textured_objs/new-1.obj"/>
			</geometry>
		</collision>
		<collision>
			<origin xyz="0 0 0"/>
			<geometry>
				<mesh filename="textured_objs/new-0.obj"/>
			</geometry>
		</collision>
	</link>
	<joint name="joint_11" type="fixed">
		<origin rpy="1.570796326794897 0 -1.570796326794897" xyz="0 0 0"/>
		<child link="link_11"/>
		<parent link="base"/>
	</joint>
	<link name="link_12">
		<visual name="caster_yoke-35">
			<origin xyz="-0.5350755245817159 0 -0.19852861955139262"/>
			<geometry>
				<mesh filename="textured_objs/original-57.obj"/>
			</geometry>
		</visual>
		<visual name="caster_stem-36">
			<origin xyz="-0.5350755245817159 0 -0.19852861955139262"/>
			<geometry>
				<mesh filename="textured_objs/original-67.obj"/>
			</geometry>
		</visual>
		<collision>
			<origin xyz="-0.5350755245817159 0 -0.19852861955139262"/>
			<geometry>
				<mesh filename="textured_objs/original-57.obj"/>
			</geometry>
		</collision>
		<collision>
			<origin xyz="-0.5350755245817159 0 -0.19852861955139262"/>
			<geometry>
				<mesh filename="textured_objs/original-67.obj"/>
			</geometry>
		</collision>
	</link>
	<joint name="joint_12" type="continuous">
		<origin xyz="0.5350755245817159 0 0.19852861955139262"/>
		<axis xyz="0 1 0"/>
		<child link="link_12"/>
		<parent link="link_11"/>
	</joint>
	<link name="link_13">
		<visual name="caster_yoke-31">
			<origin xyz="-0.039775652143231276 0 -0.5992519885972962"/>
			<geometry>
				<mesh filename="textured_objs/original-32.obj"/>
			</geometry>
		</visual>
		<visual name="caster_stem-32">
			<origin xyz="-0.039775652143231276 0 -0.5992519885972962"/>
			<geometry>
				<mesh filename="textured_objs/original-59.obj"/>
			</geometry>
		</visual>
		<collision>
			<origin xyz="-0.039775652143231276 0 -0.5992519885972962"/>
			<geometry>
				<mesh filename="textured_objs/original-32.obj"/>
			</geometry>
		</collision>
		<collision>
			<origin xyz="-0.039775652143231276 0 -0.5992519885972962"/>
			<geometry>
				<mesh filename="textured_objs/original-59.obj"/>
			</geometry>
		</collision>
	</link>
	<joint name="joint_13" type="continuous">
		<origin xyz="0.039775652143231276 0 0.5992519885972962"/>
		<axis xyz="0 1 0"/>
		<child link="link_13"/>
		<parent link="link_11"/>
	</joint>
	<link name="link_14">
		<visual name="caster_yoke-27">
			<origin xyz="0.4945367885882402 0 -0.25190194513219955"/>
			<geometry>
				<mesh filename="textured_objs/original-71.obj"/>
			</geometry>
		</visual>
		<visual name="caster_stem-28">
			<origin xyz="0.4945367885882402 0 -0.25190194513219955"/>
			<geometry>
				<mesh filename="textured_objs/original-68.obj"/>
			</geometry>
		</visual>
		<collision>
			<origin xyz="0.4945367885882402 0 -0.25190194513219955"/>
			<geometry>
				<mesh filename="textured_objs/original-71.obj"/>
			</geometry>
		</collision>
		<collision>
			<origin xyz="0.4945367885882402 0 -0.25190194513219955"/>
			<geometry>
				<mesh filename="textured_objs/original-68.obj"/>
			</geometry>
		</collision>
	</link>
	<joint name="joint_14" type="continuous">
		<origin xyz="-0.4945367885882402 0 0.25190194513219955"/>
		<axis xyz="0 1 0"/>
		<child link="link_14"/>
		<parent link="link_11"/>
	</joint>
	<link name="link_15">
		<visual name="caster_yoke-23">
			<origin xyz="0.3293101623313053 0 0.36335618215950977"/>
			<geometry>
				<mesh filename="textured_objs/original-70.obj"/>
			</geometry>
		</visual>
		<visual name="caster_stem-24">
			<origin xyz="0.3293101623313053 0 0.36335618215950977"/>
			<geometry>
				<mesh filename="textured_objs/original-69.obj"/>
			</geometry>
		</visual>
		<collision>
			<origin xyz="0.3293101623313053 0 0.36335618215950977"/>
			<geometry>
				<mesh filename="textured_objs/original-70.obj"/>
			</geometry>
		</collision>
		<collision>
			<origin xyz="0.3293101623313053 0 0.36335618215950977"/>
			<geometry>
				<mesh filename="textured_objs/original-69.obj"/>
			</geometry>
		</collision>
	</link>
	<joint name="joint_15" type="continuous">
		<origin xyz="-0.3293101623313053 0 -0.36335618215950977"/>
		<axis xyz="0 1 0"/>
		<child link="link_15"/>
		<parent link="link_11"/>
	</joint>
	<link name="link_16">
		<visual name="caster_stem-19">
			<origin xyz="-0.30686062621813437 0 0.3962558766667126"/>
			<geometry>
				<mesh filename="textured_objs/original-58.obj"/>
			</geometry>
		</visual>
		<visual name="caster_yoke-22">
			<origin xyz="-0.30686062621813437 0 0.3962558766667126"/>
			<geometry>
				<mesh filename="textured_objs/original-30.obj"/>
			</geometry>
		</visual>
		<collision>
			<origin xyz="-0.30686062621813437 0 0.3962558766667126"/>
			<geometry>
				<mesh filename="textured_objs/original-58.obj"/>
			</geometry>
		</collision>
		<collision>
			<origin xyz="-0.30686062621813437 0 0.3962558766667126"/>
			<geometry>
				<mesh filename="textured_objs/original-30.obj"/>
			</geometry>
		</collision>
	</link>
	<joint name="joint_16" type="continuous">
		<origin xyz="0.30686062621813437 0 -0.3962558766667126"/>
		<axis xyz="0 1 0"/>
		<child link="link_16"/>
		<parent link="link_11"/>
	</joint>
	<link name="link_10_helper"/>
	<joint name="joint_17" type="prismatic">
		<origin xyz="0.013638851921841371 0 0.05874068116031517"/>
		<axis xyz="0 -1 0"/>
		<child link="link_10_helper"/>
		<parent link="link_11"/>
		<limit lower="0" upper="0.1"/>
	</joint>
</robot>
