<?xml version="1.0" ?>
<robot name="partnet_2491245e09a41b59a4fb4a070051861">
	<link name="base"/>
	<link name="link_0">
		<visual name="outside_frame-1">
			<origin xyz="0 0 0"/>
			<geometry>
				<mesh filename="textured_objs/original-9.obj"/>
			</geometry>
		</visual>
		<collision>
			<origin xyz="0 0 0"/>
			<geometry>
				<mesh filename="textured_objs/original-9.obj"/>
			</geometry>
		</collision>
	</link>
	<joint name="joint_0" type="fixed">
		<origin rpy="1.570796326794897 0 -1.570796326794897" xyz="0 0 0"/>
		<child link="link_0"/>
		<parent link="base"/>
	</joint>
	<link name="link_1">
		<visual name="surface_board-8">
			<origin xyz="0.3269113278144757 0 -0.07601752325334876"/>
			<geometry>
				<mesh filename="textured_objs/original-8.obj"/>
			</geometry>
		</visual>
		<collision>
			<origin xyz="0.3269113278144757 0 -0.07601752325334876"/>
			<geometry>
				<mesh filename="textured_objs/original-8.obj"/>
			</geometry>
		</collision>
	</link>
	<joint name="joint_1" type="revolute">
		<origin xyz="-0.3269113278144757 0 0.07601752325334876"/>
		<axis xyz="0 1 0"/>
		<child link="link_1"/>
		<parent link="link_0"/>
		<limit lower="-0.4398229715025708" upper="1.1938052083641215"/>
	</joint>
	<link name="link_2">
		<visual name="movable_part-17">
			<origin xyz="-0.23196082660131712 0.05521008624747266 0.18896007730082717"/>
			<geometry>
				<mesh filename="textured_objs/original-4.obj"/>
			</geometry>
		</visual>
		<visual name="movable_part-17">
			<origin xyz="-0.23196082660131712 0.05521008624747266 0.18896007730082717"/>
			<geometry>
				<mesh filename="textured_objs/original-3.obj"/>
			</geometry>
		</visual>
		<visual name="movable_part-16">
			<origin xyz="-0.23196082660131712 0.05521008624747266 0.18896007730082717"/>
			<geometry>
				<mesh filename="textured_objs/original-6.obj"/>
			</geometry>
		</visual>
		<visual name="movable_part-16">
			<origin xyz="-0.23196082660131712 0.05521008624747266 0.18896007730082717"/>
			<geometry>
				<mesh filename="textured_objs/original-7.obj"/>
			</geometry>
		</visual>
		<collision>
			<origin xyz="-0.23196082660131712 0.05521008624747266 0.18896007730082717"/>
			<geometry>
				<mesh filename="textured_objs/original-4.obj"/>
			</geometry>
		</collision>
		<collision>
			<origin xyz="-0.23196082660131712 0.05521008624747266 0.18896007730082717"/>
			<geometry>
				<mesh filename="textured_objs/original-3.obj"/>
			</geometry>
		</collision>
		<collision>
			<origin xyz="-0.23196082660131712 0.05521008624747266 0.18896007730082717"/>
			<geometry>
				<mesh filename="textured_objs/original-6.obj"/>
			</geometry>
		</collision>
		<collision>
			<origin xyz="-0.23196082660131712 0.05521008624747266 0.18896007730082717"/>
			<geometry>
				<mesh filename="textured_objs/original-7.obj"/>
			</geometry>
		</collision>
	</link>
	<joint name="joint_2" type="revolute">
		<origin xyz="0.5588721544157929 -0.05521008624747266 -0.26497760055417596"/>
		<axis xyz="-0.4115148061598102 0 -0.9114030745566166"/>
		<child link="link_2"/>
		<parent link="link_1"/>
		<limit lower="-0.7853981633974483" upper="0.7853981633974483"/>
	</joint>
</robot>
