<?xml version="1.0" ?>
<robot name="partnet_134c9a46684ab57271f27bd49a6cd214">
	<link name="base"/>
	<link name="link_0">
		<visual name="frame-7">
			<origin xyz="-0.35202997736265695 -0.19371000489114376 0.0303852493656368"/>
			<geometry>
				<mesh filename="textured_objs/new-4.obj"/>
			</geometry>
		</visual>
		<visual name="frame-7">
			<origin xyz="-0.35202997736265695 -0.19371000489114376 0.0303852493656368"/>
			<geometry>
				<mesh filename="textured_objs/original-2.obj"/>
			</geometry>
		</visual>
		<visual name="frame-7">
			<origin xyz="-0.35202997736265695 -0.19371000489114376 0.0303852493656368"/>
			<geometry>
				<mesh filename="textured_objs/original-3.obj"/>
			</geometry>
		</visual>
		<visual name="frame-7">
			<origin xyz="-0.35202997736265695 -0.19371000489114376 0.0303852493656368"/>
			<geometry>
				<mesh filename="textured_objs/original-4.obj"/>
			</geometry>
		</visual>
		<visual name="frame-7">
			<origin xyz="-0.35202997736265695 -0.19371000489114376 0.0303852493656368"/>
			<geometry>
				<mesh filename="textured_objs/original-5.obj"/>
			</geometry>
		</visual>
		<visual name="frame-7">
			<origin xyz="-0.35202997736265695 -0.19371000489114376 0.0303852493656368"/>
			<geometry>
				<mesh filename="textured_objs/original-6.obj"/>
			</geometry>
		</visual>
		<visual name="frame-7">
			<origin xyz="-0.35202997736265695 -0.19371000489114376 0.0303852493656368"/>
			<geometry>
				<mesh filename="textured_objs/original-7.obj"/>
			</geometry>
		</visual>
		<visual name="frame-7">
			<origin xyz="-0.35202997736265695 -0.19371000489114376 0.0303852493656368"/>
			<geometry>
				<mesh filename="textured_objs/original-8.obj"/>
			</geometry>
		</visual>
		<visual name="frame-7">
			<origin xyz="-0.35202997736265695 -0.19371000489114376 0.0303852493656368"/>
			<geometry>
				<mesh filename="textured_objs/original-9.obj"/>
			</geometry>
		</visual>
		<visual name="screen-8">
			<origin xyz="-0.35202997736265695 -0.19371000489114376 0.0303852493656368"/>
			<geometry>
				<mesh filename="textured_objs/new-3.obj"/>
			</geometry>
		</visual>
		<collision>
			<origin xyz="-0.35202997736265695 -0.19371000489114376 0.0303852493656368"/>
			<geometry>
				<mesh filename="textured_objs/new-4.obj"/>
			</geometry>
		</collision>
		<collision>
			<origin xyz="-0.35202997736265695 -0.19371000489114376 0.0303852493656368"/>
			<geometry>
				<mesh filename="textured_objs/original-2.obj"/>
			</geometry>
		</collision>
		<collision>
			<origin xyz="-0.35202997736265695 -0.19371000489114376 0.0303852493656368"/>
			<geometry>
				<mesh filename="textured_objs/original-3.obj"/>
			</geometry>
		</collision>
		<collision>
			<origin xyz="-0.35202997736265695 -0.19371000489114376 0.0303852493656368"/>
			<geometry>
				<mesh filename="textured_objs/original-4.obj"/>
			</geometry>
		</collision>
		<collision>
			<origin xyz="-0.35202997736265695 -0.19371000489114376 0.0303852493656368"/>
			<geometry>
				<mesh filename="textured_objs/original-5.obj"/>
			</geometry>
		</collision>
		<collision>
			<origin xyz="-0.35202997736265695 -0.19371000489114376 0.0303852493656368"/>
			<geometry>
				<mesh filename="textured_objs/original-6.obj"/>
			</geometry>
		</collision>
		<collision>
			<origin xyz="-0.35202997736265695 -0.19371000489114376 0.0303852493656368"/>
			<geometry>
				<mesh filename="textured_objs/original-7.obj"/>
			</geometry>
		</collision>
		<collision>
			<origin xyz="-0.35202997736265695 -0.19371000489114376 0.0303852493656368"/>
			<geometry>
				<mesh filename="textured_objs/original-8.obj"/>
			</geometry>
		</collision>
		<collision>
			<origin xyz="-0.35202997736265695 -0.19371000489114376 0.0303852493656368"/>
			<geometry>
				<mesh filename="textured_objs/original-9.obj"/>
			</geometry>
		</collision>
		<collision>
			<origin xyz="-0.35202997736265695 -0.19371000489114376 0.0303852493656368"/>
			<geometry>
				<mesh filename="textured_objs/new-3.obj"/>
			</geometry>
		</collision>
	</link>
	<joint name="joint_0" type="revolute">
		<origin xyz="0.35202997736265695 0.19371000489114376 -0.0303852493656368"/>
		<axis xyz="-1 0 0"/>
		<child link="link_0"/>
		<parent link="link_1"/>
		<limit lower="-0.14451326206513046" upper="2.4315927138784996"/>
	</joint>
	<link name="link_1">
		<visual name="base_support-4">
			<origin xyz="0 0 0"/>
			<geometry>
				<mesh filename="textured_objs/new-1.obj"/>
			</geometry>
		</visual>
		<visual name="base_support-5">
			<origin xyz="0 0 0"/>
			<geometry>
				<mesh filename="textured_objs/original-23.obj"/>
			</geometry>
		</visual>
		<visual name="surface-6">
			<origin xyz="0 0 0"/>
			<geometry>
				<mesh filename="textured_objs/new-0.obj"/>
			</geometry>
		</visual>
		<collision>
			<origin xyz="0 0 0"/>
			<geometry>
				<mesh filename="textured_objs/new-1.obj"/>
			</geometry>
		</collision>
		<collision>
			<origin xyz="0 0 0"/>
			<geometry>
				<mesh filename="textured_objs/original-23.obj"/>
			</geometry>
		</collision>
		<collision>
			<origin xyz="0 0 0"/>
			<geometry>
				<mesh filename="textured_objs/new-0.obj"/>
			</geometry>
		</collision>
	</link>
	<joint name="joint_1" type="fixed">
		<origin rpy="1.570796326794897 0 -1.570796326794897" xyz="0 0 0"/>
		<child link="link_1"/>
		<parent link="base"/>
	</joint>
</robot>
