<?xml version="1.0" ?>
<robot name="partnet_2cdc36d2f2693ad9617724635ed7cc4b">
	<link name="base"/>
	<link name="link_0">
		<visual name="surface-18">
			<origin xyz="0 0 0"/>
			<geometry>
				<mesh filename="textured_objs/original-14.obj"/>
			</geometry>
		</visual>
		<visual name="surface-18">
			<origin xyz="0 0 0"/>
			<geometry>
				<mesh filename="textured_objs/original-13.obj"/>
			</geometry>
		</visual>
		<visual name="surface-18">
			<origin xyz="0 0 0"/>
			<geometry>
				<mesh filename="textured_objs/new-0.obj"/>
			</geometry>
		</visual>
		<visual name="frame-8">
			<origin xyz="0 0 0"/>
			<geometry>
				<mesh filename="textured_objs/new-1.obj"/>
			</geometry>
		</visual>
		<visual name="frame-8">
			<origin xyz="0 0 0"/>
			<geometry>
				<mesh filename="textured_objs/original-11.obj"/>
			</geometry>
		</visual>
		<collision>
			<origin xyz="0 0 0"/>
			<geometry>
				<mesh filename="textured_objs/original-14.obj"/>
			</geometry>
		</collision>
		<collision>
			<origin xyz="0 0 0"/>
			<geometry>
				<mesh filename="textured_objs/original-13.obj"/>
			</geometry>
		</collision>
		<collision>
			<origin xyz="0 0 0"/>
			<geometry>
				<mesh filename="textured_objs/new-0.obj"/>
			</geometry>
		</collision>
		<collision>
			<origin xyz="0 0 0"/>
			<geometry>
				<mesh filename="textured_objs/new-1.obj"/>
			</geometry>
		</collision>
		<collision>
			<origin xyz="0 0 0"/>
			<geometry>
				<mesh filename="textured_objs/original-11.obj"/>
			</geometry>
		</collision>
	</link>
	<joint name="joint_0" type="fixed">
		<origin rpy="1.570796326794897 0 -1.570796326794897" xyz="0 0 0"/>
		<child link="link_0"/>
		<parent link="base"/>
	</joint>
	<link name="link_1">
		<visual name="door_frame-21">
			<origin xyz="-0.3082993534109631 0.8995489999999999 -0.286877693928933"/>
			<geometry>
				<mesh filename="textured_objs/original-4.obj"/>
			</geometry>
		</visual>
		<visual name="door_frame-21">
			<origin xyz="-0.3082993534109631 0.8995489999999999 -0.286877693928933"/>
			<geometry>
				<mesh filename="textured_objs/original-5.obj"/>
			</geometry>
		</visual>
		<visual name="door_frame-21">
			<origin xyz="-0.3082993534109631 0.8995489999999999 -0.286877693928933"/>
			<geometry>
				<mesh filename="textured_objs/original-16.obj"/>
			</geometry>
		</visual>
		<visual name="door_frame-21">
			<origin xyz="-0.3082993534109631 0.8995489999999999 -0.286877693928933"/>
			<geometry>
				<mesh filename="textured_objs/original-17.obj"/>
			</geometry>
		</visual>
		<visual name="door_frame-21">
			<origin xyz="-0.3082993534109631 0.8995489999999999 -0.286877693928933"/>
			<geometry>
				<mesh filename="textured_objs/original-19.obj"/>
			</geometry>
		</visual>
		<visual name="door_frame-21">
			<origin xyz="-0.3082993534109631 0.8995489999999999 -0.286877693928933"/>
			<geometry>
				<mesh filename="textured_objs/original-18.obj"/>
			</geometry>
		</visual>
		<visual name="door_frame-21">
			<origin xyz="-0.3082993534109631 0.8995489999999999 -0.286877693928933"/>
			<geometry>
				<mesh filename="textured_objs/original-21.obj"/>
			</geometry>
		</visual>
		<visual name="door_frame-21">
			<origin xyz="-0.3082993534109631 0.8995489999999999 -0.286877693928933"/>
			<geometry>
				<mesh filename="textured_objs/original-20.obj"/>
			</geometry>
		</visual>
		<visual name="door_frame-21">
			<origin xyz="-0.3082993534109631 0.8995489999999999 -0.286877693928933"/>
			<geometry>
				<mesh filename="textured_objs/original-22.obj"/>
			</geometry>
		</visual>
		<visual name="door_frame-21">
			<origin xyz="-0.3082993534109631 0.8995489999999999 -0.286877693928933"/>
			<geometry>
				<mesh filename="textured_objs/original-6.obj"/>
			</geometry>
		</visual>
		<visual name="handle-22">
			<origin xyz="-0.3082993534109631 0.8995489999999999 -0.286877693928933"/>
			<geometry>
				<mesh filename="textured_objs/original-3.obj"/>
			</geometry>
		</visual>
		<visual name="control_panel-25">
			<origin xyz="-0.3082993534109631 0.8995489999999999 -0.286877693928933"/>
			<geometry>
				<mesh filename="textured_objs/original-2.obj"/>
			</geometry>
		</visual>
		<collision>
			<origin xyz="-0.3082993534109631 0.8995489999999999 -0.286877693928933"/>
			<geometry>
				<mesh filename="textured_objs/original-4.obj"/>
			</geometry>
		</collision>
		<collision>
			<origin xyz="-0.3082993534109631 0.8995489999999999 -0.286877693928933"/>
			<geometry>
				<mesh filename="textured_objs/original-5.obj"/>
			</geometry>
		</collision>
		<collision>
			<origin xyz="-0.3082993534109631 0.8995489999999999 -0.286877693928933"/>
			<geometry>
				<mesh filename="textured_objs/original-16.obj"/>
			</geometry>
		</collision>
		<collision>
			<origin xyz="-0.3082993534109631 0.8995489999999999 -0.286877693928933"/>
			<geometry>
				<mesh filename="textured_objs/original-17.obj"/>
			</geometry>
		</collision>
		<collision>
			<origin xyz="-0.3082993534109631 0.8995489999999999 -0.286877693928933"/>
			<geometry>
				<mesh filename="textured_objs/original-19.obj"/>
			</geometry>
		</collision>
		<collision>
			<origin xyz="-0.3082993534109631 0.8995489999999999 -0.286877693928933"/>
			<geometry>
				<mesh filename="textured_objs/original-18.obj"/>
			</geometry>
		</collision>
		<collision>
			<origin xyz="-0.3082993534109631 0.8995489999999999 -0.286877693928933"/>
			<geometry>
				<mesh filename="textured_objs/original-21.obj"/>
			</geometry>
		</collision>
		<collision>
			<origin xyz="-0.3082993534109631 0.8995489999999999 -0.286877693928933"/>
			<geometry>
				<mesh filename="textured_objs/original-20.obj"/>
			</geometry>
		</collision>
		<collision>
			<origin xyz="-0.3082993534109631 0.8995489999999999 -0.286877693928933"/>
			<geometry>
				<mesh filename="textured_objs/original-22.obj"/>
			</geometry>
		</collision>
		<collision>
			<origin xyz="-0.3082993534109631 0.8995489999999999 -0.286877693928933"/>
			<geometry>
				<mesh filename="textured_objs/original-6.obj"/>
			</geometry>
		</collision>
		<collision>
			<origin xyz="-0.3082993534109631 0.8995489999999999 -0.286877693928933"/>
			<geometry>
				<mesh filename="textured_objs/original-3.obj"/>
			</geometry>
		</collision>
		<collision>
			<origin xyz="-0.3082993534109631 0.8995489999999999 -0.286877693928933"/>
			<geometry>
				<mesh filename="textured_objs/original-2.obj"/>
			</geometry>
		</collision>
	</link>
	<joint name="joint_1" type="revolute">
		<origin xyz="0.3082993534109631 -0.8995489999999999 0.286877693928933"/>
		<axis xyz="0 1 0"/>
		<child link="link_1"/>
		<parent link="link_0"/>
		<limit lower="0.0" upper="3.141592653589793"/>
	</joint>
	<link name="link_2">
		<visual name="door_frame-19">
			<origin xyz="-0.3082993534109631 0.8995489999999999 -0.286877693928933"/>
			<geometry>
				<mesh filename="textured_objs/original-26.obj"/>
			</geometry>
		</visual>
		<visual name="door_frame-19">
			<origin xyz="-0.3082993534109631 0.8995489999999999 -0.286877693928933"/>
			<geometry>
				<mesh filename="textured_objs/original-32.obj"/>
			</geometry>
		</visual>
		<visual name="door_frame-19">
			<origin xyz="-0.3082993534109631 0.8995489999999999 -0.286877693928933"/>
			<geometry>
				<mesh filename="textured_objs/original-31.obj"/>
			</geometry>
		</visual>
		<visual name="door_frame-19">
			<origin xyz="-0.3082993534109631 0.8995489999999999 -0.286877693928933"/>
			<geometry>
				<mesh filename="textured_objs/original-30.obj"/>
			</geometry>
		</visual>
		<visual name="door_frame-19">
			<origin xyz="-0.3082993534109631 0.8995489999999999 -0.286877693928933"/>
			<geometry>
				<mesh filename="textured_objs/original-29.obj"/>
			</geometry>
		</visual>
		<visual name="door_frame-19">
			<origin xyz="-0.3082993534109631 0.8995489999999999 -0.286877693928933"/>
			<geometry>
				<mesh filename="textured_objs/original-27.obj"/>
			</geometry>
		</visual>
		<visual name="door_frame-19">
			<origin xyz="-0.3082993534109631 0.8995489999999999 -0.286877693928933"/>
			<geometry>
				<mesh filename="textured_objs/original-28.obj"/>
			</geometry>
		</visual>
		<visual name="door_frame-19">
			<origin xyz="-0.3082993534109631 0.8995489999999999 -0.286877693928933"/>
			<geometry>
				<mesh filename="textured_objs/original-25.obj"/>
			</geometry>
		</visual>
		<visual name="door_frame-19">
			<origin xyz="-0.3082993534109631 0.8995489999999999 -0.286877693928933"/>
			<geometry>
				<mesh filename="textured_objs/original-24.obj"/>
			</geometry>
		</visual>
		<visual name="door_frame-19">
			<origin xyz="-0.3082993534109631 0.8995489999999999 -0.286877693928933"/>
			<geometry>
				<mesh filename="textured_objs/original-12.obj"/>
			</geometry>
		</visual>
		<visual name="door_frame-19">
			<origin xyz="-0.3082993534109631 0.8995489999999999 -0.286877693928933"/>
			<geometry>
				<mesh filename="textured_objs/original-10.obj"/>
			</geometry>
		</visual>
		<visual name="handle-20">
			<origin xyz="-0.3082993534109631 0.8995489999999999 -0.286877693928933"/>
			<geometry>
				<mesh filename="textured_objs/original-9.obj"/>
			</geometry>
		</visual>
		<visual name="display_panel-24">
			<origin xyz="-0.3082993534109631 0.8995489999999999 -0.286877693928933"/>
			<geometry>
				<mesh filename="textured_objs/original-8.obj"/>
			</geometry>
		</visual>
		<collision>
			<origin xyz="-0.3082993534109631 0.8995489999999999 -0.286877693928933"/>
			<geometry>
				<mesh filename="textured_objs/original-26.obj"/>
			</geometry>
		</collision>
		<collision>
			<origin xyz="-0.3082993534109631 0.8995489999999999 -0.286877693928933"/>
			<geometry>
				<mesh filename="textured_objs/original-32.obj"/>
			</geometry>
		</collision>
		<collision>
			<origin xyz="-0.3082993534109631 0.8995489999999999 -0.286877693928933"/>
			<geometry>
				<mesh filename="textured_objs/original-31.obj"/>
			</geometry>
		</collision>
		<collision>
			<origin xyz="-0.3082993534109631 0.8995489999999999 -0.286877693928933"/>
			<geometry>
				<mesh filename="textured_objs/original-30.obj"/>
			</geometry>
		</collision>
		<collision>
			<origin xyz="-0.3082993534109631 0.8995489999999999 -0.286877693928933"/>
			<geometry>
				<mesh filename="textured_objs/original-29.obj"/>
			</geometry>
		</collision>
		<collision>
			<origin xyz="-0.3082993534109631 0.8995489999999999 -0.286877693928933"/>
			<geometry>
				<mesh filename="textured_objs/original-27.obj"/>
			</geometry>
		</collision>
		<collision>
			<origin xyz="-0.3082993534109631 0.8995489999999999 -0.286877693928933"/>
			<geometry>
				<mesh filename="textured_objs/original-28.obj"/>
			</geometry>
		</collision>
		<collision>
			<origin xyz="-0.3082993534109631 0.8995489999999999 -0.286877693928933"/>
			<geometry>
				<mesh filename="textured_objs/original-25.obj"/>
			</geometry>
		</collision>
		<collision>
			<origin xyz="-0.3082993534109631 0.8995489999999999 -0.286877693928933"/>
			<geometry>
				<mesh filename="textured_objs/original-24.obj"/>
			</geometry>
		</collision>
		<collision>
			<origin xyz="-0.3082993534109631 0.8995489999999999 -0.286877693928933"/>
			<geometry>
				<mesh filename="textured_objs/original-12.obj"/>
			</geometry>
		</collision>
		<collision>
			<origin xyz="-0.3082993534109631 0.8995489999999999 -0.286877693928933"/>
			<geometry>
				<mesh filename="textured_objs/original-10.obj"/>
			</geometry>
		</collision>
		<collision>
			<origin xyz="-0.3082993534109631 0.8995489999999999 -0.286877693928933"/>
			<geometry>
				<mesh filename="textured_objs/original-9.obj"/>
			</geometry>
		</collision>
		<collision>
			<origin xyz="-0.3082993534109631 0.8995489999999999 -0.286877693928933"/>
			<geometry>
				<mesh filename="textured_objs/original-8.obj"/>
			</geometry>
		</collision>
	</link>
	<joint name="joint_2" type="revolute">
		<origin xyz="0.3082993534109631 -0.8995489999999999 0.286877693928933"/>
		<axis xyz="0 1 0"/>
		<child link="link_2"/>
		<parent link="link_0"/>
		<limit lower="0.0" upper="3.141592653589793"/>
	</joint>
</robot>
