<?xml version="1.0" ?>
<robot name="partnet_2e668a71-ef65-4b9d-a2f7-d6ac84a2b9cb">
	<link name="base"/>
	<link name="link_0">
		<visual name="blade-11">
			<origin xyz="0.2148395 0 0.011122906072223599"/>
			<geometry>
				<mesh filename="textured_objs/new-0.obj"/>
			</geometry>
		</visual>
		<visual name="blade-11">
			<origin xyz="0.2148395 0 0.011122906072223599"/>
			<geometry>
				<mesh filename="textured_objs/original-4.obj"/>
			</geometry>
		</visual>
		<visual name="blade-11">
			<origin xyz="0.2148395 0 0.011122906072223599"/>
			<geometry>
				<mesh filename="textured_objs/new-4.obj"/>
			</geometry>
		</visual>
		<visual name="handle-12">
			<origin xyz="0.2148395 0 0.011122906072223599"/>
			<geometry>
				<mesh filename="textured_objs/new-5.obj"/>
			</geometry>
		</visual>
		<visual name="handle-12">
			<origin xyz="0.2148395 0 0.011122906072223599"/>
			<geometry>
				<mesh filename="textured_objs/new-1.obj"/>
			</geometry>
		</visual>
		<visual name="handle-12">
			<origin xyz="0.2148395 0 0.011122906072223599"/>
			<geometry>
				<mesh filename="textured_objs/original-8.obj"/>
			</geometry>
		</visual>
		<visual name="handle-12">
			<origin xyz="0.2148395 0 0.011122906072223599"/>
			<geometry>
				<mesh filename="textured_objs/original-9.obj"/>
			</geometry>
		</visual>
		<visual name="handle-12">
			<origin xyz="0.2148395 0 0.011122906072223599"/>
			<geometry>
				<mesh filename="textured_objs/original-3.obj"/>
			</geometry>
		</visual>
		<collision>
			<origin xyz="0.2148395 0 0.011122906072223599"/>
			<geometry>
				<mesh filename="textured_objs/new-0.obj"/>
			</geometry>
		</collision>
		<collision>
			<origin xyz="0.2148395 0 0.011122906072223599"/>
			<geometry>
				<mesh filename="textured_objs/original-4.obj"/>
			</geometry>
		</collision>
		<collision>
			<origin xyz="0.2148395 0 0.011122906072223599"/>
			<geometry>
				<mesh filename="textured_objs/new-4.obj"/>
			</geometry>
		</collision>
		<collision>
			<origin xyz="0.2148395 0 0.011122906072223599"/>
			<geometry>
				<mesh filename="textured_objs/new-5.obj"/>
			</geometry>
		</collision>
		<collision>
			<origin xyz="0.2148395 0 0.011122906072223599"/>
			<geometry>
				<mesh filename="textured_objs/new-1.obj"/>
			</geometry>
		</collision>
		<collision>
			<origin xyz="0.2148395 0 0.011122906072223599"/>
			<geometry>
				<mesh filename="textured_objs/original-8.obj"/>
			</geometry>
		</collision>
		<collision>
			<origin xyz="0.2148395 0 0.011122906072223599"/>
			<geometry>
				<mesh filename="textured_objs/original-9.obj"/>
			</geometry>
		</collision>
		<collision>
			<origin xyz="0.2148395 0 0.011122906072223599"/>
			<geometry>
				<mesh filename="textured_objs/original-3.obj"/>
			</geometry>
		</collision>
	</link>
	<joint name="joint_0" type="revolute">
		<origin xyz="-0.2148395 0 -0.011122906072223599"/>
		<axis xyz="0 1 0"/>
		<child link="link_0"/>
		<parent link="link_1"/>
		<limit lower="0.0" upper="2.463008640414398"/>
	</joint>
	<link name="link_1">
		<visual name="screw-10">
			<origin xyz="0 0 0"/>
			<geometry>
				<mesh filename="textured_objs/original-2.obj"/>
			</geometry>
		</visual>
		<visual name="screw-10">
			<origin xyz="0 0 0"/>
			<geometry>
				<mesh filename="textured_objs/original-5.obj"/>
			</geometry>
		</visual>
		<visual name="blade-13">
			<origin xyz="0 0 0"/>
			<geometry>
				<mesh filename="textured_objs/original-14.obj"/>
			</geometry>
		</visual>
		<visual name="blade-13">
			<origin xyz="0 0 0"/>
			<geometry>
				<mesh filename="textured_objs/new-3.obj"/>
			</geometry>
		</visual>
		<visual name="handle-14">
			<origin xyz="0 0 0"/>
			<geometry>
				<mesh filename="textured_objs/original-12.obj"/>
			</geometry>
		</visual>
		<visual name="handle-14">
			<origin xyz="0 0 0"/>
			<geometry>
				<mesh filename="textured_objs/original-6.obj"/>
			</geometry>
		</visual>
		<visual name="handle-14">
			<origin xyz="0 0 0"/>
			<geometry>
				<mesh filename="textured_objs/new-2.obj"/>
			</geometry>
		</visual>
		<visual name="handle-14">
			<origin xyz="0 0 0"/>
			<geometry>
				<mesh filename="textured_objs/original-13.obj"/>
			</geometry>
		</visual>
		<collision>
			<origin xyz="0 0 0"/>
			<geometry>
				<mesh filename="textured_objs/original-2.obj"/>
			</geometry>
		</collision>
		<collision>
			<origin xyz="0 0 0"/>
			<geometry>
				<mesh filename="textured_objs/original-5.obj"/>
			</geometry>
		</collision>
		<collision>
			<origin xyz="0 0 0"/>
			<geometry>
				<mesh filename="textured_objs/original-14.obj"/>
			</geometry>
		</collision>
		<collision>
			<origin xyz="0 0 0"/>
			<geometry>
				<mesh filename="textured_objs/new-3.obj"/>
			</geometry>
		</collision>
		<collision>
			<origin xyz="0 0 0"/>
			<geometry>
				<mesh filename="textured_objs/original-12.obj"/>
			</geometry>
		</collision>
		<collision>
			<origin xyz="0 0 0"/>
			<geometry>
				<mesh filename="textured_objs/original-6.obj"/>
			</geometry>
		</collision>
		<collision>
			<origin xyz="0 0 0"/>
			<geometry>
				<mesh filename="textured_objs/new-2.obj"/>
			</geometry>
		</collision>
		<collision>
			<origin xyz="0 0 0"/>
			<geometry>
				<mesh filename="textured_objs/original-13.obj"/>
			</geometry>
		</collision>
	</link>
	<joint name="joint_1" type="fixed">
		<origin rpy="1.570796326794897 0 -1.570796326794897" xyz="0 0 0"/>
		<child link="link_1"/>
		<parent link="base"/>
	</joint>
</robot>
