<?xml version="1.0" ?>
<robot name="partnet_30c6b5511ff09ac33526ea1c3de37e7">
	<link name="base"/>
	<link name="link_0">
		<visual name="lid-17">
			<origin xyz="0.015190999999999982 0 -0.010704000000000002"/>
			<geometry>
				<mesh filename="textured_objs/original-23.obj"/>
			</geometry>
		</visual>
		<collision>
			<origin xyz="0.015190999999999982 0 -0.010704000000000002"/>
			<geometry>
				<mesh filename="textured_objs/original-23.obj"/>
			</geometry>
		</collision>
	</link>
	<joint name="joint_0" type="continuous">
		<origin xyz="0.0 0 0.0"/>
		<axis xyz="0 -1 0"/>
		<child link="link_0"/>
		<parent link="link_0_helper"/>
	</joint>
	<link name="link_1">
		<visual name="body-15">
			<origin xyz="0 0 0"/>
			<geometry>
				<mesh filename="textured_objs/new-16.obj"/>
			</geometry>
		</visual>
		<visual name="neck-16">
			<origin xyz="0 0 0"/>
			<geometry>
				<mesh filename="textured_objs/new-22.obj"/>
			</geometry>
		</visual>
		<visual name="neck-16">
			<origin xyz="0 0 0"/>
			<geometry>
				<mesh filename="textured_objs/new-18.obj"/>
			</geometry>
		</visual>
		<visual name="liquid-19">
			<origin xyz="0 0 0"/>
			<geometry>
				<mesh filename="textured_objs/new-12.obj"/>
			</geometry>
		</visual>
		<collision>
			<origin xyz="0 0 0"/>
			<geometry>
				<mesh filename="textured_objs/new-16.obj"/>
			</geometry>
		</collision>
		<collision>
			<origin xyz="0 0 0"/>
			<geometry>
				<mesh filename="textured_objs/new-22.obj"/>
			</geometry>
		</collision>
		<collision>
			<origin xyz="0 0 0"/>
			<geometry>
				<mesh filename="textured_objs/new-18.obj"/>
			</geometry>
		</collision>
		<collision>
			<origin xyz="0 0 0"/>
			<geometry>
				<mesh filename="textured_objs/new-12.obj"/>
			</geometry>
		</collision>
	</link>
	<joint name="joint_1" type="fixed">
		<origin rpy="1.570796326794897 0 -1.570796326794897" xyz="0 0 0"/>
		<child link="link_1"/>
		<parent link="base"/>
	</joint>
	<link name="link_0_helper"/>
	<joint name="joint_2" type="prismatic">
		<origin xyz="-0.015190999999999982 0 0.010704000000000002"/>
		<axis xyz="0 1 0"/>
		<child link="link_0_helper"/>
		<parent link="link_1"/>
		<limit lower="-0.18000000000000016" upper="0.07600000000000007"/>
	</joint>
</robot>
