<?xml version="1.0" ?>
<robot name="partnet_3f1918f829264fcd89a2b0e9fb51847a">
	<link name="base"/>
	<link name="link_0">
		<visual name="frame-5">
			<origin xyz="0 0 0"/>
			<geometry>
				<mesh filename="textured_objs/new-6.obj"/>
			</geometry>
		</visual>
		<visual name="frame-5">
			<origin xyz="0 0 0"/>
			<geometry>
				<mesh filename="textured_objs/new-0.obj"/>
			</geometry>
		</visual>
		<collision>
			<origin xyz="0 0 0"/>
			<geometry>
				<mesh filename="textured_objs/new-6.obj"/>
			</geometry>
		</collision>
		<collision>
			<origin xyz="0 0 0"/>
			<geometry>
				<mesh filename="textured_objs/new-0.obj"/>
			</geometry>
		</collision>
	</link>
	<joint name="joint_0" type="fixed">
		<origin rpy="1.570796326794897 0 -1.570796326794897" xyz="0 0 0"/>
		<child link="link_0"/>
		<parent link="base"/>
	</joint>
	<link name="link_1">
		<visual name="door_frame-11">
			<origin xyz="-0.38567368414974135 -0.8319730000000003 -0.3740654579299192"/>
			<geometry>
				<mesh filename="textured_objs/new-2.obj"/>
			</geometry>
		</visual>
		<visual name="handle-12">
			<origin xyz="-0.38567368414974135 -0.8319730000000003 -0.3740654579299192"/>
			<geometry>
				<mesh filename="textured_objs/new-1.obj"/>
			</geometry>
		</visual>
		<collision>
			<origin xyz="-0.38567368414974135 -0.8319730000000003 -0.3740654579299192"/>
			<geometry>
				<mesh filename="textured_objs/new-2.obj"/>
			</geometry>
		</collision>
		<collision>
			<origin xyz="-0.38567368414974135 -0.8319730000000003 -0.3740654579299192"/>
			<geometry>
				<mesh filename="textured_objs/new-1.obj"/>
			</geometry>
		</collision>
	</link>
	<joint name="joint_1" type="revolute">
		<origin xyz="0.38567368414974135 0.8319730000000003 0.3740654579299192"/>
		<axis xyz="0 1 0"/>
		<child link="link_1"/>
		<parent link="link_0"/>
		<limit lower="0.0" upper="3.141592653589793"/>
	</joint>
	<link name="link_2">
		<visual name="other_leaf-15">
			<origin xyz="0.39178656086699837 -0.8319730000000001 -0.37717854554743213"/>
			<geometry>
				<mesh filename="textured_objs/new-3.obj"/>
			</geometry>
		</visual>
		<visual name="door_frame-9">
			<origin xyz="0.39178656086699837 -0.8319730000000001 -0.37717854554743213"/>
			<geometry>
				<mesh filename="textured_objs/new-5.obj"/>
			</geometry>
		</visual>
		<visual name="handle-10">
			<origin xyz="0.39178656086699837 -0.8319730000000001 -0.37717854554743213"/>
			<geometry>
				<mesh filename="textured_objs/new-4.obj"/>
			</geometry>
		</visual>
		<collision>
			<origin xyz="0.39178656086699837 -0.8319730000000001 -0.37717854554743213"/>
			<geometry>
				<mesh filename="textured_objs/new-3.obj"/>
			</geometry>
		</collision>
		<collision>
			<origin xyz="0.39178656086699837 -0.8319730000000001 -0.37717854554743213"/>
			<geometry>
				<mesh filename="textured_objs/new-5.obj"/>
			</geometry>
		</collision>
		<collision>
			<origin xyz="0.39178656086699837 -0.8319730000000001 -0.37717854554743213"/>
			<geometry>
				<mesh filename="textured_objs/new-4.obj"/>
			</geometry>
		</collision>
	</link>
	<joint name="joint_2" type="revolute">
		<origin xyz="-0.39178656086699837 0.8319730000000001 0.37717854554743213"/>
		<axis xyz="0 -1 0"/>
		<child link="link_2"/>
		<parent link="link_0"/>
		<limit lower="-0.0" upper="3.141592653589793"/>
	</joint>
</robot>
