<?xml version="1.0" ?>
<robot name="partnet_275bb61c2e1e7a20ac6c90f4cb03d6a3">
	<link name="base"/>
	<link name="link_0">
		<visual name="outside_frame-16">
			<origin xyz="0 0 0"/>
			<geometry>
				<mesh filename="textured_objs/new-9.obj"/>
			</geometry>
		</visual>
		<collision>
			<origin xyz="0 0 0"/>
			<geometry>
				<mesh filename="textured_objs/new-9.obj"/>
			</geometry>
		</collision>
	</link>
	<joint name="joint_0" type="fixed">
		<origin rpy="1.570796326794897 0 -1.570796326794897" xyz="0 0 0"/>
		<child link="link_0"/>
		<parent link="base"/>
	</joint>
	<link name="link_1">
		<visual name="movable_part-10">
			<origin xyz="0.015260868679227877 0.146172912098325 -0.044287651613987615"/>
			<geometry>
				<mesh filename="textured_objs/new-2.obj"/>
			</geometry>
		</visual>
		<collision>
			<origin xyz="0.015260868679227877 0.146172912098325 -0.044287651613987615"/>
			<geometry>
				<mesh filename="textured_objs/new-2.obj"/>
			</geometry>
		</collision>
	</link>
	<joint name="joint_1" type="revolute">
		<origin xyz="-0.4958831855233777 -0.7964929120983253 0.03164547262449057"/>
		<axis xyz="0.02349823920090934 -0.01594131926276791 -0.9995967722510009"/>
		<child link="link_1"/>
		<parent link="link_3"/>
		<limit lower="-0.0" upper="1.5707963267948966"/>
	</joint>
	<link name="link_2">
		<visual name="movable_part-8">
			<origin xyz="0.015260868679227877 0.146172912098325 -0.044287651613987615"/>
			<geometry>
				<mesh filename="textured_objs/new-0.obj"/>
			</geometry>
		</visual>
		<collision>
			<origin xyz="0.015260868679227877 0.146172912098325 -0.044287651613987615"/>
			<geometry>
				<mesh filename="textured_objs/new-0.obj"/>
			</geometry>
		</collision>
	</link>
	<joint name="joint_2" type="revolute">
		<origin xyz="0.46070863599185435 -0.7964929120983244 0.050692506301599265"/>
		<axis xyz="-0.02349823920090934 0.01594131926276791 0.9995967722510009"/>
		<child link="link_2"/>
		<parent link="link_4"/>
		<limit lower="0.0" upper="1.5707963267948966"/>
	</joint>
	<link name="link_3">
		<visual name="glass-12">
			<origin xyz="-0.4806223168441498 -0.6503200000000002 -0.012642178989497044"/>
			<geometry>
				<mesh filename="textured_objs/new-7.obj"/>
			</geometry>
		</visual>
		<visual name="glass-12">
			<origin xyz="-0.4806223168441498 -0.6503200000000002 -0.012642178989497044"/>
			<geometry>
				<mesh filename="textured_objs/new-4.obj"/>
			</geometry>
		</visual>
		<visual name="surface_board-14">
			<origin xyz="-0.4806223168441498 -0.6503200000000002 -0.012642178989497044"/>
			<geometry>
				<mesh filename="textured_objs/new-12.obj"/>
			</geometry>
		</visual>
		<visual name="surface_board-14">
			<origin xyz="-0.4806223168441498 -0.6503200000000002 -0.012642178989497044"/>
			<geometry>
				<mesh filename="textured_objs/new-11.obj"/>
			</geometry>
		</visual>
		<visual name="fixed_part-9">
			<origin xyz="-0.4806223168441498 -0.6503200000000002 -0.012642178989497044"/>
			<geometry>
				<mesh filename="textured_objs/new-3.obj"/>
			</geometry>
		</visual>
		<collision>
			<origin xyz="-0.4806223168441498 -0.6503200000000002 -0.012642178989497044"/>
			<geometry>
				<mesh filename="textured_objs/new-7.obj"/>
			</geometry>
		</collision>
		<collision>
			<origin xyz="-0.4806223168441498 -0.6503200000000002 -0.012642178989497044"/>
			<geometry>
				<mesh filename="textured_objs/new-4.obj"/>
			</geometry>
		</collision>
		<collision>
			<origin xyz="-0.4806223168441498 -0.6503200000000002 -0.012642178989497044"/>
			<geometry>
				<mesh filename="textured_objs/new-12.obj"/>
			</geometry>
		</collision>
		<collision>
			<origin xyz="-0.4806223168441498 -0.6503200000000002 -0.012642178989497044"/>
			<geometry>
				<mesh filename="textured_objs/new-11.obj"/>
			</geometry>
		</collision>
		<collision>
			<origin xyz="-0.4806223168441498 -0.6503200000000002 -0.012642178989497044"/>
			<geometry>
				<mesh filename="textured_objs/new-3.obj"/>
			</geometry>
		</collision>
	</link>
	<joint name="joint_3" type="revolute">
		<origin xyz="0.4806223168441498 0.6503200000000002 0.012642178989497044"/>
		<axis xyz="0 -1 0"/>
		<child link="link_3"/>
		<parent link="link_0"/>
		<limit lower="0.0" upper="1.5707963267948966"/>
	</joint>
	<link name="link_4">
		<visual name="glass-13">
			<origin xyz="0.47596950467108223 -0.6503199999999993 0.00640485468761165"/>
			<geometry>
				<mesh filename="textured_objs/new-5.obj"/>
			</geometry>
		</visual>
		<visual name="glass-13">
			<origin xyz="0.47596950467108223 -0.6503199999999993 0.00640485468761165"/>
			<geometry>
				<mesh filename="textured_objs/new-6.obj"/>
			</geometry>
		</visual>
		<visual name="surface_board-15">
			<origin xyz="0.47596950467108223 -0.6503199999999993 0.00640485468761165"/>
			<geometry>
				<mesh filename="textured_objs/new-10.obj"/>
			</geometry>
		</visual>
		<visual name="fixed_part-7">
			<origin xyz="0.47596950467108223 -0.6503199999999993 0.00640485468761165"/>
			<geometry>
				<mesh filename="textured_objs/new-1.obj"/>
			</geometry>
		</visual>
		<collision>
			<origin xyz="0.47596950467108223 -0.6503199999999993 0.00640485468761165"/>
			<geometry>
				<mesh filename="textured_objs/new-5.obj"/>
			</geometry>
		</collision>
		<collision>
			<origin xyz="0.47596950467108223 -0.6503199999999993 0.00640485468761165"/>
			<geometry>
				<mesh filename="textured_objs/new-6.obj"/>
			</geometry>
		</collision>
		<collision>
			<origin xyz="0.47596950467108223 -0.6503199999999993 0.00640485468761165"/>
			<geometry>
				<mesh filename="textured_objs/new-10.obj"/>
			</geometry>
		</collision>
		<collision>
			<origin xyz="0.47596950467108223 -0.6503199999999993 0.00640485468761165"/>
			<geometry>
				<mesh filename="textured_objs/new-1.obj"/>
			</geometry>
		</collision>
	</link>
	<joint name="joint_4" type="revolute">
		<origin xyz="-0.47596950467108223 0.6503199999999993 -0.00640485468761165"/>
		<axis xyz="0 1 0"/>
		<child link="link_4"/>
		<parent link="link_0"/>
		<limit lower="-0.0" upper="1.5707963267948966"/>
	</joint>
</robot>
