<?xml version="1.0" ?>
<robot name="partnet_ec245748cbad16b1d747a43c11e738e9">
	<link name="base"/>
	<link name="link_0">
		<visual name="outside_frame-1">
			<origin xyz="0 0 0"/>
			<geometry>
				<mesh filename="textured_objs/original-1.obj"/>
			</geometry>
		</visual>
		<visual name="outside_frame-1">
			<origin xyz="0 0 0"/>
			<geometry>
				<mesh filename="textured_objs/original-2.obj"/>
			</geometry>
		</visual>
		<visual name="outside_frame-1">
			<origin xyz="0 0 0"/>
			<geometry>
				<mesh filename="textured_objs/original-3.obj"/>
			</geometry>
		</visual>
		<collision>
			<origin xyz="0 0 0"/>
			<geometry>
				<mesh filename="textured_objs/original-1.obj"/>
			</geometry>
		</collision>
		<collision>
			<origin xyz="0 0 0"/>
			<geometry>
				<mesh filename="textured_objs/original-2.obj"/>
			</geometry>
		</collision>
		<collision>
			<origin xyz="0 0 0"/>
			<geometry>
				<mesh filename="textured_objs/original-3.obj"/>
			</geometry>
		</collision>
	</link>
	<joint name="joint_0" type="fixed">
		<origin rpy="1.570796326794897 0 -1.570796326794897" xyz="0 0 0"/>
		<child link="link_0"/>
		<parent link="base"/>
	</joint>
	<link name="link_1">
		<visual name="surface_board-19">
			<origin xyz="0.3114736542059362 -0.74903 0.00446620785853713"/>
			<geometry>
				<mesh filename="textured_objs/original-5.obj"/>
			</geometry>
		</visual>
		<visual name="fixed_part-17">
			<origin xyz="0.3114736542059362 -0.74903 0.00446620785853713"/>
			<geometry>
				<mesh filename="textured_objs/original-9.obj"/>
			</geometry>
		</visual>
		<visual name="fixed_part-15">
			<origin xyz="0.3114736542059362 -0.74903 0.00446620785853713"/>
			<geometry>
				<mesh filename="textured_objs/original-12.obj"/>
			</geometry>
		</visual>
		<collision>
			<origin xyz="0.3114736542059362 -0.74903 0.00446620785853713"/>
			<geometry>
				<mesh filename="textured_objs/original-5.obj"/>
			</geometry>
		</collision>
		<collision>
			<origin xyz="0.3114736542059362 -0.74903 0.00446620785853713"/>
			<geometry>
				<mesh filename="textured_objs/original-9.obj"/>
			</geometry>
		</collision>
		<collision>
			<origin xyz="0.3114736542059362 -0.74903 0.00446620785853713"/>
			<geometry>
				<mesh filename="textured_objs/original-12.obj"/>
			</geometry>
		</collision>
	</link>
	<joint name="joint_1" type="revolute">
		<origin xyz="-0.3114736542059362 0.74903 -0.00446620785853713"/>
		<axis xyz="0 1 0"/>
		<child link="link_1"/>
		<parent link="link_0"/>
		<limit lower="0.0" upper="1.5707963267948966"/>
	</joint>
	<link name="link_2">
		<visual name="movable_part-18">
			<origin xyz="-0.2386302230391824 0.26779581099866157 -0.05032100000000006"/>
			<geometry>
				<mesh filename="textured_objs/original-10.obj"/>
			</geometry>
		</visual>
		<visual name="movable_part-16">
			<origin xyz="-0.2386302230391824 0.26779581099866157 -0.05032100000000006"/>
			<geometry>
				<mesh filename="textured_objs/original-13.obj"/>
			</geometry>
		</visual>
		<collision>
			<origin xyz="-0.2386302230391824 0.26779581099866157 -0.05032100000000006"/>
			<geometry>
				<mesh filename="textured_objs/original-10.obj"/>
			</geometry>
		</collision>
		<collision>
			<origin xyz="-0.2386302230391824 0.26779581099866157 -0.05032100000000006"/>
			<geometry>
				<mesh filename="textured_objs/original-13.obj"/>
			</geometry>
		</collision>
	</link>
	<joint name="joint_2" type="revolute">
		<origin xyz="0.5501038772451186 -1.0168258109986614 0.05478720785853719"/>
		<axis xyz="0 0 1"/>
		<child link="link_2"/>
		<parent link="link_1"/>
		<limit lower="-0.0" upper="1.5707963267948966"/>
	</joint>
</robot>
