<?xml version="1.0" ?>
<robot name="partnet_b8cf469bc1b42ab64a44340bf227e40">
	<link name="base"/>
	<link name="link_0">
		<visual name="door_frame-6">
			<origin xyz="0.6867020130157472 0.41468832893905444 -0.48474770681800977"/>
			<geometry>
				<mesh filename="textured_objs/original-5.obj"/>
			</geometry>
		</visual>
		<visual name="glass-7">
			<origin xyz="0.6867020130157472 0.41468832893905444 -0.48474770681800977"/>
			<geometry>
				<mesh filename="textured_objs/original-6.obj"/>
			</geometry>
		</visual>
		<visual name="handle-8">
			<origin xyz="0.6867020130157472 0.41468832893905444 -0.48474770681800977"/>
			<geometry>
				<mesh filename="textured_objs/original-2.obj"/>
			</geometry>
		</visual>
		<collision>
			<origin xyz="0.6867020130157472 0.41468832893905444 -0.48474770681800977"/>
			<geometry>
				<mesh filename="textured_objs/original-5.obj"/>
			</geometry>
		</collision>
		<collision>
			<origin xyz="0.6867020130157472 0.41468832893905444 -0.48474770681800977"/>
			<geometry>
				<mesh filename="textured_objs/original-6.obj"/>
			</geometry>
		</collision>
		<collision>
			<origin xyz="0.6867020130157472 0.41468832893905444 -0.48474770681800977"/>
			<geometry>
				<mesh filename="textured_objs/original-2.obj"/>
			</geometry>
		</collision>
	</link>
	<joint name="joint_0" type="revolute">
		<origin xyz="-0.6867020130157472 -0.41468832893905444 0.48474770681800977"/>
		<axis xyz="1 0 0"/>
		<child link="link_0"/>
		<parent link="link_1"/>
		<limit lower="0.0" upper="1.5707963267948966"/>
	</joint>
	<link name="link_1">
		<visual name="frame-2">
			<origin xyz="0 0 0"/>
			<geometry>
				<mesh filename="textured_objs/original-4.obj"/>
			</geometry>
		</visual>
		<visual name="frame-2">
			<origin xyz="0 0 0"/>
			<geometry>
				<mesh filename="textured_objs/original-3.obj"/>
			</geometry>
		</visual>
		<visual name="display_panel-5">
			<origin xyz="0 0 0"/>
			<geometry>
				<mesh filename="textured_objs/original-1.obj"/>
			</geometry>
		</visual>
		<collision>
			<origin xyz="0 0 0"/>
			<geometry>
				<mesh filename="textured_objs/original-4.obj"/>
			</geometry>
		</collision>
		<collision>
			<origin xyz="0 0 0"/>
			<geometry>
				<mesh filename="textured_objs/original-3.obj"/>
			</geometry>
		</collision>
		<collision>
			<origin xyz="0 0 0"/>
			<geometry>
				<mesh filename="textured_objs/original-1.obj"/>
			</geometry>
		</collision>
	</link>
	<joint name="joint_1" type="fixed">
		<origin rpy="1.570796326794897 0 -1.570796326794897" xyz="0 0 0"/>
		<child link="link_1"/>
		<parent link="base"/>
	</joint>
</robot>
