<?xml version="1.0" ?>
<robot name="partnet_87b093f1fa5495968cb623bbd4140197">
	<link name="base"/>
	<link name="link_0">
		<visual name="frame-6">
			<origin xyz="-0.1770090000000002 -0.0014798959410382492 0.13340063601159122"/>
			<geometry>
				<mesh filename="textured_objs/original-19.obj"/>
			</geometry>
		</visual>
		<visual name="frame-6">
			<origin xyz="-0.1770090000000002 -0.0014798959410382492 0.13340063601159122"/>
			<geometry>
				<mesh filename="textured_objs/original-14.obj"/>
			</geometry>
		</visual>
		<visual name="frame-6">
			<origin xyz="-0.1770090000000002 -0.0014798959410382492 0.13340063601159122"/>
			<geometry>
				<mesh filename="textured_objs/original-15.obj"/>
			</geometry>
		</visual>
		<visual name="frame-6">
			<origin xyz="-0.1770090000000002 -0.0014798959410382492 0.13340063601159122"/>
			<geometry>
				<mesh filename="textured_objs/original-16.obj"/>
			</geometry>
		</visual>
		<visual name="frame-6">
			<origin xyz="-0.1770090000000002 -0.0014798959410382492 0.13340063601159122"/>
			<geometry>
				<mesh filename="textured_objs/original-17.obj"/>
			</geometry>
		</visual>
		<visual name="frame-6">
			<origin xyz="-0.1770090000000002 -0.0014798959410382492 0.13340063601159122"/>
			<geometry>
				<mesh filename="textured_objs/original-18.obj"/>
			</geometry>
		</visual>
		<visual name="frame-6">
			<origin xyz="-0.1770090000000002 -0.0014798959410382492 0.13340063601159122"/>
			<geometry>
				<mesh filename="textured_objs/original-13.obj"/>
			</geometry>
		</visual>
		<visual name="frame-6">
			<origin xyz="-0.1770090000000002 -0.0014798959410382492 0.13340063601159122"/>
			<geometry>
				<mesh filename="textured_objs/original-10.obj"/>
			</geometry>
		</visual>
		<visual name="frame-6">
			<origin xyz="-0.1770090000000002 -0.0014798959410382492 0.13340063601159122"/>
			<geometry>
				<mesh filename="textured_objs/original-8.obj"/>
			</geometry>
		</visual>
		<visual name="frame-6">
			<origin xyz="-0.1770090000000002 -0.0014798959410382492 0.13340063601159122"/>
			<geometry>
				<mesh filename="textured_objs/original-9.obj"/>
			</geometry>
		</visual>
		<visual name="frame-6">
			<origin xyz="-0.1770090000000002 -0.0014798959410382492 0.13340063601159122"/>
			<geometry>
				<mesh filename="textured_objs/original-7.obj"/>
			</geometry>
		</visual>
		<visual name="screen-7">
			<origin xyz="-0.1770090000000002 -0.0014798959410382492 0.13340063601159122"/>
			<geometry>
				<mesh filename="textured_objs/original-1.obj"/>
			</geometry>
		</visual>
		<collision>
			<origin xyz="-0.1770090000000002 -0.0014798959410382492 0.13340063601159122"/>
			<geometry>
				<mesh filename="textured_objs/original-19.obj"/>
			</geometry>
		</collision>
		<collision>
			<origin xyz="-0.1770090000000002 -0.0014798959410382492 0.13340063601159122"/>
			<geometry>
				<mesh filename="textured_objs/original-14.obj"/>
			</geometry>
		</collision>
		<collision>
			<origin xyz="-0.1770090000000002 -0.0014798959410382492 0.13340063601159122"/>
			<geometry>
				<mesh filename="textured_objs/original-15.obj"/>
			</geometry>
		</collision>
		<collision>
			<origin xyz="-0.1770090000000002 -0.0014798959410382492 0.13340063601159122"/>
			<geometry>
				<mesh filename="textured_objs/original-16.obj"/>
			</geometry>
		</collision>
		<collision>
			<origin xyz="-0.1770090000000002 -0.0014798959410382492 0.13340063601159122"/>
			<geometry>
				<mesh filename="textured_objs/original-17.obj"/>
			</geometry>
		</collision>
		<collision>
			<origin xyz="-0.1770090000000002 -0.0014798959410382492 0.13340063601159122"/>
			<geometry>
				<mesh filename="textured_objs/original-18.obj"/>
			</geometry>
		</collision>
		<collision>
			<origin xyz="-0.1770090000000002 -0.0014798959410382492 0.13340063601159122"/>
			<geometry>
				<mesh filename="textured_objs/original-13.obj"/>
			</geometry>
		</collision>
		<collision>
			<origin xyz="-0.1770090000000002 -0.0014798959410382492 0.13340063601159122"/>
			<geometry>
				<mesh filename="textured_objs/original-10.obj"/>
			</geometry>
		</collision>
		<collision>
			<origin xyz="-0.1770090000000002 -0.0014798959410382492 0.13340063601159122"/>
			<geometry>
				<mesh filename="textured_objs/original-8.obj"/>
			</geometry>
		</collision>
		<collision>
			<origin xyz="-0.1770090000000002 -0.0014798959410382492 0.13340063601159122"/>
			<geometry>
				<mesh filename="textured_objs/original-9.obj"/>
			</geometry>
		</collision>
		<collision>
			<origin xyz="-0.1770090000000002 -0.0014798959410382492 0.13340063601159122"/>
			<geometry>
				<mesh filename="textured_objs/original-7.obj"/>
			</geometry>
		</collision>
		<collision>
			<origin xyz="-0.1770090000000002 -0.0014798959410382492 0.13340063601159122"/>
			<geometry>
				<mesh filename="textured_objs/original-1.obj"/>
			</geometry>
		</collision>
	</link>
	<joint name="joint_0" type="revolute">
		<origin xyz="0.1770090000000002 0.0014798959410382492 -0.13340063601159122"/>
		<axis xyz="-1 0 0"/>
		<child link="link_0"/>
		<parent link="link_1"/>
		<limit lower="-0.25132741228718347" upper="0.7728317927830891"/>
	</joint>
	<link name="link_1">
		<visual name="base_support-4">
			<origin xyz="0 0 0"/>
			<geometry>
				<mesh filename="textured_objs/original-6.obj"/>
			</geometry>
		</visual>
		<visual name="surface-5">
			<origin xyz="0 0 0"/>
			<geometry>
				<mesh filename="textured_objs/original-11.obj"/>
			</geometry>
		</visual>
		<collision>
			<origin xyz="0 0 0"/>
			<geometry>
				<mesh filename="textured_objs/original-6.obj"/>
			</geometry>
		</collision>
		<collision>
			<origin xyz="0 0 0"/>
			<geometry>
				<mesh filename="textured_objs/original-11.obj"/>
			</geometry>
		</collision>
	</link>
	<joint name="joint_1" type="fixed">
		<origin rpy="1.570796326794897 0 -1.570796326794897" xyz="0 0 0"/>
		<child link="link_1"/>
		<parent link="base"/>
	</joint>
</robot>
