<?xml version="1.0" ?>
<robot name="partnet_5c324a7cdf6195a5303c85804d402599">
	<link name="base"/>
	<link name="link_0">
		<visual name="lamp_base_part-28">
			<origin xyz="0 0 0"/>
			<geometry>
				<mesh filename="textured_objs/original-9.obj"/>
			</geometry>
		</visual>
		<visual name="lamp_base_part-28">
			<origin xyz="0 0 0"/>
			<geometry>
				<mesh filename="textured_objs/original-10.obj"/>
			</geometry>
		</visual>
		<visual name="lamp_base_part-28">
			<origin xyz="0 0 0"/>
			<geometry>
				<mesh filename="textured_objs/original-8.obj"/>
			</geometry>
		</visual>
		<collision>
			<origin xyz="0 0 0"/>
			<geometry>
				<mesh filename="textured_objs/original-9.obj"/>
			</geometry>
		</collision>
		<collision>
			<origin xyz="0 0 0"/>
			<geometry>
				<mesh filename="textured_objs/original-10.obj"/>
			</geometry>
		</collision>
		<collision>
			<origin xyz="0 0 0"/>
			<geometry>
				<mesh filename="textured_objs/original-8.obj"/>
			</geometry>
		</collision>
	</link>
	<joint name="joint_0" type="fixed">
		<origin rpy="1.570796326794897 0 -1.570796326794897" xyz="0 0 0"/>
		<child link="link_0"/>
		<parent link="base"/>
	</joint>
	<link name="link_1">
		<visual name="lamp_shade-12">
			<origin xyz="0 -0.6976325842998978 -0.5626814341383439"/>
			<geometry>
				<mesh filename="textured_objs/original-7.obj"/>
			</geometry>
		</visual>
		<visual name="light_bulb-11">
			<origin xyz="0 -0.6976325842998978 -0.5626814341383439"/>
			<geometry>
				<mesh filename="textured_objs/original-19.obj"/>
			</geometry>
		</visual>
		<visual name="lamp_arm_straight_bar-8">
			<origin xyz="0 -0.6976325842998978 -0.5626814341383439"/>
			<geometry>
				<mesh filename="textured_objs/original-16.obj"/>
			</geometry>
		</visual>
		<visual name="lamp_arm_straight_bar-9">
			<origin xyz="0 -0.6976325842998978 -0.5626814341383439"/>
			<geometry>
				<mesh filename="textured_objs/original-6.obj"/>
			</geometry>
		</visual>
		<collision>
			<origin xyz="0 -0.6976325842998978 -0.5626814341383439"/>
			<geometry>
				<mesh filename="textured_objs/original-7.obj"/>
			</geometry>
		</collision>
		<collision>
			<origin xyz="0 -0.6976325842998978 -0.5626814341383439"/>
			<geometry>
				<mesh filename="textured_objs/original-19.obj"/>
			</geometry>
		</collision>
		<collision>
			<origin xyz="0 -0.6976325842998978 -0.5626814341383439"/>
			<geometry>
				<mesh filename="textured_objs/original-16.obj"/>
			</geometry>
		</collision>
		<collision>
			<origin xyz="0 -0.6976325842998978 -0.5626814341383439"/>
			<geometry>
				<mesh filename="textured_objs/original-6.obj"/>
			</geometry>
		</collision>
	</link>
	<joint name="joint_1" type="revolute">
		<origin xyz="0 -0.11157893822237441 0.8896519333513138"/>
		<axis xyz="1 0 0"/>
		<child link="link_1"/>
		<parent link="link_2"/>
		<limit lower="-1.6336281798666927" upper="1.0471975511965976"/>
	</joint>
	<link name="link_2">
		<visual name="lamp_arm_straight_bar-26">
			<origin xyz="0 -0.8092115225222722 0.32697049921296983"/>
			<geometry>
				<mesh filename="textured_objs/original-18.obj"/>
			</geometry>
		</visual>
		<visual name="lamp_arm_straight_bar-25">
			<origin xyz="0 -0.8092115225222722 0.32697049921296983"/>
			<geometry>
				<mesh filename="textured_objs/original-5.obj"/>
			</geometry>
		</visual>
		<visual name="lamp_joint-20">
			<origin xyz="0 -0.8092115225222722 0.32697049921296983"/>
			<geometry>
				<mesh filename="textured_objs/original-17.obj"/>
			</geometry>
		</visual>
		<visual name="lamp_joint-20">
			<origin xyz="0 -0.8092115225222722 0.32697049921296983"/>
			<geometry>
				<mesh filename="textured_objs/original-15.obj"/>
			</geometry>
		</visual>
		<visual name="lamp_joint-20">
			<origin xyz="0 -0.8092115225222722 0.32697049921296983"/>
			<geometry>
				<mesh filename="textured_objs/original-14.obj"/>
			</geometry>
		</visual>
		<visual name="lamp_joint-21">
			<origin xyz="0 -0.8092115225222722 0.32697049921296983"/>
			<geometry>
				<mesh filename="textured_objs/original-4.obj"/>
			</geometry>
		</visual>
		<visual name="lamp_joint-21">
			<origin xyz="0 -0.8092115225222722 0.32697049921296983"/>
			<geometry>
				<mesh filename="textured_objs/original-12.obj"/>
			</geometry>
		</visual>
		<visual name="lamp_joint-21">
			<origin xyz="0 -0.8092115225222722 0.32697049921296983"/>
			<geometry>
				<mesh filename="textured_objs/original-13.obj"/>
			</geometry>
		</visual>
		<collision>
			<origin xyz="0 -0.8092115225222722 0.32697049921296983"/>
			<geometry>
				<mesh filename="textured_objs/original-18.obj"/>
			</geometry>
		</collision>
		<collision>
			<origin xyz="0 -0.8092115225222722 0.32697049921296983"/>
			<geometry>
				<mesh filename="textured_objs/original-5.obj"/>
			</geometry>
		</collision>
		<collision>
			<origin xyz="0 -0.8092115225222722 0.32697049921296983"/>
			<geometry>
				<mesh filename="textured_objs/original-17.obj"/>
			</geometry>
		</collision>
		<collision>
			<origin xyz="0 -0.8092115225222722 0.32697049921296983"/>
			<geometry>
				<mesh filename="textured_objs/original-15.obj"/>
			</geometry>
		</collision>
		<collision>
			<origin xyz="0 -0.8092115225222722 0.32697049921296983"/>
			<geometry>
				<mesh filename="textured_objs/original-14.obj"/>
			</geometry>
		</collision>
		<collision>
			<origin xyz="0 -0.8092115225222722 0.32697049921296983"/>
			<geometry>
				<mesh filename="textured_objs/original-4.obj"/>
			</geometry>
		</collision>
		<collision>
			<origin xyz="0 -0.8092115225222722 0.32697049921296983"/>
			<geometry>
				<mesh filename="textured_objs/original-12.obj"/>
			</geometry>
		</collision>
		<collision>
			<origin xyz="0 -0.8092115225222722 0.32697049921296983"/>
			<geometry>
				<mesh filename="textured_objs/original-13.obj"/>
			</geometry>
		</collision>
	</link>
	<joint name="joint_2" type="revolute">
		<origin xyz="0 1.2700120225222722 -0.20012342555171792"/>
		<axis xyz="1 0 0"/>
		<child link="link_2"/>
		<parent link="link_3"/>
		<limit lower="-0.6283185307179586" upper="0.5277875658030854"/>
	</joint>
	<link name="link_3">
		<visual name="lamp_arm_straight_bar-24">
			<origin xyz="0 0.4608005 0.12684707366125192"/>
			<geometry>
				<mesh filename="textured_objs/original-3.obj"/>
			</geometry>
		</visual>
		<visual name="lamp_arm_straight_bar-23">
			<origin xyz="0 0.4608005 0.12684707366125192"/>
			<geometry>
				<mesh filename="textured_objs/original-2.obj"/>
			</geometry>
		</visual>
		<visual name="lamp_arm_straight_bar-22">
			<origin xyz="0 0.4608005 0.12684707366125192"/>
			<geometry>
				<mesh filename="textured_objs/original-1.obj"/>
			</geometry>
		</visual>
		<visual name="lamp_joint-19">
			<origin xyz="0 0.4608005 0.12684707366125192"/>
			<geometry>
				<mesh filename="textured_objs/original-11.obj"/>
			</geometry>
		</visual>
		<collision>
			<origin xyz="0 0.4608005 0.12684707366125192"/>
			<geometry>
				<mesh filename="textured_objs/original-3.obj"/>
			</geometry>
		</collision>
		<collision>
			<origin xyz="0 0.4608005 0.12684707366125192"/>
			<geometry>
				<mesh filename="textured_objs/original-2.obj"/>
			</geometry>
		</collision>
		<collision>
			<origin xyz="0 0.4608005 0.12684707366125192"/>
			<geometry>
				<mesh filename="textured_objs/original-1.obj"/>
			</geometry>
		</collision>
		<collision>
			<origin xyz="0 0.4608005 0.12684707366125192"/>
			<geometry>
				<mesh filename="textured_objs/original-11.obj"/>
			</geometry>
		</collision>
	</link>
	<joint name="joint_3" type="revolute">
		<origin xyz="0 -0.4608005 -0.12684707366125192"/>
		<axis xyz="1 0 0"/>
		<child link="link_3"/>
		<parent link="link_0"/>
		<limit lower="-0.4461061568097506" upper="0.867079572390783"/>
	</joint>
</robot>
