<?xml version="1.0" ?>
<robot name="partnet_a86e4fb88103550d4dc96c27c8aa82ed">
	<link name="base"/>
	<link name="link_0">
		<visual name="key-3">
			<origin xyz="-0.14903110127823593 -0.11195900000000003 -0.07418220952793346"/>
			<geometry>
				<mesh filename="textured_objs/original-12.obj"/>
			</geometry>
		</visual>
		<collision>
			<origin xyz="-0.14903110127823593 -0.11195900000000003 -0.07418220952793346"/>
			<geometry>
				<mesh filename="textured_objs/original-12.obj"/>
			</geometry>
		</collision>
	</link>
	<joint name="joint_0" type="prismatic">
		<origin xyz="0.14903110127823593 0.11195900000000003 0.07418220952793346"/>
		<axis xyz="0 -1 0"/>
		<child link="link_0"/>
		<parent link="link_24"/>
		<limit lower="0" upper="0.03"/>
	</joint>
	<link name="link_1">
		<visual name="key-4">
			<origin xyz="-0.14903110127823593 -0.11195900000000003 -0.07418220952793346"/>
			<geometry>
				<mesh filename="textured_objs/original-11.obj"/>
			</geometry>
		</visual>
		<collision>
			<origin xyz="-0.14903110127823593 -0.11195900000000003 -0.07418220952793346"/>
			<geometry>
				<mesh filename="textured_objs/original-11.obj"/>
			</geometry>
		</collision>
	</link>
	<joint name="joint_1" type="prismatic">
		<origin xyz="0.14903110127823593 0.11195900000000003 0.07418220952793346"/>
		<axis xyz="0 -1 0"/>
		<child link="link_1"/>
		<parent link="link_24"/>
		<limit lower="0" upper="0.03"/>
	</joint>
	<link name="link_2">
		<visual name="key-5">
			<origin xyz="-0.14903110127823593 -0.11195900000000003 -0.07418220952793346"/>
			<geometry>
				<mesh filename="textured_objs/original-17.obj"/>
			</geometry>
		</visual>
		<collision>
			<origin xyz="-0.14903110127823593 -0.11195900000000003 -0.07418220952793346"/>
			<geometry>
				<mesh filename="textured_objs/original-17.obj"/>
			</geometry>
		</collision>
	</link>
	<joint name="joint_2" type="prismatic">
		<origin xyz="0.14903110127823593 0.11195900000000003 0.07418220952793346"/>
		<axis xyz="0 -1 0"/>
		<child link="link_2"/>
		<parent link="link_24"/>
		<limit lower="0" upper="0.03"/>
	</joint>
	<link name="link_3">
		<visual name="key-6">
			<origin xyz="-0.14903110127823593 -0.11195900000000003 -0.07418220952793346"/>
			<geometry>
				<mesh filename="textured_objs/original-16.obj"/>
			</geometry>
		</visual>
		<collision>
			<origin xyz="-0.14903110127823593 -0.11195900000000003 -0.07418220952793346"/>
			<geometry>
				<mesh filename="textured_objs/original-16.obj"/>
			</geometry>
		</collision>
	</link>
	<joint name="joint_3" type="prismatic">
		<origin xyz="0.14903110127823593 0.11195900000000003 0.07418220952793346"/>
		<axis xyz="0 -1 0"/>
		<child link="link_3"/>
		<parent link="link_24"/>
		<limit lower="0" upper="0.03"/>
	</joint>
	<link name="link_4">
		<visual name="key-7">
			<origin xyz="-0.14903110127823593 -0.11195900000000003 -0.07418220952793346"/>
			<geometry>
				<mesh filename="textured_objs/original-19.obj"/>
			</geometry>
		</visual>
		<collision>
			<origin xyz="-0.14903110127823593 -0.11195900000000003 -0.07418220952793346"/>
			<geometry>
				<mesh filename="textured_objs/original-19.obj"/>
			</geometry>
		</collision>
	</link>
	<joint name="joint_4" type="prismatic">
		<origin xyz="0.14903110127823593 0.11195900000000003 0.07418220952793346"/>
		<axis xyz="0 -1 0"/>
		<child link="link_4"/>
		<parent link="link_24"/>
		<limit lower="0" upper="0.03"/>
	</joint>
	<link name="link_5">
		<visual name="key-8">
			<origin xyz="-0.14903110127823593 -0.11195900000000003 -0.07418220952793346"/>
			<geometry>
				<mesh filename="textured_objs/original-18.obj"/>
			</geometry>
		</visual>
		<collision>
			<origin xyz="-0.14903110127823593 -0.11195900000000003 -0.07418220952793346"/>
			<geometry>
				<mesh filename="textured_objs/original-18.obj"/>
			</geometry>
		</collision>
	</link>
	<joint name="joint_5" type="prismatic">
		<origin xyz="0.14903110127823593 0.11195900000000003 0.07418220952793346"/>
		<axis xyz="0 -1 0"/>
		<child link="link_5"/>
		<parent link="link_24"/>
		<limit lower="0" upper="0.03"/>
	</joint>
	<link name="link_6">
		<visual name="key-9">
			<origin xyz="-0.14903110127823593 -0.11195900000000003 -0.07418220952793346"/>
			<geometry>
				<mesh filename="textured_objs/original-14.obj"/>
			</geometry>
		</visual>
		<collision>
			<origin xyz="-0.14903110127823593 -0.11195900000000003 -0.07418220952793346"/>
			<geometry>
				<mesh filename="textured_objs/original-14.obj"/>
			</geometry>
		</collision>
	</link>
	<joint name="joint_6" type="prismatic">
		<origin xyz="0.14903110127823593 0.11195900000000003 0.07418220952793346"/>
		<axis xyz="0 -1 0"/>
		<child link="link_6"/>
		<parent link="link_24"/>
		<limit lower="0" upper="0.03"/>
	</joint>
	<link name="link_7">
		<visual name="key-10">
			<origin xyz="-0.14903110127823593 -0.11195900000000003 -0.07418220952793346"/>
			<geometry>
				<mesh filename="textured_objs/original-13.obj"/>
			</geometry>
		</visual>
		<collision>
			<origin xyz="-0.14903110127823593 -0.11195900000000003 -0.07418220952793346"/>
			<geometry>
				<mesh filename="textured_objs/original-13.obj"/>
			</geometry>
		</collision>
	</link>
	<joint name="joint_7" type="prismatic">
		<origin xyz="0.14903110127823593 0.11195900000000003 0.07418220952793346"/>
		<axis xyz="0 -1 0"/>
		<child link="link_7"/>
		<parent link="link_24"/>
		<limit lower="0" upper="0.03"/>
	</joint>
	<link name="link_8">
		<visual name="key-11">
			<origin xyz="-0.14903110127823593 -0.11195900000000003 -0.07418220952793346"/>
			<geometry>
				<mesh filename="textured_objs/original-38.obj"/>
			</geometry>
		</visual>
		<collision>
			<origin xyz="-0.14903110127823593 -0.11195900000000003 -0.07418220952793346"/>
			<geometry>
				<mesh filename="textured_objs/original-38.obj"/>
			</geometry>
		</collision>
	</link>
	<joint name="joint_8" type="prismatic">
		<origin xyz="0.14903110127823593 0.11195900000000003 0.07418220952793346"/>
		<axis xyz="0 -1 0"/>
		<child link="link_8"/>
		<parent link="link_24"/>
		<limit lower="0" upper="0.03"/>
	</joint>
	<link name="link_9">
		<visual name="key-12">
			<origin xyz="-0.14903110127823593 -0.11195900000000003 -0.07418220952793346"/>
			<geometry>
				<mesh filename="textured_objs/original-37.obj"/>
			</geometry>
		</visual>
		<collision>
			<origin xyz="-0.14903110127823593 -0.11195900000000003 -0.07418220952793346"/>
			<geometry>
				<mesh filename="textured_objs/original-37.obj"/>
			</geometry>
		</collision>
	</link>
	<joint name="joint_9" type="prismatic">
		<origin xyz="0.14903110127823593 0.11195900000000003 0.07418220952793346"/>
		<axis xyz="0 -1 0"/>
		<child link="link_9"/>
		<parent link="link_24"/>
		<limit lower="0" upper="0.03"/>
	</joint>
	<link name="link_10">
		<visual name="key-13">
			<origin xyz="-0.14903110127823593 -0.11195900000000003 -0.07418220952793346"/>
			<geometry>
				<mesh filename="textured_objs/original-32.obj"/>
			</geometry>
		</visual>
		<collision>
			<origin xyz="-0.14903110127823593 -0.11195900000000003 -0.07418220952793346"/>
			<geometry>
				<mesh filename="textured_objs/original-32.obj"/>
			</geometry>
		</collision>
	</link>
	<joint name="joint_10" type="prismatic">
		<origin xyz="0.14903110127823593 0.11195900000000003 0.07418220952793346"/>
		<axis xyz="0 -1 0"/>
		<child link="link_10"/>
		<parent link="link_24"/>
		<limit lower="0" upper="0.03"/>
	</joint>
	<link name="link_11">
		<visual name="key-14">
			<origin xyz="-0.14903110127823593 -0.11195900000000003 -0.07418220952793346"/>
			<geometry>
				<mesh filename="textured_objs/original-31.obj"/>
			</geometry>
		</visual>
		<collision>
			<origin xyz="-0.14903110127823593 -0.11195900000000003 -0.07418220952793346"/>
			<geometry>
				<mesh filename="textured_objs/original-31.obj"/>
			</geometry>
		</collision>
	</link>
	<joint name="joint_11" type="prismatic">
		<origin xyz="0.14903110127823593 0.11195900000000003 0.07418220952793346"/>
		<axis xyz="0 -1 0"/>
		<child link="link_11"/>
		<parent link="link_24"/>
		<limit lower="0" upper="0.03"/>
	</joint>
	<link name="link_12">
		<visual name="key-15">
			<origin xyz="-0.14903110127823593 -0.11195900000000003 -0.07418220952793346"/>
			<geometry>
				<mesh filename="textured_objs/original-40.obj"/>
			</geometry>
		</visual>
		<collision>
			<origin xyz="-0.14903110127823593 -0.11195900000000003 -0.07418220952793346"/>
			<geometry>
				<mesh filename="textured_objs/original-40.obj"/>
			</geometry>
		</collision>
	</link>
	<joint name="joint_12" type="prismatic">
		<origin xyz="0.14903110127823593 0.11195900000000003 0.07418220952793346"/>
		<axis xyz="0 -1 0"/>
		<child link="link_12"/>
		<parent link="link_24"/>
		<limit lower="0" upper="0.03"/>
	</joint>
	<link name="link_13">
		<visual name="key-16">
			<origin xyz="-0.14903110127823593 -0.11195900000000003 -0.07418220952793346"/>
			<geometry>
				<mesh filename="textured_objs/original-41.obj"/>
			</geometry>
		</visual>
		<collision>
			<origin xyz="-0.14903110127823593 -0.11195900000000003 -0.07418220952793346"/>
			<geometry>
				<mesh filename="textured_objs/original-41.obj"/>
			</geometry>
		</collision>
	</link>
	<joint name="joint_13" type="prismatic">
		<origin xyz="0.14903110127823593 0.11195900000000003 0.07418220952793346"/>
		<axis xyz="0 -1 0"/>
		<child link="link_13"/>
		<parent link="link_24"/>
		<limit lower="0" upper="0.03"/>
	</joint>
	<link name="link_14">
		<visual name="key-17">
			<origin xyz="-0.14903110127823593 -0.11195900000000003 -0.07418220952793346"/>
			<geometry>
				<mesh filename="textured_objs/original-34.obj"/>
			</geometry>
		</visual>
		<collision>
			<origin xyz="-0.14903110127823593 -0.11195900000000003 -0.07418220952793346"/>
			<geometry>
				<mesh filename="textured_objs/original-34.obj"/>
			</geometry>
		</collision>
	</link>
	<joint name="joint_14" type="prismatic">
		<origin xyz="0.14903110127823593 0.11195900000000003 0.07418220952793346"/>
		<axis xyz="0 -1 0"/>
		<child link="link_14"/>
		<parent link="link_24"/>
		<limit lower="0" upper="0.03"/>
	</joint>
	<link name="link_15">
		<visual name="key-18">
			<origin xyz="-0.14903110127823593 -0.11195900000000003 -0.07418220952793346"/>
			<geometry>
				<mesh filename="textured_objs/original-35.obj"/>
			</geometry>
		</visual>
		<collision>
			<origin xyz="-0.14903110127823593 -0.11195900000000003 -0.07418220952793346"/>
			<geometry>
				<mesh filename="textured_objs/original-35.obj"/>
			</geometry>
		</collision>
	</link>
	<joint name="joint_15" type="prismatic">
		<origin xyz="0.14903110127823593 0.11195900000000003 0.07418220952793346"/>
		<axis xyz="0 -1 0"/>
		<child link="link_15"/>
		<parent link="link_24"/>
		<limit lower="0" upper="0.03"/>
	</joint>
	<link name="link_16">
		<visual name="key-19">
			<origin xyz="-0.14903110127823593 -0.11195900000000003 -0.07418220952793346"/>
			<geometry>
				<mesh filename="textured_objs/original-22.obj"/>
			</geometry>
		</visual>
		<collision>
			<origin xyz="-0.14903110127823593 -0.11195900000000003 -0.07418220952793346"/>
			<geometry>
				<mesh filename="textured_objs/original-22.obj"/>
			</geometry>
		</collision>
	</link>
	<joint name="joint_16" type="prismatic">
		<origin xyz="0.14903110127823593 0.11195900000000003 0.07418220952793346"/>
		<axis xyz="0 -1 0"/>
		<child link="link_16"/>
		<parent link="link_24"/>
		<limit lower="0" upper="0.03"/>
	</joint>
	<link name="link_17">
		<visual name="key-20">
			<origin xyz="-0.14903110127823593 -0.11195900000000003 -0.07418220952793346"/>
			<geometry>
				<mesh filename="textured_objs/original-21.obj"/>
			</geometry>
		</visual>
		<collision>
			<origin xyz="-0.14903110127823593 -0.11195900000000003 -0.07418220952793346"/>
			<geometry>
				<mesh filename="textured_objs/original-21.obj"/>
			</geometry>
		</collision>
	</link>
	<joint name="joint_17" type="prismatic">
		<origin xyz="0.14903110127823593 0.11195900000000003 0.07418220952793346"/>
		<axis xyz="0 -1 0"/>
		<child link="link_17"/>
		<parent link="link_24"/>
		<limit lower="0" upper="0.03"/>
	</joint>
	<link name="link_18">
		<visual name="key-21">
			<origin xyz="-0.14903110127823593 -0.11195900000000003 -0.07418220952793346"/>
			<geometry>
				<mesh filename="textured_objs/original-27.obj"/>
			</geometry>
		</visual>
		<collision>
			<origin xyz="-0.14903110127823593 -0.11195900000000003 -0.07418220952793346"/>
			<geometry>
				<mesh filename="textured_objs/original-27.obj"/>
			</geometry>
		</collision>
	</link>
	<joint name="joint_18" type="prismatic">
		<origin xyz="0.14903110127823593 0.11195900000000003 0.07418220952793346"/>
		<axis xyz="0 -1 0"/>
		<child link="link_18"/>
		<parent link="link_24"/>
		<limit lower="0" upper="0.03"/>
	</joint>
	<link name="link_19">
		<visual name="key-22">
			<origin xyz="-0.14903110127823593 -0.11195900000000003 -0.07418220952793346"/>
			<geometry>
				<mesh filename="textured_objs/original-26.obj"/>
			</geometry>
		</visual>
		<collision>
			<origin xyz="-0.14903110127823593 -0.11195900000000003 -0.07418220952793346"/>
			<geometry>
				<mesh filename="textured_objs/original-26.obj"/>
			</geometry>
		</collision>
	</link>
	<joint name="joint_19" type="prismatic">
		<origin xyz="0.14903110127823593 0.11195900000000003 0.07418220952793346"/>
		<axis xyz="0 -1 0"/>
		<child link="link_19"/>
		<parent link="link_24"/>
		<limit lower="0" upper="0.03"/>
	</joint>
	<link name="link_20">
		<visual name="key-23">
			<origin xyz="-0.14903110127823593 -0.11195900000000003 -0.07418220952793346"/>
			<geometry>
				<mesh filename="textured_objs/original-29.obj"/>
			</geometry>
		</visual>
		<collision>
			<origin xyz="-0.14903110127823593 -0.11195900000000003 -0.07418220952793346"/>
			<geometry>
				<mesh filename="textured_objs/original-29.obj"/>
			</geometry>
		</collision>
	</link>
	<joint name="joint_20" type="prismatic">
		<origin xyz="0.14903110127823593 0.11195900000000003 0.07418220952793346"/>
		<axis xyz="0 -1 0"/>
		<child link="link_20"/>
		<parent link="link_24"/>
		<limit lower="0" upper="0.03"/>
	</joint>
	<link name="link_21">
		<visual name="key-24">
			<origin xyz="-0.14903110127823593 -0.11195900000000003 -0.07418220952793346"/>
			<geometry>
				<mesh filename="textured_objs/original-28.obj"/>
			</geometry>
		</visual>
		<collision>
			<origin xyz="-0.14903110127823593 -0.11195900000000003 -0.07418220952793346"/>
			<geometry>
				<mesh filename="textured_objs/original-28.obj"/>
			</geometry>
		</collision>
	</link>
	<joint name="joint_21" type="prismatic">
		<origin xyz="0.14903110127823593 0.11195900000000003 0.07418220952793346"/>
		<axis xyz="0 -1 0"/>
		<child link="link_21"/>
		<parent link="link_24"/>
		<limit lower="0" upper="0.03"/>
	</joint>
	<link name="link_22">
		<visual name="key-25">
			<origin xyz="-0.14903110127823593 -0.11195900000000003 -0.07418220952793346"/>
			<geometry>
				<mesh filename="textured_objs/original-24.obj"/>
			</geometry>
		</visual>
		<collision>
			<origin xyz="-0.14903110127823593 -0.11195900000000003 -0.07418220952793346"/>
			<geometry>
				<mesh filename="textured_objs/original-24.obj"/>
			</geometry>
		</collision>
	</link>
	<joint name="joint_22" type="prismatic">
		<origin xyz="0.14903110127823593 0.11195900000000003 0.07418220952793346"/>
		<axis xyz="0 -1 0"/>
		<child link="link_22"/>
		<parent link="link_24"/>
		<limit lower="0" upper="0.03"/>
	</joint>
	<link name="link_23">
		<visual name="key-26">
			<origin xyz="-0.14903110127823593 -0.11195900000000003 -0.07418220952793346"/>
			<geometry>
				<mesh filename="textured_objs/original-23.obj"/>
			</geometry>
		</visual>
		<collision>
			<origin xyz="-0.14903110127823593 -0.11195900000000003 -0.07418220952793346"/>
			<geometry>
				<mesh filename="textured_objs/original-23.obj"/>
			</geometry>
		</collision>
	</link>
	<joint name="joint_23" type="prismatic">
		<origin xyz="0.14903110127823593 0.11195900000000003 0.07418220952793346"/>
		<axis xyz="0 -1 0"/>
		<child link="link_23"/>
		<parent link="link_24"/>
		<limit lower="0" upper="0.03"/>
	</joint>
	<link name="link_24">
		<visual name="frame-2">
			<origin xyz="0 0 0"/>
			<geometry>
				<mesh filename="textured_objs/original-42.obj"/>
			</geometry>
		</visual>
		<visual name="tilt_leg-27">
			<origin xyz="0 0 0"/>
			<geometry>
				<mesh filename="textured_objs/original-6.obj"/>
			</geometry>
		</visual>
		<visual name="tilt_leg-27">
			<origin xyz="0 0 0"/>
			<geometry>
				<mesh filename="textured_objs/original-5.obj"/>
			</geometry>
		</visual>
		<visual name="tilt_leg-28">
			<origin xyz="0 0 0"/>
			<geometry>
				<mesh filename="textured_objs/original-9.obj"/>
			</geometry>
		</visual>
		<visual name="tilt_leg-28">
			<origin xyz="0 0 0"/>
			<geometry>
				<mesh filename="textured_objs/original-8.obj"/>
			</geometry>
		</visual>
		<collision>
			<origin xyz="0 0 0"/>
			<geometry>
				<mesh filename="textured_objs/original-42.obj"/>
			</geometry>
		</collision>
		<collision>
			<origin xyz="0 0 0"/>
			<geometry>
				<mesh filename="textured_objs/original-6.obj"/>
			</geometry>
		</collision>
		<collision>
			<origin xyz="0 0 0"/>
			<geometry>
				<mesh filename="textured_objs/original-5.obj"/>
			</geometry>
		</collision>
		<collision>
			<origin xyz="0 0 0"/>
			<geometry>
				<mesh filename="textured_objs/original-9.obj"/>
			</geometry>
		</collision>
		<collision>
			<origin xyz="0 0 0"/>
			<geometry>
				<mesh filename="textured_objs/original-8.obj"/>
			</geometry>
		</collision>
	</link>
	<joint name="joint_24" type="fixed">
		<origin rpy="1.570796326794897 0 -1.570796326794897" xyz="0 0 0"/>
		<child link="link_24"/>
		<parent link="base"/>
	</joint>
</robot>
