<?xml version="1.0" ?>
<robot name="partnet_1eb1a8acd4185f49492d9da2668ec34c">
	<link name="base"/>
	<link name="link_0">
		<visual name="other_leaf-50">
			<origin xyz="0.08758178884536025 0.17931442082973814 0"/>
			<geometry>
				<mesh filename="textured_objs/original-38.obj"/>
			</geometry>
		</visual>
		<visual name="other_leaf-50">
			<origin xyz="0.08758178884536025 0.17931442082973814 0"/>
			<geometry>
				<mesh filename="textured_objs/original-39.obj"/>
			</geometry>
		</visual>
		<collision>
			<origin xyz="0.08758178884536025 0.17931442082973814 0"/>
			<geometry>
				<mesh filename="textured_objs/original-38.obj"/>
			</geometry>
		</collision>
		<collision>
			<origin xyz="0.08758178884536025 0.17931442082973814 0"/>
			<geometry>
				<mesh filename="textured_objs/original-39.obj"/>
			</geometry>
		</collision>
	</link>
	<joint name="joint_0" type="revolute">
		<origin xyz="-0.09024308911687266 -0.17931442082973814 -0.04584507514915078"/>
		<axis xyz="0 0 1"/>
		<child link="link_0"/>
		<parent link="link_12"/>
		<limit lower="0.0" upper="0.3490658503988659"/>
	</joint>
	<link name="link_1">
		<visual name="other_leaf-49">
			<origin xyz="-0.0019056438466762127 -0.02998431136688887 -0.16884661957582242"/>
			<geometry>
				<mesh filename="textured_objs/original-40.obj"/>
			</geometry>
		</visual>
		<collision>
			<origin xyz="-0.0019056438466762127 -0.02998431136688887 -0.16884661957582242"/>
			<geometry>
				<mesh filename="textured_objs/original-40.obj"/>
			</geometry>
		</collision>
	</link>
	<joint name="joint_1" type="continuous">
		<origin xyz="-0.0007556564248362041 0.02998431136688887 0.12300154442667163"/>
		<axis xyz="0.0015166058333588857 -0.9845973336465781 0.17483074810454702"/>
		<child link="link_1"/>
		<parent link="link_12"/>
	</joint>
	<link name="link_2">
		<visual name="wheel-36">
			<origin xyz="0 0.7676384494744843 0.08673227475918789"/>
			<geometry>
				<mesh filename="textured_objs/original-32.obj"/>
			</geometry>
		</visual>
		<collision>
			<origin xyz="0 0.7676384494744843 0.08673227475918789"/>
			<geometry>
				<mesh filename="textured_objs/original-32.obj"/>
			</geometry>
		</collision>
	</link>
	<joint name="joint_2" type="continuous">
		<origin xyz="-0.49892527319437047 -0.7676384494744843 0.029070909002104406"/>
		<axis xyz="1 0 0"/>
		<child link="link_2"/>
		<parent link="link_14"/>
	</joint>
	<link name="link_3">
		<visual name="wheel-37">
			<origin xyz="0 0.7676384494744843 0.08673227475918789"/>
			<geometry>
				<mesh filename="textured_objs/original-33.obj"/>
			</geometry>
		</visual>
		<collision>
			<origin xyz="0 0.7676384494744843 0.08673227475918789"/>
			<geometry>
				<mesh filename="textured_objs/original-33.obj"/>
			</geometry>
		</collision>
	</link>
	<joint name="joint_3" type="continuous">
		<origin xyz="-0.49892527319437047 -0.7676384494744843 0.029070909002104406"/>
		<axis xyz="1 0 0"/>
		<child link="link_3"/>
		<parent link="link_14"/>
	</joint>
	<link name="link_4">
		<visual name="wheel-28">
			<origin xyz="0 0.7676384494744843 0.08673227475918789"/>
			<geometry>
				<mesh filename="textured_objs/original-19.obj"/>
			</geometry>
		</visual>
		<collision>
			<origin xyz="0 0.7676384494744843 0.08673227475918789"/>
			<geometry>
				<mesh filename="textured_objs/original-19.obj"/>
			</geometry>
		</collision>
	</link>
	<joint name="joint_4" type="continuous">
		<origin xyz="0.4943110266693962 -0.7676384494744843 0.02903601737750762"/>
		<axis xyz="1 0 0"/>
		<child link="link_4"/>
		<parent link="link_15"/>
	</joint>
	<link name="link_5">
		<visual name="wheel-29">
			<origin xyz="0 0.7676384494744843 0.08673227475918789"/>
			<geometry>
				<mesh filename="textured_objs/original-18.obj"/>
			</geometry>
		</visual>
		<collision>
			<origin xyz="0 0.7676384494744843 0.08673227475918789"/>
			<geometry>
				<mesh filename="textured_objs/original-18.obj"/>
			</geometry>
		</collision>
	</link>
	<joint name="joint_5" type="continuous">
		<origin xyz="0.4943110266693962 -0.7676384494744843 0.02903601737750762"/>
		<axis xyz="1 0 0"/>
		<child link="link_5"/>
		<parent link="link_15"/>
	</joint>
	<link name="link_6">
		<visual name="wheel-40">
			<origin xyz="0 0.7668542907433894 -0.49712682961576904"/>
			<geometry>
				<mesh filename="textured_objs/original-27.obj"/>
			</geometry>
		</visual>
		<collision>
			<origin xyz="0 0.7668542907433894 -0.49712682961576904"/>
			<geometry>
				<mesh filename="textured_objs/original-27.obj"/>
			</geometry>
		</collision>
	</link>
	<joint name="joint_6" type="continuous">
		<origin xyz="-0.31220304188806614 -0.7668542907433894 0.027962431978830082"/>
		<axis xyz="1 0 0"/>
		<child link="link_6"/>
		<parent link="link_16"/>
	</joint>
	<link name="link_7">
		<visual name="wheel-41">
			<origin xyz="0 0.7668542907433894 -0.49712682961576904"/>
			<geometry>
				<mesh filename="textured_objs/original-28.obj"/>
			</geometry>
		</visual>
		<collision>
			<origin xyz="0 0.7668542907433894 -0.49712682961576904"/>
			<geometry>
				<mesh filename="textured_objs/original-28.obj"/>
			</geometry>
		</collision>
	</link>
	<joint name="joint_7" type="continuous">
		<origin xyz="-0.31220304188806614 -0.7668542907433894 0.027962431978830082"/>
		<axis xyz="1 0 0"/>
		<child link="link_7"/>
		<parent link="link_16"/>
	</joint>
	<link name="link_8">
		<visual name="wheel-32">
			<origin xyz="0 0.7669958088497665 0.44746406393353894"/>
			<geometry>
				<mesh filename="textured_objs/original-16.obj"/>
			</geometry>
		</visual>
		<collision>
			<origin xyz="0 0.7669958088497665 0.44746406393353894"/>
			<geometry>
				<mesh filename="textured_objs/original-16.obj"/>
			</geometry>
		</collision>
	</link>
	<joint name="joint_8" type="continuous">
		<origin xyz="-0.002661499999999999 -0.7669958088497665 0.028867436066461083"/>
		<axis xyz="1 0 0"/>
		<child link="link_8"/>
		<parent link="link_17"/>
	</joint>
	<link name="link_9">
		<visual name="wheel-33">
			<origin xyz="0 0.7669958088497665 0.44746406393353894"/>
			<geometry>
				<mesh filename="textured_objs/original-15.obj"/>
			</geometry>
		</visual>
		<collision>
			<origin xyz="0 0.7669958088497665 0.44746406393353894"/>
			<geometry>
				<mesh filename="textured_objs/original-15.obj"/>
			</geometry>
		</collision>
	</link>
	<joint name="joint_9" type="continuous">
		<origin xyz="-0.002661499999999999 -0.7669958088497665 0.028867436066461083"/>
		<axis xyz="1 0 0"/>
		<child link="link_9"/>
		<parent link="link_17"/>
	</joint>
	<link name="link_10">
		<visual name="wheel-22">
			<origin xyz="0 0.7668466622264941 -0.497145060363395"/>
			<geometry>
				<mesh filename="textured_objs/original-23.obj"/>
			</geometry>
		</visual>
		<collision>
			<origin xyz="0 0.7668466622264941 -0.497145060363395"/>
			<geometry>
				<mesh filename="textured_objs/original-23.obj"/>
			</geometry>
		</collision>
	</link>
	<joint name="joint_10" type="continuous">
		<origin xyz="0.3023610324586857 -0.7668466622264941 0.026481793139690457"/>
		<axis xyz="1 0 0"/>
		<child link="link_10"/>
		<parent link="link_18"/>
	</joint>
	<link name="link_11">
		<visual name="wheel-23">
			<origin xyz="0 0.7668466622264941 -0.497145060363395"/>
			<geometry>
				<mesh filename="textured_objs/original-22.obj"/>
			</geometry>
		</visual>
		<collision>
			<origin xyz="0 0.7668466622264941 -0.497145060363395"/>
			<geometry>
				<mesh filename="textured_objs/original-22.obj"/>
			</geometry>
		</collision>
	</link>
	<joint name="joint_11" type="continuous">
		<origin xyz="0.3023610324586857 -0.7668466622264941 0.026481793139690457"/>
		<axis xyz="1 0 0"/>
		<child link="link_11"/>
		<parent link="link_18"/>
	</joint>
	<link name="link_12">
		<visual name="back_soft_surface-45">
			<origin xyz="-0.002661300271512417 0 -0.04584507514915078"/>
			<geometry>
				<mesh filename="textured_objs/new-6.obj"/>
			</geometry>
		</visual>
		<visual name="seat_soft_surface-43">
			<origin xyz="-0.002661300271512417 0 -0.04584507514915078"/>
			<geometry>
				<mesh filename="textured_objs/new-7.obj"/>
			</geometry>
		</visual>
		<visual name="seat_support-46">
			<origin xyz="-0.002661300271512417 0 -0.04584507514915078"/>
			<geometry>
				<mesh filename="textured_objs/original-37.obj"/>
			</geometry>
		</visual>
		<collision>
			<origin xyz="-0.002661300271512417 0 -0.04584507514915078"/>
			<geometry>
				<mesh filename="textured_objs/new-6.obj"/>
			</geometry>
		</collision>
		<collision>
			<origin xyz="-0.002661300271512417 0 -0.04584507514915078"/>
			<geometry>
				<mesh filename="textured_objs/new-7.obj"/>
			</geometry>
		</collision>
		<collision>
			<origin xyz="-0.002661300271512417 0 -0.04584507514915078"/>
			<geometry>
				<mesh filename="textured_objs/original-37.obj"/>
			</geometry>
		</collision>
	</link>
	<joint name="joint_12" type="continuous">
		<origin xyz="0.0 0 0.0"/>
		<axis xyz="0 1 0"/>
		<child link="link_12"/>
		<parent link="link_12_helper"/>
	</joint>
	<link name="link_13">
		<visual name="central_support-5">
			<origin xyz="0 0 0"/>
			<geometry>
				<mesh filename="textured_objs/original-13.obj"/>
			</geometry>
		</visual>
		<visual name="central_support-5">
			<origin xyz="0 0 0"/>
			<geometry>
				<mesh filename="textured_objs/original-14.obj"/>
			</geometry>
		</visual>
		<visual name="leg-7">
			<origin xyz="0 0 0"/>
			<geometry>
				<mesh filename="textured_objs/original-1.obj"/>
			</geometry>
		</visual>
		<visual name="leg-7">
			<origin xyz="0 0 0"/>
			<geometry>
				<mesh filename="textured_objs/new-2.obj"/>
			</geometry>
		</visual>
		<visual name="leg-8">
			<origin xyz="0 0 0"/>
			<geometry>
				<mesh filename="textured_objs/original-4.obj"/>
			</geometry>
		</visual>
		<visual name="leg-8">
			<origin xyz="0 0 0"/>
			<geometry>
				<mesh filename="textured_objs/new-1.obj"/>
			</geometry>
		</visual>
		<visual name="leg-8">
			<origin xyz="0 0 0"/>
			<geometry>
				<mesh filename="textured_objs/original-5.obj"/>
			</geometry>
		</visual>
		<visual name="leg-9">
			<origin xyz="0 0 0"/>
			<geometry>
				<mesh filename="textured_objs/new-0.obj"/>
			</geometry>
		</visual>
		<visual name="leg-9">
			<origin xyz="0 0 0"/>
			<geometry>
				<mesh filename="textured_objs/original-8.obj"/>
			</geometry>
		</visual>
		<visual name="leg-9">
			<origin xyz="0 0 0"/>
			<geometry>
				<mesh filename="textured_objs/original-6.obj"/>
			</geometry>
		</visual>
		<visual name="leg-9">
			<origin xyz="0 0 0"/>
			<geometry>
				<mesh filename="textured_objs/original-7.obj"/>
			</geometry>
		</visual>
		<visual name="leg-10">
			<origin xyz="0 0 0"/>
			<geometry>
				<mesh filename="textured_objs/new-4.obj"/>
			</geometry>
		</visual>
		<visual name="leg-10">
			<origin xyz="0 0 0"/>
			<geometry>
				<mesh filename="textured_objs/original-9.obj"/>
			</geometry>
		</visual>
		<visual name="leg-10">
			<origin xyz="0 0 0"/>
			<geometry>
				<mesh filename="textured_objs/original-10.obj"/>
			</geometry>
		</visual>
		<visual name="leg-11">
			<origin xyz="0 0 0"/>
			<geometry>
				<mesh filename="textured_objs/new-3.obj"/>
			</geometry>
		</visual>
		<visual name="leg-11">
			<origin xyz="0 0 0"/>
			<geometry>
				<mesh filename="textured_objs/original-11.obj"/>
			</geometry>
		</visual>
		<visual name="leg-11">
			<origin xyz="0 0 0"/>
			<geometry>
				<mesh filename="textured_objs/original-12.obj"/>
			</geometry>
		</visual>
		<collision>
			<origin xyz="0 0 0"/>
			<geometry>
				<mesh filename="textured_objs/original-13.obj"/>
			</geometry>
		</collision>
		<collision>
			<origin xyz="0 0 0"/>
			<geometry>
				<mesh filename="textured_objs/original-14.obj"/>
			</geometry>
		</collision>
		<collision>
			<origin xyz="0 0 0"/>
			<geometry>
				<mesh filename="textured_objs/original-1.obj"/>
			</geometry>
		</collision>
		<collision>
			<origin xyz="0 0 0"/>
			<geometry>
				<mesh filename="textured_objs/new-2.obj"/>
			</geometry>
		</collision>
		<collision>
			<origin xyz="0 0 0"/>
			<geometry>
				<mesh filename="textured_objs/original-4.obj"/>
			</geometry>
		</collision>
		<collision>
			<origin xyz="0 0 0"/>
			<geometry>
				<mesh filename="textured_objs/new-1.obj"/>
			</geometry>
		</collision>
		<collision>
			<origin xyz="0 0 0"/>
			<geometry>
				<mesh filename="textured_objs/original-5.obj"/>
			</geometry>
		</collision>
		<collision>
			<origin xyz="0 0 0"/>
			<geometry>
				<mesh filename="textured_objs/new-0.obj"/>
			</geometry>
		</collision>
		<collision>
			<origin xyz="0 0 0"/>
			<geometry>
				<mesh filename="textured_objs/original-8.obj"/>
			</geometry>
		</collision>
		<collision>
			<origin xyz="0 0 0"/>
			<geometry>
				<mesh filename="textured_objs/original-6.obj"/>
			</geometry>
		</collision>
		<collision>
			<origin xyz="0 0 0"/>
			<geometry>
				<mesh filename="textured_objs/original-7.obj"/>
			</geometry>
		</collision>
		<collision>
			<origin xyz="0 0 0"/>
			<geometry>
				<mesh filename="textured_objs/new-4.obj"/>
			</geometry>
		</collision>
		<collision>
			<origin xyz="0 0 0"/>
			<geometry>
				<mesh filename="textured_objs/original-9.obj"/>
			</geometry>
		</collision>
		<collision>
			<origin xyz="0 0 0"/>
			<geometry>
				<mesh filename="textured_objs/original-10.obj"/>
			</geometry>
		</collision>
		<collision>
			<origin xyz="0 0 0"/>
			<geometry>
				<mesh filename="textured_objs/new-3.obj"/>
			</geometry>
		</collision>
		<collision>
			<origin xyz="0 0 0"/>
			<geometry>
				<mesh filename="textured_objs/original-11.obj"/>
			</geometry>
		</collision>
		<collision>
			<origin xyz="0 0 0"/>
			<geometry>
				<mesh filename="textured_objs/original-12.obj"/>
			</geometry>
		</collision>
	</link>
	<joint name="joint_13" type="fixed">
		<origin rpy="1.570796326794897 0 -1.570796326794897" xyz="0 0 0"/>
		<child link="link_13"/>
		<parent link="base"/>
	</joint>
	<link name="link_14">
		<visual name="caster_yoke-34">
			<origin xyz="-0.49892527319437047 0 0.1158031837612923"/>
			<geometry>
				<mesh filename="textured_objs/original-35.obj"/>
			</geometry>
		</visual>
		<visual name="caster_stem-35">
			<origin xyz="-0.49892527319437047 0 0.1158031837612923"/>
			<geometry>
				<mesh filename="textured_objs/original-34.obj"/>
			</geometry>
		</visual>
		<collision>
			<origin xyz="-0.49892527319437047 0 0.1158031837612923"/>
			<geometry>
				<mesh filename="textured_objs/original-35.obj"/>
			</geometry>
		</collision>
		<collision>
			<origin xyz="-0.49892527319437047 0 0.1158031837612923"/>
			<geometry>
				<mesh filename="textured_objs/original-34.obj"/>
			</geometry>
		</collision>
	</link>
	<joint name="joint_14" type="continuous">
		<origin xyz="0.49892527319437047 0 -0.1158031837612923"/>
		<axis xyz="0 1 0"/>
		<child link="link_14"/>
		<parent link="link_13"/>
	</joint>
	<link name="link_15">
		<visual name="caster_yoke-26">
			<origin xyz="0.4943110266693962 0 0.11576829213669551"/>
			<geometry>
				<mesh filename="textured_objs/original-20.obj"/>
			</geometry>
		</visual>
		<visual name="caster_stem-27">
			<origin xyz="0.4943110266693962 0 0.11576829213669551"/>
			<geometry>
				<mesh filename="textured_objs/original-21.obj"/>
			</geometry>
		</visual>
		<collision>
			<origin xyz="0.4943110266693962 0 0.11576829213669551"/>
			<geometry>
				<mesh filename="textured_objs/original-20.obj"/>
			</geometry>
		</collision>
		<collision>
			<origin xyz="0.4943110266693962 0 0.11576829213669551"/>
			<geometry>
				<mesh filename="textured_objs/original-21.obj"/>
			</geometry>
		</collision>
	</link>
	<joint name="joint_15" type="continuous">
		<origin xyz="-0.4943110266693962 0 -0.11576829213669551"/>
		<axis xyz="0 1 0"/>
		<child link="link_15"/>
		<parent link="link_13"/>
	</joint>
	<link name="link_16">
		<visual name="caster_yoke-38">
			<origin xyz="-0.31220304188806614 0 -0.46916439763693896"/>
			<geometry>
				<mesh filename="textured_objs/original-30.obj"/>
			</geometry>
		</visual>
		<visual name="caster_stem-39">
			<origin xyz="-0.31220304188806614 0 -0.46916439763693896"/>
			<geometry>
				<mesh filename="textured_objs/original-29.obj"/>
			</geometry>
		</visual>
		<collision>
			<origin xyz="-0.31220304188806614 0 -0.46916439763693896"/>
			<geometry>
				<mesh filename="textured_objs/original-30.obj"/>
			</geometry>
		</collision>
		<collision>
			<origin xyz="-0.31220304188806614 0 -0.46916439763693896"/>
			<geometry>
				<mesh filename="textured_objs/original-29.obj"/>
			</geometry>
		</collision>
	</link>
	<joint name="joint_16" type="continuous">
		<origin xyz="0.31220304188806614 0 0.46916439763693896"/>
		<axis xyz="0 1 0"/>
		<child link="link_16"/>
		<parent link="link_13"/>
	</joint>
	<link name="link_17">
		<visual name="caster_yoke-30">
			<origin xyz="-0.002661499999999999 0 0.4763315"/>
			<geometry>
				<mesh filename="textured_objs/original-2.obj"/>
			</geometry>
		</visual>
		<visual name="caster_stem-31">
			<origin xyz="-0.002661499999999999 0 0.4763315"/>
			<geometry>
				<mesh filename="textured_objs/original-17.obj"/>
			</geometry>
		</visual>
		<collision>
			<origin xyz="-0.002661499999999999 0 0.4763315"/>
			<geometry>
				<mesh filename="textured_objs/original-2.obj"/>
			</geometry>
		</collision>
		<collision>
			<origin xyz="-0.002661499999999999 0 0.4763315"/>
			<geometry>
				<mesh filename="textured_objs/original-17.obj"/>
			</geometry>
		</collision>
	</link>
	<joint name="joint_17" type="continuous">
		<origin xyz="0.002661499999999999 0 -0.4763315"/>
		<axis xyz="0 1 0"/>
		<child link="link_17"/>
		<parent link="link_13"/>
	</joint>
	<link name="link_18">
		<visual name="caster_yoke-24">
			<origin xyz="0.3023610324586857 0 -0.47066326722370455"/>
			<geometry>
				<mesh filename="textured_objs/original-24.obj"/>
			</geometry>
		</visual>
		<visual name="caster_stem-25">
			<origin xyz="0.3023610324586857 0 -0.47066326722370455"/>
			<geometry>
				<mesh filename="textured_objs/original-25.obj"/>
			</geometry>
		</visual>
		<collision>
			<origin xyz="0.3023610324586857 0 -0.47066326722370455"/>
			<geometry>
				<mesh filename="textured_objs/original-24.obj"/>
			</geometry>
		</collision>
		<collision>
			<origin xyz="0.3023610324586857 0 -0.47066326722370455"/>
			<geometry>
				<mesh filename="textured_objs/original-25.obj"/>
			</geometry>
		</collision>
	</link>
	<joint name="joint_18" type="continuous">
		<origin xyz="-0.3023610324586857 0 0.47066326722370455"/>
		<axis xyz="0 1 0"/>
		<child link="link_18"/>
		<parent link="link_13"/>
	</joint>
	<link name="link_12_helper"/>
	<joint name="joint_19" type="prismatic">
		<origin xyz="0.002661300271512417 0 0.04584507514915078"/>
		<axis xyz="0 -1 0"/>
		<child link="link_12_helper"/>
		<parent link="link_13"/>
		<limit lower="0" upper="0.1"/>
	</joint>
</robot>
