<?xml version="1.0" ?>
<robot name="partnet_af913c310f1b978ae6488a574e8954a5">
	<link name="base"/>
	<link name="link_0">
		<visual name="surface-4">
			<origin xyz="0 0 0"/>
			<geometry>
				<mesh filename="textured_objs/new-0.obj"/>
			</geometry>
		</visual>
		<visual name="frame-9">
			<origin xyz="0 0 0"/>
			<geometry>
				<mesh filename="textured_objs/new-4.obj"/>
			</geometry>
		</visual>
		<collision>
			<origin xyz="0 0 0"/>
			<geometry>
				<mesh filename="textured_objs/new-0.obj"/>
			</geometry>
		</collision>
		<collision>
			<origin xyz="0 0 0"/>
			<geometry>
				<mesh filename="textured_objs/new-4.obj"/>
			</geometry>
		</collision>
	</link>
	<joint name="joint_0" type="fixed">
		<origin rpy="1.570796326794897 0 -1.570796326794897" xyz="0 0 0"/>
		<child link="link_0"/>
		<parent link="base"/>
	</joint>
	<link name="link_1">
		<visual name="control_button-11">
			<origin xyz="-0.40451000000000015 0.6242565289820224 -0.5253691514495505"/>
			<geometry>
				<mesh filename="textured_objs/new-1.obj"/>
			</geometry>
		</visual>
		<visual name="door_frame-7">
			<origin xyz="-0.40451000000000015 0.6242565289820224 -0.5253691514495505"/>
			<geometry>
				<mesh filename="textured_objs/original-2.obj"/>
			</geometry>
		</visual>
		<visual name="door_frame-7">
			<origin xyz="-0.40451000000000015 0.6242565289820224 -0.5253691514495505"/>
			<geometry>
				<mesh filename="textured_objs/new-3.obj"/>
			</geometry>
		</visual>
		<visual name="handle-8">
			<origin xyz="-0.40451000000000015 0.6242565289820224 -0.5253691514495505"/>
			<geometry>
				<mesh filename="textured_objs/new-2.obj"/>
			</geometry>
		</visual>
		<collision>
			<origin xyz="-0.40451000000000015 0.6242565289820224 -0.5253691514495505"/>
			<geometry>
				<mesh filename="textured_objs/new-1.obj"/>
			</geometry>
		</collision>
		<collision>
			<origin xyz="-0.40451000000000015 0.6242565289820224 -0.5253691514495505"/>
			<geometry>
				<mesh filename="textured_objs/original-2.obj"/>
			</geometry>
		</collision>
		<collision>
			<origin xyz="-0.40451000000000015 0.6242565289820224 -0.5253691514495505"/>
			<geometry>
				<mesh filename="textured_objs/new-3.obj"/>
			</geometry>
		</collision>
		<collision>
			<origin xyz="-0.40451000000000015 0.6242565289820224 -0.5253691514495505"/>
			<geometry>
				<mesh filename="textured_objs/new-2.obj"/>
			</geometry>
		</collision>
	</link>
	<joint name="joint_1" type="revolute">
		<origin xyz="0.40451000000000015 -0.6242565289820224 0.5253691514495505"/>
		<axis xyz="1 0 0"/>
		<child link="link_1"/>
		<parent link="link_0"/>
		<limit lower="0.0" upper="1.5707963267948966"/>
	</joint>
</robot>
