<?xml version="1.0" ?>
<robot name="partnet_d95f6ea8-cda0-4d59-aa49-11309e3f0ce3">
	<link name="base"/>
	<link name="link_0">
		<visual name="door_frame-8">
			<origin xyz="-0.5346630000000001 0.5370628002460592 -0.40417018345276656"/>
			<geometry>
				<mesh filename="textured_objs/original-13.obj"/>
			</geometry>
		</visual>
		<visual name="door_frame-8">
			<origin xyz="-0.5346630000000001 0.5370628002460592 -0.40417018345276656"/>
			<geometry>
				<mesh filename="textured_objs/original-6.obj"/>
			</geometry>
		</visual>
		<visual name="door_frame-8">
			<origin xyz="-0.5346630000000001 0.5370628002460592 -0.40417018345276656"/>
			<geometry>
				<mesh filename="textured_objs/original-12.obj"/>
			</geometry>
		</visual>
		<visual name="door_frame-8">
			<origin xyz="-0.5346630000000001 0.5370628002460592 -0.40417018345276656"/>
			<geometry>
				<mesh filename="textured_objs/original-16.obj"/>
			</geometry>
		</visual>
		<visual name="door_frame-8">
			<origin xyz="-0.5346630000000001 0.5370628002460592 -0.40417018345276656"/>
			<geometry>
				<mesh filename="textured_objs/original-15.obj"/>
			</geometry>
		</visual>
		<visual name="door_frame-8">
			<origin xyz="-0.5346630000000001 0.5370628002460592 -0.40417018345276656"/>
			<geometry>
				<mesh filename="textured_objs/original-14.obj"/>
			</geometry>
		</visual>
		<visual name="door_frame-8">
			<origin xyz="-0.5346630000000001 0.5370628002460592 -0.40417018345276656"/>
			<geometry>
				<mesh filename="textured_objs/original-10.obj"/>
			</geometry>
		</visual>
		<visual name="door_frame-8">
			<origin xyz="-0.5346630000000001 0.5370628002460592 -0.40417018345276656"/>
			<geometry>
				<mesh filename="textured_objs/original-11.obj"/>
			</geometry>
		</visual>
		<visual name="door_frame-8">
			<origin xyz="-0.5346630000000001 0.5370628002460592 -0.40417018345276656"/>
			<geometry>
				<mesh filename="textured_objs/original-9.obj"/>
			</geometry>
		</visual>
		<visual name="door_frame-8">
			<origin xyz="-0.5346630000000001 0.5370628002460592 -0.40417018345276656"/>
			<geometry>
				<mesh filename="textured_objs/original-7.obj"/>
			</geometry>
		</visual>
		<visual name="door_frame-8">
			<origin xyz="-0.5346630000000001 0.5370628002460592 -0.40417018345276656"/>
			<geometry>
				<mesh filename="textured_objs/original-1.obj"/>
			</geometry>
		</visual>
		<visual name="door_frame-8">
			<origin xyz="-0.5346630000000001 0.5370628002460592 -0.40417018345276656"/>
			<geometry>
				<mesh filename="textured_objs/original-8.obj"/>
			</geometry>
		</visual>
		<collision>
			<origin xyz="-0.5346630000000001 0.5370628002460592 -0.40417018345276656"/>
			<geometry>
				<mesh filename="textured_objs/original-13.obj"/>
			</geometry>
		</collision>
		<collision>
			<origin xyz="-0.5346630000000001 0.5370628002460592 -0.40417018345276656"/>
			<geometry>
				<mesh filename="textured_objs/original-6.obj"/>
			</geometry>
		</collision>
		<collision>
			<origin xyz="-0.5346630000000001 0.5370628002460592 -0.40417018345276656"/>
			<geometry>
				<mesh filename="textured_objs/original-12.obj"/>
			</geometry>
		</collision>
		<collision>
			<origin xyz="-0.5346630000000001 0.5370628002460592 -0.40417018345276656"/>
			<geometry>
				<mesh filename="textured_objs/original-16.obj"/>
			</geometry>
		</collision>
		<collision>
			<origin xyz="-0.5346630000000001 0.5370628002460592 -0.40417018345276656"/>
			<geometry>
				<mesh filename="textured_objs/original-15.obj"/>
			</geometry>
		</collision>
		<collision>
			<origin xyz="-0.5346630000000001 0.5370628002460592 -0.40417018345276656"/>
			<geometry>
				<mesh filename="textured_objs/original-14.obj"/>
			</geometry>
		</collision>
		<collision>
			<origin xyz="-0.5346630000000001 0.5370628002460592 -0.40417018345276656"/>
			<geometry>
				<mesh filename="textured_objs/original-10.obj"/>
			</geometry>
		</collision>
		<collision>
			<origin xyz="-0.5346630000000001 0.5370628002460592 -0.40417018345276656"/>
			<geometry>
				<mesh filename="textured_objs/original-11.obj"/>
			</geometry>
		</collision>
		<collision>
			<origin xyz="-0.5346630000000001 0.5370628002460592 -0.40417018345276656"/>
			<geometry>
				<mesh filename="textured_objs/original-9.obj"/>
			</geometry>
		</collision>
		<collision>
			<origin xyz="-0.5346630000000001 0.5370628002460592 -0.40417018345276656"/>
			<geometry>
				<mesh filename="textured_objs/original-7.obj"/>
			</geometry>
		</collision>
		<collision>
			<origin xyz="-0.5346630000000001 0.5370628002460592 -0.40417018345276656"/>
			<geometry>
				<mesh filename="textured_objs/original-1.obj"/>
			</geometry>
		</collision>
		<collision>
			<origin xyz="-0.5346630000000001 0.5370628002460592 -0.40417018345276656"/>
			<geometry>
				<mesh filename="textured_objs/original-8.obj"/>
			</geometry>
		</collision>
	</link>
	<joint name="joint_0" type="revolute">
		<origin xyz="0.5346630000000001 -0.5370628002460592 0.40417018345276656"/>
		<axis xyz="1 0 0"/>
		<child link="link_0"/>
		<parent link="link_1"/>
		<limit lower="0.0" upper="1.5707963267948966"/>
	</joint>
	<link name="link_1">
		<visual name="surface-5">
			<origin xyz="0 0 0"/>
			<geometry>
				<mesh filename="textured_objs/new-0.obj"/>
			</geometry>
		</visual>
		<visual name="frame-6">
			<origin xyz="0 0 0"/>
			<geometry>
				<mesh filename="textured_objs/original-4.obj"/>
			</geometry>
		</visual>
		<visual name="frame-6">
			<origin xyz="0 0 0"/>
			<geometry>
				<mesh filename="textured_objs/new-1.obj"/>
			</geometry>
		</visual>
		<collision>
			<origin xyz="0 0 0"/>
			<geometry>
				<mesh filename="textured_objs/new-0.obj"/>
			</geometry>
		</collision>
		<collision>
			<origin xyz="0 0 0"/>
			<geometry>
				<mesh filename="textured_objs/original-4.obj"/>
			</geometry>
		</collision>
		<collision>
			<origin xyz="0 0 0"/>
			<geometry>
				<mesh filename="textured_objs/new-1.obj"/>
			</geometry>
		</collision>
	</link>
	<joint name="joint_1" type="fixed">
		<origin rpy="1.570796326794897 0 -1.570796326794897" xyz="0 0 0"/>
		<child link="link_1"/>
		<parent link="base"/>
	</joint>
</robot>
