<?xml version="1.0" ?>
<robot name="partnet_a5252a98af4fe8d7ad03649619e9c56b">
	<link name="base"/>
	<link name="link_0">
		<visual name="outside_frame-1">
			<origin xyz="0 0 0"/>
			<geometry>
				<mesh filename="textured_objs/original-1.obj"/>
			</geometry>
		</visual>
		<collision>
			<origin xyz="0 0 0"/>
			<geometry>
				<mesh filename="textured_objs/original-1.obj"/>
			</geometry>
		</collision>
	</link>
	<joint name="joint_0" type="fixed">
		<origin rpy="1.570796326794897 0 -1.570796326794897" xyz="0 0 0"/>
		<child link="link_0"/>
		<parent link="base"/>
	</joint>
	<link name="link_1">
		<visual name="surface_board-20">
			<origin xyz="0.2809992904653847 -0.909563 -0.016888047664576966"/>
			<geometry>
				<mesh filename="textured_objs/original-3.obj"/>
			</geometry>
		</visual>
		<visual name="fixed_part-18">
			<origin xyz="0.2809992904653847 -0.909563 -0.016888047664576966"/>
			<geometry>
				<mesh filename="textured_objs/original-9.obj"/>
			</geometry>
		</visual>
		<visual name="fixed_part-16">
			<origin xyz="0.2809992904653847 -0.909563 -0.016888047664576966"/>
			<geometry>
				<mesh filename="textured_objs/original-6.obj"/>
			</geometry>
		</visual>
		<collision>
			<origin xyz="0.2809992904653847 -0.909563 -0.016888047664576966"/>
			<geometry>
				<mesh filename="textured_objs/original-3.obj"/>
			</geometry>
		</collision>
		<collision>
			<origin xyz="0.2809992904653847 -0.909563 -0.016888047664576966"/>
			<geometry>
				<mesh filename="textured_objs/original-9.obj"/>
			</geometry>
		</collision>
		<collision>
			<origin xyz="0.2809992904653847 -0.909563 -0.016888047664576966"/>
			<geometry>
				<mesh filename="textured_objs/original-6.obj"/>
			</geometry>
		</collision>
	</link>
	<joint name="joint_1" type="revolute">
		<origin xyz="-0.2809992904653847 0.909563 0.016888047664576966"/>
		<axis xyz="0 -0.9999999999999999 0"/>
		<child link="link_1"/>
		<parent link="link_0"/>
		<limit lower="0.0" upper="1.5707963267948966"/>
	</joint>
	<link name="link_2">
		<visual name="movable_part-19">
			<origin xyz="-0.22911797863060732 0.16891035454162084 0"/>
			<geometry>
				<mesh filename="textured_objs/original-8.obj"/>
			</geometry>
		</visual>
		<visual name="movable_part-17">
			<origin xyz="-0.22911797863060732 0.16891035454162084 0"/>
			<geometry>
				<mesh filename="textured_objs/original-5.obj"/>
			</geometry>
		</visual>
		<collision>
			<origin xyz="-0.22911797863060732 0.16891035454162084 0"/>
			<geometry>
				<mesh filename="textured_objs/original-8.obj"/>
			</geometry>
		</collision>
		<collision>
			<origin xyz="-0.22911797863060732 0.16891035454162084 0"/>
			<geometry>
				<mesh filename="textured_objs/original-5.obj"/>
			</geometry>
		</collision>
	</link>
	<joint name="joint_2" type="continuous">
		<origin xyz="0.510117269095992 -1.0784733545416207 -0.016888047664576966"/>
		<axis xyz="0 0 1"/>
		<child link="link_2"/>
		<parent link="link_1"/>
	</joint>
</robot>
