<?xml version="1.0" ?>
<robot name="partnet_36ae8016a104fc855a831e480312527">
	<link name="base"/>
	<link name="link_0">
		<visual name="surface_board-3">
			<origin xyz="0.185722201829581 -0.7968090000000005 -0.19679270717073824"/>
			<geometry>
				<mesh filename="textured_objs/original-2.obj"/>
			</geometry>
		</visual>
		<collision>
			<origin xyz="0.185722201829581 -0.7968090000000005 -0.19679270717073824"/>
			<geometry>
				<mesh filename="textured_objs/original-2.obj"/>
			</geometry>
		</collision>
	</link>
	<joint name="joint_0" type="revolute">
		<origin xyz="-0.185722201829581 0.7968090000000005 0.19679270717073824"/>
		<axis xyz="0 1 0"/>
		<child link="link_0"/>
		<parent link="link_1"/>
		<limit lower="-1.413716694115407" upper="0.15707963267948966"/>
	</joint>
	<link name="link_1">
		<visual name="outside_frame-4">
			<origin xyz="0 0 0"/>
			<geometry>
				<mesh filename="textured_objs/original-1.obj"/>
			</geometry>
		</visual>
		<collision>
			<origin xyz="0 0 0"/>
			<geometry>
				<mesh filename="textured_objs/original-1.obj"/>
			</geometry>
		</collision>
	</link>
	<joint name="joint_1" type="fixed">
		<origin rpy="1.570796326794897 0 -1.570796326794897" xyz="0 0 0"/>
		<child link="link_1"/>
		<parent link="base"/>
	</joint>
</robot>
