<?xml version="1.0" ?>
<robot name="partnet_d8844694dff0986d30fff73f53312a3f">
	<link name="base"/>
	<link name="link_0">
		<visual name="switch-2">
			<origin xyz="0.5886995 -0.001270499999999999 0"/>
			<geometry>
				<mesh filename="textured_objs/original-3.obj"/>
			</geometry>
		</visual>
		<collision>
			<origin xyz="0.5886995 -0.001270499999999999 0"/>
			<geometry>
				<mesh filename="textured_objs/original-3.obj"/>
			</geometry>
		</collision>
	</link>
	<joint name="joint_0" type="revolute">
		<origin xyz="-0.5886995 0.001270499999999999 0"/>
		<axis xyz="0 0 -1"/>
		<child link="link_0"/>
		<parent link="link_2"/>
		<limit lower="-0.0" upper="1.5707963267948966"/>
	</joint>
	<link name="link_1">
		<visual name="switch-11">
			<origin xyz="-0.5303785 -0.001270499999999999 0"/>
			<geometry>
				<mesh filename="textured_objs/original-6.obj"/>
			</geometry>
		</visual>
		<collision>
			<origin xyz="-0.5303785 -0.001270499999999999 0"/>
			<geometry>
				<mesh filename="textured_objs/original-6.obj"/>
			</geometry>
		</collision>
	</link>
	<joint name="joint_1" type="revolute">
		<origin xyz="0.5303785 0.001270499999999999 0"/>
		<axis xyz="0 0 1"/>
		<child link="link_1"/>
		<parent link="link_2"/>
		<limit lower="0.0" upper="1.5707963267948966"/>
	</joint>
	<link name="link_2">
		<visual name="horizontal_support-10">
			<origin xyz="0 0 0"/>
			<geometry>
				<mesh filename="textured_objs/original-8.obj"/>
			</geometry>
		</visual>
		<visual name="tube-5">
			<origin xyz="0 0 0"/>
			<geometry>
				<mesh filename="textured_objs/original-9.obj"/>
			</geometry>
		</visual>
		<visual name="mouth-6">
			<origin xyz="0 0 0"/>
			<geometry>
				<mesh filename="textured_objs/original-7.obj"/>
			</geometry>
		</visual>
		<collision>
			<origin xyz="0 0 0"/>
			<geometry>
				<mesh filename="textured_objs/original-8.obj"/>
			</geometry>
		</collision>
		<collision>
			<origin xyz="0 0 0"/>
			<geometry>
				<mesh filename="textured_objs/original-9.obj"/>
			</geometry>
		</collision>
		<collision>
			<origin xyz="0 0 0"/>
			<geometry>
				<mesh filename="textured_objs/original-7.obj"/>
			</geometry>
		</collision>
	</link>
	<joint name="joint_2" type="fixed">
		<origin rpy="1.570796326794897 0 -1.570796326794897" xyz="0 0 0"/>
		<child link="link_2"/>
		<parent link="base"/>
	</joint>
</robot>
