<?xml version="1.0" ?>
<robot name="partnet_1d0abb4d48b46e3f492d9da2668ec34c">
	<link name="base"/>
	<link name="link_0">
		<visual name="caster_yoke-30">
			<origin xyz="0.6129895 0 0.15508450000000001"/>
			<geometry>
				<mesh filename="textured_objs/original-29.obj"/>
			</geometry>
		</visual>
		<collision>
			<origin xyz="0.6129895 0 0.15508450000000001"/>
			<geometry>
				<mesh filename="textured_objs/original-29.obj"/>
			</geometry>
		</collision>
	</link>
	<joint name="joint_0" type="continuous">
		<origin xyz="-0.6129895 0 -0.15508450000000001"/>
		<axis xyz="0 1 0"/>
		<child link="link_0"/>
		<parent link="link_16"/>
	</joint>
	<link name="link_1">
		<visual name="wheel-31">
			<origin xyz="0 0.6877885808560213 0.17230707721248692"/>
			<geometry>
				<mesh filename="textured_objs/original-27.obj"/>
			</geometry>
		</visual>
		<collision>
			<origin xyz="0 0.6877885808560213 0.17230707721248692"/>
			<geometry>
				<mesh filename="textured_objs/original-27.obj"/>
			</geometry>
		</collision>
	</link>
	<joint name="joint_1" type="continuous">
		<origin xyz="0.6129895 -0.6877885808560213 -0.017222577212486906"/>
		<axis xyz="1 0 0"/>
		<child link="link_1"/>
		<parent link="link_0"/>
	</joint>
	<link name="link_2">
		<visual name="wheel-32">
			<origin xyz="0 0.6877885808560213 0.17230707721248692"/>
			<geometry>
				<mesh filename="textured_objs/original-28.obj"/>
			</geometry>
		</visual>
		<collision>
			<origin xyz="0 0.6877885808560213 0.17230707721248692"/>
			<geometry>
				<mesh filename="textured_objs/original-28.obj"/>
			</geometry>
		</collision>
	</link>
	<joint name="joint_2" type="continuous">
		<origin xyz="0.6129895 -0.6877885808560213 -0.017222577212486906"/>
		<axis xyz="1 0 0"/>
		<child link="link_2"/>
		<parent link="link_0"/>
	</joint>
	<link name="link_3">
		<visual name="caster_yoke-27">
			<origin xyz="0.3741453993850386 0 -0.562076724626634"/>
			<geometry>
				<mesh filename="textured_objs/original-17.obj"/>
			</geometry>
		</visual>
		<collision>
			<origin xyz="0.3741453993850386 0 -0.562076724626634"/>
			<geometry>
				<mesh filename="textured_objs/original-17.obj"/>
			</geometry>
		</collision>
	</link>
	<joint name="joint_3" type="continuous">
		<origin xyz="-0.3741453993850386 0 0.562076724626634"/>
		<axis xyz="0 1 0"/>
		<child link="link_3"/>
		<parent link="link_16"/>
	</joint>
	<link name="link_4">
		<visual name="wheel-28">
			<origin xyz="0 0.6868199668084863 -0.5397147225562565"/>
			<geometry>
				<mesh filename="textured_objs/original-16.obj"/>
			</geometry>
		</visual>
		<collision>
			<origin xyz="0 0.6868199668084863 -0.5397147225562565"/>
			<geometry>
				<mesh filename="textured_objs/original-16.obj"/>
			</geometry>
		</collision>
	</link>
	<joint name="joint_4" type="continuous">
		<origin xyz="0.3741453993850386 -0.6868199668084863 -0.02236200207037753"/>
		<axis xyz="1 0 0"/>
		<child link="link_4"/>
		<parent link="link_3"/>
	</joint>
	<link name="link_5">
		<visual name="wheel-29">
			<origin xyz="0 0.6868199668084863 -0.5397147225562565"/>
			<geometry>
				<mesh filename="textured_objs/original-15.obj"/>
			</geometry>
		</visual>
		<collision>
			<origin xyz="0 0.6868199668084863 -0.5397147225562565"/>
			<geometry>
				<mesh filename="textured_objs/original-15.obj"/>
			</geometry>
		</collision>
	</link>
	<joint name="joint_5" type="continuous">
		<origin xyz="0.3741453993850386 -0.6868199668084863 -0.02236200207037753"/>
		<axis xyz="1 0 0"/>
		<child link="link_5"/>
		<parent link="link_3"/>
	</joint>
	<link name="link_6">
		<visual name="caster_yoke-24">
			<origin xyz="-0.37581575980048504 0 -0.5557737883450228"/>
			<geometry>
				<mesh filename="textured_objs/original-20.obj"/>
			</geometry>
		</visual>
		<collision>
			<origin xyz="-0.37581575980048504 0 -0.5557737883450228"/>
			<geometry>
				<mesh filename="textured_objs/original-20.obj"/>
			</geometry>
		</collision>
	</link>
	<joint name="joint_6" type="continuous">
		<origin xyz="0.37581575980048504 0 0.5557737883450228"/>
		<axis xyz="0 1 0"/>
		<child link="link_6"/>
		<parent link="link_16"/>
	</joint>
	<link name="link_7">
		<visual name="wheel-25">
			<origin xyz="0 0.6868199668084863 -0.5397147225562565"/>
			<geometry>
				<mesh filename="textured_objs/original-18.obj"/>
			</geometry>
		</visual>
		<collision>
			<origin xyz="0 0.6868199668084863 -0.5397147225562565"/>
			<geometry>
				<mesh filename="textured_objs/original-18.obj"/>
			</geometry>
		</collision>
	</link>
	<joint name="joint_7" type="continuous">
		<origin xyz="-0.37581575980048504 -0.6868199668084863 -0.016059065788766258"/>
		<axis xyz="1 0 0"/>
		<child link="link_7"/>
		<parent link="link_6"/>
	</joint>
	<link name="link_8">
		<visual name="wheel-26">
			<origin xyz="0 0.6868199668084863 -0.5397147225562565"/>
			<geometry>
				<mesh filename="textured_objs/original-19.obj"/>
			</geometry>
		</visual>
		<collision>
			<origin xyz="0 0.6868199668084863 -0.5397147225562565"/>
			<geometry>
				<mesh filename="textured_objs/original-19.obj"/>
			</geometry>
		</collision>
	</link>
	<joint name="joint_8" type="continuous">
		<origin xyz="-0.37581575980048504 -0.6868199668084863 -0.016059065788766258"/>
		<axis xyz="1 0 0"/>
		<child link="link_8"/>
		<parent link="link_6"/>
	</joint>
	<link name="link_9">
		<visual name="caster_yoke-21">
			<origin xyz="-0.5982305 0 0.1550895"/>
			<geometry>
				<mesh filename="textured_objs/original-23.obj"/>
			</geometry>
		</visual>
		<collision>
			<origin xyz="-0.5982305 0 0.1550895"/>
			<geometry>
				<mesh filename="textured_objs/original-23.obj"/>
			</geometry>
		</collision>
	</link>
	<joint name="joint_9" type="continuous">
		<origin xyz="0.5982305 0 -0.1550895"/>
		<axis xyz="0 1 0"/>
		<child link="link_9"/>
		<parent link="link_16"/>
	</joint>
	<link name="link_10">
		<visual name="wheel-22">
			<origin xyz="0 0.6865592703286956 0.17228675811281302"/>
			<geometry>
				<mesh filename="textured_objs/original-22.obj"/>
			</geometry>
		</visual>
		<collision>
			<origin xyz="0 0.6865592703286956 0.17228675811281302"/>
			<geometry>
				<mesh filename="textured_objs/original-22.obj"/>
			</geometry>
		</collision>
	</link>
	<joint name="joint_10" type="continuous">
		<origin xyz="-0.5982305 -0.6865592703286956 -0.01719725811281303"/>
		<axis xyz="1 0 0"/>
		<child link="link_10"/>
		<parent link="link_9"/>
	</joint>
	<link name="link_11">
		<visual name="wheel-23">
			<origin xyz="0 0.6865592703286956 0.17228675811281302"/>
			<geometry>
				<mesh filename="textured_objs/original-21.obj"/>
			</geometry>
		</visual>
		<collision>
			<origin xyz="0 0.6865592703286956 0.17228675811281302"/>
			<geometry>
				<mesh filename="textured_objs/original-21.obj"/>
			</geometry>
		</collision>
	</link>
	<joint name="joint_11" type="continuous">
		<origin xyz="-0.5982305 -0.6865592703286956 -0.01719725811281303"/>
		<axis xyz="1 0 0"/>
		<child link="link_11"/>
		<parent link="link_9"/>
	</joint>
	<link name="link_12">
		<visual name="caster_yoke-18">
			<origin xyz="0.008587055579200614 0 0.5994720912186231"/>
			<geometry>
				<mesh filename="textured_objs/original-26.obj"/>
			</geometry>
		</visual>
		<collision>
			<origin xyz="0.008587055579200614 0 0.5994720912186231"/>
			<geometry>
				<mesh filename="textured_objs/original-26.obj"/>
			</geometry>
		</collision>
	</link>
	<joint name="joint_12" type="continuous">
		<origin xyz="-0.008587055579200614 0 -0.5994720912186231"/>
		<axis xyz="0 1 0"/>
		<child link="link_12"/>
		<parent link="link_16"/>
	</joint>
	<link name="link_13">
		<visual name="wheel-19">
			<origin xyz="0 0.6878949419566591 0.6118211161623823"/>
			<geometry>
				<mesh filename="textured_objs/original-24.obj"/>
			</geometry>
		</visual>
		<collision>
			<origin xyz="0 0.6878949419566591 0.6118211161623823"/>
			<geometry>
				<mesh filename="textured_objs/original-24.obj"/>
			</geometry>
		</collision>
	</link>
	<joint name="joint_13" type="continuous">
		<origin xyz="0.008587055579200614 -0.6878949419566591 -0.012349024943759224"/>
		<axis xyz="1 0 0"/>
		<child link="link_13"/>
		<parent link="link_12"/>
	</joint>
	<link name="link_14">
		<visual name="wheel-20">
			<origin xyz="0 0.6878949419566591 0.6118211161623823"/>
			<geometry>
				<mesh filename="textured_objs/original-25.obj"/>
			</geometry>
		</visual>
		<collision>
			<origin xyz="0 0.6878949419566591 0.6118211161623823"/>
			<geometry>
				<mesh filename="textured_objs/original-25.obj"/>
			</geometry>
		</collision>
	</link>
	<joint name="joint_14" type="continuous">
		<origin xyz="0.008587055579200614 -0.6878949419566591 -0.012349024943759224"/>
		<axis xyz="1 0 0"/>
		<child link="link_14"/>
		<parent link="link_12"/>
	</joint>
	<link name="link_15">
		<visual name="back_hard_surface-37">
			<origin xyz="-0.005757407216160767 0 -0.04332446103199799"/>
			<geometry>
				<mesh filename="textured_objs/new-6.obj"/>
			</geometry>
		</visual>
		<visual name="seat_hard_surface-35">
			<origin xyz="-0.005757407216160767 0 -0.04332446103199799"/>
			<geometry>
				<mesh filename="textured_objs/new-7.obj"/>
			</geometry>
		</visual>
		<visual name="seat_support-34">
			<origin xyz="-0.005757407216160767 0 -0.04332446103199799"/>
			<geometry>
				<mesh filename="textured_objs/original-5.obj"/>
			</geometry>
		</visual>
		<visual name="seat_support-34">
			<origin xyz="-0.005757407216160767 0 -0.04332446103199799"/>
			<geometry>
				<mesh filename="textured_objs/original-12.obj"/>
			</geometry>
		</visual>
		<visual name="seat_support-34">
			<origin xyz="-0.005757407216160767 0 -0.04332446103199799"/>
			<geometry>
				<mesh filename="textured_objs/original-2.obj"/>
			</geometry>
		</visual>
		<visual name="seat_support-34">
			<origin xyz="-0.005757407216160767 0 -0.04332446103199799"/>
			<geometry>
				<mesh filename="textured_objs/original-11.obj"/>
			</geometry>
		</visual>
		<visual name="seat_support-34">
			<origin xyz="-0.005757407216160767 0 -0.04332446103199799"/>
			<geometry>
				<mesh filename="textured_objs/original-10.obj"/>
			</geometry>
		</visual>
		<visual name="seat_support-34">
			<origin xyz="-0.005757407216160767 0 -0.04332446103199799"/>
			<geometry>
				<mesh filename="textured_objs/original-1.obj"/>
			</geometry>
		</visual>
		<visual name="seat_support-34">
			<origin xyz="-0.005757407216160767 0 -0.04332446103199799"/>
			<geometry>
				<mesh filename="textured_objs/original-8.obj"/>
			</geometry>
		</visual>
		<visual name="seat_support-34">
			<origin xyz="-0.005757407216160767 0 -0.04332446103199799"/>
			<geometry>
				<mesh filename="textured_objs/original-9.obj"/>
			</geometry>
		</visual>
		<collision>
			<origin xyz="-0.005757407216160767 0 -0.04332446103199799"/>
			<geometry>
				<mesh filename="textured_objs/new-6.obj"/>
			</geometry>
		</collision>
		<collision>
			<origin xyz="-0.005757407216160767 0 -0.04332446103199799"/>
			<geometry>
				<mesh filename="textured_objs/new-7.obj"/>
			</geometry>
		</collision>
		<collision>
			<origin xyz="-0.005757407216160767 0 -0.04332446103199799"/>
			<geometry>
				<mesh filename="textured_objs/original-5.obj"/>
			</geometry>
		</collision>
		<collision>
			<origin xyz="-0.005757407216160767 0 -0.04332446103199799"/>
			<geometry>
				<mesh filename="textured_objs/original-12.obj"/>
			</geometry>
		</collision>
		<collision>
			<origin xyz="-0.005757407216160767 0 -0.04332446103199799"/>
			<geometry>
				<mesh filename="textured_objs/original-2.obj"/>
			</geometry>
		</collision>
		<collision>
			<origin xyz="-0.005757407216160767 0 -0.04332446103199799"/>
			<geometry>
				<mesh filename="textured_objs/original-11.obj"/>
			</geometry>
		</collision>
		<collision>
			<origin xyz="-0.005757407216160767 0 -0.04332446103199799"/>
			<geometry>
				<mesh filename="textured_objs/original-10.obj"/>
			</geometry>
		</collision>
		<collision>
			<origin xyz="-0.005757407216160767 0 -0.04332446103199799"/>
			<geometry>
				<mesh filename="textured_objs/original-1.obj"/>
			</geometry>
		</collision>
		<collision>
			<origin xyz="-0.005757407216160767 0 -0.04332446103199799"/>
			<geometry>
				<mesh filename="textured_objs/original-8.obj"/>
			</geometry>
		</collision>
		<collision>
			<origin xyz="-0.005757407216160767 0 -0.04332446103199799"/>
			<geometry>
				<mesh filename="textured_objs/original-9.obj"/>
			</geometry>
		</collision>
	</link>
	<joint name="joint_15" type="continuous">
		<origin xyz="0.0 0 0.0"/>
		<axis xyz="0 1 0"/>
		<child link="link_15"/>
		<parent link="link_15_helper"/>
	</joint>
	<link name="link_16">
		<visual name="central_support-6">
			<origin xyz="0 0 0"/>
			<geometry>
				<mesh filename="textured_objs/original-13.obj"/>
			</geometry>
		</visual>
		<visual name="central_support-6">
			<origin xyz="0 0 0"/>
			<geometry>
				<mesh filename="textured_objs/new-5.obj"/>
			</geometry>
		</visual>
		<visual name="central_support-6">
			<origin xyz="0 0 0"/>
			<geometry>
				<mesh filename="textured_objs/original-14.obj"/>
			</geometry>
		</visual>
		<visual name="central_support-6">
			<origin xyz="0 0 0"/>
			<geometry>
				<mesh filename="textured_objs/original-7.obj"/>
			</geometry>
		</visual>
		<visual name="leg-8">
			<origin xyz="0 0 0"/>
			<geometry>
				<mesh filename="textured_objs/new-2.obj"/>
			</geometry>
		</visual>
		<visual name="leg-9">
			<origin xyz="0 0 0"/>
			<geometry>
				<mesh filename="textured_objs/new-1.obj"/>
			</geometry>
		</visual>
		<visual name="leg-10">
			<origin xyz="0 0 0"/>
			<geometry>
				<mesh filename="textured_objs/new-0.obj"/>
			</geometry>
		</visual>
		<visual name="leg-11">
			<origin xyz="0 0 0"/>
			<geometry>
				<mesh filename="textured_objs/new-4.obj"/>
			</geometry>
		</visual>
		<visual name="leg-12">
			<origin xyz="0 0 0"/>
			<geometry>
				<mesh filename="textured_objs/new-3.obj"/>
			</geometry>
		</visual>
		<collision>
			<origin xyz="0 0 0"/>
			<geometry>
				<mesh filename="textured_objs/original-13.obj"/>
			</geometry>
		</collision>
		<collision>
			<origin xyz="0 0 0"/>
			<geometry>
				<mesh filename="textured_objs/new-5.obj"/>
			</geometry>
		</collision>
		<collision>
			<origin xyz="0 0 0"/>
			<geometry>
				<mesh filename="textured_objs/original-14.obj"/>
			</geometry>
		</collision>
		<collision>
			<origin xyz="0 0 0"/>
			<geometry>
				<mesh filename="textured_objs/original-7.obj"/>
			</geometry>
		</collision>
		<collision>
			<origin xyz="0 0 0"/>
			<geometry>
				<mesh filename="textured_objs/new-2.obj"/>
			</geometry>
		</collision>
		<collision>
			<origin xyz="0 0 0"/>
			<geometry>
				<mesh filename="textured_objs/new-1.obj"/>
			</geometry>
		</collision>
		<collision>
			<origin xyz="0 0 0"/>
			<geometry>
				<mesh filename="textured_objs/new-0.obj"/>
			</geometry>
		</collision>
		<collision>
			<origin xyz="0 0 0"/>
			<geometry>
				<mesh filename="textured_objs/new-4.obj"/>
			</geometry>
		</collision>
		<collision>
			<origin xyz="0 0 0"/>
			<geometry>
				<mesh filename="textured_objs/new-3.obj"/>
			</geometry>
		</collision>
	</link>
	<joint name="joint_16" type="fixed">
		<origin rpy="1.570796326794897 0 -1.570796326794897" xyz="0 0 0"/>
		<child link="link_16"/>
		<parent link="base"/>
	</joint>
	<link name="link_15_helper"/>
	<joint name="joint_17" type="prismatic">
		<origin xyz="0.005757407216160767 0 0.04332446103199799"/>
		<axis xyz="0 -1 0"/>
		<child link="link_15_helper"/>
		<parent link="link_16"/>
		<limit lower="0" upper="0.1"/>
	</joint>
</robot>
