<?xml version="1.0" ?>
<!-- =================================================================================== -->
<!-- |    This document was autogenerated by xacro from tiago_titanium111.urdf.xacro   | -->
<!-- |    EDITING THIS FILE BY HAND IS NOT RECOMMENDED                                 | -->
<!-- =================================================================================== -->
<!--
  Copyright (c) 2011, PAL Robotics, S.L.
  All rights reserved.

  This work is licensed under the Creative Commons Attribution-NonCommercial-NoDerivs 3.0 Unported License.
  To view a copy of this license, visit http://creativecommons.org/licenses/by-nc-nd/3.0/ or send a letter to
  Creative Commons, 444 Castro Street, Suite 900, Mountain View, California, 94041, USA.
-->
<robot name="tiago" xmlns:xacro="http://www.ros.org/wiki/xacro">

  <!--***********************-->
  <!--        TOOL           -->
  <!--***********************-->


    <link name="base_link">
  </link>


  <joint name="translationX" type="prismatic">
    <parent link="base_link"/>
    <child link="base_link2"/>
    <origin rpy="0 0 0" xyz="0 0 0"/>
	<axis xyz="1 0 0"/>
    <limit effort="20" lower="-1000" upper="1000.0" velocity="1"/>
    <dynamics damping="0.00001"/>
  </joint>

  <link name="base_link2">
  </link>

  <joint name="translationY" type="prismatic">
    <parent link="base_link2"/>
    <child link="base_link3"/>
    <origin rpy="0 0 0" xyz="0 0 0"/>
	<axis xyz="0 1 0"/>
    <limit effort="10000" lower="-1000" upper="1000.0" velocity="1"/>
  </joint>

 <link name="base_link3">
  </link>

  <joint name="translationZ" type="prismatic">
    <parent link="base_link3"/>
    <child link="base_link4"/>
    <origin rpy="0 0 0" xyz="0 0 0"/>
	<axis xyz="0 0 1"/>
    <limit effort="20" lower="-100" upper="100.0" velocity="0.2"/>
  </joint>

  <link name="base_link4">
  </link>

  <joint name="rotationX" type="revolute">
    <parent link="base_link4"/>
    <child link="base_link5"/>
    <origin rpy="0 0 0" xyz="0 0 0"/>
	<axis xyz="1 0 0"/>
    <limit effort="20" lower="-100.0" upper="100.0" velocity="0.2"/>

  </joint>

<link name="base_link5">
  </link>

  <joint name="rotationY" type="revolute">
    <parent link="base_link5"/>
    <child link="base_link6"/>
    <origin rpy="0 0 0" xyz="0 0 0"/>
	<axis xyz="0 1 0"/>
    <limit effort="20" lower="-100.0" upper="100.0" velocity="0.2"/>
  </joint>

<link name="base_link6">
  </link>

  <joint name="rotationZ" type="revolute">
    <parent link="base_link6"/>
    <child link="gripper_link"/>
    <origin rpy="0 0 0" xyz="0 0 0"/>
	<axis xyz="0 0 1"/>
    <limit effort="20" lower="-100.0" upper="100.0" velocity="0.2"/>
  </joint>


  <link name="gripper_link">
    <inertial>
      <origin rpy="0.0 0.0 0.0" xyz="-0.000294 0.000291 -0.033086"/>
      <mass value="0.001"/>
      <inertia ixx="0.000693" ixy="0.000045" ixz="-0.000000" iyy="0.001024" iyz="0.000000" izz="0.000672"/>
    </inertial>
    <visual>
      <origin rpy="0 0 0" xyz="0 0 0"/>
      <geometry>
        <mesh filename="tiago/meshes/gripper/gripper_link.stl"/>
      </geometry>
      <material name="White"/>
    </visual>
    <collision>
      <origin rpy="0 0 0" xyz="0 0 0"/>
      <geometry>
        <mesh filename="tiago/meshes/gripper/gripper_link_collision.stl"/>
      </geometry>
    </collision>
  </link>

  <link name="gripper_right_finger_link">
    <inertial>
      <origin rpy="0 0 0" xyz="-0.004470 0.010766 -0.121013"/>
      <mass value="1.10109980"/>
      <inertia ixx="0.000232" ixy="-0.000005" ixz="-0.000032" iyy="0.000224" iyz="0.000036" izz="0.000029"/>
    </inertial>
    <visual>
      <origin rpy="0 0 3.1415" xyz="0 0 0"/>
      <geometry>
        <mesh filename="tiago/meshes/gripper/gripper_finger_link.stl" scale="-1 -1 1"/>
      </geometry>
      <material name="White"/>
    </visual>
    <collision>
      <origin rpy="0 0 3.1415" xyz="0.005 0 -0.165"/>
      <geometry>
        <box size="0.01 0.05 0.11"/>
      </geometry>
    </collision>
  </link>

  <joint name="gripper_right_finger_joint" type="prismatic">
    <origin rpy="0 0 0" xyz="0. 0 0"/>
    <parent link="gripper_link"/>
    <child link="gripper_right_finger_link"/>
    <axis xyz="1 0 0"/>
<limit effort="500" lower="0" upper="0.045" velocity="500"/>
    <!--<limit effort="16" lower="0.0" upper="0.045" velocity="0.05"/>-->
     <!-- <limit effort="40" lower="0.0" upper="0.045" velocity="0.1"/>-->

  
    <safety_controller k_position="100" k_velocity="20" soft_lower_limit="0.001" soft_upper_limit="0.044"/>
  </joint>
  <link name="gripper_left_finger_link">
    <inertial>
      <origin rpy="0 0 0" xyz="-0.004470 0.010766 -0.121013"/>
      <mass value="1.10109980"/>
      <inertia ixx="0.000232" ixy="-0.000005" ixz="-0.000032" iyy="0.000224" iyz="0.000036" izz="0.000029"/>
    </inertial>
    <visual>
      <origin rpy="0 0 3.1415" xyz="0 0 0"/>
      <geometry>
        <mesh filename="tiago/meshes/gripper/gripper_finger_link.stl"/>
      </geometry>
      <material name="White"/>
    </visual>
    <collision>
      <origin rpy="0 0 3.1415" xyz="-0.005 0 -0.165"/>
      <geometry>
        <box size="0.01 0.05 0.11"/>
      </geometry>
    </collision>
  </link>

  <joint name="gripper_left_finger_joint" type="prismatic">
    <origin rpy="0 0 0" xyz="0. 0 0"/>
    <parent link="gripper_link"/>
    <child link="gripper_left_finger_link"/>
    <axis xyz="-1 0 0"/>
    <limit effort="500" lower="0" upper="0.045" velocity="500"/>
    <!--<limit effort="16" lower="0" upper="0.045" velocity="0.05"/>-->!


    <safety_controller k_position="100" k_velocity="20" soft_lower_limit="0.001" soft_upper_limit="0.044"/>
  </joint>

</robot>
