<?xml version="1.0" ?>
<robot name="partnet_26f0f37f0f2623c4a3fa46ae73c48b4">
	<link name="base"/>
	<link name="link_0">
		<visual name="lamp_base_part-16">
			<origin xyz="0 0 0"/>
			<geometry>
				<mesh filename="textured_objs/original-45.obj"/>
			</geometry>
		</visual>
		<collision>
			<origin xyz="0 0 0"/>
			<geometry>
				<mesh filename="textured_objs/original-45.obj"/>
			</geometry>
		</collision>
	</link>
	<joint name="joint_0" type="fixed">
		<origin rpy="1.570796326794897 0 -1.570796326794897" xyz="0 0 0"/>
		<child link="link_0"/>
		<parent link="base"/>
	</joint>
	<link name="link_1">
		<visual name="lamp_body_curved-14">
			<origin xyz="0 0.04458036572765195 0.11022591714378824"/>
			<geometry>
				<mesh filename="textured_objs/original-38.obj"/>
			</geometry>
		</visual>
		<visual name="lamp_body_curved-14">
			<origin xyz="0 0.04458036572765195 0.11022591714378824"/>
			<geometry>
				<mesh filename="textured_objs/original-40.obj"/>
			</geometry>
		</visual>
		<collision>
			<origin xyz="0 0.04458036572765195 0.11022591714378824"/>
			<geometry>
				<mesh filename="textured_objs/original-38.obj"/>
			</geometry>
		</collision>
		<collision>
			<origin xyz="0 0.04458036572765195 0.11022591714378824"/>
			<geometry>
				<mesh filename="textured_objs/original-40.obj"/>
			</geometry>
		</collision>
	</link>
	<joint name="joint_1" type="revolute">
		<origin xyz="0 -0.04458036572765195 -0.11022591714378824"/>
		<axis xyz="1 0 0"/>
		<child link="link_1"/>
		<parent link="link_0"/>
		<limit lower="-1.0471975511965976" upper="1.0471975511965976"/>
	</joint>
	<link name="link_2">
		<visual name="lamp_cover_holder-7">
			<origin xyz="0 -0.5477006266751309 0.2006962525440315"/>
			<geometry>
				<mesh filename="textured_objs/original-36.obj"/>
			</geometry>
		</visual>
		<visual name="lamp_cover_holder-7">
			<origin xyz="0 -0.5477006266751309 0.2006962525440315"/>
			<geometry>
				<mesh filename="textured_objs/original-41.obj"/>
			</geometry>
		</visual>
		<visual name="lamp_cover_holder-7">
			<origin xyz="0 -0.5477006266751309 0.2006962525440315"/>
			<geometry>
				<mesh filename="textured_objs/original-39.obj"/>
			</geometry>
		</visual>
		<visual name="lamp_shade-13">
			<origin xyz="0 -0.5477006266751309 0.2006962525440315"/>
			<geometry>
				<mesh filename="textured_objs/original-37.obj"/>
			</geometry>
		</visual>
		<visual name="light_bulb-9">
			<origin xyz="0 -0.5477006266751309 0.2006962525440315"/>
			<geometry>
				<mesh filename="textured_objs/original-44.obj"/>
			</geometry>
		</visual>
		<visual name="light_bulb-9">
			<origin xyz="0 -0.5477006266751309 0.2006962525440315"/>
			<geometry>
				<mesh filename="textured_objs/original-43.obj"/>
			</geometry>
		</visual>
		<visual name="pull_chain-12">
			<origin xyz="0 -0.5477006266751309 0.2006962525440315"/>
			<geometry>
				<mesh filename="textured_objs/original-14.obj"/>
			</geometry>
		</visual>
		<visual name="pull_chain-12">
			<origin xyz="0 -0.5477006266751309 0.2006962525440315"/>
			<geometry>
				<mesh filename="textured_objs/original-15.obj"/>
			</geometry>
		</visual>
		<visual name="pull_chain-12">
			<origin xyz="0 -0.5477006266751309 0.2006962525440315"/>
			<geometry>
				<mesh filename="textured_objs/original-12.obj"/>
			</geometry>
		</visual>
		<visual name="pull_chain-12">
			<origin xyz="0 -0.5477006266751309 0.2006962525440315"/>
			<geometry>
				<mesh filename="textured_objs/original-13.obj"/>
			</geometry>
		</visual>
		<visual name="pull_chain-12">
			<origin xyz="0 -0.5477006266751309 0.2006962525440315"/>
			<geometry>
				<mesh filename="textured_objs/original-10.obj"/>
			</geometry>
		</visual>
		<visual name="pull_chain-12">
			<origin xyz="0 -0.5477006266751309 0.2006962525440315"/>
			<geometry>
				<mesh filename="textured_objs/original-11.obj"/>
			</geometry>
		</visual>
		<visual name="pull_chain-12">
			<origin xyz="0 -0.5477006266751309 0.2006962525440315"/>
			<geometry>
				<mesh filename="textured_objs/original-9.obj"/>
			</geometry>
		</visual>
		<visual name="pull_chain-12">
			<origin xyz="0 -0.5477006266751309 0.2006962525440315"/>
			<geometry>
				<mesh filename="textured_objs/original-18.obj"/>
			</geometry>
		</visual>
		<visual name="pull_chain-12">
			<origin xyz="0 -0.5477006266751309 0.2006962525440315"/>
			<geometry>
				<mesh filename="textured_objs/original-19.obj"/>
			</geometry>
		</visual>
		<visual name="pull_chain-12">
			<origin xyz="0 -0.5477006266751309 0.2006962525440315"/>
			<geometry>
				<mesh filename="textured_objs/original-17.obj"/>
			</geometry>
		</visual>
		<visual name="pull_chain-12">
			<origin xyz="0 -0.5477006266751309 0.2006962525440315"/>
			<geometry>
				<mesh filename="textured_objs/original-26.obj"/>
			</geometry>
		</visual>
		<visual name="pull_chain-12">
			<origin xyz="0 -0.5477006266751309 0.2006962525440315"/>
			<geometry>
				<mesh filename="textured_objs/original-24.obj"/>
			</geometry>
		</visual>
		<visual name="pull_chain-12">
			<origin xyz="0 -0.5477006266751309 0.2006962525440315"/>
			<geometry>
				<mesh filename="textured_objs/original-25.obj"/>
			</geometry>
		</visual>
		<visual name="pull_chain-12">
			<origin xyz="0 -0.5477006266751309 0.2006962525440315"/>
			<geometry>
				<mesh filename="textured_objs/original-22.obj"/>
			</geometry>
		</visual>
		<visual name="pull_chain-12">
			<origin xyz="0 -0.5477006266751309 0.2006962525440315"/>
			<geometry>
				<mesh filename="textured_objs/original-27.obj"/>
			</geometry>
		</visual>
		<visual name="pull_chain-12">
			<origin xyz="0 -0.5477006266751309 0.2006962525440315"/>
			<geometry>
				<mesh filename="textured_objs/original-28.obj"/>
			</geometry>
		</visual>
		<visual name="pull_chain-12">
			<origin xyz="0 -0.5477006266751309 0.2006962525440315"/>
			<geometry>
				<mesh filename="textured_objs/original-20.obj"/>
			</geometry>
		</visual>
		<visual name="pull_chain-12">
			<origin xyz="0 -0.5477006266751309 0.2006962525440315"/>
			<geometry>
				<mesh filename="textured_objs/original-30.obj"/>
			</geometry>
		</visual>
		<visual name="pull_chain-12">
			<origin xyz="0 -0.5477006266751309 0.2006962525440315"/>
			<geometry>
				<mesh filename="textured_objs/original-7.obj"/>
			</geometry>
		</visual>
		<visual name="pull_chain-12">
			<origin xyz="0 -0.5477006266751309 0.2006962525440315"/>
			<geometry>
				<mesh filename="textured_objs/original-32.obj"/>
			</geometry>
		</visual>
		<visual name="pull_chain-12">
			<origin xyz="0 -0.5477006266751309 0.2006962525440315"/>
			<geometry>
				<mesh filename="textured_objs/original-4.obj"/>
			</geometry>
		</visual>
		<visual name="pull_chain-12">
			<origin xyz="0 -0.5477006266751309 0.2006962525440315"/>
			<geometry>
				<mesh filename="textured_objs/original-3.obj"/>
			</geometry>
		</visual>
		<visual name="pull_chain-12">
			<origin xyz="0 -0.5477006266751309 0.2006962525440315"/>
			<geometry>
				<mesh filename="textured_objs/original-5.obj"/>
			</geometry>
		</visual>
		<visual name="pull_chain-12">
			<origin xyz="0 -0.5477006266751309 0.2006962525440315"/>
			<geometry>
				<mesh filename="textured_objs/original-6.obj"/>
			</geometry>
		</visual>
		<visual name="pull_chain-12">
			<origin xyz="0 -0.5477006266751309 0.2006962525440315"/>
			<geometry>
				<mesh filename="textured_objs/original-34.obj"/>
			</geometry>
		</visual>
		<visual name="pull_chain-12">
			<origin xyz="0 -0.5477006266751309 0.2006962525440315"/>
			<geometry>
				<mesh filename="textured_objs/original-35.obj"/>
			</geometry>
		</visual>
		<visual name="pull_chain-12">
			<origin xyz="0 -0.5477006266751309 0.2006962525440315"/>
			<geometry>
				<mesh filename="textured_objs/original-23.obj"/>
			</geometry>
		</visual>
		<visual name="pull_chain-12">
			<origin xyz="0 -0.5477006266751309 0.2006962525440315"/>
			<geometry>
				<mesh filename="textured_objs/original-33.obj"/>
			</geometry>
		</visual>
		<visual name="pull_chain-12">
			<origin xyz="0 -0.5477006266751309 0.2006962525440315"/>
			<geometry>
				<mesh filename="textured_objs/original-8.obj"/>
			</geometry>
		</visual>
		<visual name="pull_chain-12">
			<origin xyz="0 -0.5477006266751309 0.2006962525440315"/>
			<geometry>
				<mesh filename="textured_objs/original-21.obj"/>
			</geometry>
		</visual>
		<visual name="pull_chain-12">
			<origin xyz="0 -0.5477006266751309 0.2006962525440315"/>
			<geometry>
				<mesh filename="textured_objs/original-31.obj"/>
			</geometry>
		</visual>
		<visual name="pull_chain-12">
			<origin xyz="0 -0.5477006266751309 0.2006962525440315"/>
			<geometry>
				<mesh filename="textured_objs/original-16.obj"/>
			</geometry>
		</visual>
		<visual name="pull_chain-12">
			<origin xyz="0 -0.5477006266751309 0.2006962525440315"/>
			<geometry>
				<mesh filename="textured_objs/original-29.obj"/>
			</geometry>
		</visual>
		<collision>
			<origin xyz="0 -0.5477006266751309 0.2006962525440315"/>
			<geometry>
				<mesh filename="textured_objs/original-36.obj"/>
			</geometry>
		</collision>
		<collision>
			<origin xyz="0 -0.5477006266751309 0.2006962525440315"/>
			<geometry>
				<mesh filename="textured_objs/original-41.obj"/>
			</geometry>
		</collision>
		<collision>
			<origin xyz="0 -0.5477006266751309 0.2006962525440315"/>
			<geometry>
				<mesh filename="textured_objs/original-39.obj"/>
			</geometry>
		</collision>
		<collision>
			<origin xyz="0 -0.5477006266751309 0.2006962525440315"/>
			<geometry>
				<mesh filename="textured_objs/original-37.obj"/>
			</geometry>
		</collision>
		<collision>
			<origin xyz="0 -0.5477006266751309 0.2006962525440315"/>
			<geometry>
				<mesh filename="textured_objs/original-44.obj"/>
			</geometry>
		</collision>
		<collision>
			<origin xyz="0 -0.5477006266751309 0.2006962525440315"/>
			<geometry>
				<mesh filename="textured_objs/original-43.obj"/>
			</geometry>
		</collision>
		<collision>
			<origin xyz="0 -0.5477006266751309 0.2006962525440315"/>
			<geometry>
				<mesh filename="textured_objs/original-14.obj"/>
			</geometry>
		</collision>
		<collision>
			<origin xyz="0 -0.5477006266751309 0.2006962525440315"/>
			<geometry>
				<mesh filename="textured_objs/original-15.obj"/>
			</geometry>
		</collision>
		<collision>
			<origin xyz="0 -0.5477006266751309 0.2006962525440315"/>
			<geometry>
				<mesh filename="textured_objs/original-12.obj"/>
			</geometry>
		</collision>
		<collision>
			<origin xyz="0 -0.5477006266751309 0.2006962525440315"/>
			<geometry>
				<mesh filename="textured_objs/original-13.obj"/>
			</geometry>
		</collision>
		<collision>
			<origin xyz="0 -0.5477006266751309 0.2006962525440315"/>
			<geometry>
				<mesh filename="textured_objs/original-10.obj"/>
			</geometry>
		</collision>
		<collision>
			<origin xyz="0 -0.5477006266751309 0.2006962525440315"/>
			<geometry>
				<mesh filename="textured_objs/original-11.obj"/>
			</geometry>
		</collision>
		<collision>
			<origin xyz="0 -0.5477006266751309 0.2006962525440315"/>
			<geometry>
				<mesh filename="textured_objs/original-9.obj"/>
			</geometry>
		</collision>
		<collision>
			<origin xyz="0 -0.5477006266751309 0.2006962525440315"/>
			<geometry>
				<mesh filename="textured_objs/original-18.obj"/>
			</geometry>
		</collision>
		<collision>
			<origin xyz="0 -0.5477006266751309 0.2006962525440315"/>
			<geometry>
				<mesh filename="textured_objs/original-19.obj"/>
			</geometry>
		</collision>
		<collision>
			<origin xyz="0 -0.5477006266751309 0.2006962525440315"/>
			<geometry>
				<mesh filename="textured_objs/original-17.obj"/>
			</geometry>
		</collision>
		<collision>
			<origin xyz="0 -0.5477006266751309 0.2006962525440315"/>
			<geometry>
				<mesh filename="textured_objs/original-26.obj"/>
			</geometry>
		</collision>
		<collision>
			<origin xyz="0 -0.5477006266751309 0.2006962525440315"/>
			<geometry>
				<mesh filename="textured_objs/original-24.obj"/>
			</geometry>
		</collision>
		<collision>
			<origin xyz="0 -0.5477006266751309 0.2006962525440315"/>
			<geometry>
				<mesh filename="textured_objs/original-25.obj"/>
			</geometry>
		</collision>
		<collision>
			<origin xyz="0 -0.5477006266751309 0.2006962525440315"/>
			<geometry>
				<mesh filename="textured_objs/original-22.obj"/>
			</geometry>
		</collision>
		<collision>
			<origin xyz="0 -0.5477006266751309 0.2006962525440315"/>
			<geometry>
				<mesh filename="textured_objs/original-27.obj"/>
			</geometry>
		</collision>
		<collision>
			<origin xyz="0 -0.5477006266751309 0.2006962525440315"/>
			<geometry>
				<mesh filename="textured_objs/original-28.obj"/>
			</geometry>
		</collision>
		<collision>
			<origin xyz="0 -0.5477006266751309 0.2006962525440315"/>
			<geometry>
				<mesh filename="textured_objs/original-20.obj"/>
			</geometry>
		</collision>
		<collision>
			<origin xyz="0 -0.5477006266751309 0.2006962525440315"/>
			<geometry>
				<mesh filename="textured_objs/original-30.obj"/>
			</geometry>
		</collision>
		<collision>
			<origin xyz="0 -0.5477006266751309 0.2006962525440315"/>
			<geometry>
				<mesh filename="textured_objs/original-7.obj"/>
			</geometry>
		</collision>
		<collision>
			<origin xyz="0 -0.5477006266751309 0.2006962525440315"/>
			<geometry>
				<mesh filename="textured_objs/original-32.obj"/>
			</geometry>
		</collision>
		<collision>
			<origin xyz="0 -0.5477006266751309 0.2006962525440315"/>
			<geometry>
				<mesh filename="textured_objs/original-4.obj"/>
			</geometry>
		</collision>
		<collision>
			<origin xyz="0 -0.5477006266751309 0.2006962525440315"/>
			<geometry>
				<mesh filename="textured_objs/original-3.obj"/>
			</geometry>
		</collision>
		<collision>
			<origin xyz="0 -0.5477006266751309 0.2006962525440315"/>
			<geometry>
				<mesh filename="textured_objs/original-5.obj"/>
			</geometry>
		</collision>
		<collision>
			<origin xyz="0 -0.5477006266751309 0.2006962525440315"/>
			<geometry>
				<mesh filename="textured_objs/original-6.obj"/>
			</geometry>
		</collision>
		<collision>
			<origin xyz="0 -0.5477006266751309 0.2006962525440315"/>
			<geometry>
				<mesh filename="textured_objs/original-34.obj"/>
			</geometry>
		</collision>
		<collision>
			<origin xyz="0 -0.5477006266751309 0.2006962525440315"/>
			<geometry>
				<mesh filename="textured_objs/original-35.obj"/>
			</geometry>
		</collision>
		<collision>
			<origin xyz="0 -0.5477006266751309 0.2006962525440315"/>
			<geometry>
				<mesh filename="textured_objs/original-23.obj"/>
			</geometry>
		</collision>
		<collision>
			<origin xyz="0 -0.5477006266751309 0.2006962525440315"/>
			<geometry>
				<mesh filename="textured_objs/original-33.obj"/>
			</geometry>
		</collision>
		<collision>
			<origin xyz="0 -0.5477006266751309 0.2006962525440315"/>
			<geometry>
				<mesh filename="textured_objs/original-8.obj"/>
			</geometry>
		</collision>
		<collision>
			<origin xyz="0 -0.5477006266751309 0.2006962525440315"/>
			<geometry>
				<mesh filename="textured_objs/original-21.obj"/>
			</geometry>
		</collision>
		<collision>
			<origin xyz="0 -0.5477006266751309 0.2006962525440315"/>
			<geometry>
				<mesh filename="textured_objs/original-31.obj"/>
			</geometry>
		</collision>
		<collision>
			<origin xyz="0 -0.5477006266751309 0.2006962525440315"/>
			<geometry>
				<mesh filename="textured_objs/original-16.obj"/>
			</geometry>
		</collision>
		<collision>
			<origin xyz="0 -0.5477006266751309 0.2006962525440315"/>
			<geometry>
				<mesh filename="textured_objs/original-29.obj"/>
			</geometry>
		</collision>
	</link>
	<joint name="joint_2" type="revolute">
		<origin xyz="0 0.5922809924027828 -0.09047033540024327"/>
		<axis xyz="-1 0 0"/>
		<child link="link_2"/>
		<parent link="link_1"/>
		<limit lower="-0.30159289474462014" upper="2.042035224833365"/>
	</joint>
</robot>
