<?xml version="1.0" ?>
<robot name="partnet_3211fc4f31b15964aee892adc836ce83">
	<link name="base"/>
	<link name="link_0">
		<visual name="lever-48">
			<origin xyz="0.06789344420656562 -0.07856660777135693 0"/>
			<geometry>
				<mesh filename="textured_objs/original-38.obj"/>
			</geometry>
		</visual>
		<visual name="lever-48">
			<origin xyz="0.06789344420656562 -0.07856660777135693 0"/>
			<geometry>
				<mesh filename="textured_objs/original-14.obj"/>
			</geometry>
		</visual>
		<collision>
			<origin xyz="0.06789344420656562 -0.07856660777135693 0"/>
			<geometry>
				<mesh filename="textured_objs/original-38.obj"/>
			</geometry>
		</collision>
		<collision>
			<origin xyz="0.06789344420656562 -0.07856660777135693 0"/>
			<geometry>
				<mesh filename="textured_objs/original-14.obj"/>
			</geometry>
		</collision>
	</link>
	<joint name="joint_0" type="revolute">
		<origin xyz="-0.07060444420656563 0.07856660777135693 -0.07935049999999999"/>
		<axis xyz="0 0 1"/>
		<child link="link_0"/>
		<parent link="link_11"/>
		<limit lower="0.0" upper="0.3204424506661589"/>
	</joint>
	<link name="link_1">
		<visual name="wheel-41">
			<origin xyz="-0.0992845498061307 0.7724105 0.03254063003487493"/>
			<geometry>
				<mesh filename="textured_objs/original-27.obj"/>
			</geometry>
		</visual>
		<collision>
			<origin xyz="-0.0992845498061307 0.7724105 0.03254063003487493"/>
			<geometry>
				<mesh filename="textured_objs/original-27.obj"/>
			</geometry>
		</collision>
	</link>
	<joint name="joint_1" type="continuous">
		<origin xyz="-0.197808351359873 -0.7724105 -0.5143238240154263"/>
		<axis xyz="-0.3114497151998492 0 -0.9502626346973415"/>
		<child link="link_1"/>
		<parent link="link_13"/>
	</joint>
	<link name="link_2">
		<visual name="wheel-42">
			<origin xyz="-0.0992845498061307 0.7724105 0.03254063003487493"/>
			<geometry>
				<mesh filename="textured_objs/original-62.obj"/>
			</geometry>
		</visual>
		<collision>
			<origin xyz="-0.0992845498061307 0.7724105 0.03254063003487493"/>
			<geometry>
				<mesh filename="textured_objs/original-62.obj"/>
			</geometry>
		</collision>
	</link>
	<joint name="joint_2" type="continuous">
		<origin xyz="-0.197808351359873 -0.7724105 -0.5143238240154263"/>
		<axis xyz="-0.3114497151998492 0 -0.9502626346973415"/>
		<child link="link_2"/>
		<parent link="link_13"/>
	</joint>
	<link name="link_3">
		<visual name="wheel-37">
			<origin xyz="-0.11366920558191895 0.7724105 -0.15563188487680593"/>
			<geometry>
				<mesh filename="textured_objs/original-30.obj"/>
			</geometry>
		</visual>
		<collision>
			<origin xyz="-0.11366920558191895 0.7724105 -0.15563188487680593"/>
			<geometry>
				<mesh filename="textured_objs/original-30.obj"/>
			</geometry>
		</collision>
	</link>
	<joint name="joint_3" type="continuous">
		<origin xyz="0.3993188256924866 -0.7724105 -0.32605481484086696"/>
		<axis xyz="0.8075438209519561 0 -0.5898075764538084"/>
		<child link="link_3"/>
		<parent link="link_14"/>
	</joint>
	<link name="link_4">
		<visual name="wheel-38">
			<origin xyz="-0.11366920558191895 0.7724105 -0.15563188487680593"/>
			<geometry>
				<mesh filename="textured_objs/original-18.obj"/>
			</geometry>
		</visual>
		<collision>
			<origin xyz="-0.11366920558191895 0.7724105 -0.15563188487680593"/>
			<geometry>
				<mesh filename="textured_objs/original-18.obj"/>
			</geometry>
		</collision>
	</link>
	<joint name="joint_4" type="continuous">
		<origin xyz="0.3993188256924866 -0.7724105 -0.32605481484086696"/>
		<axis xyz="0.8075438209519561 0 -0.5898075764538084"/>
		<child link="link_4"/>
		<parent link="link_14"/>
	</joint>
	<link name="link_5">
		<visual name="wheel-33">
			<origin xyz="0.10893206364454598 0.7724105 -0.15074318419851823"/>
			<geometry>
				<mesh filename="textured_objs/original-60.obj"/>
			</geometry>
		</visual>
		<collision>
			<origin xyz="0.10893206364454598 0.7724105 -0.15074318419851823"/>
			<geometry>
				<mesh filename="textured_objs/original-60.obj"/>
			</geometry>
		</collision>
	</link>
	<joint name="joint_5" type="continuous">
		<origin xyz="0.3565424378658624 -0.7724105 0.22337104390782778"/>
		<axis xyz="0.8105210053801724 0 0.5857095695287168"/>
		<child link="link_5"/>
		<parent link="link_15"/>
	</joint>
	<link name="link_6">
		<visual name="wheel-34">
			<origin xyz="0.10893206364454598 0.7724105 -0.15074318419851823"/>
			<geometry>
				<mesh filename="textured_objs/original-29.obj"/>
			</geometry>
		</visual>
		<collision>
			<origin xyz="0.10893206364454598 0.7724105 -0.15074318419851823"/>
			<geometry>
				<mesh filename="textured_objs/original-29.obj"/>
			</geometry>
		</collision>
	</link>
	<joint name="joint_6" type="continuous">
		<origin xyz="0.3565424378658624 -0.7724105 0.22337104390782778"/>
		<axis xyz="0.8105210053801724 0 0.5857095695287168"/>
		<child link="link_6"/>
		<parent link="link_15"/>
	</joint>
	<link name="link_7">
		<visual name="wheel-29">
			<origin xyz="0.0890578648291246 0.7724105 0.028685456959102604"/>
			<geometry>
				<mesh filename="textured_objs/original-21.obj"/>
			</geometry>
		</visual>
		<visual name="wheel-29">
			<origin xyz="0.0890578648291246 0.7724105 0.028685456959102604"/>
			<geometry>
				<mesh filename="textured_objs/original-39.obj"/>
			</geometry>
		</visual>
		<collision>
			<origin xyz="0.0890578648291246 0.7724105 0.028685456959102604"/>
			<geometry>
				<mesh filename="textured_objs/original-21.obj"/>
			</geometry>
		</collision>
		<collision>
			<origin xyz="0.0890578648291246 0.7724105 0.028685456959102604"/>
			<geometry>
				<mesh filename="textured_objs/original-39.obj"/>
			</geometry>
		</collision>
	</link>
	<joint name="joint_7" type="continuous">
		<origin xyz="-0.09512860552627321 -0.7724105 0.3865359146205625"/>
		<axis xyz="-0.306587611084101 0 0.9518424432277353"/>
		<child link="link_7"/>
		<parent link="link_16"/>
	</joint>
	<link name="link_8">
		<visual name="wheel-30">
			<origin xyz="0.0890578648291246 0.7724105 0.028685456959102604"/>
			<geometry>
				<mesh filename="textured_objs/original-54.obj"/>
			</geometry>
		</visual>
		<visual name="wheel-30">
			<origin xyz="0.0890578648291246 0.7724105 0.028685456959102604"/>
			<geometry>
				<mesh filename="textured_objs/original-40.obj"/>
			</geometry>
		</visual>
		<collision>
			<origin xyz="0.0890578648291246 0.7724105 0.028685456959102604"/>
			<geometry>
				<mesh filename="textured_objs/original-54.obj"/>
			</geometry>
		</collision>
		<collision>
			<origin xyz="0.0890578648291246 0.7724105 0.028685456959102604"/>
			<geometry>
				<mesh filename="textured_objs/original-40.obj"/>
			</geometry>
		</collision>
	</link>
	<joint name="joint_8" type="continuous">
		<origin xyz="-0.09512860552627321 -0.7724105 0.3865359146205625"/>
		<axis xyz="-0.306587611084101 0 0.9518424432277353"/>
		<child link="link_8"/>
		<parent link="link_16"/>
	</joint>
	<link name="link_9">
		<visual name="wheel-23">
			<origin xyz="0.00010778227419602529 0.7724105 0.04312558927971338"/>
			<geometry>
				<mesh filename="textured_objs/original-5.obj"/>
			</geometry>
		</visual>
		<collision>
			<origin xyz="0.00010778227419602529 0.7724105 0.04312558927971338"/>
			<geometry>
				<mesh filename="textured_objs/original-5.obj"/>
			</geometry>
		</collision>
	</link>
	<joint name="joint_9" type="continuous">
		<origin xyz="-0.47762738069550686 -0.7724105 0.028975511241278007"/>
		<axis xyz="-0.9999968768520557 0 0.002499257116506058"/>
		<child link="link_9"/>
		<parent link="link_17"/>
	</joint>
	<link name="link_10">
		<visual name="wheel-24">
			<origin xyz="0.00010778227419602529 0.7724105 0.04312558927971338"/>
			<geometry>
				<mesh filename="textured_objs/original-12.obj"/>
			</geometry>
		</visual>
		<collision>
			<origin xyz="0.00010778227419602529 0.7724105 0.04312558927971338"/>
			<geometry>
				<mesh filename="textured_objs/original-12.obj"/>
			</geometry>
		</collision>
	</link>
	<joint name="joint_10" type="continuous">
		<origin xyz="-0.47762738069550686 -0.7724105 0.028975511241278007"/>
		<axis xyz="-0.9999968768520557 0 0.002499257116506058"/>
		<child link="link_10"/>
		<parent link="link_17"/>
	</joint>
	<link name="link_11">
		<visual name="seat_soft_surface-59">
			<origin xyz="-0.002711 0 -0.07935049999999999"/>
			<geometry>
				<mesh filename="textured_objs/original-68.obj"/>
			</geometry>
		</visual>
		<visual name="back_soft_surface-75">
			<origin xyz="-0.002711 0 -0.07935049999999999"/>
			<geometry>
				<mesh filename="textured_objs/original-48.obj"/>
			</geometry>
		</visual>
		<visual name="back_connector-74">
			<origin xyz="-0.002711 0 -0.07935049999999999"/>
			<geometry>
				<mesh filename="textured_objs/original-2.obj"/>
			</geometry>
		</visual>
		<visual name="back_support-76">
			<origin xyz="-0.002711 0 -0.07935049999999999"/>
			<geometry>
				<mesh filename="textured_objs/original-1.obj"/>
			</geometry>
		</visual>
		<visual name="armrest_soft_surface-67">
			<origin xyz="-0.002711 0 -0.07935049999999999"/>
			<geometry>
				<mesh filename="textured_objs/original-17.obj"/>
			</geometry>
		</visual>
		<visual name="armrest_soft_surface-67">
			<origin xyz="-0.002711 0 -0.07935049999999999"/>
			<geometry>
				<mesh filename="textured_objs/original-59.obj"/>
			</geometry>
		</visual>
		<visual name="arm_vertical_bar-68">
			<origin xyz="-0.002711 0 -0.07935049999999999"/>
			<geometry>
				<mesh filename="textured_objs/new-11.obj"/>
			</geometry>
		</visual>
		<visual name="arm_horizontal_bar-69">
			<origin xyz="-0.002711 0 -0.07935049999999999"/>
			<geometry>
				<mesh filename="textured_objs/new-7.obj"/>
			</geometry>
		</visual>
		<visual name="arm_connector-70">
			<origin xyz="-0.002711 0 -0.07935049999999999"/>
			<geometry>
				<mesh filename="textured_objs/original-44.obj"/>
			</geometry>
		</visual>
		<visual name="other_leaf-83">
			<origin xyz="-0.002711 0 -0.07935049999999999"/>
			<geometry>
				<mesh filename="textured_objs/original-65.obj"/>
			</geometry>
		</visual>
		<visual name="other_leaf-83">
			<origin xyz="-0.002711 0 -0.07935049999999999"/>
			<geometry>
				<mesh filename="textured_objs/original-64.obj"/>
			</geometry>
		</visual>
		<visual name="arm_vertical_bar-61">
			<origin xyz="-0.002711 0 -0.07935049999999999"/>
			<geometry>
				<mesh filename="textured_objs/new-6.obj"/>
			</geometry>
		</visual>
		<visual name="arm_horizontal_bar-62">
			<origin xyz="-0.002711 0 -0.07935049999999999"/>
			<geometry>
				<mesh filename="textured_objs/new-9.obj"/>
			</geometry>
		</visual>
		<visual name="arm_connector-63">
			<origin xyz="-0.002711 0 -0.07935049999999999"/>
			<geometry>
				<mesh filename="textured_objs/original-57.obj"/>
			</geometry>
		</visual>
		<visual name="armrest_soft_surface-64">
			<origin xyz="-0.002711 0 -0.07935049999999999"/>
			<geometry>
				<mesh filename="textured_objs/original-56.obj"/>
			</geometry>
		</visual>
		<visual name="other_leaf-85">
			<origin xyz="-0.002711 0 -0.07935049999999999"/>
			<geometry>
				<mesh filename="textured_objs/original-67.obj"/>
			</geometry>
		</visual>
		<visual name="other_leaf-85">
			<origin xyz="-0.002711 0 -0.07935049999999999"/>
			<geometry>
				<mesh filename="textured_objs/original-66.obj"/>
			</geometry>
		</visual>
		<visual name="central_support-45">
			<origin xyz="-0.002711 0 -0.07935049999999999"/>
			<geometry>
				<mesh filename="textured_objs/original-16.obj"/>
			</geometry>
		</visual>
		<visual name="seat_connector-47">
			<origin xyz="-0.002711 0 -0.07935049999999999"/>
			<geometry>
				<mesh filename="textured_objs/original-49.obj"/>
			</geometry>
		</visual>
		<visual name="seat_connector-52">
			<origin xyz="-0.002711 0 -0.07935049999999999"/>
			<geometry>
				<mesh filename="textured_objs/original-31.obj"/>
			</geometry>
		</visual>
		<visual name="seat_connector-52">
			<origin xyz="-0.002711 0 -0.07935049999999999"/>
			<geometry>
				<mesh filename="textured_objs/original-15.obj"/>
			</geometry>
		</visual>
		<visual name="seat_connector-52">
			<origin xyz="-0.002711 0 -0.07935049999999999"/>
			<geometry>
				<mesh filename="textured_objs/original-9.obj"/>
			</geometry>
		</visual>
		<visual name="seat_connector-52">
			<origin xyz="-0.002711 0 -0.07935049999999999"/>
			<geometry>
				<mesh filename="textured_objs/original-32.obj"/>
			</geometry>
		</visual>
		<visual name="mounting_plate-49">
			<origin xyz="-0.002711 0 -0.07935049999999999"/>
			<geometry>
				<mesh filename="textured_objs/original-51.obj"/>
			</geometry>
		</visual>
		<collision>
			<origin xyz="-0.002711 0 -0.07935049999999999"/>
			<geometry>
				<mesh filename="textured_objs/original-68.obj"/>
			</geometry>
		</collision>
		<collision>
			<origin xyz="-0.002711 0 -0.07935049999999999"/>
			<geometry>
				<mesh filename="textured_objs/original-48.obj"/>
			</geometry>
		</collision>
		<collision>
			<origin xyz="-0.002711 0 -0.07935049999999999"/>
			<geometry>
				<mesh filename="textured_objs/original-2.obj"/>
			</geometry>
		</collision>
		<collision>
			<origin xyz="-0.002711 0 -0.07935049999999999"/>
			<geometry>
				<mesh filename="textured_objs/original-1.obj"/>
			</geometry>
		</collision>
		<collision>
			<origin xyz="-0.002711 0 -0.07935049999999999"/>
			<geometry>
				<mesh filename="textured_objs/original-17.obj"/>
			</geometry>
		</collision>
		<collision>
			<origin xyz="-0.002711 0 -0.07935049999999999"/>
			<geometry>
				<mesh filename="textured_objs/original-59.obj"/>
			</geometry>
		</collision>
		<collision>
			<origin xyz="-0.002711 0 -0.07935049999999999"/>
			<geometry>
				<mesh filename="textured_objs/new-11.obj"/>
			</geometry>
		</collision>
		<collision>
			<origin xyz="-0.002711 0 -0.07935049999999999"/>
			<geometry>
				<mesh filename="textured_objs/new-7.obj"/>
			</geometry>
		</collision>
		<collision>
			<origin xyz="-0.002711 0 -0.07935049999999999"/>
			<geometry>
				<mesh filename="textured_objs/original-44.obj"/>
			</geometry>
		</collision>
		<collision>
			<origin xyz="-0.002711 0 -0.07935049999999999"/>
			<geometry>
				<mesh filename="textured_objs/original-65.obj"/>
			</geometry>
		</collision>
		<collision>
			<origin xyz="-0.002711 0 -0.07935049999999999"/>
			<geometry>
				<mesh filename="textured_objs/original-64.obj"/>
			</geometry>
		</collision>
		<collision>
			<origin xyz="-0.002711 0 -0.07935049999999999"/>
			<geometry>
				<mesh filename="textured_objs/new-6.obj"/>
			</geometry>
		</collision>
		<collision>
			<origin xyz="-0.002711 0 -0.07935049999999999"/>
			<geometry>
				<mesh filename="textured_objs/new-9.obj"/>
			</geometry>
		</collision>
		<collision>
			<origin xyz="-0.002711 0 -0.07935049999999999"/>
			<geometry>
				<mesh filename="textured_objs/original-57.obj"/>
			</geometry>
		</collision>
		<collision>
			<origin xyz="-0.002711 0 -0.07935049999999999"/>
			<geometry>
				<mesh filename="textured_objs/original-56.obj"/>
			</geometry>
		</collision>
		<collision>
			<origin xyz="-0.002711 0 -0.07935049999999999"/>
			<geometry>
				<mesh filename="textured_objs/original-67.obj"/>
			</geometry>
		</collision>
		<collision>
			<origin xyz="-0.002711 0 -0.07935049999999999"/>
			<geometry>
				<mesh filename="textured_objs/original-66.obj"/>
			</geometry>
		</collision>
		<collision>
			<origin xyz="-0.002711 0 -0.07935049999999999"/>
			<geometry>
				<mesh filename="textured_objs/original-16.obj"/>
			</geometry>
		</collision>
		<collision>
			<origin xyz="-0.002711 0 -0.07935049999999999"/>
			<geometry>
				<mesh filename="textured_objs/original-49.obj"/>
			</geometry>
		</collision>
		<collision>
			<origin xyz="-0.002711 0 -0.07935049999999999"/>
			<geometry>
				<mesh filename="textured_objs/original-31.obj"/>
			</geometry>
		</collision>
		<collision>
			<origin xyz="-0.002711 0 -0.07935049999999999"/>
			<geometry>
				<mesh filename="textured_objs/original-15.obj"/>
			</geometry>
		</collision>
		<collision>
			<origin xyz="-0.002711 0 -0.07935049999999999"/>
			<geometry>
				<mesh filename="textured_objs/original-9.obj"/>
			</geometry>
		</collision>
		<collision>
			<origin xyz="-0.002711 0 -0.07935049999999999"/>
			<geometry>
				<mesh filename="textured_objs/original-32.obj"/>
			</geometry>
		</collision>
		<collision>
			<origin xyz="-0.002711 0 -0.07935049999999999"/>
			<geometry>
				<mesh filename="textured_objs/original-51.obj"/>
			</geometry>
		</collision>
	</link>
	<joint name="joint_11" type="continuous">
		<origin xyz="0.0 0 0.0"/>
		<axis xyz="0 -1 0"/>
		<child link="link_11"/>
		<parent link="link_11_helper"/>
	</joint>
	<link name="link_12">
		<visual name="central_support-43">
			<origin xyz="0 0 0"/>
			<geometry>
				<mesh filename="textured_objs/original-58.obj"/>
			</geometry>
		</visual>
		<visual name="central_support-44">
			<origin xyz="0 0 0"/>
			<geometry>
				<mesh filename="textured_objs/original-8.obj"/>
			</geometry>
		</visual>
		<visual name="central_support-50">
			<origin xyz="0 0 0"/>
			<geometry>
				<mesh filename="textured_objs/original-10.obj"/>
			</geometry>
		</visual>
		<visual name="central_support-50">
			<origin xyz="0 0 0"/>
			<geometry>
				<mesh filename="textured_objs/original-11.obj"/>
			</geometry>
		</visual>
		<visual name="central_support-50">
			<origin xyz="0 0 0"/>
			<geometry>
				<mesh filename="textured_objs/original-6.obj"/>
			</geometry>
		</visual>
		<visual name="leg-12">
			<origin xyz="0 0 0"/>
			<geometry>
				<mesh filename="textured_objs/new-1.obj"/>
			</geometry>
		</visual>
		<visual name="leg-13">
			<origin xyz="0 0 0"/>
			<geometry>
				<mesh filename="textured_objs/new-0.obj"/>
			</geometry>
		</visual>
		<visual name="leg-14">
			<origin xyz="0 0 0"/>
			<geometry>
				<mesh filename="textured_objs/new-4.obj"/>
			</geometry>
		</visual>
		<visual name="leg-15">
			<origin xyz="0 0 0"/>
			<geometry>
				<mesh filename="textured_objs/new-3.obj"/>
			</geometry>
		</visual>
		<visual name="leg-16">
			<origin xyz="0 0 0"/>
			<geometry>
				<mesh filename="textured_objs/new-2.obj"/>
			</geometry>
		</visual>
		<visual name="footrest_bar-53">
			<origin xyz="0 0 0"/>
			<geometry>
				<mesh filename="textured_objs/original-13.obj"/>
			</geometry>
		</visual>
		<visual name="footrest_bar-54">
			<origin xyz="0 0 0"/>
			<geometry>
				<mesh filename="textured_objs/original-3.obj"/>
			</geometry>
		</visual>
		<visual name="footrest_bar-55">
			<origin xyz="0 0 0"/>
			<geometry>
				<mesh filename="textured_objs/original-33.obj"/>
			</geometry>
		</visual>
		<visual name="footrest_bar-56">
			<origin xyz="0 0 0"/>
			<geometry>
				<mesh filename="textured_objs/original-36.obj"/>
			</geometry>
		</visual>
		<visual name="footrest_circular-57">
			<origin xyz="0 0 0"/>
			<geometry>
				<mesh filename="textured_objs/original-37.obj"/>
			</geometry>
		</visual>
		<visual name="other_leaf-78">
			<origin xyz="0 0 0"/>
			<geometry>
				<mesh filename="textured_objs/original-7.obj"/>
			</geometry>
		</visual>
		<visual name="other_leaf-79">
			<origin xyz="0 0 0"/>
			<geometry>
				<mesh filename="textured_objs/original-34.obj"/>
			</geometry>
		</visual>
		<visual name="other_leaf-80">
			<origin xyz="0 0 0"/>
			<geometry>
				<mesh filename="textured_objs/original-35.obj"/>
			</geometry>
		</visual>
		<visual name="other_leaf-81">
			<origin xyz="0 0 0"/>
			<geometry>
				<mesh filename="textured_objs/original-63.obj"/>
			</geometry>
		</visual>
		<collision>
			<origin xyz="0 0 0"/>
			<geometry>
				<mesh filename="textured_objs/original-58.obj"/>
			</geometry>
		</collision>
		<collision>
			<origin xyz="0 0 0"/>
			<geometry>
				<mesh filename="textured_objs/original-8.obj"/>
			</geometry>
		</collision>
		<collision>
			<origin xyz="0 0 0"/>
			<geometry>
				<mesh filename="textured_objs/original-10.obj"/>
			</geometry>
		</collision>
		<collision>
			<origin xyz="0 0 0"/>
			<geometry>
				<mesh filename="textured_objs/original-11.obj"/>
			</geometry>
		</collision>
		<collision>
			<origin xyz="0 0 0"/>
			<geometry>
				<mesh filename="textured_objs/original-6.obj"/>
			</geometry>
		</collision>
		<collision>
			<origin xyz="0 0 0"/>
			<geometry>
				<mesh filename="textured_objs/new-1.obj"/>
			</geometry>
		</collision>
		<collision>
			<origin xyz="0 0 0"/>
			<geometry>
				<mesh filename="textured_objs/new-0.obj"/>
			</geometry>
		</collision>
		<collision>
			<origin xyz="0 0 0"/>
			<geometry>
				<mesh filename="textured_objs/new-4.obj"/>
			</geometry>
		</collision>
		<collision>
			<origin xyz="0 0 0"/>
			<geometry>
				<mesh filename="textured_objs/new-3.obj"/>
			</geometry>
		</collision>
		<collision>
			<origin xyz="0 0 0"/>
			<geometry>
				<mesh filename="textured_objs/new-2.obj"/>
			</geometry>
		</collision>
		<collision>
			<origin xyz="0 0 0"/>
			<geometry>
				<mesh filename="textured_objs/original-13.obj"/>
			</geometry>
		</collision>
		<collision>
			<origin xyz="0 0 0"/>
			<geometry>
				<mesh filename="textured_objs/original-3.obj"/>
			</geometry>
		</collision>
		<collision>
			<origin xyz="0 0 0"/>
			<geometry>
				<mesh filename="textured_objs/original-33.obj"/>
			</geometry>
		</collision>
		<collision>
			<origin xyz="0 0 0"/>
			<geometry>
				<mesh filename="textured_objs/original-36.obj"/>
			</geometry>
		</collision>
		<collision>
			<origin xyz="0 0 0"/>
			<geometry>
				<mesh filename="textured_objs/original-37.obj"/>
			</geometry>
		</collision>
		<collision>
			<origin xyz="0 0 0"/>
			<geometry>
				<mesh filename="textured_objs/original-7.obj"/>
			</geometry>
		</collision>
		<collision>
			<origin xyz="0 0 0"/>
			<geometry>
				<mesh filename="textured_objs/original-34.obj"/>
			</geometry>
		</collision>
		<collision>
			<origin xyz="0 0 0"/>
			<geometry>
				<mesh filename="textured_objs/original-35.obj"/>
			</geometry>
		</collision>
		<collision>
			<origin xyz="0 0 0"/>
			<geometry>
				<mesh filename="textured_objs/original-63.obj"/>
			</geometry>
		</collision>
	</link>
	<joint name="joint_12" type="fixed">
		<origin rpy="1.570796326794897 0 -1.570796326794897" xyz="0 0 0"/>
		<child link="link_12"/>
		<parent link="base"/>
	</joint>
	<link name="link_13">
		<visual name="caster_yoke-39">
			<origin xyz="-0.29709290116600373 0 -0.48178319398055136"/>
			<geometry>
				<mesh filename="textured_objs/original-52.obj"/>
			</geometry>
		</visual>
		<visual name="caster_stem-40">
			<origin xyz="-0.29709290116600373 0 -0.48178319398055136"/>
			<geometry>
				<mesh filename="textured_objs/original-28.obj"/>
			</geometry>
		</visual>
		<collision>
			<origin xyz="-0.29709290116600373 0 -0.48178319398055136"/>
			<geometry>
				<mesh filename="textured_objs/original-52.obj"/>
			</geometry>
		</collision>
		<collision>
			<origin xyz="-0.29709290116600373 0 -0.48178319398055136"/>
			<geometry>
				<mesh filename="textured_objs/original-28.obj"/>
			</geometry>
		</collision>
	</link>
	<joint name="joint_13" type="continuous">
		<origin xyz="0.29709290116600373 0 0.48178319398055136"/>
		<axis xyz="0 1 0"/>
		<child link="link_13"/>
		<parent link="link_12"/>
	</joint>
	<link name="link_14">
		<visual name="caster_yoke-35">
			<origin xyz="0.28564962011056766 0 -0.4816866997176729"/>
			<geometry>
				<mesh filename="textured_objs/original-19.obj"/>
			</geometry>
		</visual>
		<visual name="caster_stem-36">
			<origin xyz="0.28564962011056766 0 -0.4816866997176729"/>
			<geometry>
				<mesh filename="textured_objs/original-61.obj"/>
			</geometry>
		</visual>
		<collision>
			<origin xyz="0.28564962011056766 0 -0.4816866997176729"/>
			<geometry>
				<mesh filename="textured_objs/original-19.obj"/>
			</geometry>
		</collision>
		<collision>
			<origin xyz="0.28564962011056766 0 -0.4816866997176729"/>
			<geometry>
				<mesh filename="textured_objs/original-61.obj"/>
			</geometry>
		</collision>
	</link>
	<joint name="joint_14" type="continuous">
		<origin xyz="-0.28564962011056766 0 0.4816866997176729"/>
		<axis xyz="0 1 0"/>
		<child link="link_14"/>
		<parent link="link_12"/>
	</joint>
	<link name="link_15">
		<visual name="caster_yoke-31">
			<origin xyz="0.4654745015104084 0 0.07262785970930954"/>
			<geometry>
				<mesh filename="textured_objs/original-20.obj"/>
			</geometry>
		</visual>
		<visual name="caster_stem-32">
			<origin xyz="0.4654745015104084 0 0.07262785970930954"/>
			<geometry>
				<mesh filename="textured_objs/original-26.obj"/>
			</geometry>
		</visual>
		<collision>
			<origin xyz="0.4654745015104084 0 0.07262785970930954"/>
			<geometry>
				<mesh filename="textured_objs/original-20.obj"/>
			</geometry>
		</collision>
		<collision>
			<origin xyz="0.4654745015104084 0 0.07262785970930954"/>
			<geometry>
				<mesh filename="textured_objs/original-26.obj"/>
			</geometry>
		</collision>
	</link>
	<joint name="joint_15" type="continuous">
		<origin xyz="-0.4654745015104084 0 -0.07262785970930954"/>
		<axis xyz="0 1 0"/>
		<child link="link_15"/>
		<parent link="link_12"/>
	</joint>
	<link name="link_16">
		<visual name="caster_yoke-27">
			<origin xyz="-0.006070740697148607 0 0.41522137157966515"/>
			<geometry>
				<mesh filename="textured_objs/original-50.obj"/>
			</geometry>
		</visual>
		<visual name="caster_yoke-27">
			<origin xyz="-0.006070740697148607 0 0.41522137157966515"/>
			<geometry>
				<mesh filename="textured_objs/original-4.obj"/>
			</geometry>
		</visual>
		<visual name="caster_stem-28">
			<origin xyz="-0.006070740697148607 0 0.41522137157966515"/>
			<geometry>
				<mesh filename="textured_objs/original-47.obj"/>
			</geometry>
		</visual>
		<visual name="caster_stem-28">
			<origin xyz="-0.006070740697148607 0 0.41522137157966515"/>
			<geometry>
				<mesh filename="textured_objs/original-53.obj"/>
			</geometry>
		</visual>
		<collision>
			<origin xyz="-0.006070740697148607 0 0.41522137157966515"/>
			<geometry>
				<mesh filename="textured_objs/original-50.obj"/>
			</geometry>
		</collision>
		<collision>
			<origin xyz="-0.006070740697148607 0 0.41522137157966515"/>
			<geometry>
				<mesh filename="textured_objs/original-4.obj"/>
			</geometry>
		</collision>
		<collision>
			<origin xyz="-0.006070740697148607 0 0.41522137157966515"/>
			<geometry>
				<mesh filename="textured_objs/original-47.obj"/>
			</geometry>
		</collision>
		<collision>
			<origin xyz="-0.006070740697148607 0 0.41522137157966515"/>
			<geometry>
				<mesh filename="textured_objs/original-53.obj"/>
			</geometry>
		</collision>
	</link>
	<joint name="joint_16" type="continuous">
		<origin xyz="0.006070740697148607 0 -0.41522137157966515"/>
		<axis xyz="0 1 0"/>
		<child link="link_16"/>
		<parent link="link_12"/>
	</joint>
	<link name="link_17">
		<visual name="caster_yoke-25">
			<origin xyz="-0.47751959842131086 0 0.07210110052099139"/>
			<geometry>
				<mesh filename="textured_objs/original-23.obj"/>
			</geometry>
		</visual>
		<visual name="caster_stem-26">
			<origin xyz="-0.47751959842131086 0 0.07210110052099139"/>
			<geometry>
				<mesh filename="textured_objs/original-25.obj"/>
			</geometry>
		</visual>
		<collision>
			<origin xyz="-0.47751959842131086 0 0.07210110052099139"/>
			<geometry>
				<mesh filename="textured_objs/original-23.obj"/>
			</geometry>
		</collision>
		<collision>
			<origin xyz="-0.47751959842131086 0 0.07210110052099139"/>
			<geometry>
				<mesh filename="textured_objs/original-25.obj"/>
			</geometry>
		</collision>
	</link>
	<joint name="joint_17" type="continuous">
		<origin xyz="0.47751959842131086 0 -0.07210110052099139"/>
		<axis xyz="0 1 0"/>
		<child link="link_17"/>
		<parent link="link_12"/>
	</joint>
	<link name="link_11_helper"/>
	<joint name="joint_18" type="prismatic">
		<origin xyz="0.002711 0 0.07935049999999999"/>
		<axis xyz="0 -1 0"/>
		<child link="link_11_helper"/>
		<parent link="link_12"/>
		<limit lower="0" upper="0.1120000000000001"/>
	</joint>
</robot>
