<?xml version="1.0" ?>
<robot name="partnet_496dcf99-6e76-480c-8fab-a5579f16f2c7">
	<link name="base"/>
	<link name="link_0">
		<visual name="frame-2">
			<origin xyz="0 0 0"/>
			<geometry>
				<mesh filename="textured_objs/new-0.obj"/>
			</geometry>
		</visual>
		<visual name="frame-2">
			<origin xyz="0 0 0"/>
			<geometry>
				<mesh filename="textured_objs/new-1.obj"/>
			</geometry>
		</visual>
		<collision>
			<origin xyz="0 0 0"/>
			<geometry>
				<mesh filename="textured_objs/new-0.obj"/>
			</geometry>
		</collision>
		<collision>
			<origin xyz="0 0 0"/>
			<geometry>
				<mesh filename="textured_objs/new-1.obj"/>
			</geometry>
		</collision>
	</link>
	<joint name="joint_0" type="fixed">
		<origin rpy="1.570796326794897 0 -1.570796326794897" xyz="0 0 0"/>
		<child link="link_0"/>
		<parent link="base"/>
	</joint>
	<link name="link_1">
		<visual name="door_frame-4">
			<origin xyz="-0.7889629999999999 0.4118613067350796 -0.4760670618255048"/>
			<geometry>
				<mesh filename="textured_objs/original-4.obj"/>
			</geometry>
		</visual>
		<visual name="handle-5">
			<origin xyz="-0.7889629999999999 0.4118613067350796 -0.4760670618255048"/>
			<geometry>
				<mesh filename="textured_objs/original-1.obj"/>
			</geometry>
		</visual>
		<collision>
			<origin xyz="-0.7889629999999999 0.4118613067350796 -0.4760670618255048"/>
			<geometry>
				<mesh filename="textured_objs/original-4.obj"/>
			</geometry>
		</collision>
		<collision>
			<origin xyz="-0.7889629999999999 0.4118613067350796 -0.4760670618255048"/>
			<geometry>
				<mesh filename="textured_objs/original-1.obj"/>
			</geometry>
		</collision>
	</link>
	<joint name="joint_1" type="revolute">
		<origin xyz="0.7889629999999999 -0.4118613067350796 0.4760670618255048"/>
		<axis xyz="1 0 0"/>
		<child link="link_1"/>
		<parent link="link_0"/>
		<limit lower="0.0" upper="1.5707963267948966"/>
	</joint>
</robot>
