<?xml version="1.0" ?>
<robot name="partnet_u8ee196b0-0772-48fb-8ad8-541f4620bc9a">
	<link name="base"/>
	<link name="link_0">
		<visual name="blade-4">
			<origin xyz="0.32242095264437604 0.0356360003352163 -0.03222159394190899"/>
			<geometry>
				<mesh filename="textured_objs/original-5.obj"/>
			</geometry>
		</visual>
		<visual name="handle-5">
			<origin xyz="0.32242095264437604 0.0356360003352163 -0.03222159394190899"/>
			<geometry>
				<mesh filename="textured_objs/original-8.obj"/>
			</geometry>
		</visual>
		<visual name="handle-5">
			<origin xyz="0.32242095264437604 0.0356360003352163 -0.03222159394190899"/>
			<geometry>
				<mesh filename="textured_objs/original-9.obj"/>
			</geometry>
		</visual>
		<collision>
			<origin xyz="0.32242095264437604 0.0356360003352163 -0.03222159394190899"/>
			<geometry>
				<mesh filename="textured_objs/original-5.obj"/>
			</geometry>
		</collision>
		<collision>
			<origin xyz="0.32242095264437604 0.0356360003352163 -0.03222159394190899"/>
			<geometry>
				<mesh filename="textured_objs/original-8.obj"/>
			</geometry>
		</collision>
		<collision>
			<origin xyz="0.32242095264437604 0.0356360003352163 -0.03222159394190899"/>
			<geometry>
				<mesh filename="textured_objs/original-9.obj"/>
			</geometry>
		</collision>
	</link>
	<joint name="joint_0" type="revolute">
		<origin xyz="-0.32242095264437604 -0.0356360003352163 0.03222159394190899"/>
		<axis xyz="0 -1 0"/>
		<child link="link_0"/>
		<parent link="link_1"/>
		<limit lower="-0.0" upper="1.0471975511965976"/>
	</joint>
	<link name="link_1">
		<visual name="screw-3">
			<origin xyz="0 0 0"/>
			<geometry>
				<mesh filename="textured_objs/original-10.obj"/>
			</geometry>
		</visual>
		<visual name="blade-6">
			<origin xyz="0 0 0"/>
			<geometry>
				<mesh filename="textured_objs/original-1.obj"/>
			</geometry>
		</visual>
		<visual name="handle-7">
			<origin xyz="0 0 0"/>
			<geometry>
				<mesh filename="textured_objs/original-12.obj"/>
			</geometry>
		</visual>
		<visual name="handle-7">
			<origin xyz="0 0 0"/>
			<geometry>
				<mesh filename="textured_objs/original-13.obj"/>
			</geometry>
		</visual>
		<collision>
			<origin xyz="0 0 0"/>
			<geometry>
				<mesh filename="textured_objs/original-10.obj"/>
			</geometry>
		</collision>
		<collision>
			<origin xyz="0 0 0"/>
			<geometry>
				<mesh filename="textured_objs/original-1.obj"/>
			</geometry>
		</collision>
		<collision>
			<origin xyz="0 0 0"/>
			<geometry>
				<mesh filename="textured_objs/original-12.obj"/>
			</geometry>
		</collision>
		<collision>
			<origin xyz="0 0 0"/>
			<geometry>
				<mesh filename="textured_objs/original-13.obj"/>
			</geometry>
		</collision>
	</link>
	<joint name="joint_1" type="fixed">
		<origin rpy="1.570796326794897 0 -1.570796326794897" xyz="0 0 0"/>
		<child link="link_1"/>
		<parent link="base"/>
	</joint>
</robot>
