<?xml version="1.0" ?>
<robot name="partnet_441d06d5a657a5dfe7ae87d20a4fdaa5">
	<link name="base"/>
	<link name="link_0">
		<visual name="lamp_arm_straight_bar-35">
			<origin xyz="-0.03980319263821358 0.4602363704233049 0.061404541876177846"/>
			<geometry>
				<mesh filename="textured_objs/original-3.obj"/>
			</geometry>
		</visual>
		<collision>
			<origin xyz="-0.03980319263821358 0.4602363704233049 0.061404541876177846"/>
			<geometry>
				<mesh filename="textured_objs/original-3.obj"/>
			</geometry>
		</collision>
	</link>
	<joint name="joint_0" type="revolute">
		<origin xyz="0.03980319263821358 -0.4602363704233049 -0.061404541876177846"/>
		<axis xyz="-0.9160790234348367 -0.12984492899208308 0.37939361781363323"/>
		<child link="link_0"/>
		<parent link="link_2"/>
		<limit lower="-1.0471975511965976" upper="1.0471975511965976"/>
	</joint>
	<link name="link_1">
		<visual name="lamp_shade-13">
			<origin xyz="0.003533896811481113 -0.8533634844568707 -0.012224281949472116"/>
			<geometry>
				<mesh filename="textured_objs/original-14.obj"/>
			</geometry>
		</visual>
		<visual name="other_leaf-18">
			<origin xyz="0.003533896811481113 -0.8533634844568707 -0.012224281949472116"/>
			<geometry>
				<mesh filename="textured_objs/original-7.obj"/>
			</geometry>
		</visual>
		<visual name="other_leaf-18">
			<origin xyz="0.003533896811481113 -0.8533634844568707 -0.012224281949472116"/>
			<geometry>
				<mesh filename="textured_objs/original-4.obj"/>
			</geometry>
		</visual>
		<visual name="lamp_cover_holder-19">
			<origin xyz="0.003533896811481113 -0.8533634844568707 -0.012224281949472116"/>
			<geometry>
				<mesh filename="textured_objs/original-12.obj"/>
			</geometry>
		</visual>
		<visual name="lamp_cover_holder-19">
			<origin xyz="0.003533896811481113 -0.8533634844568707 -0.012224281949472116"/>
			<geometry>
				<mesh filename="textured_objs/original-13.obj"/>
			</geometry>
		</visual>
		<visual name="lamp_cover_holder-20">
			<origin xyz="0.003533896811481113 -0.8533634844568707 -0.012224281949472116"/>
			<geometry>
				<mesh filename="textured_objs/original-6.obj"/>
			</geometry>
		</visual>
		<collision>
			<origin xyz="0.003533896811481113 -0.8533634844568707 -0.012224281949472116"/>
			<geometry>
				<mesh filename="textured_objs/original-14.obj"/>
			</geometry>
		</collision>
		<collision>
			<origin xyz="0.003533896811481113 -0.8533634844568707 -0.012224281949472116"/>
			<geometry>
				<mesh filename="textured_objs/original-7.obj"/>
			</geometry>
		</collision>
		<collision>
			<origin xyz="0.003533896811481113 -0.8533634844568707 -0.012224281949472116"/>
			<geometry>
				<mesh filename="textured_objs/original-4.obj"/>
			</geometry>
		</collision>
		<collision>
			<origin xyz="0.003533896811481113 -0.8533634844568707 -0.012224281949472116"/>
			<geometry>
				<mesh filename="textured_objs/original-12.obj"/>
			</geometry>
		</collision>
		<collision>
			<origin xyz="0.003533896811481113 -0.8533634844568707 -0.012224281949472116"/>
			<geometry>
				<mesh filename="textured_objs/original-13.obj"/>
			</geometry>
		</collision>
		<collision>
			<origin xyz="0.003533896811481113 -0.8533634844568707 -0.012224281949472116"/>
			<geometry>
				<mesh filename="textured_objs/original-6.obj"/>
			</geometry>
		</collision>
	</link>
	<joint name="joint_1" type="revolute">
		<origin xyz="-0.003533896811481113 0.24385668806503114 0.24914967990810527"/>
		<axis xyz="-0.07982163317864585 0.7915492508041638 -0.6058698626174276"/>
		<child link="link_1"/>
		<parent link="link_3"/>
		<limit lower="-0.6981317007977318" upper="0.7853981633974483"/>
	</joint>
	<link name="link_2">
		<visual name="lamp_base_part-27">
			<origin xyz="0 0 0"/>
			<geometry>
				<mesh filename="textured_objs/original-1.obj"/>
			</geometry>
		</visual>
		<visual name="lamp_base_part-27">
			<origin xyz="0 0 0"/>
			<geometry>
				<mesh filename="textured_objs/original-2.obj"/>
			</geometry>
		</visual>
		<visual name="lamp_joint-33">
			<origin xyz="0 0 0"/>
			<geometry>
				<mesh filename="textured_objs/original-10.obj"/>
			</geometry>
		</visual>
		<visual name="lamp_joint-33">
			<origin xyz="0 0 0"/>
			<geometry>
				<mesh filename="textured_objs/original-8.obj"/>
			</geometry>
		</visual>
		<collision>
			<origin xyz="0 0 0"/>
			<geometry>
				<mesh filename="textured_objs/original-1.obj"/>
			</geometry>
		</collision>
		<collision>
			<origin xyz="0 0 0"/>
			<geometry>
				<mesh filename="textured_objs/original-2.obj"/>
			</geometry>
		</collision>
		<collision>
			<origin xyz="0 0 0"/>
			<geometry>
				<mesh filename="textured_objs/original-10.obj"/>
			</geometry>
		</collision>
		<collision>
			<origin xyz="0 0 0"/>
			<geometry>
				<mesh filename="textured_objs/original-8.obj"/>
			</geometry>
		</collision>
	</link>
	<joint name="joint_2" type="fixed">
		<origin rpy="1.570796326794897 0 -1.570796326794897" xyz="0 0 0"/>
		<child link="link_2"/>
		<parent link="base"/>
	</joint>
	<link name="link_3">
		<visual name="lamp_arm_straight_bar-34">
			<origin xyz="0 -0.6095067963918396 0.23692539795863315"/>
			<geometry>
				<mesh filename="textured_objs/original-5.obj"/>
			</geometry>
		</visual>
		<visual name="lamp_joint-31">
			<origin xyz="0 -0.6095067963918396 0.23692539795863315"/>
			<geometry>
				<mesh filename="textured_objs/original-11.obj"/>
			</geometry>
		</visual>
		<visual name="lamp_joint-32">
			<origin xyz="0 -0.6095067963918396 0.23692539795863315"/>
			<geometry>
				<mesh filename="textured_objs/original-9.obj"/>
			</geometry>
		</visual>
		<collision>
			<origin xyz="0 -0.6095067963918396 0.23692539795863315"/>
			<geometry>
				<mesh filename="textured_objs/original-5.obj"/>
			</geometry>
		</collision>
		<collision>
			<origin xyz="0 -0.6095067963918396 0.23692539795863315"/>
			<geometry>
				<mesh filename="textured_objs/original-11.obj"/>
			</geometry>
		</collision>
		<collision>
			<origin xyz="0 -0.6095067963918396 0.23692539795863315"/>
			<geometry>
				<mesh filename="textured_objs/original-9.obj"/>
			</geometry>
		</collision>
	</link>
	<joint name="joint_3" type="revolute">
		<origin xyz="-0.03980319263821358 1.0697431668151445 -0.17552085608245532"/>
		<axis xyz="1 0 0"/>
		<child link="link_3"/>
		<parent link="link_0"/>
		<limit lower="-0.7853981633974483" upper="1.3089969389957472"/>
	</joint>
</robot>
