<?xml version="1.0" ?>
<robot name="partnet_35c2de57ee36f652492d9da2668ec34c">
	<link name="base"/>
	<link name="link_0">
		<visual name="knob-34">
			<origin xyz="0.009746848559431533 -0.0826339701651703 -0.2754931092061461"/>
			<geometry>
				<mesh filename="textured_objs/original-31.obj"/>
			</geometry>
		</visual>
		<collision>
			<origin xyz="0.009746848559431533 -0.0826339701651703 -0.2754931092061461"/>
			<geometry>
				<mesh filename="textured_objs/original-31.obj"/>
			</geometry>
		</collision>
	</link>
	<joint name="joint_0" type="continuous">
		<origin xyz="-0.00019734855943154446 0.0826339701651703 0.15189110920614612"/>
		<axis xyz="0.0007165922567898293 -0.9578324255490651 0.2873265234229728"/>
		<child link="link_0"/>
		<parent link="link_11"/>
	</joint>
	<link name="link_1">
		<visual name="caster_stem-27">
			<origin xyz="0.3142825 0 0.315462"/>
			<geometry>
				<mesh filename="textured_objs/original-7.obj"/>
			</geometry>
		</visual>
		<collision>
			<origin xyz="0.3142825 0 0.315462"/>
			<geometry>
				<mesh filename="textured_objs/original-7.obj"/>
			</geometry>
		</collision>
	</link>
	<joint name="joint_1" type="continuous">
		<origin xyz="-0.3142825 0 -0.315462"/>
		<axis xyz="0 1 0"/>
		<child link="link_1"/>
		<parent link="link_12"/>
	</joint>
	<link name="link_2">
		<visual name="wheel-28">
			<origin xyz="0 0.74277 0.2905821496573666"/>
			<geometry>
				<mesh filename="textured_objs/original-6.obj"/>
			</geometry>
		</visual>
		<collision>
			<origin xyz="0 0.74277 0.2905821496573666"/>
			<geometry>
				<mesh filename="textured_objs/original-6.obj"/>
			</geometry>
		</collision>
	</link>
	<joint name="joint_2" type="continuous">
		<origin xyz="0.3142825 -0.74277 0.024879850342633403"/>
		<axis xyz="-1 0 0"/>
		<child link="link_2"/>
		<parent link="link_1"/>
	</joint>
	<link name="link_3">
		<visual name="caster_stem-25">
			<origin xyz="-0.298053 0 0.31489"/>
			<geometry>
				<mesh filename="textured_objs/original-11.obj"/>
			</geometry>
		</visual>
		<collision>
			<origin xyz="-0.298053 0 0.31489"/>
			<geometry>
				<mesh filename="textured_objs/original-11.obj"/>
			</geometry>
		</collision>
	</link>
	<joint name="joint_3" type="continuous">
		<origin xyz="0.298053 0 -0.31489"/>
		<axis xyz="0 1 0"/>
		<child link="link_3"/>
		<parent link="link_12"/>
	</joint>
	<link name="link_4">
		<visual name="wheel-26">
			<origin xyz="0 0.74277 0.2905821496573666"/>
			<geometry>
				<mesh filename="textured_objs/original-10.obj"/>
			</geometry>
		</visual>
		<collision>
			<origin xyz="0 0.74277 0.2905821496573666"/>
			<geometry>
				<mesh filename="textured_objs/original-10.obj"/>
			</geometry>
		</collision>
	</link>
	<joint name="joint_4" type="continuous">
		<origin xyz="-0.298053 -0.74277 0.024307850342633386"/>
		<axis xyz="-1 0 0"/>
		<child link="link_4"/>
		<parent link="link_3"/>
	</joint>
	<link name="link_5">
		<visual name="caster_stem-23">
			<origin xyz="-0.4866755 0 -0.26770499999999997"/>
			<geometry>
				<mesh filename="textured_objs/original-9.obj"/>
			</geometry>
		</visual>
		<collision>
			<origin xyz="-0.4866755 0 -0.26770499999999997"/>
			<geometry>
				<mesh filename="textured_objs/original-9.obj"/>
			</geometry>
		</collision>
	</link>
	<joint name="joint_5" type="continuous">
		<origin xyz="0.4866755 0 0.26770499999999997"/>
		<axis xyz="0 1 0"/>
		<child link="link_5"/>
		<parent link="link_12"/>
	</joint>
	<link name="link_6">
		<visual name="wheel-24">
			<origin xyz="0 0.7427699999999999 -0.29196"/>
			<geometry>
				<mesh filename="textured_objs/original-8.obj"/>
			</geometry>
		</visual>
		<collision>
			<origin xyz="0 0.7427699999999999 -0.29196"/>
			<geometry>
				<mesh filename="textured_objs/original-8.obj"/>
			</geometry>
		</collision>
	</link>
	<joint name="joint_6" type="continuous">
		<origin xyz="-0.4866755 -0.7427699999999999 0.024255000000000027"/>
		<axis xyz="-1 0 0"/>
		<child link="link_6"/>
		<parent link="link_5"/>
	</joint>
	<link name="link_7">
		<visual name="caster_stem-21">
			<origin xyz="0.009176 0 -0.6271165000000001"/>
			<geometry>
				<mesh filename="textured_objs/original-2.obj"/>
			</geometry>
		</visual>
		<collision>
			<origin xyz="0.009176 0 -0.6271165000000001"/>
			<geometry>
				<mesh filename="textured_objs/original-2.obj"/>
			</geometry>
		</collision>
	</link>
	<joint name="joint_7" type="continuous">
		<origin xyz="-0.009176 0 0.6271165000000001"/>
		<axis xyz="0 1 0"/>
		<child link="link_7"/>
		<parent link="link_12"/>
	</joint>
	<link name="link_8">
		<visual name="wheel-22">
			<origin xyz="0 0.7427699999999999 -0.6514178904291851"/>
			<geometry>
				<mesh filename="textured_objs/original-3.obj"/>
			</geometry>
		</visual>
		<collision>
			<origin xyz="0 0.7427699999999999 -0.6514178904291851"/>
			<geometry>
				<mesh filename="textured_objs/original-3.obj"/>
			</geometry>
		</collision>
	</link>
	<joint name="joint_8" type="continuous">
		<origin xyz="0.009176 -0.7427699999999999 0.024301390429185"/>
		<axis xyz="-1 0 0"/>
		<child link="link_8"/>
		<parent link="link_7"/>
	</joint>
	<link name="link_9">
		<visual name="caster_stem-19">
			<origin xyz="0.5041285 0 -0.26681499999999997"/>
			<geometry>
				<mesh filename="textured_objs/original-5.obj"/>
			</geometry>
		</visual>
		<collision>
			<origin xyz="0.5041285 0 -0.26681499999999997"/>
			<geometry>
				<mesh filename="textured_objs/original-5.obj"/>
			</geometry>
		</collision>
	</link>
	<joint name="joint_9" type="continuous">
		<origin xyz="-0.5041285 0 0.26681499999999997"/>
		<axis xyz="0 1 0"/>
		<child link="link_9"/>
		<parent link="link_12"/>
	</joint>
	<link name="link_10">
		<visual name="wheel-20">
			<origin xyz="1.652065151467475e-05 0.7439810248591078 -0.2892663923381096"/>
			<geometry>
				<mesh filename="textured_objs/original-4.obj"/>
			</geometry>
		</visual>
		<collision>
			<origin xyz="1.652065151467475e-05 0.7439810248591078 -0.2892663923381096"/>
			<geometry>
				<mesh filename="textured_objs/original-4.obj"/>
			</geometry>
		</collision>
	</link>
	<joint name="joint_10" type="continuous">
		<origin xyz="0.5041119793484853 -0.7439810248591078 0.02245139233810961"/>
		<axis xyz="0.9999995520251832 -0.00036221838802538264 -0.0008744982974655233"/>
		<child link="link_10"/>
		<parent link="link_9"/>
	</joint>
	<link name="link_11">
		<visual name="back_soft_surface-46">
			<origin xyz="0.009549499999999989 0 -0.123602"/>
			<geometry>
				<mesh filename="textured_objs/original-12.obj"/>
			</geometry>
		</visual>
		<visual name="back_soft_surface-46">
			<origin xyz="0.009549499999999989 0 -0.123602"/>
			<geometry>
				<mesh filename="textured_objs/original-28.obj"/>
			</geometry>
		</visual>
		<visual name="back_soft_surface-46">
			<origin xyz="0.009549499999999989 0 -0.123602"/>
			<geometry>
				<mesh filename="textured_objs/original-29.obj"/>
			</geometry>
		</visual>
		<visual name="back_soft_surface-46">
			<origin xyz="0.009549499999999989 0 -0.123602"/>
			<geometry>
				<mesh filename="textured_objs/original-24.obj"/>
			</geometry>
		</visual>
		<visual name="back_soft_surface-46">
			<origin xyz="0.009549499999999989 0 -0.123602"/>
			<geometry>
				<mesh filename="textured_objs/original-21.obj"/>
			</geometry>
		</visual>
		<visual name="back_support-45">
			<origin xyz="0.009549499999999989 0 -0.123602"/>
			<geometry>
				<mesh filename="textured_objs/original-13.obj"/>
			</geometry>
		</visual>
		<visual name="back_support-45">
			<origin xyz="0.009549499999999989 0 -0.123602"/>
			<geometry>
				<mesh filename="textured_objs/original-18.obj"/>
			</geometry>
		</visual>
		<visual name="back_support-45">
			<origin xyz="0.009549499999999989 0 -0.123602"/>
			<geometry>
				<mesh filename="textured_objs/original-19.obj"/>
			</geometry>
		</visual>
		<visual name="back_support-45">
			<origin xyz="0.009549499999999989 0 -0.123602"/>
			<geometry>
				<mesh filename="textured_objs/original-25.obj"/>
			</geometry>
		</visual>
		<visual name="back_support-45">
			<origin xyz="0.009549499999999989 0 -0.123602"/>
			<geometry>
				<mesh filename="textured_objs/original-17.obj"/>
			</geometry>
		</visual>
		<visual name="back_support-45">
			<origin xyz="0.009549499999999989 0 -0.123602"/>
			<geometry>
				<mesh filename="textured_objs/original-20.obj"/>
			</geometry>
		</visual>
		<visual name="back_support-45">
			<origin xyz="0.009549499999999989 0 -0.123602"/>
			<geometry>
				<mesh filename="textured_objs/original-26.obj"/>
			</geometry>
		</visual>
		<visual name="armrest_soft_surface-41">
			<origin xyz="0.009549499999999989 0 -0.123602"/>
			<geometry>
				<mesh filename="textured_objs/original-50.obj"/>
			</geometry>
		</visual>
		<visual name="armrest_soft_surface-41">
			<origin xyz="0.009549499999999989 0 -0.123602"/>
			<geometry>
				<mesh filename="textured_objs/original-46.obj"/>
			</geometry>
		</visual>
		<visual name="armrest_soft_surface-41">
			<origin xyz="0.009549499999999989 0 -0.123602"/>
			<geometry>
				<mesh filename="textured_objs/original-45.obj"/>
			</geometry>
		</visual>
		<visual name="armrest_soft_surface-41">
			<origin xyz="0.009549499999999989 0 -0.123602"/>
			<geometry>
				<mesh filename="textured_objs/original-44.obj"/>
			</geometry>
		</visual>
		<visual name="armrest_soft_surface-41">
			<origin xyz="0.009549499999999989 0 -0.123602"/>
			<geometry>
				<mesh filename="textured_objs/original-51.obj"/>
			</geometry>
		</visual>
		<visual name="armrest_soft_surface-41">
			<origin xyz="0.009549499999999989 0 -0.123602"/>
			<geometry>
				<mesh filename="textured_objs/original-47.obj"/>
			</geometry>
		</visual>
		<visual name="arm_vertical_bar-42">
			<origin xyz="0.009549499999999989 0 -0.123602"/>
			<geometry>
				<mesh filename="textured_objs/original-48.obj"/>
			</geometry>
		</visual>
		<visual name="arm_connector-43">
			<origin xyz="0.009549499999999989 0 -0.123602"/>
			<geometry>
				<mesh filename="textured_objs/original-49.obj"/>
			</geometry>
		</visual>
		<visual name="arm_connector-43">
			<origin xyz="0.009549499999999989 0 -0.123602"/>
			<geometry>
				<mesh filename="textured_objs/original-43.obj"/>
			</geometry>
		</visual>
		<visual name="arm_connector-38">
			<origin xyz="0.009549499999999989 0 -0.123602"/>
			<geometry>
				<mesh filename="textured_objs/original-40.obj"/>
			</geometry>
		</visual>
		<visual name="arm_connector-38">
			<origin xyz="0.009549499999999989 0 -0.123602"/>
			<geometry>
				<mesh filename="textured_objs/original-34.obj"/>
			</geometry>
		</visual>
		<visual name="armrest_soft_surface-39">
			<origin xyz="0.009549499999999989 0 -0.123602"/>
			<geometry>
				<mesh filename="textured_objs/original-38.obj"/>
			</geometry>
		</visual>
		<visual name="armrest_soft_surface-39">
			<origin xyz="0.009549499999999989 0 -0.123602"/>
			<geometry>
				<mesh filename="textured_objs/original-37.obj"/>
			</geometry>
		</visual>
		<visual name="armrest_soft_surface-39">
			<origin xyz="0.009549499999999989 0 -0.123602"/>
			<geometry>
				<mesh filename="textured_objs/original-42.obj"/>
			</geometry>
		</visual>
		<visual name="armrest_soft_surface-39">
			<origin xyz="0.009549499999999989 0 -0.123602"/>
			<geometry>
				<mesh filename="textured_objs/original-36.obj"/>
			</geometry>
		</visual>
		<visual name="armrest_soft_surface-39">
			<origin xyz="0.009549499999999989 0 -0.123602"/>
			<geometry>
				<mesh filename="textured_objs/original-41.obj"/>
			</geometry>
		</visual>
		<visual name="armrest_soft_surface-39">
			<origin xyz="0.009549499999999989 0 -0.123602"/>
			<geometry>
				<mesh filename="textured_objs/original-35.obj"/>
			</geometry>
		</visual>
		<visual name="arm_vertical_bar-40">
			<origin xyz="0.009549499999999989 0 -0.123602"/>
			<geometry>
				<mesh filename="textured_objs/original-39.obj"/>
			</geometry>
		</visual>
		<visual name="seat_soft_surface-31">
			<origin xyz="0.009549499999999989 0 -0.123602"/>
			<geometry>
				<mesh filename="textured_objs/original-16.obj"/>
			</geometry>
		</visual>
		<visual name="seat_support-30">
			<origin xyz="0.009549499999999989 0 -0.123602"/>
			<geometry>
				<mesh filename="textured_objs/original-14.obj"/>
			</geometry>
		</visual>
		<visual name="seat_support-30">
			<origin xyz="0.009549499999999989 0 -0.123602"/>
			<geometry>
				<mesh filename="textured_objs/original-15.obj"/>
			</geometry>
		</visual>
		<visual name="seat_support-30">
			<origin xyz="0.009549499999999989 0 -0.123602"/>
			<geometry>
				<mesh filename="textured_objs/original-27.obj"/>
			</geometry>
		</visual>
		<visual name="seat_connector-32">
			<origin xyz="0.009549499999999989 0 -0.123602"/>
			<geometry>
				<mesh filename="textured_objs/original-32.obj"/>
			</geometry>
		</visual>
		<collision>
			<origin xyz="0.009549499999999989 0 -0.123602"/>
			<geometry>
				<mesh filename="textured_objs/original-12.obj"/>
			</geometry>
		</collision>
		<collision>
			<origin xyz="0.009549499999999989 0 -0.123602"/>
			<geometry>
				<mesh filename="textured_objs/original-28.obj"/>
			</geometry>
		</collision>
		<collision>
			<origin xyz="0.009549499999999989 0 -0.123602"/>
			<geometry>
				<mesh filename="textured_objs/original-29.obj"/>
			</geometry>
		</collision>
		<collision>
			<origin xyz="0.009549499999999989 0 -0.123602"/>
			<geometry>
				<mesh filename="textured_objs/original-24.obj"/>
			</geometry>
		</collision>
		<collision>
			<origin xyz="0.009549499999999989 0 -0.123602"/>
			<geometry>
				<mesh filename="textured_objs/original-21.obj"/>
			</geometry>
		</collision>
		<collision>
			<origin xyz="0.009549499999999989 0 -0.123602"/>
			<geometry>
				<mesh filename="textured_objs/original-13.obj"/>
			</geometry>
		</collision>
		<collision>
			<origin xyz="0.009549499999999989 0 -0.123602"/>
			<geometry>
				<mesh filename="textured_objs/original-18.obj"/>
			</geometry>
		</collision>
		<collision>
			<origin xyz="0.009549499999999989 0 -0.123602"/>
			<geometry>
				<mesh filename="textured_objs/original-19.obj"/>
			</geometry>
		</collision>
		<collision>
			<origin xyz="0.009549499999999989 0 -0.123602"/>
			<geometry>
				<mesh filename="textured_objs/original-25.obj"/>
			</geometry>
		</collision>
		<collision>
			<origin xyz="0.009549499999999989 0 -0.123602"/>
			<geometry>
				<mesh filename="textured_objs/original-17.obj"/>
			</geometry>
		</collision>
		<collision>
			<origin xyz="0.009549499999999989 0 -0.123602"/>
			<geometry>
				<mesh filename="textured_objs/original-20.obj"/>
			</geometry>
		</collision>
		<collision>
			<origin xyz="0.009549499999999989 0 -0.123602"/>
			<geometry>
				<mesh filename="textured_objs/original-26.obj"/>
			</geometry>
		</collision>
		<collision>
			<origin xyz="0.009549499999999989 0 -0.123602"/>
			<geometry>
				<mesh filename="textured_objs/original-50.obj"/>
			</geometry>
		</collision>
		<collision>
			<origin xyz="0.009549499999999989 0 -0.123602"/>
			<geometry>
				<mesh filename="textured_objs/original-46.obj"/>
			</geometry>
		</collision>
		<collision>
			<origin xyz="0.009549499999999989 0 -0.123602"/>
			<geometry>
				<mesh filename="textured_objs/original-45.obj"/>
			</geometry>
		</collision>
		<collision>
			<origin xyz="0.009549499999999989 0 -0.123602"/>
			<geometry>
				<mesh filename="textured_objs/original-44.obj"/>
			</geometry>
		</collision>
		<collision>
			<origin xyz="0.009549499999999989 0 -0.123602"/>
			<geometry>
				<mesh filename="textured_objs/original-51.obj"/>
			</geometry>
		</collision>
		<collision>
			<origin xyz="0.009549499999999989 0 -0.123602"/>
			<geometry>
				<mesh filename="textured_objs/original-47.obj"/>
			</geometry>
		</collision>
		<collision>
			<origin xyz="0.009549499999999989 0 -0.123602"/>
			<geometry>
				<mesh filename="textured_objs/original-48.obj"/>
			</geometry>
		</collision>
		<collision>
			<origin xyz="0.009549499999999989 0 -0.123602"/>
			<geometry>
				<mesh filename="textured_objs/original-49.obj"/>
			</geometry>
		</collision>
		<collision>
			<origin xyz="0.009549499999999989 0 -0.123602"/>
			<geometry>
				<mesh filename="textured_objs/original-43.obj"/>
			</geometry>
		</collision>
		<collision>
			<origin xyz="0.009549499999999989 0 -0.123602"/>
			<geometry>
				<mesh filename="textured_objs/original-40.obj"/>
			</geometry>
		</collision>
		<collision>
			<origin xyz="0.009549499999999989 0 -0.123602"/>
			<geometry>
				<mesh filename="textured_objs/original-34.obj"/>
			</geometry>
		</collision>
		<collision>
			<origin xyz="0.009549499999999989 0 -0.123602"/>
			<geometry>
				<mesh filename="textured_objs/original-38.obj"/>
			</geometry>
		</collision>
		<collision>
			<origin xyz="0.009549499999999989 0 -0.123602"/>
			<geometry>
				<mesh filename="textured_objs/original-37.obj"/>
			</geometry>
		</collision>
		<collision>
			<origin xyz="0.009549499999999989 0 -0.123602"/>
			<geometry>
				<mesh filename="textured_objs/original-42.obj"/>
			</geometry>
		</collision>
		<collision>
			<origin xyz="0.009549499999999989 0 -0.123602"/>
			<geometry>
				<mesh filename="textured_objs/original-36.obj"/>
			</geometry>
		</collision>
		<collision>
			<origin xyz="0.009549499999999989 0 -0.123602"/>
			<geometry>
				<mesh filename="textured_objs/original-41.obj"/>
			</geometry>
		</collision>
		<collision>
			<origin xyz="0.009549499999999989 0 -0.123602"/>
			<geometry>
				<mesh filename="textured_objs/original-35.obj"/>
			</geometry>
		</collision>
		<collision>
			<origin xyz="0.009549499999999989 0 -0.123602"/>
			<geometry>
				<mesh filename="textured_objs/original-39.obj"/>
			</geometry>
		</collision>
		<collision>
			<origin xyz="0.009549499999999989 0 -0.123602"/>
			<geometry>
				<mesh filename="textured_objs/original-16.obj"/>
			</geometry>
		</collision>
		<collision>
			<origin xyz="0.009549499999999989 0 -0.123602"/>
			<geometry>
				<mesh filename="textured_objs/original-14.obj"/>
			</geometry>
		</collision>
		<collision>
			<origin xyz="0.009549499999999989 0 -0.123602"/>
			<geometry>
				<mesh filename="textured_objs/original-15.obj"/>
			</geometry>
		</collision>
		<collision>
			<origin xyz="0.009549499999999989 0 -0.123602"/>
			<geometry>
				<mesh filename="textured_objs/original-27.obj"/>
			</geometry>
		</collision>
		<collision>
			<origin xyz="0.009549499999999989 0 -0.123602"/>
			<geometry>
				<mesh filename="textured_objs/original-32.obj"/>
			</geometry>
		</collision>
	</link>
	<joint name="joint_11" type="continuous">
		<origin xyz="0.0 0 0.0"/>
		<axis xyz="0 1 0"/>
		<child link="link_11"/>
		<parent link="link_11_helper"/>
	</joint>
	<link name="link_12">
		<visual name="central_support-7">
			<origin xyz="0 0 0"/>
			<geometry>
				<mesh filename="textured_objs/new-5.obj"/>
			</geometry>
		</visual>
		<visual name="leg-9">
			<origin xyz="0 0 0"/>
			<geometry>
				<mesh filename="textured_objs/new-0.obj"/>
			</geometry>
		</visual>
		<visual name="leg-10">
			<origin xyz="0 0 0"/>
			<geometry>
				<mesh filename="textured_objs/new-4.obj"/>
			</geometry>
		</visual>
		<visual name="leg-11">
			<origin xyz="0 0 0"/>
			<geometry>
				<mesh filename="textured_objs/new-3.obj"/>
			</geometry>
		</visual>
		<visual name="leg-12">
			<origin xyz="0 0 0"/>
			<geometry>
				<mesh filename="textured_objs/new-2.obj"/>
			</geometry>
		</visual>
		<visual name="leg-13">
			<origin xyz="0 0 0"/>
			<geometry>
				<mesh filename="textured_objs/new-1.obj"/>
			</geometry>
		</visual>
		<collision>
			<origin xyz="0 0 0"/>
			<geometry>
				<mesh filename="textured_objs/new-5.obj"/>
			</geometry>
		</collision>
		<collision>
			<origin xyz="0 0 0"/>
			<geometry>
				<mesh filename="textured_objs/new-0.obj"/>
			</geometry>
		</collision>
		<collision>
			<origin xyz="0 0 0"/>
			<geometry>
				<mesh filename="textured_objs/new-4.obj"/>
			</geometry>
		</collision>
		<collision>
			<origin xyz="0 0 0"/>
			<geometry>
				<mesh filename="textured_objs/new-3.obj"/>
			</geometry>
		</collision>
		<collision>
			<origin xyz="0 0 0"/>
			<geometry>
				<mesh filename="textured_objs/new-2.obj"/>
			</geometry>
		</collision>
		<collision>
			<origin xyz="0 0 0"/>
			<geometry>
				<mesh filename="textured_objs/new-1.obj"/>
			</geometry>
		</collision>
	</link>
	<joint name="joint_12" type="fixed">
		<origin rpy="1.570796326794897 0 -1.570796326794897" xyz="0 0 0"/>
		<child link="link_12"/>
		<parent link="base"/>
	</joint>
	<link name="link_11_helper"/>
	<joint name="joint_13" type="prismatic">
		<origin xyz="-0.009549499999999989 0 0.123602"/>
		<axis xyz="0 -1 0"/>
		<child link="link_11_helper"/>
		<parent link="link_12"/>
		<limit lower="0" upper="0.1"/>
	</joint>
</robot>
