<?xml version="1.0" ?>
<robot name="partnet_16efeb266e249dd63a52a79d6f5aab84">
	<link name="base"/>
	<link name="link_0">
		<visual name="lamp_base_part-22">
			<origin xyz="0 0 0"/>
			<geometry>
				<mesh filename="textured_objs/original-27.obj"/>
			</geometry>
		</visual>
		<visual name="other_leaf-24">
			<origin xyz="0 0 0"/>
			<geometry>
				<mesh filename="textured_objs/original-2.obj"/>
			</geometry>
		</visual>
		<visual name="other_leaf-24">
			<origin xyz="0 0 0"/>
			<geometry>
				<mesh filename="textured_objs/original-22.obj"/>
			</geometry>
		</visual>
		<visual name="other_leaf-24">
			<origin xyz="0 0 0"/>
			<geometry>
				<mesh filename="textured_objs/original-24.obj"/>
			</geometry>
		</visual>
		<visual name="other_leaf-24">
			<origin xyz="0 0 0"/>
			<geometry>
				<mesh filename="textured_objs/original-23.obj"/>
			</geometry>
		</visual>
		<collision>
			<origin xyz="0 0 0"/>
			<geometry>
				<mesh filename="textured_objs/original-27.obj"/>
			</geometry>
		</collision>
		<collision>
			<origin xyz="0 0 0"/>
			<geometry>
				<mesh filename="textured_objs/original-2.obj"/>
			</geometry>
		</collision>
		<collision>
			<origin xyz="0 0 0"/>
			<geometry>
				<mesh filename="textured_objs/original-22.obj"/>
			</geometry>
		</collision>
		<collision>
			<origin xyz="0 0 0"/>
			<geometry>
				<mesh filename="textured_objs/original-24.obj"/>
			</geometry>
		</collision>
		<collision>
			<origin xyz="0 0 0"/>
			<geometry>
				<mesh filename="textured_objs/original-23.obj"/>
			</geometry>
		</collision>
	</link>
	<joint name="joint_0" type="fixed">
		<origin rpy="1.570796326794897 0 -1.570796326794897" xyz="0 0 0"/>
		<child link="link_0"/>
		<parent link="base"/>
	</joint>
	<link name="link_1">
		<visual name="lamp_arm_curved_bar-20">
			<origin xyz="0.009921 0 0.34463900000000003"/>
			<geometry>
				<mesh filename="textured_objs/original-26.obj"/>
			</geometry>
		</visual>
		<collision>
			<origin xyz="0.009921 0 0.34463900000000003"/>
			<geometry>
				<mesh filename="textured_objs/original-26.obj"/>
			</geometry>
		</collision>
	</link>
	<joint name="joint_1" type="revolute">
		<origin xyz="-0.009921 0 -0.34463900000000003"/>
		<axis xyz="0 -1 0"/>
		<child link="link_1"/>
		<parent link="link_0"/>
		<limit lower="-1.0471975511965976" upper="1.0471975511965976"/>
	</joint>
	<link name="link_2">
		<visual name="lamp_joint-17">
			<origin xyz="0 0.1258519513490073 0.3450570945342542"/>
			<geometry>
				<mesh filename="textured_objs/original-8.obj"/>
			</geometry>
		</visual>
		<visual name="lamp_joint-17">
			<origin xyz="0 0.1258519513490073 0.3450570945342542"/>
			<geometry>
				<mesh filename="textured_objs/original-7.obj"/>
			</geometry>
		</visual>
		<visual name="lamp_joint-17">
			<origin xyz="0 0.1258519513490073 0.3450570945342542"/>
			<geometry>
				<mesh filename="textured_objs/original-6.obj"/>
			</geometry>
		</visual>
		<visual name="lamp_joint-17">
			<origin xyz="0 0.1258519513490073 0.3450570945342542"/>
			<geometry>
				<mesh filename="textured_objs/original-3.obj"/>
			</geometry>
		</visual>
		<visual name="lamp_joint-17">
			<origin xyz="0 0.1258519513490073 0.3450570945342542"/>
			<geometry>
				<mesh filename="textured_objs/original-25.obj"/>
			</geometry>
		</visual>
		<visual name="lamp_joint-17">
			<origin xyz="0 0.1258519513490073 0.3450570945342542"/>
			<geometry>
				<mesh filename="textured_objs/original-1.obj"/>
			</geometry>
		</visual>
		<collision>
			<origin xyz="0 0.1258519513490073 0.3450570945342542"/>
			<geometry>
				<mesh filename="textured_objs/original-8.obj"/>
			</geometry>
		</collision>
		<collision>
			<origin xyz="0 0.1258519513490073 0.3450570945342542"/>
			<geometry>
				<mesh filename="textured_objs/original-7.obj"/>
			</geometry>
		</collision>
		<collision>
			<origin xyz="0 0.1258519513490073 0.3450570945342542"/>
			<geometry>
				<mesh filename="textured_objs/original-6.obj"/>
			</geometry>
		</collision>
		<collision>
			<origin xyz="0 0.1258519513490073 0.3450570945342542"/>
			<geometry>
				<mesh filename="textured_objs/original-3.obj"/>
			</geometry>
		</collision>
		<collision>
			<origin xyz="0 0.1258519513490073 0.3450570945342542"/>
			<geometry>
				<mesh filename="textured_objs/original-25.obj"/>
			</geometry>
		</collision>
		<collision>
			<origin xyz="0 0.1258519513490073 0.3450570945342542"/>
			<geometry>
				<mesh filename="textured_objs/original-1.obj"/>
			</geometry>
		</collision>
	</link>
	<joint name="joint_2" type="revolute">
		<origin xyz="0.009921 -0.1258519513490073 -0.0004180945342541764"/>
		<axis xyz="1 0 0"/>
		<child link="link_2"/>
		<parent link="link_1"/>
		<limit lower="-1.3089969389957472" upper="1.3089969389957472"/>
	</joint>
	<link name="link_3">
		<visual name="connector-12">
			<origin xyz="0 -0.1399134688901 0.07114282724045976"/>
			<geometry>
				<mesh filename="textured_objs/original-10.obj"/>
			</geometry>
		</visual>
		<visual name="connector-12">
			<origin xyz="0 -0.1399134688901 0.07114282724045976"/>
			<geometry>
				<mesh filename="textured_objs/original-13.obj"/>
			</geometry>
		</visual>
		<visual name="connector-12">
			<origin xyz="0 -0.1399134688901 0.07114282724045976"/>
			<geometry>
				<mesh filename="textured_objs/original-12.obj"/>
			</geometry>
		</visual>
		<visual name="connector-12">
			<origin xyz="0 -0.1399134688901 0.07114282724045976"/>
			<geometry>
				<mesh filename="textured_objs/original-9.obj"/>
			</geometry>
		</visual>
		<collision>
			<origin xyz="0 -0.1399134688901 0.07114282724045976"/>
			<geometry>
				<mesh filename="textured_objs/original-10.obj"/>
			</geometry>
		</collision>
		<collision>
			<origin xyz="0 -0.1399134688901 0.07114282724045976"/>
			<geometry>
				<mesh filename="textured_objs/original-13.obj"/>
			</geometry>
		</collision>
		<collision>
			<origin xyz="0 -0.1399134688901 0.07114282724045976"/>
			<geometry>
				<mesh filename="textured_objs/original-12.obj"/>
			</geometry>
		</collision>
		<collision>
			<origin xyz="0 -0.1399134688901 0.07114282724045976"/>
			<geometry>
				<mesh filename="textured_objs/original-9.obj"/>
			</geometry>
		</collision>
	</link>
	<joint name="joint_3" type="revolute">
		<origin xyz="0 0.2657654202391073 0.2739142672937944"/>
		<axis xyz="-1 0 0"/>
		<child link="link_3"/>
		<parent link="link_4"/>
		<limit lower="-1.3089969389957472" upper="1.3089969389957472"/>
	</joint>
	<link name="link_4">
		<visual name="lamp_arm_straight_bar-18">
			<origin xyz="0 0.1258519513490073 0.3450570945342542"/>
			<geometry>
				<mesh filename="textured_objs/original-4.obj"/>
			</geometry>
		</visual>
		<visual name="lamp_arm_straight_bar-19">
			<origin xyz="0 0.1258519513490073 0.3450570945342542"/>
			<geometry>
				<mesh filename="textured_objs/original-5.obj"/>
			</geometry>
		</visual>
		<collision>
			<origin xyz="0 0.1258519513490073 0.3450570945342542"/>
			<geometry>
				<mesh filename="textured_objs/original-4.obj"/>
			</geometry>
		</collision>
		<collision>
			<origin xyz="0 0.1258519513490073 0.3450570945342542"/>
			<geometry>
				<mesh filename="textured_objs/original-5.obj"/>
			</geometry>
		</collision>
	</link>
	<joint name="joint_4" type="revolute">
		<origin xyz="0.009921 -0.1258519513490073 -0.0004180945342541764"/>
		<axis xyz="1 0 0"/>
		<child link="link_4"/>
		<parent link="link_1"/>
		<limit lower="-0.5235987755982988" upper="0.5235987755982988"/>
	</joint>
	<link name="link_5">
		<visual name="lamp_arm_straight_bar-13">
			<origin xyz="0 -0.1399134688901 0.07114282724045976"/>
			<geometry>
				<mesh filename="textured_objs/new-1.obj"/>
			</geometry>
		</visual>
		<visual name="lamp_cover_holder-6">
			<origin xyz="0 -0.1399134688901 0.07114282724045976"/>
			<geometry>
				<mesh filename="textured_objs/new-2.obj"/>
			</geometry>
		</visual>
		<visual name="lamp_shade-10">
			<origin xyz="0 -0.1399134688901 0.07114282724045976"/>
			<geometry>
				<mesh filename="textured_objs/new-0.obj"/>
			</geometry>
		</visual>
		<visual name="light_socket-8">
			<origin xyz="0 -0.1399134688901 0.07114282724045976"/>
			<geometry>
				<mesh filename="textured_objs/original-18.obj"/>
			</geometry>
		</visual>
		<visual name="light_bulb-9">
			<origin xyz="0 -0.1399134688901 0.07114282724045976"/>
			<geometry>
				<mesh filename="textured_objs/original-20.obj"/>
			</geometry>
		</visual>
		<visual name="light_bulb-9">
			<origin xyz="0 -0.1399134688901 0.07114282724045976"/>
			<geometry>
				<mesh filename="textured_objs/original-19.obj"/>
			</geometry>
		</visual>
		<visual name="light_bulb-9">
			<origin xyz="0 -0.1399134688901 0.07114282724045976"/>
			<geometry>
				<mesh filename="textured_objs/original-17.obj"/>
			</geometry>
		</visual>
		<collision>
			<origin xyz="0 -0.1399134688901 0.07114282724045976"/>
			<geometry>
				<mesh filename="textured_objs/new-1.obj"/>
			</geometry>
		</collision>
		<collision>
			<origin xyz="0 -0.1399134688901 0.07114282724045976"/>
			<geometry>
				<mesh filename="textured_objs/new-2.obj"/>
			</geometry>
		</collision>
		<collision>
			<origin xyz="0 -0.1399134688901 0.07114282724045976"/>
			<geometry>
				<mesh filename="textured_objs/new-0.obj"/>
			</geometry>
		</collision>
		<collision>
			<origin xyz="0 -0.1399134688901 0.07114282724045976"/>
			<geometry>
				<mesh filename="textured_objs/original-18.obj"/>
			</geometry>
		</collision>
		<collision>
			<origin xyz="0 -0.1399134688901 0.07114282724045976"/>
			<geometry>
				<mesh filename="textured_objs/original-20.obj"/>
			</geometry>
		</collision>
		<collision>
			<origin xyz="0 -0.1399134688901 0.07114282724045976"/>
			<geometry>
				<mesh filename="textured_objs/original-19.obj"/>
			</geometry>
		</collision>
		<collision>
			<origin xyz="0 -0.1399134688901 0.07114282724045976"/>
			<geometry>
				<mesh filename="textured_objs/original-17.obj"/>
			</geometry>
		</collision>
	</link>
	<joint name="joint_5" type="revolute">
		<origin xyz="0 0.2657654202391073 0.2739142672937944"/>
		<axis xyz="-1 0 0"/>
		<child link="link_5"/>
		<parent link="link_4"/>
		<limit lower="-0.5235987755982988" upper="0.5235987755982988"/>
	</joint>
</robot>
