<?xml version="1.0" ?>
<robot name="partnet_5a22adeed868c76743c8f1cd479ffb1e">
	<link name="base"/>
	<link name="link_0">
		<visual name="frame-5">
			<origin xyz="0 0 0"/>
			<geometry>
				<mesh filename="textured_objs/new-5.obj"/>
			</geometry>
		</visual>
		<visual name="frame-5">
			<origin xyz="0 0 0"/>
			<geometry>
				<mesh filename="textured_objs/new-0.obj"/>
			</geometry>
		</visual>
		<collision>
			<origin xyz="0 0 0"/>
			<geometry>
				<mesh filename="textured_objs/new-5.obj"/>
			</geometry>
		</collision>
		<collision>
			<origin xyz="0 0 0"/>
			<geometry>
				<mesh filename="textured_objs/new-0.obj"/>
			</geometry>
		</collision>
	</link>
	<joint name="joint_0" type="fixed">
		<origin rpy="1.570796326794897 0 -1.570796326794897" xyz="0 0 0"/>
		<child link="link_0"/>
		<parent link="base"/>
	</joint>
	<link name="link_1">
		<visual name="door_frame-10">
			<origin xyz="-0.34724910567463385 -0.8853680000000002 -0.2866029991140471"/>
			<geometry>
				<mesh filename="textured_objs/new-4.obj"/>
			</geometry>
		</visual>
		<visual name="handle-11">
			<origin xyz="-0.34724910567463385 -0.8853680000000002 -0.2866029991140471"/>
			<geometry>
				<mesh filename="textured_objs/new-2.obj"/>
			</geometry>
		</visual>
		<collision>
			<origin xyz="-0.34724910567463385 -0.8853680000000002 -0.2866029991140471"/>
			<geometry>
				<mesh filename="textured_objs/new-4.obj"/>
			</geometry>
		</collision>
		<collision>
			<origin xyz="-0.34724910567463385 -0.8853680000000002 -0.2866029991140471"/>
			<geometry>
				<mesh filename="textured_objs/new-2.obj"/>
			</geometry>
		</collision>
	</link>
	<joint name="joint_1" type="revolute">
		<origin xyz="0.34724910567463385 0.8853680000000002 0.2866029991140471"/>
		<axis xyz="0 1 0"/>
		<child link="link_1"/>
		<parent link="link_0"/>
		<limit lower="-0.0" upper="3.141592653589793"/>
	</joint>
	<link name="link_2">
		<visual name="door_frame-8">
			<origin xyz="-0.34724910567463385 -0.8853680000000002 -0.2866029991140471"/>
			<geometry>
				<mesh filename="textured_objs/new-3.obj"/>
			</geometry>
		</visual>
		<visual name="handle-9">
			<origin xyz="-0.34724910567463385 -0.8853680000000002 -0.2866029991140471"/>
			<geometry>
				<mesh filename="textured_objs/new-1.obj"/>
			</geometry>
		</visual>
		<collision>
			<origin xyz="-0.34724910567463385 -0.8853680000000002 -0.2866029991140471"/>
			<geometry>
				<mesh filename="textured_objs/new-3.obj"/>
			</geometry>
		</collision>
		<collision>
			<origin xyz="-0.34724910567463385 -0.8853680000000002 -0.2866029991140471"/>
			<geometry>
				<mesh filename="textured_objs/new-1.obj"/>
			</geometry>
		</collision>
	</link>
	<joint name="joint_2" type="revolute">
		<origin xyz="0.34724910567463385 0.8853680000000002 0.2866029991140471"/>
		<axis xyz="0 1 0"/>
		<child link="link_2"/>
		<parent link="link_0"/>
		<limit lower="-0.0" upper="3.141592653589793"/>
	</joint>
</robot>
