<?xml version="1.0" ?>
<robot name="partnet_64050bcb4cffb2d176c18e71fd49c4dc">
	<link name="base"/>
	<link name="link_0">
		<visual name="switch-2">
			<origin xyz="-0.43931200000000015 0.4139924110887381 0.23139238117212824"/>
			<geometry>
				<mesh filename="textured_objs/new-4.obj"/>
			</geometry>
		</visual>
		<collision>
			<origin xyz="-0.43931200000000015 0.4139924110887381 0.23139238117212824"/>
			<geometry>
				<mesh filename="textured_objs/new-4.obj"/>
			</geometry>
		</collision>
	</link>
	<joint name="joint_0" type="revolute">
		<origin xyz="0.43931200000000015 -0.4139924110887381 -0.23139238117212824"/>
		<axis xyz="0.9999999999999999 0 0"/>
		<child link="link_0"/>
		<parent link="link_1"/>
		<limit lower="-0.0" upper="1.5707963267948966"/>
	</joint>
	<link name="link_1">
		<visual name="surface_base-11">
			<origin xyz="0 0 0"/>
			<geometry>
				<mesh filename="textured_objs/original-3.obj"/>
			</geometry>
		</visual>
		<visual name="vertical_support-12">
			<origin xyz="0 0 0"/>
			<geometry>
				<mesh filename="textured_objs/new-6.obj"/>
			</geometry>
		</visual>
		<visual name="horizontal_support-13">
			<origin xyz="0 0 0"/>
			<geometry>
				<mesh filename="textured_objs/new-5.obj"/>
			</geometry>
		</visual>
		<collision>
			<origin xyz="0 0 0"/>
			<geometry>
				<mesh filename="textured_objs/original-3.obj"/>
			</geometry>
		</collision>
		<collision>
			<origin xyz="0 0 0"/>
			<geometry>
				<mesh filename="textured_objs/new-6.obj"/>
			</geometry>
		</collision>
		<collision>
			<origin xyz="0 0 0"/>
			<geometry>
				<mesh filename="textured_objs/new-5.obj"/>
			</geometry>
		</collision>
	</link>
	<joint name="joint_1" type="fixed">
		<origin rpy="1.570796326794897 0 -1.570796326794897" xyz="0 0 0"/>
		<child link="link_1"/>
		<parent link="base"/>
	</joint>
	<link name="link_2">
		<visual name="head-6">
			<origin xyz="0.04655285175333916 0 0.22282432559837356"/>
			<geometry>
				<mesh filename="textured_objs/new-2.obj"/>
			</geometry>
		</visual>
		<visual name="mouth-7">
			<origin xyz="0.04655285175333916 0 0.22282432559837356"/>
			<geometry>
				<mesh filename="textured_objs/new-1.obj"/>
			</geometry>
		</visual>
		<visual name="tube-8">
			<origin xyz="0.04655285175333916 0 0.22282432559837356"/>
			<geometry>
				<mesh filename="textured_objs/new-3.obj"/>
			</geometry>
		</visual>
		<visual name="other_leaf-10">
			<origin xyz="0.04655285175333916 0 0.22282432559837356"/>
			<geometry>
				<mesh filename="textured_objs/new-0.obj"/>
			</geometry>
		</visual>
		<collision>
			<origin xyz="0.04655285175333916 0 0.22282432559837356"/>
			<geometry>
				<mesh filename="textured_objs/new-2.obj"/>
			</geometry>
		</collision>
		<collision>
			<origin xyz="0.04655285175333916 0 0.22282432559837356"/>
			<geometry>
				<mesh filename="textured_objs/new-1.obj"/>
			</geometry>
		</collision>
		<collision>
			<origin xyz="0.04655285175333916 0 0.22282432559837356"/>
			<geometry>
				<mesh filename="textured_objs/new-3.obj"/>
			</geometry>
		</collision>
		<collision>
			<origin xyz="0.04655285175333916 0 0.22282432559837356"/>
			<geometry>
				<mesh filename="textured_objs/new-0.obj"/>
			</geometry>
		</collision>
	</link>
	<joint name="joint_2" type="continuous">
		<origin xyz="-0.04655285175333916 0 -0.22282432559837356"/>
		<axis xyz="0 1 0"/>
		<child link="link_2"/>
		<parent link="link_1"/>
	</joint>
</robot>
