<?xml version="1.0" ?>
<robot name="partnet_feecb34cf74c7d63be2bc1bafa1e1137">
	<link name="base"/>
	<link name="link_0">
		<visual name="frame-112">
			<origin xyz="0 0 0"/>
			<geometry>
				<mesh filename="textured_objs/original-229.obj"/>
			</geometry>
		</visual>
		<visual name="frame-112">
			<origin xyz="0 0 0"/>
			<geometry>
				<mesh filename="textured_objs/original-207.obj"/>
			</geometry>
		</visual>
		<visual name="frame-112">
			<origin xyz="0 0 0"/>
			<geometry>
				<mesh filename="textured_objs/original-206.obj"/>
			</geometry>
		</visual>
		<visual name="frame-112">
			<origin xyz="0 0 0"/>
			<geometry>
				<mesh filename="textured_objs/original-204.obj"/>
			</geometry>
		</visual>
		<collision>
			<origin xyz="0 0 0"/>
			<geometry>
				<mesh filename="textured_objs/original-229.obj"/>
			</geometry>
		</collision>
		<collision>
			<origin xyz="0 0 0"/>
			<geometry>
				<mesh filename="textured_objs/original-207.obj"/>
			</geometry>
		</collision>
		<collision>
			<origin xyz="0 0 0"/>
			<geometry>
				<mesh filename="textured_objs/original-206.obj"/>
			</geometry>
		</collision>
		<collision>
			<origin xyz="0 0 0"/>
			<geometry>
				<mesh filename="textured_objs/original-204.obj"/>
			</geometry>
		</collision>
	</link>
	<joint name="joint_0" type="fixed">
		<origin rpy="1.570796326794897 0 -1.570796326794897" xyz="0 0 0"/>
		<child link="link_0"/>
		<parent link="base"/>
	</joint>
	<link name="link_1">
		<visual name="key-113">
			<origin xyz="-0.911923877178733 -0.05530041397070634 0.018974219854632768"/>
			<geometry>
				<mesh filename="textured_objs/original-4.obj"/>
			</geometry>
		</visual>
		<visual name="key-113">
			<origin xyz="-0.911923877178733 -0.05530041397070634 0.018974219854632768"/>
			<geometry>
				<mesh filename="textured_objs/original-119.obj"/>
			</geometry>
		</visual>
		<collision>
			<origin xyz="-0.911923877178733 -0.05530041397070634 0.018974219854632768"/>
			<geometry>
				<mesh filename="textured_objs/original-4.obj"/>
			</geometry>
		</collision>
		<collision>
			<origin xyz="-0.911923877178733 -0.05530041397070634 0.018974219854632768"/>
			<geometry>
				<mesh filename="textured_objs/original-119.obj"/>
			</geometry>
		</collision>
	</link>
	<joint name="joint_1" type="prismatic">
		<origin xyz="0.911923877178733 0.05530041397070634 -0.018974219854632768"/>
		<axis xyz="-0.05880441485746992 -0.9696166147022008 -0.2374566513844455"/>
		<child link="link_1"/>
		<parent link="link_0"/>
		<limit lower="0" upper="0.02"/>
	</joint>
	<link name="link_2">
		<visual name="key-114">
			<origin xyz="-0.911923877178733 -0.05530041397070634 0.018974219854632768"/>
			<geometry>
				<mesh filename="textured_objs/original-117.obj"/>
			</geometry>
		</visual>
		<visual name="key-114">
			<origin xyz="-0.911923877178733 -0.05530041397070634 0.018974219854632768"/>
			<geometry>
				<mesh filename="textured_objs/original-2.obj"/>
			</geometry>
		</visual>
		<collision>
			<origin xyz="-0.911923877178733 -0.05530041397070634 0.018974219854632768"/>
			<geometry>
				<mesh filename="textured_objs/original-117.obj"/>
			</geometry>
		</collision>
		<collision>
			<origin xyz="-0.911923877178733 -0.05530041397070634 0.018974219854632768"/>
			<geometry>
				<mesh filename="textured_objs/original-2.obj"/>
			</geometry>
		</collision>
	</link>
	<joint name="joint_2" type="prismatic">
		<origin xyz="0.911923877178733 0.05530041397070634 -0.018974219854632768"/>
		<axis xyz="-0.05880441485746992 -0.9696166147022008 -0.2374566513844455"/>
		<child link="link_2"/>
		<parent link="link_0"/>
		<limit lower="0" upper="0.02"/>
	</joint>
	<link name="link_3">
		<visual name="key-115">
			<origin xyz="-0.911923877178733 -0.05530041397070634 0.018974219854632768"/>
			<geometry>
				<mesh filename="textured_objs/original-53.obj"/>
			</geometry>
		</visual>
		<visual name="key-115">
			<origin xyz="-0.911923877178733 -0.05530041397070634 0.018974219854632768"/>
			<geometry>
				<mesh filename="textured_objs/original-182.obj"/>
			</geometry>
		</visual>
		<collision>
			<origin xyz="-0.911923877178733 -0.05530041397070634 0.018974219854632768"/>
			<geometry>
				<mesh filename="textured_objs/original-53.obj"/>
			</geometry>
		</collision>
		<collision>
			<origin xyz="-0.911923877178733 -0.05530041397070634 0.018974219854632768"/>
			<geometry>
				<mesh filename="textured_objs/original-182.obj"/>
			</geometry>
		</collision>
	</link>
	<joint name="joint_3" type="prismatic">
		<origin xyz="0.911923877178733 0.05530041397070634 -0.018974219854632768"/>
		<axis xyz="-0.05880441485746992 -0.9696166147022008 -0.2374566513844455"/>
		<child link="link_3"/>
		<parent link="link_0"/>
		<limit lower="0" upper="0.02"/>
	</joint>
	<link name="link_4">
		<visual name="key-116">
			<origin xyz="-0.911923877178733 -0.05530041397070634 0.018974219854632768"/>
			<geometry>
				<mesh filename="textured_objs/original-156.obj"/>
			</geometry>
		</visual>
		<visual name="key-116">
			<origin xyz="-0.911923877178733 -0.05530041397070634 0.018974219854632768"/>
			<geometry>
				<mesh filename="textured_objs/original-66.obj"/>
			</geometry>
		</visual>
		<collision>
			<origin xyz="-0.911923877178733 -0.05530041397070634 0.018974219854632768"/>
			<geometry>
				<mesh filename="textured_objs/original-156.obj"/>
			</geometry>
		</collision>
		<collision>
			<origin xyz="-0.911923877178733 -0.05530041397070634 0.018974219854632768"/>
			<geometry>
				<mesh filename="textured_objs/original-66.obj"/>
			</geometry>
		</collision>
	</link>
	<joint name="joint_4" type="prismatic">
		<origin xyz="0.911923877178733 0.05530041397070634 -0.018974219854632768"/>
		<axis xyz="-0.05880441485746992 -0.9696166147022008 -0.2374566513844455"/>
		<child link="link_4"/>
		<parent link="link_0"/>
		<limit lower="0" upper="0.02"/>
	</joint>
	<link name="link_5">
		<visual name="key-117">
			<origin xyz="-0.911923877178733 -0.05530041397070634 0.018974219854632768"/>
			<geometry>
				<mesh filename="textured_objs/original-196.obj"/>
			</geometry>
		</visual>
		<visual name="key-117">
			<origin xyz="-0.911923877178733 -0.05530041397070634 0.018974219854632768"/>
			<geometry>
				<mesh filename="textured_objs/original-91.obj"/>
			</geometry>
		</visual>
		<collision>
			<origin xyz="-0.911923877178733 -0.05530041397070634 0.018974219854632768"/>
			<geometry>
				<mesh filename="textured_objs/original-196.obj"/>
			</geometry>
		</collision>
		<collision>
			<origin xyz="-0.911923877178733 -0.05530041397070634 0.018974219854632768"/>
			<geometry>
				<mesh filename="textured_objs/original-91.obj"/>
			</geometry>
		</collision>
	</link>
	<joint name="joint_5" type="prismatic">
		<origin xyz="0.911923877178733 0.05530041397070634 -0.018974219854632768"/>
		<axis xyz="-0.05880441485746992 -0.9696166147022008 -0.2374566513844455"/>
		<child link="link_5"/>
		<parent link="link_0"/>
		<limit lower="0" upper="0.02"/>
	</joint>
	<link name="link_6">
		<visual name="key-118">
			<origin xyz="-0.911923877178733 -0.05530041397070634 0.018974219854632768"/>
			<geometry>
				<mesh filename="textured_objs/original-118.obj"/>
			</geometry>
		</visual>
		<visual name="key-118">
			<origin xyz="-0.911923877178733 -0.05530041397070634 0.018974219854632768"/>
			<geometry>
				<mesh filename="textured_objs/original-3.obj"/>
			</geometry>
		</visual>
		<collision>
			<origin xyz="-0.911923877178733 -0.05530041397070634 0.018974219854632768"/>
			<geometry>
				<mesh filename="textured_objs/original-118.obj"/>
			</geometry>
		</collision>
		<collision>
			<origin xyz="-0.911923877178733 -0.05530041397070634 0.018974219854632768"/>
			<geometry>
				<mesh filename="textured_objs/original-3.obj"/>
			</geometry>
		</collision>
	</link>
	<joint name="joint_6" type="prismatic">
		<origin xyz="0.911923877178733 0.05530041397070634 -0.018974219854632768"/>
		<axis xyz="-0.05880441485746992 -0.9696166147022008 -0.2374566513844455"/>
		<child link="link_6"/>
		<parent link="link_0"/>
		<limit lower="0" upper="0.02"/>
	</joint>
	<link name="link_7">
		<visual name="key-119">
			<origin xyz="-0.911923877178733 -0.05530041397070634 0.018974219854632768"/>
			<geometry>
				<mesh filename="textured_objs/original-145.obj"/>
			</geometry>
		</visual>
		<visual name="key-119">
			<origin xyz="-0.911923877178733 -0.05530041397070634 0.018974219854632768"/>
			<geometry>
				<mesh filename="textured_objs/original-49.obj"/>
			</geometry>
		</visual>
		<collision>
			<origin xyz="-0.911923877178733 -0.05530041397070634 0.018974219854632768"/>
			<geometry>
				<mesh filename="textured_objs/original-145.obj"/>
			</geometry>
		</collision>
		<collision>
			<origin xyz="-0.911923877178733 -0.05530041397070634 0.018974219854632768"/>
			<geometry>
				<mesh filename="textured_objs/original-49.obj"/>
			</geometry>
		</collision>
	</link>
	<joint name="joint_7" type="prismatic">
		<origin xyz="0.911923877178733 0.05530041397070634 -0.018974219854632768"/>
		<axis xyz="-0.05880441485746992 -0.9696166147022008 -0.2374566513844455"/>
		<child link="link_7"/>
		<parent link="link_0"/>
		<limit lower="0" upper="0.02"/>
	</joint>
	<link name="link_8">
		<visual name="key-120">
			<origin xyz="-0.911923877178733 -0.05530041397070634 0.018974219854632768"/>
			<geometry>
				<mesh filename="textured_objs/original-227.obj"/>
			</geometry>
		</visual>
		<visual name="key-120">
			<origin xyz="-0.911923877178733 -0.05530041397070634 0.018974219854632768"/>
			<geometry>
				<mesh filename="textured_objs/original-56.obj"/>
			</geometry>
		</visual>
		<collision>
			<origin xyz="-0.911923877178733 -0.05530041397070634 0.018974219854632768"/>
			<geometry>
				<mesh filename="textured_objs/original-227.obj"/>
			</geometry>
		</collision>
		<collision>
			<origin xyz="-0.911923877178733 -0.05530041397070634 0.018974219854632768"/>
			<geometry>
				<mesh filename="textured_objs/original-56.obj"/>
			</geometry>
		</collision>
	</link>
	<joint name="joint_8" type="prismatic">
		<origin xyz="0.911923877178733 0.05530041397070634 -0.018974219854632768"/>
		<axis xyz="-0.05880441485746992 -0.9696166147022008 -0.2374566513844455"/>
		<child link="link_8"/>
		<parent link="link_0"/>
		<limit lower="0" upper="0.02"/>
	</joint>
	<link name="link_9">
		<visual name="key-121">
			<origin xyz="-0.911923877178733 -0.05530041397070634 0.018974219854632768"/>
			<geometry>
				<mesh filename="textured_objs/original-124.obj"/>
			</geometry>
		</visual>
		<visual name="key-121">
			<origin xyz="-0.911923877178733 -0.05530041397070634 0.018974219854632768"/>
			<geometry>
				<mesh filename="textured_objs/original-10.obj"/>
			</geometry>
		</visual>
		<collision>
			<origin xyz="-0.911923877178733 -0.05530041397070634 0.018974219854632768"/>
			<geometry>
				<mesh filename="textured_objs/original-124.obj"/>
			</geometry>
		</collision>
		<collision>
			<origin xyz="-0.911923877178733 -0.05530041397070634 0.018974219854632768"/>
			<geometry>
				<mesh filename="textured_objs/original-10.obj"/>
			</geometry>
		</collision>
	</link>
	<joint name="joint_9" type="prismatic">
		<origin xyz="0.911923877178733 0.05530041397070634 -0.018974219854632768"/>
		<axis xyz="-0.05880441485746992 -0.9696166147022008 -0.2374566513844455"/>
		<child link="link_9"/>
		<parent link="link_0"/>
		<limit lower="0" upper="0.02"/>
	</joint>
	<link name="link_10">
		<visual name="key-122">
			<origin xyz="-0.911923877178733 -0.05530041397070634 0.018974219854632768"/>
			<geometry>
				<mesh filename="textured_objs/original-121.obj"/>
			</geometry>
		</visual>
		<visual name="key-122">
			<origin xyz="-0.911923877178733 -0.05530041397070634 0.018974219854632768"/>
			<geometry>
				<mesh filename="textured_objs/original-7.obj"/>
			</geometry>
		</visual>
		<collision>
			<origin xyz="-0.911923877178733 -0.05530041397070634 0.018974219854632768"/>
			<geometry>
				<mesh filename="textured_objs/original-121.obj"/>
			</geometry>
		</collision>
		<collision>
			<origin xyz="-0.911923877178733 -0.05530041397070634 0.018974219854632768"/>
			<geometry>
				<mesh filename="textured_objs/original-7.obj"/>
			</geometry>
		</collision>
	</link>
	<joint name="joint_10" type="prismatic">
		<origin xyz="0.911923877178733 0.05530041397070634 -0.018974219854632768"/>
		<axis xyz="-0.05880441485746992 -0.9696166147022008 -0.2374566513844455"/>
		<child link="link_10"/>
		<parent link="link_0"/>
		<limit lower="0" upper="0.02"/>
	</joint>
	<link name="link_11">
		<visual name="key-123">
			<origin xyz="-0.911923877178733 -0.05530041397070634 0.018974219854632768"/>
			<geometry>
				<mesh filename="textured_objs/original-122.obj"/>
			</geometry>
		</visual>
		<visual name="key-123">
			<origin xyz="-0.911923877178733 -0.05530041397070634 0.018974219854632768"/>
			<geometry>
				<mesh filename="textured_objs/original-8.obj"/>
			</geometry>
		</visual>
		<collision>
			<origin xyz="-0.911923877178733 -0.05530041397070634 0.018974219854632768"/>
			<geometry>
				<mesh filename="textured_objs/original-122.obj"/>
			</geometry>
		</collision>
		<collision>
			<origin xyz="-0.911923877178733 -0.05530041397070634 0.018974219854632768"/>
			<geometry>
				<mesh filename="textured_objs/original-8.obj"/>
			</geometry>
		</collision>
	</link>
	<joint name="joint_11" type="prismatic">
		<origin xyz="0.911923877178733 0.05530041397070634 -0.018974219854632768"/>
		<axis xyz="-0.05880441485746992 -0.9696166147022008 -0.2374566513844455"/>
		<child link="link_11"/>
		<parent link="link_0"/>
		<limit lower="0" upper="0.02"/>
	</joint>
	<link name="link_12">
		<visual name="key-124">
			<origin xyz="-0.911923877178733 -0.05530041397070634 0.018974219854632768"/>
			<geometry>
				<mesh filename="textured_objs/original-126.obj"/>
			</geometry>
		</visual>
		<visual name="key-124">
			<origin xyz="-0.911923877178733 -0.05530041397070634 0.018974219854632768"/>
			<geometry>
				<mesh filename="textured_objs/original-6.obj"/>
			</geometry>
		</visual>
		<collision>
			<origin xyz="-0.911923877178733 -0.05530041397070634 0.018974219854632768"/>
			<geometry>
				<mesh filename="textured_objs/original-126.obj"/>
			</geometry>
		</collision>
		<collision>
			<origin xyz="-0.911923877178733 -0.05530041397070634 0.018974219854632768"/>
			<geometry>
				<mesh filename="textured_objs/original-6.obj"/>
			</geometry>
		</collision>
	</link>
	<joint name="joint_12" type="prismatic">
		<origin xyz="0.911923877178733 0.05530041397070634 -0.018974219854632768"/>
		<axis xyz="-0.05880441485746992 -0.9696166147022008 -0.2374566513844455"/>
		<child link="link_12"/>
		<parent link="link_0"/>
		<limit lower="0" upper="0.02"/>
	</joint>
	<link name="link_13">
		<visual name="key-125">
			<origin xyz="-0.911923877178733 -0.05530041397070634 0.018974219854632768"/>
			<geometry>
				<mesh filename="textured_objs/original-123.obj"/>
			</geometry>
		</visual>
		<visual name="key-125">
			<origin xyz="-0.911923877178733 -0.05530041397070634 0.018974219854632768"/>
			<geometry>
				<mesh filename="textured_objs/original-9.obj"/>
			</geometry>
		</visual>
		<collision>
			<origin xyz="-0.911923877178733 -0.05530041397070634 0.018974219854632768"/>
			<geometry>
				<mesh filename="textured_objs/original-123.obj"/>
			</geometry>
		</collision>
		<collision>
			<origin xyz="-0.911923877178733 -0.05530041397070634 0.018974219854632768"/>
			<geometry>
				<mesh filename="textured_objs/original-9.obj"/>
			</geometry>
		</collision>
	</link>
	<joint name="joint_13" type="prismatic">
		<origin xyz="0.911923877178733 0.05530041397070634 -0.018974219854632768"/>
		<axis xyz="-0.05880441485746992 -0.9696166147022008 -0.2374566513844455"/>
		<child link="link_13"/>
		<parent link="link_0"/>
		<limit lower="0" upper="0.02"/>
	</joint>
	<link name="link_14">
		<visual name="key-126">
			<origin xyz="-0.911923877178733 -0.05530041397070634 0.018974219854632768"/>
			<geometry>
				<mesh filename="textured_objs/original-120.obj"/>
			</geometry>
		</visual>
		<visual name="key-126">
			<origin xyz="-0.911923877178733 -0.05530041397070634 0.018974219854632768"/>
			<geometry>
				<mesh filename="textured_objs/original-5.obj"/>
			</geometry>
		</visual>
		<collision>
			<origin xyz="-0.911923877178733 -0.05530041397070634 0.018974219854632768"/>
			<geometry>
				<mesh filename="textured_objs/original-120.obj"/>
			</geometry>
		</collision>
		<collision>
			<origin xyz="-0.911923877178733 -0.05530041397070634 0.018974219854632768"/>
			<geometry>
				<mesh filename="textured_objs/original-5.obj"/>
			</geometry>
		</collision>
	</link>
	<joint name="joint_14" type="prismatic">
		<origin xyz="0.911923877178733 0.05530041397070634 -0.018974219854632768"/>
		<axis xyz="-0.05880441485746992 -0.9696166147022008 -0.2374566513844455"/>
		<child link="link_14"/>
		<parent link="link_0"/>
		<limit lower="0" upper="0.02"/>
	</joint>
	<link name="link_15">
		<visual name="key-127">
			<origin xyz="-0.911923877178733 -0.05530041397070634 0.018974219854632768"/>
			<geometry>
				<mesh filename="textured_objs/original-218.obj"/>
			</geometry>
		</visual>
		<visual name="key-127">
			<origin xyz="-0.911923877178733 -0.05530041397070634 0.018974219854632768"/>
			<geometry>
				<mesh filename="textured_objs/original-108.obj"/>
			</geometry>
		</visual>
		<collision>
			<origin xyz="-0.911923877178733 -0.05530041397070634 0.018974219854632768"/>
			<geometry>
				<mesh filename="textured_objs/original-218.obj"/>
			</geometry>
		</collision>
		<collision>
			<origin xyz="-0.911923877178733 -0.05530041397070634 0.018974219854632768"/>
			<geometry>
				<mesh filename="textured_objs/original-108.obj"/>
			</geometry>
		</collision>
	</link>
	<joint name="joint_15" type="prismatic">
		<origin xyz="0.911923877178733 0.05530041397070634 -0.018974219854632768"/>
		<axis xyz="-0.05880441485746992 -0.9696166147022008 -0.2374566513844455"/>
		<child link="link_15"/>
		<parent link="link_0"/>
		<limit lower="0" upper="0.02"/>
	</joint>
	<link name="link_16">
		<visual name="key-128">
			<origin xyz="-0.911923877178733 -0.05530041397070634 0.018974219854632768"/>
			<geometry>
				<mesh filename="textured_objs/original-215.obj"/>
			</geometry>
		</visual>
		<visual name="key-128">
			<origin xyz="-0.911923877178733 -0.05530041397070634 0.018974219854632768"/>
			<geometry>
				<mesh filename="textured_objs/original-104.obj"/>
			</geometry>
		</visual>
		<collision>
			<origin xyz="-0.911923877178733 -0.05530041397070634 0.018974219854632768"/>
			<geometry>
				<mesh filename="textured_objs/original-215.obj"/>
			</geometry>
		</collision>
		<collision>
			<origin xyz="-0.911923877178733 -0.05530041397070634 0.018974219854632768"/>
			<geometry>
				<mesh filename="textured_objs/original-104.obj"/>
			</geometry>
		</collision>
	</link>
	<joint name="joint_16" type="prismatic">
		<origin xyz="0.911923877178733 0.05530041397070634 -0.018974219854632768"/>
		<axis xyz="-0.05880441485746992 -0.9696166147022008 -0.2374566513844455"/>
		<child link="link_16"/>
		<parent link="link_0"/>
		<limit lower="0" upper="0.02"/>
	</joint>
	<link name="link_17">
		<visual name="key-129">
			<origin xyz="-0.911923877178733 -0.05530041397070634 0.018974219854632768"/>
			<geometry>
				<mesh filename="textured_objs/original-220.obj"/>
			</geometry>
		</visual>
		<visual name="key-129">
			<origin xyz="-0.911923877178733 -0.05530041397070634 0.018974219854632768"/>
			<geometry>
				<mesh filename="textured_objs/original-99.obj"/>
			</geometry>
		</visual>
		<collision>
			<origin xyz="-0.911923877178733 -0.05530041397070634 0.018974219854632768"/>
			<geometry>
				<mesh filename="textured_objs/original-220.obj"/>
			</geometry>
		</collision>
		<collision>
			<origin xyz="-0.911923877178733 -0.05530041397070634 0.018974219854632768"/>
			<geometry>
				<mesh filename="textured_objs/original-99.obj"/>
			</geometry>
		</collision>
	</link>
	<joint name="joint_17" type="prismatic">
		<origin xyz="0.911923877178733 0.05530041397070634 -0.018974219854632768"/>
		<axis xyz="-0.05880441485746992 -0.9696166147022008 -0.2374566513844455"/>
		<child link="link_17"/>
		<parent link="link_0"/>
		<limit lower="0" upper="0.02"/>
	</joint>
	<link name="link_18">
		<visual name="key-130">
			<origin xyz="-0.911923877178733 -0.05530041397070634 0.018974219854632768"/>
			<geometry>
				<mesh filename="textured_objs/original-208.obj"/>
			</geometry>
		</visual>
		<visual name="key-130">
			<origin xyz="-0.911923877178733 -0.05530041397070634 0.018974219854632768"/>
			<geometry>
				<mesh filename="textured_objs/original-35.obj"/>
			</geometry>
		</visual>
		<collision>
			<origin xyz="-0.911923877178733 -0.05530041397070634 0.018974219854632768"/>
			<geometry>
				<mesh filename="textured_objs/original-208.obj"/>
			</geometry>
		</collision>
		<collision>
			<origin xyz="-0.911923877178733 -0.05530041397070634 0.018974219854632768"/>
			<geometry>
				<mesh filename="textured_objs/original-35.obj"/>
			</geometry>
		</collision>
	</link>
	<joint name="joint_18" type="prismatic">
		<origin xyz="0.911923877178733 0.05530041397070634 -0.018974219854632768"/>
		<axis xyz="-0.05880441485746992 -0.9696166147022008 -0.2374566513844455"/>
		<child link="link_18"/>
		<parent link="link_0"/>
		<limit lower="0" upper="0.02"/>
	</joint>
	<link name="link_19">
		<visual name="key-131">
			<origin xyz="-0.911923877178733 -0.05530041397070634 0.018974219854632768"/>
			<geometry>
				<mesh filename="textured_objs/original-159.obj"/>
			</geometry>
		</visual>
		<visual name="key-131">
			<origin xyz="-0.911923877178733 -0.05530041397070634 0.018974219854632768"/>
			<geometry>
				<mesh filename="textured_objs/original-41.obj"/>
			</geometry>
		</visual>
		<collision>
			<origin xyz="-0.911923877178733 -0.05530041397070634 0.018974219854632768"/>
			<geometry>
				<mesh filename="textured_objs/original-159.obj"/>
			</geometry>
		</collision>
		<collision>
			<origin xyz="-0.911923877178733 -0.05530041397070634 0.018974219854632768"/>
			<geometry>
				<mesh filename="textured_objs/original-41.obj"/>
			</geometry>
		</collision>
	</link>
	<joint name="joint_19" type="prismatic">
		<origin xyz="0.911923877178733 0.05530041397070634 -0.018974219854632768"/>
		<axis xyz="-0.05880441485746992 -0.9696166147022008 -0.2374566513844455"/>
		<child link="link_19"/>
		<parent link="link_0"/>
		<limit lower="0" upper="0.02"/>
	</joint>
	<link name="link_20">
		<visual name="key-132">
			<origin xyz="-0.911923877178733 -0.05530041397070634 0.018974219854632768"/>
			<geometry>
				<mesh filename="textured_objs/original-168.obj"/>
			</geometry>
		</visual>
		<visual name="key-132">
			<origin xyz="-0.911923877178733 -0.05530041397070634 0.018974219854632768"/>
			<geometry>
				<mesh filename="textured_objs/original-47.obj"/>
			</geometry>
		</visual>
		<collision>
			<origin xyz="-0.911923877178733 -0.05530041397070634 0.018974219854632768"/>
			<geometry>
				<mesh filename="textured_objs/original-168.obj"/>
			</geometry>
		</collision>
		<collision>
			<origin xyz="-0.911923877178733 -0.05530041397070634 0.018974219854632768"/>
			<geometry>
				<mesh filename="textured_objs/original-47.obj"/>
			</geometry>
		</collision>
	</link>
	<joint name="joint_20" type="prismatic">
		<origin xyz="0.911923877178733 0.05530041397070634 -0.018974219854632768"/>
		<axis xyz="-0.05880441485746992 -0.9696166147022008 -0.2374566513844455"/>
		<child link="link_20"/>
		<parent link="link_0"/>
		<limit lower="0" upper="0.02"/>
	</joint>
	<link name="link_21">
		<visual name="key-133">
			<origin xyz="-0.911923877178733 -0.05530041397070634 0.018974219854632768"/>
			<geometry>
				<mesh filename="textured_objs/original-153.obj"/>
			</geometry>
		</visual>
		<visual name="key-133">
			<origin xyz="-0.911923877178733 -0.05530041397070634 0.018974219854632768"/>
			<geometry>
				<mesh filename="textured_objs/original-58.obj"/>
			</geometry>
		</visual>
		<collision>
			<origin xyz="-0.911923877178733 -0.05530041397070634 0.018974219854632768"/>
			<geometry>
				<mesh filename="textured_objs/original-153.obj"/>
			</geometry>
		</collision>
		<collision>
			<origin xyz="-0.911923877178733 -0.05530041397070634 0.018974219854632768"/>
			<geometry>
				<mesh filename="textured_objs/original-58.obj"/>
			</geometry>
		</collision>
	</link>
	<joint name="joint_21" type="prismatic">
		<origin xyz="0.911923877178733 0.05530041397070634 -0.018974219854632768"/>
		<axis xyz="-0.05880441485746992 -0.9696166147022008 -0.2374566513844455"/>
		<child link="link_21"/>
		<parent link="link_0"/>
		<limit lower="0" upper="0.02"/>
	</joint>
	<link name="link_22">
		<visual name="key-134">
			<origin xyz="-0.911923877178733 -0.05530041397070634 0.018974219854632768"/>
			<geometry>
				<mesh filename="textured_objs/original-219.obj"/>
			</geometry>
		</visual>
		<visual name="key-134">
			<origin xyz="-0.911923877178733 -0.05530041397070634 0.018974219854632768"/>
			<geometry>
				<mesh filename="textured_objs/original-107.obj"/>
			</geometry>
		</visual>
		<collision>
			<origin xyz="-0.911923877178733 -0.05530041397070634 0.018974219854632768"/>
			<geometry>
				<mesh filename="textured_objs/original-219.obj"/>
			</geometry>
		</collision>
		<collision>
			<origin xyz="-0.911923877178733 -0.05530041397070634 0.018974219854632768"/>
			<geometry>
				<mesh filename="textured_objs/original-107.obj"/>
			</geometry>
		</collision>
	</link>
	<joint name="joint_22" type="prismatic">
		<origin xyz="0.911923877178733 0.05530041397070634 -0.018974219854632768"/>
		<axis xyz="-0.05880441485746992 -0.9696166147022008 -0.2374566513844455"/>
		<child link="link_22"/>
		<parent link="link_0"/>
		<limit lower="0" upper="0.02"/>
	</joint>
	<link name="link_23">
		<visual name="key-135">
			<origin xyz="-0.911923877178733 -0.05530041397070634 0.018974219854632768"/>
			<geometry>
				<mesh filename="textured_objs/original-150.obj"/>
			</geometry>
		</visual>
		<visual name="key-135">
			<origin xyz="-0.911923877178733 -0.05530041397070634 0.018974219854632768"/>
			<geometry>
				<mesh filename="textured_objs/original-62.obj"/>
			</geometry>
		</visual>
		<collision>
			<origin xyz="-0.911923877178733 -0.05530041397070634 0.018974219854632768"/>
			<geometry>
				<mesh filename="textured_objs/original-150.obj"/>
			</geometry>
		</collision>
		<collision>
			<origin xyz="-0.911923877178733 -0.05530041397070634 0.018974219854632768"/>
			<geometry>
				<mesh filename="textured_objs/original-62.obj"/>
			</geometry>
		</collision>
	</link>
	<joint name="joint_23" type="prismatic">
		<origin xyz="0.911923877178733 0.05530041397070634 -0.018974219854632768"/>
		<axis xyz="-0.05880441485746992 -0.9696166147022008 -0.2374566513844455"/>
		<child link="link_23"/>
		<parent link="link_0"/>
		<limit lower="0" upper="0.02"/>
	</joint>
	<link name="link_24">
		<visual name="key-136">
			<origin xyz="-0.911923877178733 -0.05530041397070634 0.018974219854632768"/>
			<geometry>
				<mesh filename="textured_objs/original-177.obj"/>
			</geometry>
		</visual>
		<visual name="key-136">
			<origin xyz="-0.911923877178733 -0.05530041397070634 0.018974219854632768"/>
			<geometry>
				<mesh filename="textured_objs/original-25.obj"/>
			</geometry>
		</visual>
		<collision>
			<origin xyz="-0.911923877178733 -0.05530041397070634 0.018974219854632768"/>
			<geometry>
				<mesh filename="textured_objs/original-177.obj"/>
			</geometry>
		</collision>
		<collision>
			<origin xyz="-0.911923877178733 -0.05530041397070634 0.018974219854632768"/>
			<geometry>
				<mesh filename="textured_objs/original-25.obj"/>
			</geometry>
		</collision>
	</link>
	<joint name="joint_24" type="prismatic">
		<origin xyz="0.911923877178733 0.05530041397070634 -0.018974219854632768"/>
		<axis xyz="-0.05880441485746992 -0.9696166147022008 -0.2374566513844455"/>
		<child link="link_24"/>
		<parent link="link_0"/>
		<limit lower="0" upper="0.02"/>
	</joint>
	<link name="link_25">
		<visual name="key-137">
			<origin xyz="-0.911923877178733 -0.05530041397070634 0.018974219854632768"/>
			<geometry>
				<mesh filename="textured_objs/original-175.obj"/>
			</geometry>
		</visual>
		<visual name="key-137">
			<origin xyz="-0.911923877178733 -0.05530041397070634 0.018974219854632768"/>
			<geometry>
				<mesh filename="textured_objs/original-69.obj"/>
			</geometry>
		</visual>
		<collision>
			<origin xyz="-0.911923877178733 -0.05530041397070634 0.018974219854632768"/>
			<geometry>
				<mesh filename="textured_objs/original-175.obj"/>
			</geometry>
		</collision>
		<collision>
			<origin xyz="-0.911923877178733 -0.05530041397070634 0.018974219854632768"/>
			<geometry>
				<mesh filename="textured_objs/original-69.obj"/>
			</geometry>
		</collision>
	</link>
	<joint name="joint_25" type="prismatic">
		<origin xyz="0.911923877178733 0.05530041397070634 -0.018974219854632768"/>
		<axis xyz="-0.05880441485746992 -0.9696166147022008 -0.2374566513844455"/>
		<child link="link_25"/>
		<parent link="link_0"/>
		<limit lower="0" upper="0.02"/>
	</joint>
	<link name="link_26">
		<visual name="key-138">
			<origin xyz="-0.911923877178733 -0.05530041397070634 0.018974219854632768"/>
			<geometry>
				<mesh filename="textured_objs/original-127.obj"/>
			</geometry>
		</visual>
		<visual name="key-138">
			<origin xyz="-0.911923877178733 -0.05530041397070634 0.018974219854632768"/>
			<geometry>
				<mesh filename="textured_objs/original-14.obj"/>
			</geometry>
		</visual>
		<collision>
			<origin xyz="-0.911923877178733 -0.05530041397070634 0.018974219854632768"/>
			<geometry>
				<mesh filename="textured_objs/original-127.obj"/>
			</geometry>
		</collision>
		<collision>
			<origin xyz="-0.911923877178733 -0.05530041397070634 0.018974219854632768"/>
			<geometry>
				<mesh filename="textured_objs/original-14.obj"/>
			</geometry>
		</collision>
	</link>
	<joint name="joint_26" type="prismatic">
		<origin xyz="0.911923877178733 0.05530041397070634 -0.018974219854632768"/>
		<axis xyz="-0.05880441485746992 -0.9696166147022008 -0.2374566513844455"/>
		<child link="link_26"/>
		<parent link="link_0"/>
		<limit lower="0" upper="0.02"/>
	</joint>
	<link name="link_27">
		<visual name="key-139">
			<origin xyz="-0.911923877178733 -0.05530041397070634 0.018974219854632768"/>
			<geometry>
				<mesh filename="textured_objs/original-178.obj"/>
			</geometry>
		</visual>
		<visual name="key-139">
			<origin xyz="-0.911923877178733 -0.05530041397070634 0.018974219854632768"/>
			<geometry>
				<mesh filename="textured_objs/original-48.obj"/>
			</geometry>
		</visual>
		<collision>
			<origin xyz="-0.911923877178733 -0.05530041397070634 0.018974219854632768"/>
			<geometry>
				<mesh filename="textured_objs/original-178.obj"/>
			</geometry>
		</collision>
		<collision>
			<origin xyz="-0.911923877178733 -0.05530041397070634 0.018974219854632768"/>
			<geometry>
				<mesh filename="textured_objs/original-48.obj"/>
			</geometry>
		</collision>
	</link>
	<joint name="joint_27" type="prismatic">
		<origin xyz="0.911923877178733 0.05530041397070634 -0.018974219854632768"/>
		<axis xyz="-0.05880441485746992 -0.9696166147022008 -0.2374566513844455"/>
		<child link="link_27"/>
		<parent link="link_0"/>
		<limit lower="0" upper="0.02"/>
	</joint>
	<link name="link_28">
		<visual name="key-140">
			<origin xyz="-0.911923877178733 -0.05530041397070634 0.018974219854632768"/>
			<geometry>
				<mesh filename="textured_objs/original-130.obj"/>
			</geometry>
		</visual>
		<visual name="key-140">
			<origin xyz="-0.911923877178733 -0.05530041397070634 0.018974219854632768"/>
			<geometry>
				<mesh filename="textured_objs/original-15.obj"/>
			</geometry>
		</visual>
		<collision>
			<origin xyz="-0.911923877178733 -0.05530041397070634 0.018974219854632768"/>
			<geometry>
				<mesh filename="textured_objs/original-130.obj"/>
			</geometry>
		</collision>
		<collision>
			<origin xyz="-0.911923877178733 -0.05530041397070634 0.018974219854632768"/>
			<geometry>
				<mesh filename="textured_objs/original-15.obj"/>
			</geometry>
		</collision>
	</link>
	<joint name="joint_28" type="prismatic">
		<origin xyz="0.911923877178733 0.05530041397070634 -0.018974219854632768"/>
		<axis xyz="-0.05880441485746992 -0.9696166147022008 -0.2374566513844455"/>
		<child link="link_28"/>
		<parent link="link_0"/>
		<limit lower="0" upper="0.02"/>
	</joint>
	<link name="link_29">
		<visual name="key-141">
			<origin xyz="-0.911923877178733 -0.05530041397070634 0.018974219854632768"/>
			<geometry>
				<mesh filename="textured_objs/original-163.obj"/>
			</geometry>
		</visual>
		<visual name="key-141">
			<origin xyz="-0.911923877178733 -0.05530041397070634 0.018974219854632768"/>
			<geometry>
				<mesh filename="textured_objs/original-81.obj"/>
			</geometry>
		</visual>
		<collision>
			<origin xyz="-0.911923877178733 -0.05530041397070634 0.018974219854632768"/>
			<geometry>
				<mesh filename="textured_objs/original-163.obj"/>
			</geometry>
		</collision>
		<collision>
			<origin xyz="-0.911923877178733 -0.05530041397070634 0.018974219854632768"/>
			<geometry>
				<mesh filename="textured_objs/original-81.obj"/>
			</geometry>
		</collision>
	</link>
	<joint name="joint_29" type="prismatic">
		<origin xyz="0.911923877178733 0.05530041397070634 -0.018974219854632768"/>
		<axis xyz="-0.05880441485746992 -0.9696166147022008 -0.2374566513844455"/>
		<child link="link_29"/>
		<parent link="link_0"/>
		<limit lower="0" upper="0.02"/>
	</joint>
	<link name="link_30">
		<visual name="key-142">
			<origin xyz="-0.911923877178733 -0.05530041397070634 0.018974219854632768"/>
			<geometry>
				<mesh filename="textured_objs/original-214.obj"/>
			</geometry>
		</visual>
		<visual name="key-142">
			<origin xyz="-0.911923877178733 -0.05530041397070634 0.018974219854632768"/>
			<geometry>
				<mesh filename="textured_objs/original-109.obj"/>
			</geometry>
		</visual>
		<collision>
			<origin xyz="-0.911923877178733 -0.05530041397070634 0.018974219854632768"/>
			<geometry>
				<mesh filename="textured_objs/original-214.obj"/>
			</geometry>
		</collision>
		<collision>
			<origin xyz="-0.911923877178733 -0.05530041397070634 0.018974219854632768"/>
			<geometry>
				<mesh filename="textured_objs/original-109.obj"/>
			</geometry>
		</collision>
	</link>
	<joint name="joint_30" type="prismatic">
		<origin xyz="0.911923877178733 0.05530041397070634 -0.018974219854632768"/>
		<axis xyz="-0.05880441485746992 -0.9696166147022008 -0.2374566513844455"/>
		<child link="link_30"/>
		<parent link="link_0"/>
		<limit lower="0" upper="0.02"/>
	</joint>
	<link name="link_31">
		<visual name="key-143">
			<origin xyz="-0.911923877178733 -0.05530041397070634 0.018974219854632768"/>
			<geometry>
				<mesh filename="textured_objs/original-213.obj"/>
			</geometry>
		</visual>
		<visual name="key-143">
			<origin xyz="-0.911923877178733 -0.05530041397070634 0.018974219854632768"/>
			<geometry>
				<mesh filename="textured_objs/original-102.obj"/>
			</geometry>
		</visual>
		<collision>
			<origin xyz="-0.911923877178733 -0.05530041397070634 0.018974219854632768"/>
			<geometry>
				<mesh filename="textured_objs/original-213.obj"/>
			</geometry>
		</collision>
		<collision>
			<origin xyz="-0.911923877178733 -0.05530041397070634 0.018974219854632768"/>
			<geometry>
				<mesh filename="textured_objs/original-102.obj"/>
			</geometry>
		</collision>
	</link>
	<joint name="joint_31" type="prismatic">
		<origin xyz="0.911923877178733 0.05530041397070634 -0.018974219854632768"/>
		<axis xyz="-0.05880441485746992 -0.9696166147022008 -0.2374566513844455"/>
		<child link="link_31"/>
		<parent link="link_0"/>
		<limit lower="0" upper="0.02"/>
	</joint>
	<link name="link_32">
		<visual name="key-144">
			<origin xyz="-0.911923877178733 -0.05530041397070634 0.018974219854632768"/>
			<geometry>
				<mesh filename="textured_objs/original-212.obj"/>
			</geometry>
		</visual>
		<visual name="key-144">
			<origin xyz="-0.911923877178733 -0.05530041397070634 0.018974219854632768"/>
			<geometry>
				<mesh filename="textured_objs/original-106.obj"/>
			</geometry>
		</visual>
		<collision>
			<origin xyz="-0.911923877178733 -0.05530041397070634 0.018974219854632768"/>
			<geometry>
				<mesh filename="textured_objs/original-212.obj"/>
			</geometry>
		</collision>
		<collision>
			<origin xyz="-0.911923877178733 -0.05530041397070634 0.018974219854632768"/>
			<geometry>
				<mesh filename="textured_objs/original-106.obj"/>
			</geometry>
		</collision>
	</link>
	<joint name="joint_32" type="prismatic">
		<origin xyz="0.911923877178733 0.05530041397070634 -0.018974219854632768"/>
		<axis xyz="-0.05880441485746992 -0.9696166147022008 -0.2374566513844455"/>
		<child link="link_32"/>
		<parent link="link_0"/>
		<limit lower="0" upper="0.02"/>
	</joint>
	<link name="link_33">
		<visual name="key-145">
			<origin xyz="-0.911923877178733 -0.05530041397070634 0.018974219854632768"/>
			<geometry>
				<mesh filename="textured_objs/original-87.obj"/>
			</geometry>
		</visual>
		<visual name="key-145">
			<origin xyz="-0.911923877178733 -0.05530041397070634 0.018974219854632768"/>
			<geometry>
				<mesh filename="textured_objs/original-195.obj"/>
			</geometry>
		</visual>
		<collision>
			<origin xyz="-0.911923877178733 -0.05530041397070634 0.018974219854632768"/>
			<geometry>
				<mesh filename="textured_objs/original-87.obj"/>
			</geometry>
		</collision>
		<collision>
			<origin xyz="-0.911923877178733 -0.05530041397070634 0.018974219854632768"/>
			<geometry>
				<mesh filename="textured_objs/original-195.obj"/>
			</geometry>
		</collision>
	</link>
	<joint name="joint_33" type="prismatic">
		<origin xyz="0.911923877178733 0.05530041397070634 -0.018974219854632768"/>
		<axis xyz="-0.05880441485746992 -0.9696166147022008 -0.2374566513844455"/>
		<child link="link_33"/>
		<parent link="link_0"/>
		<limit lower="0" upper="0.02"/>
	</joint>
	<link name="link_34">
		<visual name="key-146">
			<origin xyz="-0.911923877178733 -0.05530041397070634 0.018974219854632768"/>
			<geometry>
				<mesh filename="textured_objs/original-132.obj"/>
			</geometry>
		</visual>
		<visual name="key-146">
			<origin xyz="-0.911923877178733 -0.05530041397070634 0.018974219854632768"/>
			<geometry>
				<mesh filename="textured_objs/original-51.obj"/>
			</geometry>
		</visual>
		<collision>
			<origin xyz="-0.911923877178733 -0.05530041397070634 0.018974219854632768"/>
			<geometry>
				<mesh filename="textured_objs/original-132.obj"/>
			</geometry>
		</collision>
		<collision>
			<origin xyz="-0.911923877178733 -0.05530041397070634 0.018974219854632768"/>
			<geometry>
				<mesh filename="textured_objs/original-51.obj"/>
			</geometry>
		</collision>
	</link>
	<joint name="joint_34" type="prismatic">
		<origin xyz="0.911923877178733 0.05530041397070634 -0.018974219854632768"/>
		<axis xyz="-0.05880441485746992 -0.9696166147022008 -0.2374566513844455"/>
		<child link="link_34"/>
		<parent link="link_0"/>
		<limit lower="0" upper="0.02"/>
	</joint>
	<link name="link_35">
		<visual name="key-147">
			<origin xyz="-0.911923877178733 -0.05530041397070634 0.018974219854632768"/>
			<geometry>
				<mesh filename="textured_objs/original-200.obj"/>
			</geometry>
		</visual>
		<visual name="key-147">
			<origin xyz="-0.911923877178733 -0.05530041397070634 0.018974219854632768"/>
			<geometry>
				<mesh filename="textured_objs/original-94.obj"/>
			</geometry>
		</visual>
		<collision>
			<origin xyz="-0.911923877178733 -0.05530041397070634 0.018974219854632768"/>
			<geometry>
				<mesh filename="textured_objs/original-200.obj"/>
			</geometry>
		</collision>
		<collision>
			<origin xyz="-0.911923877178733 -0.05530041397070634 0.018974219854632768"/>
			<geometry>
				<mesh filename="textured_objs/original-94.obj"/>
			</geometry>
		</collision>
	</link>
	<joint name="joint_35" type="prismatic">
		<origin xyz="0.911923877178733 0.05530041397070634 -0.018974219854632768"/>
		<axis xyz="-0.05880441485746992 -0.9696166147022008 -0.2374566513844455"/>
		<child link="link_35"/>
		<parent link="link_0"/>
		<limit lower="0" upper="0.02"/>
	</joint>
	<link name="link_36">
		<visual name="key-148">
			<origin xyz="-0.911923877178733 -0.05530041397070634 0.018974219854632768"/>
			<geometry>
				<mesh filename="textured_objs/original-128.obj"/>
			</geometry>
		</visual>
		<visual name="key-148">
			<origin xyz="-0.911923877178733 -0.05530041397070634 0.018974219854632768"/>
			<geometry>
				<mesh filename="textured_objs/original-12.obj"/>
			</geometry>
		</visual>
		<collision>
			<origin xyz="-0.911923877178733 -0.05530041397070634 0.018974219854632768"/>
			<geometry>
				<mesh filename="textured_objs/original-128.obj"/>
			</geometry>
		</collision>
		<collision>
			<origin xyz="-0.911923877178733 -0.05530041397070634 0.018974219854632768"/>
			<geometry>
				<mesh filename="textured_objs/original-12.obj"/>
			</geometry>
		</collision>
	</link>
	<joint name="joint_36" type="prismatic">
		<origin xyz="0.911923877178733 0.05530041397070634 -0.018974219854632768"/>
		<axis xyz="-0.05880441485746992 -0.9696166147022008 -0.2374566513844455"/>
		<child link="link_36"/>
		<parent link="link_0"/>
		<limit lower="0" upper="0.02"/>
	</joint>
	<link name="link_37">
		<visual name="key-149">
			<origin xyz="-0.911923877178733 -0.05530041397070634 0.018974219854632768"/>
			<geometry>
				<mesh filename="textured_objs/original-170.obj"/>
			</geometry>
		</visual>
		<visual name="key-149">
			<origin xyz="-0.911923877178733 -0.05530041397070634 0.018974219854632768"/>
			<geometry>
				<mesh filename="textured_objs/original-80.obj"/>
			</geometry>
		</visual>
		<collision>
			<origin xyz="-0.911923877178733 -0.05530041397070634 0.018974219854632768"/>
			<geometry>
				<mesh filename="textured_objs/original-170.obj"/>
			</geometry>
		</collision>
		<collision>
			<origin xyz="-0.911923877178733 -0.05530041397070634 0.018974219854632768"/>
			<geometry>
				<mesh filename="textured_objs/original-80.obj"/>
			</geometry>
		</collision>
	</link>
	<joint name="joint_37" type="prismatic">
		<origin xyz="0.911923877178733 0.05530041397070634 -0.018974219854632768"/>
		<axis xyz="-0.05880441485746992 -0.9696166147022008 -0.2374566513844455"/>
		<child link="link_37"/>
		<parent link="link_0"/>
		<limit lower="0" upper="0.02"/>
	</joint>
	<link name="link_38">
		<visual name="key-150">
			<origin xyz="-0.911923877178733 -0.05530041397070634 0.018974219854632768"/>
			<geometry>
				<mesh filename="textured_objs/original-147.obj"/>
			</geometry>
		</visual>
		<visual name="key-150">
			<origin xyz="-0.911923877178733 -0.05530041397070634 0.018974219854632768"/>
			<geometry>
				<mesh filename="textured_objs/original-63.obj"/>
			</geometry>
		</visual>
		<collision>
			<origin xyz="-0.911923877178733 -0.05530041397070634 0.018974219854632768"/>
			<geometry>
				<mesh filename="textured_objs/original-147.obj"/>
			</geometry>
		</collision>
		<collision>
			<origin xyz="-0.911923877178733 -0.05530041397070634 0.018974219854632768"/>
			<geometry>
				<mesh filename="textured_objs/original-63.obj"/>
			</geometry>
		</collision>
	</link>
	<joint name="joint_38" type="prismatic">
		<origin xyz="0.911923877178733 0.05530041397070634 -0.018974219854632768"/>
		<axis xyz="-0.05880441485746992 -0.9696166147022008 -0.2374566513844455"/>
		<child link="link_38"/>
		<parent link="link_0"/>
		<limit lower="0" upper="0.02"/>
	</joint>
	<link name="link_39">
		<visual name="key-151">
			<origin xyz="-0.911923877178733 -0.05530041397070634 0.018974219854632768"/>
			<geometry>
				<mesh filename="textured_objs/original-179.obj"/>
			</geometry>
		</visual>
		<visual name="key-151">
			<origin xyz="-0.911923877178733 -0.05530041397070634 0.018974219854632768"/>
			<geometry>
				<mesh filename="textured_objs/original-82.obj"/>
			</geometry>
		</visual>
		<collision>
			<origin xyz="-0.911923877178733 -0.05530041397070634 0.018974219854632768"/>
			<geometry>
				<mesh filename="textured_objs/original-179.obj"/>
			</geometry>
		</collision>
		<collision>
			<origin xyz="-0.911923877178733 -0.05530041397070634 0.018974219854632768"/>
			<geometry>
				<mesh filename="textured_objs/original-82.obj"/>
			</geometry>
		</collision>
	</link>
	<joint name="joint_39" type="prismatic">
		<origin xyz="0.911923877178733 0.05530041397070634 -0.018974219854632768"/>
		<axis xyz="-0.05880441485746992 -0.9696166147022008 -0.2374566513844455"/>
		<child link="link_39"/>
		<parent link="link_0"/>
		<limit lower="0" upper="0.02"/>
	</joint>
	<link name="link_40">
		<visual name="key-152">
			<origin xyz="-0.911923877178733 -0.05530041397070634 0.018974219854632768"/>
			<geometry>
				<mesh filename="textured_objs/original-201.obj"/>
			</geometry>
		</visual>
		<visual name="key-152">
			<origin xyz="-0.911923877178733 -0.05530041397070634 0.018974219854632768"/>
			<geometry>
				<mesh filename="textured_objs/original-95.obj"/>
			</geometry>
		</visual>
		<collision>
			<origin xyz="-0.911923877178733 -0.05530041397070634 0.018974219854632768"/>
			<geometry>
				<mesh filename="textured_objs/original-201.obj"/>
			</geometry>
		</collision>
		<collision>
			<origin xyz="-0.911923877178733 -0.05530041397070634 0.018974219854632768"/>
			<geometry>
				<mesh filename="textured_objs/original-95.obj"/>
			</geometry>
		</collision>
	</link>
	<joint name="joint_40" type="prismatic">
		<origin xyz="0.911923877178733 0.05530041397070634 -0.018974219854632768"/>
		<axis xyz="-0.05880441485746992 -0.9696166147022008 -0.2374566513844455"/>
		<child link="link_40"/>
		<parent link="link_0"/>
		<limit lower="0" upper="0.02"/>
	</joint>
	<link name="link_41">
		<visual name="key-153">
			<origin xyz="-0.911923877178733 -0.05530041397070634 0.018974219854632768"/>
			<geometry>
				<mesh filename="textured_objs/original-203.obj"/>
			</geometry>
		</visual>
		<visual name="key-153">
			<origin xyz="-0.911923877178733 -0.05530041397070634 0.018974219854632768"/>
			<geometry>
				<mesh filename="textured_objs/original-97.obj"/>
			</geometry>
		</visual>
		<collision>
			<origin xyz="-0.911923877178733 -0.05530041397070634 0.018974219854632768"/>
			<geometry>
				<mesh filename="textured_objs/original-203.obj"/>
			</geometry>
		</collision>
		<collision>
			<origin xyz="-0.911923877178733 -0.05530041397070634 0.018974219854632768"/>
			<geometry>
				<mesh filename="textured_objs/original-97.obj"/>
			</geometry>
		</collision>
	</link>
	<joint name="joint_41" type="prismatic">
		<origin xyz="0.911923877178733 0.05530041397070634 -0.018974219854632768"/>
		<axis xyz="-0.05880441485746992 -0.9696166147022008 -0.2374566513844455"/>
		<child link="link_41"/>
		<parent link="link_0"/>
		<limit lower="0" upper="0.02"/>
	</joint>
	<link name="link_42">
		<visual name="key-154">
			<origin xyz="-0.911923877178733 -0.05530041397070634 0.018974219854632768"/>
			<geometry>
				<mesh filename="textured_objs/original-224.obj"/>
			</geometry>
		</visual>
		<visual name="key-154">
			<origin xyz="-0.911923877178733 -0.05530041397070634 0.018974219854632768"/>
			<geometry>
				<mesh filename="textured_objs/original-79.obj"/>
			</geometry>
		</visual>
		<collision>
			<origin xyz="-0.911923877178733 -0.05530041397070634 0.018974219854632768"/>
			<geometry>
				<mesh filename="textured_objs/original-224.obj"/>
			</geometry>
		</collision>
		<collision>
			<origin xyz="-0.911923877178733 -0.05530041397070634 0.018974219854632768"/>
			<geometry>
				<mesh filename="textured_objs/original-79.obj"/>
			</geometry>
		</collision>
	</link>
	<joint name="joint_42" type="prismatic">
		<origin xyz="0.911923877178733 0.05530041397070634 -0.018974219854632768"/>
		<axis xyz="-0.05880441485746992 -0.9696166147022008 -0.2374566513844455"/>
		<child link="link_42"/>
		<parent link="link_0"/>
		<limit lower="0" upper="0.02"/>
	</joint>
	<link name="link_43">
		<visual name="key-155">
			<origin xyz="-0.911923877178733 -0.05530041397070634 0.018974219854632768"/>
			<geometry>
				<mesh filename="textured_objs/original-160.obj"/>
			</geometry>
		</visual>
		<visual name="key-155">
			<origin xyz="-0.911923877178733 -0.05530041397070634 0.018974219854632768"/>
			<geometry>
				<mesh filename="textured_objs/original-28.obj"/>
			</geometry>
		</visual>
		<collision>
			<origin xyz="-0.911923877178733 -0.05530041397070634 0.018974219854632768"/>
			<geometry>
				<mesh filename="textured_objs/original-160.obj"/>
			</geometry>
		</collision>
		<collision>
			<origin xyz="-0.911923877178733 -0.05530041397070634 0.018974219854632768"/>
			<geometry>
				<mesh filename="textured_objs/original-28.obj"/>
			</geometry>
		</collision>
	</link>
	<joint name="joint_43" type="prismatic">
		<origin xyz="0.911923877178733 0.05530041397070634 -0.018974219854632768"/>
		<axis xyz="-0.05880441485746992 -0.9696166147022008 -0.2374566513844455"/>
		<child link="link_43"/>
		<parent link="link_0"/>
		<limit lower="0" upper="0.02"/>
	</joint>
	<link name="link_44">
		<visual name="key-156">
			<origin xyz="-0.911923877178733 -0.05530041397070634 0.018974219854632768"/>
			<geometry>
				<mesh filename="textured_objs/original-155.obj"/>
			</geometry>
		</visual>
		<visual name="key-156">
			<origin xyz="-0.911923877178733 -0.05530041397070634 0.018974219854632768"/>
			<geometry>
				<mesh filename="textured_objs/original-52.obj"/>
			</geometry>
		</visual>
		<collision>
			<origin xyz="-0.911923877178733 -0.05530041397070634 0.018974219854632768"/>
			<geometry>
				<mesh filename="textured_objs/original-155.obj"/>
			</geometry>
		</collision>
		<collision>
			<origin xyz="-0.911923877178733 -0.05530041397070634 0.018974219854632768"/>
			<geometry>
				<mesh filename="textured_objs/original-52.obj"/>
			</geometry>
		</collision>
	</link>
	<joint name="joint_44" type="prismatic">
		<origin xyz="0.911923877178733 0.05530041397070634 -0.018974219854632768"/>
		<axis xyz="-0.05880441485746992 -0.9696166147022008 -0.2374566513844455"/>
		<child link="link_44"/>
		<parent link="link_0"/>
		<limit lower="0" upper="0.02"/>
	</joint>
	<link name="link_45">
		<visual name="key-157">
			<origin xyz="-0.911923877178733 -0.05530041397070634 0.018974219854632768"/>
			<geometry>
				<mesh filename="textured_objs/original-171.obj"/>
			</geometry>
		</visual>
		<visual name="key-157">
			<origin xyz="-0.911923877178733 -0.05530041397070634 0.018974219854632768"/>
			<geometry>
				<mesh filename="textured_objs/original-61.obj"/>
			</geometry>
		</visual>
		<collision>
			<origin xyz="-0.911923877178733 -0.05530041397070634 0.018974219854632768"/>
			<geometry>
				<mesh filename="textured_objs/original-171.obj"/>
			</geometry>
		</collision>
		<collision>
			<origin xyz="-0.911923877178733 -0.05530041397070634 0.018974219854632768"/>
			<geometry>
				<mesh filename="textured_objs/original-61.obj"/>
			</geometry>
		</collision>
	</link>
	<joint name="joint_45" type="prismatic">
		<origin xyz="0.911923877178733 0.05530041397070634 -0.018974219854632768"/>
		<axis xyz="-0.05880441485746992 -0.9696166147022008 -0.2374566513844455"/>
		<child link="link_45"/>
		<parent link="link_0"/>
		<limit lower="0" upper="0.02"/>
	</joint>
	<link name="link_46">
		<visual name="key-158">
			<origin xyz="-0.911923877178733 -0.05530041397070634 0.018974219854632768"/>
			<geometry>
				<mesh filename="textured_objs/original-164.obj"/>
			</geometry>
		</visual>
		<visual name="key-158">
			<origin xyz="-0.911923877178733 -0.05530041397070634 0.018974219854632768"/>
			<geometry>
				<mesh filename="textured_objs/original-29.obj"/>
			</geometry>
		</visual>
		<collision>
			<origin xyz="-0.911923877178733 -0.05530041397070634 0.018974219854632768"/>
			<geometry>
				<mesh filename="textured_objs/original-164.obj"/>
			</geometry>
		</collision>
		<collision>
			<origin xyz="-0.911923877178733 -0.05530041397070634 0.018974219854632768"/>
			<geometry>
				<mesh filename="textured_objs/original-29.obj"/>
			</geometry>
		</collision>
	</link>
	<joint name="joint_46" type="prismatic">
		<origin xyz="0.911923877178733 0.05530041397070634 -0.018974219854632768"/>
		<axis xyz="-0.05880441485746992 -0.9696166147022008 -0.2374566513844455"/>
		<child link="link_46"/>
		<parent link="link_0"/>
		<limit lower="0" upper="0.02"/>
	</joint>
	<link name="link_47">
		<visual name="key-159">
			<origin xyz="-0.911923877178733 -0.05530041397070634 0.018974219854632768"/>
			<geometry>
				<mesh filename="textured_objs/original-135.obj"/>
			</geometry>
		</visual>
		<visual name="key-159">
			<origin xyz="-0.911923877178733 -0.05530041397070634 0.018974219854632768"/>
			<geometry>
				<mesh filename="textured_objs/original-20.obj"/>
			</geometry>
		</visual>
		<collision>
			<origin xyz="-0.911923877178733 -0.05530041397070634 0.018974219854632768"/>
			<geometry>
				<mesh filename="textured_objs/original-135.obj"/>
			</geometry>
		</collision>
		<collision>
			<origin xyz="-0.911923877178733 -0.05530041397070634 0.018974219854632768"/>
			<geometry>
				<mesh filename="textured_objs/original-20.obj"/>
			</geometry>
		</collision>
	</link>
	<joint name="joint_47" type="prismatic">
		<origin xyz="0.911923877178733 0.05530041397070634 -0.018974219854632768"/>
		<axis xyz="-0.05880441485746992 -0.9696166147022008 -0.2374566513844455"/>
		<child link="link_47"/>
		<parent link="link_0"/>
		<limit lower="0" upper="0.02"/>
	</joint>
	<link name="link_48">
		<visual name="key-160">
			<origin xyz="-0.911923877178733 -0.05530041397070634 0.018974219854632768"/>
			<geometry>
				<mesh filename="textured_objs/original-211.obj"/>
			</geometry>
		</visual>
		<visual name="key-160">
			<origin xyz="-0.911923877178733 -0.05530041397070634 0.018974219854632768"/>
			<geometry>
				<mesh filename="textured_objs/original-101.obj"/>
			</geometry>
		</visual>
		<collision>
			<origin xyz="-0.911923877178733 -0.05530041397070634 0.018974219854632768"/>
			<geometry>
				<mesh filename="textured_objs/original-211.obj"/>
			</geometry>
		</collision>
		<collision>
			<origin xyz="-0.911923877178733 -0.05530041397070634 0.018974219854632768"/>
			<geometry>
				<mesh filename="textured_objs/original-101.obj"/>
			</geometry>
		</collision>
	</link>
	<joint name="joint_48" type="prismatic">
		<origin xyz="0.911923877178733 0.05530041397070634 -0.018974219854632768"/>
		<axis xyz="-0.05880441485746992 -0.9696166147022008 -0.2374566513844455"/>
		<child link="link_48"/>
		<parent link="link_0"/>
		<limit lower="0" upper="0.02"/>
	</joint>
	<link name="link_49">
		<visual name="key-161">
			<origin xyz="-0.911923877178733 -0.05530041397070634 0.018974219854632768"/>
			<geometry>
				<mesh filename="textured_objs/original-125.obj"/>
			</geometry>
		</visual>
		<visual name="key-161">
			<origin xyz="-0.911923877178733 -0.05530041397070634 0.018974219854632768"/>
			<geometry>
				<mesh filename="textured_objs/original-11.obj"/>
			</geometry>
		</visual>
		<collision>
			<origin xyz="-0.911923877178733 -0.05530041397070634 0.018974219854632768"/>
			<geometry>
				<mesh filename="textured_objs/original-125.obj"/>
			</geometry>
		</collision>
		<collision>
			<origin xyz="-0.911923877178733 -0.05530041397070634 0.018974219854632768"/>
			<geometry>
				<mesh filename="textured_objs/original-11.obj"/>
			</geometry>
		</collision>
	</link>
	<joint name="joint_49" type="prismatic">
		<origin xyz="0.911923877178733 0.05530041397070634 -0.018974219854632768"/>
		<axis xyz="-0.05880441485746992 -0.9696166147022008 -0.2374566513844455"/>
		<child link="link_49"/>
		<parent link="link_0"/>
		<limit lower="0" upper="0.02"/>
	</joint>
	<link name="link_50">
		<visual name="key-162">
			<origin xyz="-0.911923877178733 -0.05530041397070634 0.018974219854632768"/>
			<geometry>
				<mesh filename="textured_objs/original-221.obj"/>
			</geometry>
		</visual>
		<visual name="key-162">
			<origin xyz="-0.911923877178733 -0.05530041397070634 0.018974219854632768"/>
			<geometry>
				<mesh filename="textured_objs/original-77.obj"/>
			</geometry>
		</visual>
		<collision>
			<origin xyz="-0.911923877178733 -0.05530041397070634 0.018974219854632768"/>
			<geometry>
				<mesh filename="textured_objs/original-221.obj"/>
			</geometry>
		</collision>
		<collision>
			<origin xyz="-0.911923877178733 -0.05530041397070634 0.018974219854632768"/>
			<geometry>
				<mesh filename="textured_objs/original-77.obj"/>
			</geometry>
		</collision>
	</link>
	<joint name="joint_50" type="prismatic">
		<origin xyz="0.911923877178733 0.05530041397070634 -0.018974219854632768"/>
		<axis xyz="-0.05880441485746992 -0.9696166147022008 -0.2374566513844455"/>
		<child link="link_50"/>
		<parent link="link_0"/>
		<limit lower="0" upper="0.02"/>
	</joint>
	<link name="link_51">
		<visual name="key-163">
			<origin xyz="-0.911923877178733 -0.05530041397070634 0.018974219854632768"/>
			<geometry>
				<mesh filename="textured_objs/original-157.obj"/>
			</geometry>
		</visual>
		<visual name="key-163">
			<origin xyz="-0.911923877178733 -0.05530041397070634 0.018974219854632768"/>
			<geometry>
				<mesh filename="textured_objs/original-54.obj"/>
			</geometry>
		</visual>
		<collision>
			<origin xyz="-0.911923877178733 -0.05530041397070634 0.018974219854632768"/>
			<geometry>
				<mesh filename="textured_objs/original-157.obj"/>
			</geometry>
		</collision>
		<collision>
			<origin xyz="-0.911923877178733 -0.05530041397070634 0.018974219854632768"/>
			<geometry>
				<mesh filename="textured_objs/original-54.obj"/>
			</geometry>
		</collision>
	</link>
	<joint name="joint_51" type="prismatic">
		<origin xyz="0.911923877178733 0.05530041397070634 -0.018974219854632768"/>
		<axis xyz="-0.05880441485746992 -0.9696166147022008 -0.2374566513844455"/>
		<child link="link_51"/>
		<parent link="link_0"/>
		<limit lower="0" upper="0.02"/>
	</joint>
	<link name="link_52">
		<visual name="key-164">
			<origin xyz="-0.911923877178733 -0.05530041397070634 0.018974219854632768"/>
			<geometry>
				<mesh filename="textured_objs/original-151.obj"/>
			</geometry>
		</visual>
		<visual name="key-164">
			<origin xyz="-0.911923877178733 -0.05530041397070634 0.018974219854632768"/>
			<geometry>
				<mesh filename="textured_objs/original-32.obj"/>
			</geometry>
		</visual>
		<collision>
			<origin xyz="-0.911923877178733 -0.05530041397070634 0.018974219854632768"/>
			<geometry>
				<mesh filename="textured_objs/original-151.obj"/>
			</geometry>
		</collision>
		<collision>
			<origin xyz="-0.911923877178733 -0.05530041397070634 0.018974219854632768"/>
			<geometry>
				<mesh filename="textured_objs/original-32.obj"/>
			</geometry>
		</collision>
	</link>
	<joint name="joint_52" type="prismatic">
		<origin xyz="0.911923877178733 0.05530041397070634 -0.018974219854632768"/>
		<axis xyz="-0.05880441485746992 -0.9696166147022008 -0.2374566513844455"/>
		<child link="link_52"/>
		<parent link="link_0"/>
		<limit lower="0" upper="0.02"/>
	</joint>
	<link name="link_53">
		<visual name="key-165">
			<origin xyz="-0.911923877178733 -0.05530041397070634 0.018974219854632768"/>
			<geometry>
				<mesh filename="textured_objs/original-187.obj"/>
			</geometry>
		</visual>
		<visual name="key-165">
			<origin xyz="-0.911923877178733 -0.05530041397070634 0.018974219854632768"/>
			<geometry>
				<mesh filename="textured_objs/original-42.obj"/>
			</geometry>
		</visual>
		<collision>
			<origin xyz="-0.911923877178733 -0.05530041397070634 0.018974219854632768"/>
			<geometry>
				<mesh filename="textured_objs/original-187.obj"/>
			</geometry>
		</collision>
		<collision>
			<origin xyz="-0.911923877178733 -0.05530041397070634 0.018974219854632768"/>
			<geometry>
				<mesh filename="textured_objs/original-42.obj"/>
			</geometry>
		</collision>
	</link>
	<joint name="joint_53" type="prismatic">
		<origin xyz="0.911923877178733 0.05530041397070634 -0.018974219854632768"/>
		<axis xyz="-0.05880441485746992 -0.9696166147022008 -0.2374566513844455"/>
		<child link="link_53"/>
		<parent link="link_0"/>
		<limit lower="0" upper="0.02"/>
	</joint>
	<link name="link_54">
		<visual name="key-166">
			<origin xyz="-0.911923877178733 -0.05530041397070634 0.018974219854632768"/>
			<geometry>
				<mesh filename="textured_objs/original-180.obj"/>
			</geometry>
		</visual>
		<visual name="key-166">
			<origin xyz="-0.911923877178733 -0.05530041397070634 0.018974219854632768"/>
			<geometry>
				<mesh filename="textured_objs/original-44.obj"/>
			</geometry>
		</visual>
		<collision>
			<origin xyz="-0.911923877178733 -0.05530041397070634 0.018974219854632768"/>
			<geometry>
				<mesh filename="textured_objs/original-180.obj"/>
			</geometry>
		</collision>
		<collision>
			<origin xyz="-0.911923877178733 -0.05530041397070634 0.018974219854632768"/>
			<geometry>
				<mesh filename="textured_objs/original-44.obj"/>
			</geometry>
		</collision>
	</link>
	<joint name="joint_54" type="prismatic">
		<origin xyz="0.911923877178733 0.05530041397070634 -0.018974219854632768"/>
		<axis xyz="-0.05880441485746992 -0.9696166147022008 -0.2374566513844455"/>
		<child link="link_54"/>
		<parent link="link_0"/>
		<limit lower="0" upper="0.02"/>
	</joint>
	<link name="link_55">
		<visual name="key-167">
			<origin xyz="-0.911923877178733 -0.05530041397070634 0.018974219854632768"/>
			<geometry>
				<mesh filename="textured_objs/original-190.obj"/>
			</geometry>
		</visual>
		<visual name="key-167">
			<origin xyz="-0.911923877178733 -0.05530041397070634 0.018974219854632768"/>
			<geometry>
				<mesh filename="textured_objs/original-39.obj"/>
			</geometry>
		</visual>
		<collision>
			<origin xyz="-0.911923877178733 -0.05530041397070634 0.018974219854632768"/>
			<geometry>
				<mesh filename="textured_objs/original-190.obj"/>
			</geometry>
		</collision>
		<collision>
			<origin xyz="-0.911923877178733 -0.05530041397070634 0.018974219854632768"/>
			<geometry>
				<mesh filename="textured_objs/original-39.obj"/>
			</geometry>
		</collision>
	</link>
	<joint name="joint_55" type="prismatic">
		<origin xyz="0.911923877178733 0.05530041397070634 -0.018974219854632768"/>
		<axis xyz="-0.05880441485746992 -0.9696166147022008 -0.2374566513844455"/>
		<child link="link_55"/>
		<parent link="link_0"/>
		<limit lower="0" upper="0.02"/>
	</joint>
	<link name="link_56">
		<visual name="key-168">
			<origin xyz="-0.911923877178733 -0.05530041397070634 0.018974219854632768"/>
			<geometry>
				<mesh filename="textured_objs/original-167.obj"/>
			</geometry>
		</visual>
		<visual name="key-168">
			<origin xyz="-0.911923877178733 -0.05530041397070634 0.018974219854632768"/>
			<geometry>
				<mesh filename="textured_objs/original-68.obj"/>
			</geometry>
		</visual>
		<collision>
			<origin xyz="-0.911923877178733 -0.05530041397070634 0.018974219854632768"/>
			<geometry>
				<mesh filename="textured_objs/original-167.obj"/>
			</geometry>
		</collision>
		<collision>
			<origin xyz="-0.911923877178733 -0.05530041397070634 0.018974219854632768"/>
			<geometry>
				<mesh filename="textured_objs/original-68.obj"/>
			</geometry>
		</collision>
	</link>
	<joint name="joint_56" type="prismatic">
		<origin xyz="0.911923877178733 0.05530041397070634 -0.018974219854632768"/>
		<axis xyz="-0.05880441485746992 -0.9696166147022008 -0.2374566513844455"/>
		<child link="link_56"/>
		<parent link="link_0"/>
		<limit lower="0" upper="0.02"/>
	</joint>
	<link name="link_57">
		<visual name="key-169">
			<origin xyz="-0.911923877178733 -0.05530041397070634 0.018974219854632768"/>
			<geometry>
				<mesh filename="textured_objs/original-131.obj"/>
			</geometry>
		</visual>
		<visual name="key-169">
			<origin xyz="-0.911923877178733 -0.05530041397070634 0.018974219854632768"/>
			<geometry>
				<mesh filename="textured_objs/original-16.obj"/>
			</geometry>
		</visual>
		<collision>
			<origin xyz="-0.911923877178733 -0.05530041397070634 0.018974219854632768"/>
			<geometry>
				<mesh filename="textured_objs/original-131.obj"/>
			</geometry>
		</collision>
		<collision>
			<origin xyz="-0.911923877178733 -0.05530041397070634 0.018974219854632768"/>
			<geometry>
				<mesh filename="textured_objs/original-16.obj"/>
			</geometry>
		</collision>
	</link>
	<joint name="joint_57" type="prismatic">
		<origin xyz="0.911923877178733 0.05530041397070634 -0.018974219854632768"/>
		<axis xyz="-0.05880441485746992 -0.9696166147022008 -0.2374566513844455"/>
		<child link="link_57"/>
		<parent link="link_0"/>
		<limit lower="0" upper="0.02"/>
	</joint>
	<link name="link_58">
		<visual name="key-170">
			<origin xyz="-0.911923877178733 -0.05530041397070634 0.018974219854632768"/>
			<geometry>
				<mesh filename="textured_objs/original-137.obj"/>
			</geometry>
		</visual>
		<visual name="key-170">
			<origin xyz="-0.911923877178733 -0.05530041397070634 0.018974219854632768"/>
			<geometry>
				<mesh filename="textured_objs/original-21.obj"/>
			</geometry>
		</visual>
		<collision>
			<origin xyz="-0.911923877178733 -0.05530041397070634 0.018974219854632768"/>
			<geometry>
				<mesh filename="textured_objs/original-137.obj"/>
			</geometry>
		</collision>
		<collision>
			<origin xyz="-0.911923877178733 -0.05530041397070634 0.018974219854632768"/>
			<geometry>
				<mesh filename="textured_objs/original-21.obj"/>
			</geometry>
		</collision>
	</link>
	<joint name="joint_58" type="prismatic">
		<origin xyz="0.911923877178733 0.05530041397070634 -0.018974219854632768"/>
		<axis xyz="-0.05880441485746992 -0.9696166147022008 -0.2374566513844455"/>
		<child link="link_58"/>
		<parent link="link_0"/>
		<limit lower="0" upper="0.02"/>
	</joint>
	<link name="link_59">
		<visual name="key-171">
			<origin xyz="-0.911923877178733 -0.05530041397070634 0.018974219854632768"/>
			<geometry>
				<mesh filename="textured_objs/original-158.obj"/>
			</geometry>
		</visual>
		<visual name="key-171">
			<origin xyz="-0.911923877178733 -0.05530041397070634 0.018974219854632768"/>
			<geometry>
				<mesh filename="textured_objs/original-110.obj"/>
			</geometry>
		</visual>
		<collision>
			<origin xyz="-0.911923877178733 -0.05530041397070634 0.018974219854632768"/>
			<geometry>
				<mesh filename="textured_objs/original-158.obj"/>
			</geometry>
		</collision>
		<collision>
			<origin xyz="-0.911923877178733 -0.05530041397070634 0.018974219854632768"/>
			<geometry>
				<mesh filename="textured_objs/original-110.obj"/>
			</geometry>
		</collision>
	</link>
	<joint name="joint_59" type="prismatic">
		<origin xyz="0.911923877178733 0.05530041397070634 -0.018974219854632768"/>
		<axis xyz="-0.05880441485746992 -0.9696166147022008 -0.2374566513844455"/>
		<child link="link_59"/>
		<parent link="link_0"/>
		<limit lower="0" upper="0.02"/>
	</joint>
	<link name="link_60">
		<visual name="key-172">
			<origin xyz="-0.911923877178733 -0.05530041397070634 0.018974219854632768"/>
			<geometry>
				<mesh filename="textured_objs/original-186.obj"/>
			</geometry>
		</visual>
		<visual name="key-172">
			<origin xyz="-0.911923877178733 -0.05530041397070634 0.018974219854632768"/>
			<geometry>
				<mesh filename="textured_objs/original-50.obj"/>
			</geometry>
		</visual>
		<collision>
			<origin xyz="-0.911923877178733 -0.05530041397070634 0.018974219854632768"/>
			<geometry>
				<mesh filename="textured_objs/original-186.obj"/>
			</geometry>
		</collision>
		<collision>
			<origin xyz="-0.911923877178733 -0.05530041397070634 0.018974219854632768"/>
			<geometry>
				<mesh filename="textured_objs/original-50.obj"/>
			</geometry>
		</collision>
	</link>
	<joint name="joint_60" type="prismatic">
		<origin xyz="0.911923877178733 0.05530041397070634 -0.018974219854632768"/>
		<axis xyz="-0.05880441485746992 -0.9696166147022008 -0.2374566513844455"/>
		<child link="link_60"/>
		<parent link="link_0"/>
		<limit lower="0" upper="0.02"/>
	</joint>
	<link name="link_61">
		<visual name="key-173">
			<origin xyz="-0.911923877178733 -0.05530041397070634 0.018974219854632768"/>
			<geometry>
				<mesh filename="textured_objs/original-169.obj"/>
			</geometry>
		</visual>
		<visual name="key-173">
			<origin xyz="-0.911923877178733 -0.05530041397070634 0.018974219854632768"/>
			<geometry>
				<mesh filename="textured_objs/original-72.obj"/>
			</geometry>
		</visual>
		<collision>
			<origin xyz="-0.911923877178733 -0.05530041397070634 0.018974219854632768"/>
			<geometry>
				<mesh filename="textured_objs/original-169.obj"/>
			</geometry>
		</collision>
		<collision>
			<origin xyz="-0.911923877178733 -0.05530041397070634 0.018974219854632768"/>
			<geometry>
				<mesh filename="textured_objs/original-72.obj"/>
			</geometry>
		</collision>
	</link>
	<joint name="joint_61" type="prismatic">
		<origin xyz="0.911923877178733 0.05530041397070634 -0.018974219854632768"/>
		<axis xyz="-0.05880441485746992 -0.9696166147022008 -0.2374566513844455"/>
		<child link="link_61"/>
		<parent link="link_0"/>
		<limit lower="0" upper="0.02"/>
	</joint>
	<link name="link_62">
		<visual name="key-174">
			<origin xyz="-0.911923877178733 -0.05530041397070634 0.018974219854632768"/>
			<geometry>
				<mesh filename="textured_objs/original-176.obj"/>
			</geometry>
		</visual>
		<visual name="key-174">
			<origin xyz="-0.911923877178733 -0.05530041397070634 0.018974219854632768"/>
			<geometry>
				<mesh filename="textured_objs/original-34.obj"/>
			</geometry>
		</visual>
		<collision>
			<origin xyz="-0.911923877178733 -0.05530041397070634 0.018974219854632768"/>
			<geometry>
				<mesh filename="textured_objs/original-176.obj"/>
			</geometry>
		</collision>
		<collision>
			<origin xyz="-0.911923877178733 -0.05530041397070634 0.018974219854632768"/>
			<geometry>
				<mesh filename="textured_objs/original-34.obj"/>
			</geometry>
		</collision>
	</link>
	<joint name="joint_62" type="prismatic">
		<origin xyz="0.911923877178733 0.05530041397070634 -0.018974219854632768"/>
		<axis xyz="-0.05880441485746992 -0.9696166147022008 -0.2374566513844455"/>
		<child link="link_62"/>
		<parent link="link_0"/>
		<limit lower="0" upper="0.02"/>
	</joint>
	<link name="link_63">
		<visual name="key-175">
			<origin xyz="-0.911923877178733 -0.05530041397070634 0.018974219854632768"/>
			<geometry>
				<mesh filename="textured_objs/original-146.obj"/>
			</geometry>
		</visual>
		<visual name="key-175">
			<origin xyz="-0.911923877178733 -0.05530041397070634 0.018974219854632768"/>
			<geometry>
				<mesh filename="textured_objs/original-57.obj"/>
			</geometry>
		</visual>
		<collision>
			<origin xyz="-0.911923877178733 -0.05530041397070634 0.018974219854632768"/>
			<geometry>
				<mesh filename="textured_objs/original-146.obj"/>
			</geometry>
		</collision>
		<collision>
			<origin xyz="-0.911923877178733 -0.05530041397070634 0.018974219854632768"/>
			<geometry>
				<mesh filename="textured_objs/original-57.obj"/>
			</geometry>
		</collision>
	</link>
	<joint name="joint_63" type="prismatic">
		<origin xyz="0.911923877178733 0.05530041397070634 -0.018974219854632768"/>
		<axis xyz="-0.05880441485746992 -0.9696166147022008 -0.2374566513844455"/>
		<child link="link_63"/>
		<parent link="link_0"/>
		<limit lower="0" upper="0.02"/>
	</joint>
	<link name="link_64">
		<visual name="key-176">
			<origin xyz="-0.911923877178733 -0.05530041397070634 0.018974219854632768"/>
			<geometry>
				<mesh filename="textured_objs/original-166.obj"/>
			</geometry>
		</visual>
		<visual name="key-176">
			<origin xyz="-0.911923877178733 -0.05530041397070634 0.018974219854632768"/>
			<geometry>
				<mesh filename="textured_objs/original-31.obj"/>
			</geometry>
		</visual>
		<collision>
			<origin xyz="-0.911923877178733 -0.05530041397070634 0.018974219854632768"/>
			<geometry>
				<mesh filename="textured_objs/original-166.obj"/>
			</geometry>
		</collision>
		<collision>
			<origin xyz="-0.911923877178733 -0.05530041397070634 0.018974219854632768"/>
			<geometry>
				<mesh filename="textured_objs/original-31.obj"/>
			</geometry>
		</collision>
	</link>
	<joint name="joint_64" type="prismatic">
		<origin xyz="0.911923877178733 0.05530041397070634 -0.018974219854632768"/>
		<axis xyz="-0.05880441485746992 -0.9696166147022008 -0.2374566513844455"/>
		<child link="link_64"/>
		<parent link="link_0"/>
		<limit lower="0" upper="0.02"/>
	</joint>
	<link name="link_65">
		<visual name="key-177">
			<origin xyz="-0.911923877178733 -0.05530041397070634 0.018974219854632768"/>
			<geometry>
				<mesh filename="textured_objs/original-152.obj"/>
			</geometry>
		</visual>
		<visual name="key-177">
			<origin xyz="-0.911923877178733 -0.05530041397070634 0.018974219854632768"/>
			<geometry>
				<mesh filename="textured_objs/original-38.obj"/>
			</geometry>
		</visual>
		<collision>
			<origin xyz="-0.911923877178733 -0.05530041397070634 0.018974219854632768"/>
			<geometry>
				<mesh filename="textured_objs/original-152.obj"/>
			</geometry>
		</collision>
		<collision>
			<origin xyz="-0.911923877178733 -0.05530041397070634 0.018974219854632768"/>
			<geometry>
				<mesh filename="textured_objs/original-38.obj"/>
			</geometry>
		</collision>
	</link>
	<joint name="joint_65" type="prismatic">
		<origin xyz="0.911923877178733 0.05530041397070634 -0.018974219854632768"/>
		<axis xyz="-0.05880441485746992 -0.9696166147022008 -0.2374566513844455"/>
		<child link="link_65"/>
		<parent link="link_0"/>
		<limit lower="0" upper="0.02"/>
	</joint>
	<link name="link_66">
		<visual name="key-178">
			<origin xyz="-0.911923877178733 -0.05530041397070634 0.018974219854632768"/>
			<geometry>
				<mesh filename="textured_objs/original-116.obj"/>
			</geometry>
		</visual>
		<visual name="key-178">
			<origin xyz="-0.911923877178733 -0.05530041397070634 0.018974219854632768"/>
			<geometry>
				<mesh filename="textured_objs/original-75.obj"/>
			</geometry>
		</visual>
		<collision>
			<origin xyz="-0.911923877178733 -0.05530041397070634 0.018974219854632768"/>
			<geometry>
				<mesh filename="textured_objs/original-116.obj"/>
			</geometry>
		</collision>
		<collision>
			<origin xyz="-0.911923877178733 -0.05530041397070634 0.018974219854632768"/>
			<geometry>
				<mesh filename="textured_objs/original-75.obj"/>
			</geometry>
		</collision>
	</link>
	<joint name="joint_66" type="prismatic">
		<origin xyz="0.911923877178733 0.05530041397070634 -0.018974219854632768"/>
		<axis xyz="-0.05880441485746992 -0.9696166147022008 -0.2374566513844455"/>
		<child link="link_66"/>
		<parent link="link_0"/>
		<limit lower="0" upper="0.02"/>
	</joint>
	<link name="link_67">
		<visual name="key-179">
			<origin xyz="-0.911923877178733 -0.05530041397070634 0.018974219854632768"/>
			<geometry>
				<mesh filename="textured_objs/original-129.obj"/>
			</geometry>
		</visual>
		<visual name="key-179">
			<origin xyz="-0.911923877178733 -0.05530041397070634 0.018974219854632768"/>
			<geometry>
				<mesh filename="textured_objs/original-13.obj"/>
			</geometry>
		</visual>
		<collision>
			<origin xyz="-0.911923877178733 -0.05530041397070634 0.018974219854632768"/>
			<geometry>
				<mesh filename="textured_objs/original-129.obj"/>
			</geometry>
		</collision>
		<collision>
			<origin xyz="-0.911923877178733 -0.05530041397070634 0.018974219854632768"/>
			<geometry>
				<mesh filename="textured_objs/original-13.obj"/>
			</geometry>
		</collision>
	</link>
	<joint name="joint_67" type="prismatic">
		<origin xyz="0.911923877178733 0.05530041397070634 -0.018974219854632768"/>
		<axis xyz="-0.05880441485746992 -0.9696166147022008 -0.2374566513844455"/>
		<child link="link_67"/>
		<parent link="link_0"/>
		<limit lower="0" upper="0.02"/>
	</joint>
	<link name="link_68">
		<visual name="key-180">
			<origin xyz="-0.911923877178733 -0.05530041397070634 0.018974219854632768"/>
			<geometry>
				<mesh filename="textured_objs/original-142.obj"/>
			</geometry>
		</visual>
		<visual name="key-180">
			<origin xyz="-0.911923877178733 -0.05530041397070634 0.018974219854632768"/>
			<geometry>
				<mesh filename="textured_objs/original-113.obj"/>
			</geometry>
		</visual>
		<collision>
			<origin xyz="-0.911923877178733 -0.05530041397070634 0.018974219854632768"/>
			<geometry>
				<mesh filename="textured_objs/original-142.obj"/>
			</geometry>
		</collision>
		<collision>
			<origin xyz="-0.911923877178733 -0.05530041397070634 0.018974219854632768"/>
			<geometry>
				<mesh filename="textured_objs/original-113.obj"/>
			</geometry>
		</collision>
	</link>
	<joint name="joint_68" type="prismatic">
		<origin xyz="0.911923877178733 0.05530041397070634 -0.018974219854632768"/>
		<axis xyz="-0.05880441485746992 -0.9696166147022008 -0.2374566513844455"/>
		<child link="link_68"/>
		<parent link="link_0"/>
		<limit lower="0" upper="0.02"/>
	</joint>
	<link name="link_69">
		<visual name="key-181">
			<origin xyz="-0.911923877178733 -0.05530041397070634 0.018974219854632768"/>
			<geometry>
				<mesh filename="textured_objs/original-133.obj"/>
			</geometry>
		</visual>
		<visual name="key-181">
			<origin xyz="-0.911923877178733 -0.05530041397070634 0.018974219854632768"/>
			<geometry>
				<mesh filename="textured_objs/original-17.obj"/>
			</geometry>
		</visual>
		<collision>
			<origin xyz="-0.911923877178733 -0.05530041397070634 0.018974219854632768"/>
			<geometry>
				<mesh filename="textured_objs/original-133.obj"/>
			</geometry>
		</collision>
		<collision>
			<origin xyz="-0.911923877178733 -0.05530041397070634 0.018974219854632768"/>
			<geometry>
				<mesh filename="textured_objs/original-17.obj"/>
			</geometry>
		</collision>
	</link>
	<joint name="joint_69" type="prismatic">
		<origin xyz="0.911923877178733 0.05530041397070634 -0.018974219854632768"/>
		<axis xyz="-0.05880441485746992 -0.9696166147022008 -0.2374566513844455"/>
		<child link="link_69"/>
		<parent link="link_0"/>
		<limit lower="0" upper="0.02"/>
	</joint>
	<link name="link_70">
		<visual name="key-182">
			<origin xyz="-0.911923877178733 -0.05530041397070634 0.018974219854632768"/>
			<geometry>
				<mesh filename="textured_objs/original-148.obj"/>
			</geometry>
		</visual>
		<visual name="key-182">
			<origin xyz="-0.911923877178733 -0.05530041397070634 0.018974219854632768"/>
			<geometry>
				<mesh filename="textured_objs/original-76.obj"/>
			</geometry>
		</visual>
		<collision>
			<origin xyz="-0.911923877178733 -0.05530041397070634 0.018974219854632768"/>
			<geometry>
				<mesh filename="textured_objs/original-148.obj"/>
			</geometry>
		</collision>
		<collision>
			<origin xyz="-0.911923877178733 -0.05530041397070634 0.018974219854632768"/>
			<geometry>
				<mesh filename="textured_objs/original-76.obj"/>
			</geometry>
		</collision>
	</link>
	<joint name="joint_70" type="prismatic">
		<origin xyz="0.911923877178733 0.05530041397070634 -0.018974219854632768"/>
		<axis xyz="-0.05880441485746992 -0.9696166147022008 -0.2374566513844455"/>
		<child link="link_70"/>
		<parent link="link_0"/>
		<limit lower="0" upper="0.02"/>
	</joint>
	<link name="link_71">
		<visual name="key-183">
			<origin xyz="-0.911923877178733 -0.05530041397070634 0.018974219854632768"/>
			<geometry>
				<mesh filename="textured_objs/original-165.obj"/>
			</geometry>
		</visual>
		<visual name="key-183">
			<origin xyz="-0.911923877178733 -0.05530041397070634 0.018974219854632768"/>
			<geometry>
				<mesh filename="textured_objs/original-60.obj"/>
			</geometry>
		</visual>
		<collision>
			<origin xyz="-0.911923877178733 -0.05530041397070634 0.018974219854632768"/>
			<geometry>
				<mesh filename="textured_objs/original-165.obj"/>
			</geometry>
		</collision>
		<collision>
			<origin xyz="-0.911923877178733 -0.05530041397070634 0.018974219854632768"/>
			<geometry>
				<mesh filename="textured_objs/original-60.obj"/>
			</geometry>
		</collision>
	</link>
	<joint name="joint_71" type="prismatic">
		<origin xyz="0.911923877178733 0.05530041397070634 -0.018974219854632768"/>
		<axis xyz="-0.05880441485746992 -0.9696166147022008 -0.2374566513844455"/>
		<child link="link_71"/>
		<parent link="link_0"/>
		<limit lower="0" upper="0.02"/>
	</joint>
	<link name="link_72">
		<visual name="key-184">
			<origin xyz="-0.911923877178733 -0.05530041397070634 0.018974219854632768"/>
			<geometry>
				<mesh filename="textured_objs/original-144.obj"/>
			</geometry>
		</visual>
		<visual name="key-184">
			<origin xyz="-0.911923877178733 -0.05530041397070634 0.018974219854632768"/>
			<geometry>
				<mesh filename="textured_objs/original-26.obj"/>
			</geometry>
		</visual>
		<collision>
			<origin xyz="-0.911923877178733 -0.05530041397070634 0.018974219854632768"/>
			<geometry>
				<mesh filename="textured_objs/original-144.obj"/>
			</geometry>
		</collision>
		<collision>
			<origin xyz="-0.911923877178733 -0.05530041397070634 0.018974219854632768"/>
			<geometry>
				<mesh filename="textured_objs/original-26.obj"/>
			</geometry>
		</collision>
	</link>
	<joint name="joint_72" type="prismatic">
		<origin xyz="0.911923877178733 0.05530041397070634 -0.018974219854632768"/>
		<axis xyz="-0.05880441485746992 -0.9696166147022008 -0.2374566513844455"/>
		<child link="link_72"/>
		<parent link="link_0"/>
		<limit lower="0" upper="0.02"/>
	</joint>
	<link name="link_73">
		<visual name="key-185">
			<origin xyz="-0.911923877178733 -0.05530041397070634 0.018974219854632768"/>
			<geometry>
				<mesh filename="textured_objs/original-189.obj"/>
			</geometry>
		</visual>
		<visual name="key-185">
			<origin xyz="-0.911923877178733 -0.05530041397070634 0.018974219854632768"/>
			<geometry>
				<mesh filename="textured_objs/original-73.obj"/>
			</geometry>
		</visual>
		<collision>
			<origin xyz="-0.911923877178733 -0.05530041397070634 0.018974219854632768"/>
			<geometry>
				<mesh filename="textured_objs/original-189.obj"/>
			</geometry>
		</collision>
		<collision>
			<origin xyz="-0.911923877178733 -0.05530041397070634 0.018974219854632768"/>
			<geometry>
				<mesh filename="textured_objs/original-73.obj"/>
			</geometry>
		</collision>
	</link>
	<joint name="joint_73" type="prismatic">
		<origin xyz="0.911923877178733 0.05530041397070634 -0.018974219854632768"/>
		<axis xyz="-0.05880441485746992 -0.9696166147022008 -0.2374566513844455"/>
		<child link="link_73"/>
		<parent link="link_0"/>
		<limit lower="0" upper="0.02"/>
	</joint>
	<link name="link_74">
		<visual name="key-186">
			<origin xyz="-0.911923877178733 -0.05530041397070634 0.018974219854632768"/>
			<geometry>
				<mesh filename="textured_objs/original-209.obj"/>
			</geometry>
		</visual>
		<visual name="key-186">
			<origin xyz="-0.911923877178733 -0.05530041397070634 0.018974219854632768"/>
			<geometry>
				<mesh filename="textured_objs/original-55.obj"/>
			</geometry>
		</visual>
		<collision>
			<origin xyz="-0.911923877178733 -0.05530041397070634 0.018974219854632768"/>
			<geometry>
				<mesh filename="textured_objs/original-209.obj"/>
			</geometry>
		</collision>
		<collision>
			<origin xyz="-0.911923877178733 -0.05530041397070634 0.018974219854632768"/>
			<geometry>
				<mesh filename="textured_objs/original-55.obj"/>
			</geometry>
		</collision>
	</link>
	<joint name="joint_74" type="prismatic">
		<origin xyz="0.911923877178733 0.05530041397070634 -0.018974219854632768"/>
		<axis xyz="-0.05880441485746992 -0.9696166147022008 -0.2374566513844455"/>
		<child link="link_74"/>
		<parent link="link_0"/>
		<limit lower="0" upper="0.02"/>
	</joint>
	<link name="link_75">
		<visual name="key-187">
			<origin xyz="-0.911923877178733 -0.05530041397070634 0.018974219854632768"/>
			<geometry>
				<mesh filename="textured_objs/original-183.obj"/>
			</geometry>
		</visual>
		<visual name="key-187">
			<origin xyz="-0.911923877178733 -0.05530041397070634 0.018974219854632768"/>
			<geometry>
				<mesh filename="textured_objs/original-23.obj"/>
			</geometry>
		</visual>
		<collision>
			<origin xyz="-0.911923877178733 -0.05530041397070634 0.018974219854632768"/>
			<geometry>
				<mesh filename="textured_objs/original-183.obj"/>
			</geometry>
		</collision>
		<collision>
			<origin xyz="-0.911923877178733 -0.05530041397070634 0.018974219854632768"/>
			<geometry>
				<mesh filename="textured_objs/original-23.obj"/>
			</geometry>
		</collision>
	</link>
	<joint name="joint_75" type="prismatic">
		<origin xyz="0.911923877178733 0.05530041397070634 -0.018974219854632768"/>
		<axis xyz="-0.05880441485746992 -0.9696166147022008 -0.2374566513844455"/>
		<child link="link_75"/>
		<parent link="link_0"/>
		<limit lower="0" upper="0.02"/>
	</joint>
	<link name="link_76">
		<visual name="key-188">
			<origin xyz="-0.911923877178733 -0.05530041397070634 0.018974219854632768"/>
			<geometry>
				<mesh filename="textured_objs/original-225.obj"/>
			</geometry>
		</visual>
		<visual name="key-188">
			<origin xyz="-0.911923877178733 -0.05530041397070634 0.018974219854632768"/>
			<geometry>
				<mesh filename="textured_objs/original-46.obj"/>
			</geometry>
		</visual>
		<collision>
			<origin xyz="-0.911923877178733 -0.05530041397070634 0.018974219854632768"/>
			<geometry>
				<mesh filename="textured_objs/original-225.obj"/>
			</geometry>
		</collision>
		<collision>
			<origin xyz="-0.911923877178733 -0.05530041397070634 0.018974219854632768"/>
			<geometry>
				<mesh filename="textured_objs/original-46.obj"/>
			</geometry>
		</collision>
	</link>
	<joint name="joint_76" type="prismatic">
		<origin xyz="0.911923877178733 0.05530041397070634 -0.018974219854632768"/>
		<axis xyz="-0.05880441485746992 -0.9696166147022008 -0.2374566513844455"/>
		<child link="link_76"/>
		<parent link="link_0"/>
		<limit lower="0" upper="0.02"/>
	</joint>
	<link name="link_77">
		<visual name="key-189">
			<origin xyz="-0.911923877178733 -0.05530041397070634 0.018974219854632768"/>
			<geometry>
				<mesh filename="textured_objs/original-141.obj"/>
			</geometry>
		</visual>
		<visual name="key-189">
			<origin xyz="-0.911923877178733 -0.05530041397070634 0.018974219854632768"/>
			<geometry>
				<mesh filename="textured_objs/original-64.obj"/>
			</geometry>
		</visual>
		<collision>
			<origin xyz="-0.911923877178733 -0.05530041397070634 0.018974219854632768"/>
			<geometry>
				<mesh filename="textured_objs/original-141.obj"/>
			</geometry>
		</collision>
		<collision>
			<origin xyz="-0.911923877178733 -0.05530041397070634 0.018974219854632768"/>
			<geometry>
				<mesh filename="textured_objs/original-64.obj"/>
			</geometry>
		</collision>
	</link>
	<joint name="joint_77" type="prismatic">
		<origin xyz="0.911923877178733 0.05530041397070634 -0.018974219854632768"/>
		<axis xyz="-0.05880441485746992 -0.9696166147022008 -0.2374566513844455"/>
		<child link="link_77"/>
		<parent link="link_0"/>
		<limit lower="0" upper="0.02"/>
	</joint>
	<link name="link_78">
		<visual name="key-190">
			<origin xyz="-0.911923877178733 -0.05530041397070634 0.018974219854632768"/>
			<geometry>
				<mesh filename="textured_objs/original-223.obj"/>
			</geometry>
		</visual>
		<visual name="key-190">
			<origin xyz="-0.911923877178733 -0.05530041397070634 0.018974219854632768"/>
			<geometry>
				<mesh filename="textured_objs/original-37.obj"/>
			</geometry>
		</visual>
		<collision>
			<origin xyz="-0.911923877178733 -0.05530041397070634 0.018974219854632768"/>
			<geometry>
				<mesh filename="textured_objs/original-223.obj"/>
			</geometry>
		</collision>
		<collision>
			<origin xyz="-0.911923877178733 -0.05530041397070634 0.018974219854632768"/>
			<geometry>
				<mesh filename="textured_objs/original-37.obj"/>
			</geometry>
		</collision>
	</link>
	<joint name="joint_78" type="prismatic">
		<origin xyz="0.911923877178733 0.05530041397070634 -0.018974219854632768"/>
		<axis xyz="-0.05880441485746992 -0.9696166147022008 -0.2374566513844455"/>
		<child link="link_78"/>
		<parent link="link_0"/>
		<limit lower="0" upper="0.02"/>
	</joint>
	<link name="link_79">
		<visual name="key-191">
			<origin xyz="-0.911923877178733 -0.05530041397070634 0.018974219854632768"/>
			<geometry>
				<mesh filename="textured_objs/original-217.obj"/>
			</geometry>
		</visual>
		<visual name="key-191">
			<origin xyz="-0.911923877178733 -0.05530041397070634 0.018974219854632768"/>
			<geometry>
				<mesh filename="textured_objs/original-100.obj"/>
			</geometry>
		</visual>
		<collision>
			<origin xyz="-0.911923877178733 -0.05530041397070634 0.018974219854632768"/>
			<geometry>
				<mesh filename="textured_objs/original-217.obj"/>
			</geometry>
		</collision>
		<collision>
			<origin xyz="-0.911923877178733 -0.05530041397070634 0.018974219854632768"/>
			<geometry>
				<mesh filename="textured_objs/original-100.obj"/>
			</geometry>
		</collision>
	</link>
	<joint name="joint_79" type="prismatic">
		<origin xyz="0.911923877178733 0.05530041397070634 -0.018974219854632768"/>
		<axis xyz="-0.05880441485746992 -0.9696166147022008 -0.2374566513844455"/>
		<child link="link_79"/>
		<parent link="link_0"/>
		<limit lower="0" upper="0.02"/>
	</joint>
	<link name="link_80">
		<visual name="key-192">
			<origin xyz="-0.911923877178733 -0.05530041397070634 0.018974219854632768"/>
			<geometry>
				<mesh filename="textured_objs/original-188.obj"/>
			</geometry>
		</visual>
		<visual name="key-192">
			<origin xyz="-0.911923877178733 -0.05530041397070634 0.018974219854632768"/>
			<geometry>
				<mesh filename="textured_objs/original-98.obj"/>
			</geometry>
		</visual>
		<collision>
			<origin xyz="-0.911923877178733 -0.05530041397070634 0.018974219854632768"/>
			<geometry>
				<mesh filename="textured_objs/original-188.obj"/>
			</geometry>
		</collision>
		<collision>
			<origin xyz="-0.911923877178733 -0.05530041397070634 0.018974219854632768"/>
			<geometry>
				<mesh filename="textured_objs/original-98.obj"/>
			</geometry>
		</collision>
	</link>
	<joint name="joint_80" type="prismatic">
		<origin xyz="0.911923877178733 0.05530041397070634 -0.018974219854632768"/>
		<axis xyz="-0.05880441485746992 -0.9696166147022008 -0.2374566513844455"/>
		<child link="link_80"/>
		<parent link="link_0"/>
		<limit lower="0" upper="0.02"/>
	</joint>
	<link name="link_81">
		<visual name="key-193">
			<origin xyz="-0.911923877178733 -0.05530041397070634 0.018974219854632768"/>
			<geometry>
				<mesh filename="textured_objs/original-143.obj"/>
			</geometry>
		</visual>
		<visual name="key-193">
			<origin xyz="-0.911923877178733 -0.05530041397070634 0.018974219854632768"/>
			<geometry>
				<mesh filename="textured_objs/original-24.obj"/>
			</geometry>
		</visual>
		<collision>
			<origin xyz="-0.911923877178733 -0.05530041397070634 0.018974219854632768"/>
			<geometry>
				<mesh filename="textured_objs/original-143.obj"/>
			</geometry>
		</collision>
		<collision>
			<origin xyz="-0.911923877178733 -0.05530041397070634 0.018974219854632768"/>
			<geometry>
				<mesh filename="textured_objs/original-24.obj"/>
			</geometry>
		</collision>
	</link>
	<joint name="joint_81" type="prismatic">
		<origin xyz="0.911923877178733 0.05530041397070634 -0.018974219854632768"/>
		<axis xyz="-0.05880441485746992 -0.9696166147022008 -0.2374566513844455"/>
		<child link="link_81"/>
		<parent link="link_0"/>
		<limit lower="0" upper="0.02"/>
	</joint>
	<link name="link_82">
		<visual name="key-194">
			<origin xyz="-0.911923877178733 -0.05530041397070634 0.018974219854632768"/>
			<geometry>
				<mesh filename="textured_objs/original-228.obj"/>
			</geometry>
		</visual>
		<visual name="key-194">
			<origin xyz="-0.911923877178733 -0.05530041397070634 0.018974219854632768"/>
			<geometry>
				<mesh filename="textured_objs/original-70.obj"/>
			</geometry>
		</visual>
		<collision>
			<origin xyz="-0.911923877178733 -0.05530041397070634 0.018974219854632768"/>
			<geometry>
				<mesh filename="textured_objs/original-228.obj"/>
			</geometry>
		</collision>
		<collision>
			<origin xyz="-0.911923877178733 -0.05530041397070634 0.018974219854632768"/>
			<geometry>
				<mesh filename="textured_objs/original-70.obj"/>
			</geometry>
		</collision>
	</link>
	<joint name="joint_82" type="prismatic">
		<origin xyz="0.911923877178733 0.05530041397070634 -0.018974219854632768"/>
		<axis xyz="-0.05880441485746992 -0.9696166147022008 -0.2374566513844455"/>
		<child link="link_82"/>
		<parent link="link_0"/>
		<limit lower="0" upper="0.02"/>
	</joint>
	<link name="link_83">
		<visual name="key-195">
			<origin xyz="-0.911923877178733 -0.05530041397070634 0.018974219854632768"/>
			<geometry>
				<mesh filename="textured_objs/original-138.obj"/>
			</geometry>
		</visual>
		<visual name="key-195">
			<origin xyz="-0.911923877178733 -0.05530041397070634 0.018974219854632768"/>
			<geometry>
				<mesh filename="textured_objs/original-22.obj"/>
			</geometry>
		</visual>
		<collision>
			<origin xyz="-0.911923877178733 -0.05530041397070634 0.018974219854632768"/>
			<geometry>
				<mesh filename="textured_objs/original-138.obj"/>
			</geometry>
		</collision>
		<collision>
			<origin xyz="-0.911923877178733 -0.05530041397070634 0.018974219854632768"/>
			<geometry>
				<mesh filename="textured_objs/original-22.obj"/>
			</geometry>
		</collision>
	</link>
	<joint name="joint_83" type="prismatic">
		<origin xyz="0.911923877178733 0.05530041397070634 -0.018974219854632768"/>
		<axis xyz="-0.05880441485746992 -0.9696166147022008 -0.2374566513844455"/>
		<child link="link_83"/>
		<parent link="link_0"/>
		<limit lower="0" upper="0.02"/>
	</joint>
	<link name="link_84">
		<visual name="key-196">
			<origin xyz="-0.911923877178733 -0.05530041397070634 0.018974219854632768"/>
			<geometry>
				<mesh filename="textured_objs/original-136.obj"/>
			</geometry>
		</visual>
		<visual name="key-196">
			<origin xyz="-0.911923877178733 -0.05530041397070634 0.018974219854632768"/>
			<geometry>
				<mesh filename="textured_objs/original-19.obj"/>
			</geometry>
		</visual>
		<collision>
			<origin xyz="-0.911923877178733 -0.05530041397070634 0.018974219854632768"/>
			<geometry>
				<mesh filename="textured_objs/original-136.obj"/>
			</geometry>
		</collision>
		<collision>
			<origin xyz="-0.911923877178733 -0.05530041397070634 0.018974219854632768"/>
			<geometry>
				<mesh filename="textured_objs/original-19.obj"/>
			</geometry>
		</collision>
	</link>
	<joint name="joint_84" type="prismatic">
		<origin xyz="0.911923877178733 0.05530041397070634 -0.018974219854632768"/>
		<axis xyz="-0.05880441485746992 -0.9696166147022008 -0.2374566513844455"/>
		<child link="link_84"/>
		<parent link="link_0"/>
		<limit lower="0" upper="0.02"/>
	</joint>
	<link name="link_85">
		<visual name="key-197">
			<origin xyz="-0.911923877178733 -0.05530041397070634 0.018974219854632768"/>
			<geometry>
				<mesh filename="textured_objs/original-193.obj"/>
			</geometry>
		</visual>
		<visual name="key-197">
			<origin xyz="-0.911923877178733 -0.05530041397070634 0.018974219854632768"/>
			<geometry>
				<mesh filename="textured_objs/original-85.obj"/>
			</geometry>
		</visual>
		<collision>
			<origin xyz="-0.911923877178733 -0.05530041397070634 0.018974219854632768"/>
			<geometry>
				<mesh filename="textured_objs/original-193.obj"/>
			</geometry>
		</collision>
		<collision>
			<origin xyz="-0.911923877178733 -0.05530041397070634 0.018974219854632768"/>
			<geometry>
				<mesh filename="textured_objs/original-85.obj"/>
			</geometry>
		</collision>
	</link>
	<joint name="joint_85" type="prismatic">
		<origin xyz="0.911923877178733 0.05530041397070634 -0.018974219854632768"/>
		<axis xyz="-0.05880441485746992 -0.9696166147022008 -0.2374566513844455"/>
		<child link="link_85"/>
		<parent link="link_0"/>
		<limit lower="0" upper="0.02"/>
	</joint>
	<link name="link_86">
		<visual name="key-198">
			<origin xyz="-0.911923877178733 -0.05530041397070634 0.018974219854632768"/>
			<geometry>
				<mesh filename="textured_objs/original-105.obj"/>
			</geometry>
		</visual>
		<visual name="key-198">
			<origin xyz="-0.911923877178733 -0.05530041397070634 0.018974219854632768"/>
			<geometry>
				<mesh filename="textured_objs/original-216.obj"/>
			</geometry>
		</visual>
		<collision>
			<origin xyz="-0.911923877178733 -0.05530041397070634 0.018974219854632768"/>
			<geometry>
				<mesh filename="textured_objs/original-105.obj"/>
			</geometry>
		</collision>
		<collision>
			<origin xyz="-0.911923877178733 -0.05530041397070634 0.018974219854632768"/>
			<geometry>
				<mesh filename="textured_objs/original-216.obj"/>
			</geometry>
		</collision>
	</link>
	<joint name="joint_86" type="prismatic">
		<origin xyz="0.911923877178733 0.05530041397070634 -0.018974219854632768"/>
		<axis xyz="-0.05880441485746992 -0.9696166147022008 -0.2374566513844455"/>
		<child link="link_86"/>
		<parent link="link_0"/>
		<limit lower="0" upper="0.02"/>
	</joint>
	<link name="link_87">
		<visual name="key-199">
			<origin xyz="-0.911923877178733 -0.05530041397070634 0.018974219854632768"/>
			<geometry>
				<mesh filename="textured_objs/original-185.obj"/>
			</geometry>
		</visual>
		<visual name="key-199">
			<origin xyz="-0.911923877178733 -0.05530041397070634 0.018974219854632768"/>
			<geometry>
				<mesh filename="textured_objs/original-30.obj"/>
			</geometry>
		</visual>
		<collision>
			<origin xyz="-0.911923877178733 -0.05530041397070634 0.018974219854632768"/>
			<geometry>
				<mesh filename="textured_objs/original-185.obj"/>
			</geometry>
		</collision>
		<collision>
			<origin xyz="-0.911923877178733 -0.05530041397070634 0.018974219854632768"/>
			<geometry>
				<mesh filename="textured_objs/original-30.obj"/>
			</geometry>
		</collision>
	</link>
	<joint name="joint_87" type="prismatic">
		<origin xyz="0.911923877178733 0.05530041397070634 -0.018974219854632768"/>
		<axis xyz="-0.05880441485746992 -0.9696166147022008 -0.2374566513844455"/>
		<child link="link_87"/>
		<parent link="link_0"/>
		<limit lower="0" upper="0.02"/>
	</joint>
	<link name="link_88">
		<visual name="key-200">
			<origin xyz="-0.911923877178733 -0.05530041397070634 0.018974219854632768"/>
			<geometry>
				<mesh filename="textured_objs/original-161.obj"/>
			</geometry>
		</visual>
		<visual name="key-200">
			<origin xyz="-0.911923877178733 -0.05530041397070634 0.018974219854632768"/>
			<geometry>
				<mesh filename="textured_objs/original-36.obj"/>
			</geometry>
		</visual>
		<collision>
			<origin xyz="-0.911923877178733 -0.05530041397070634 0.018974219854632768"/>
			<geometry>
				<mesh filename="textured_objs/original-161.obj"/>
			</geometry>
		</collision>
		<collision>
			<origin xyz="-0.911923877178733 -0.05530041397070634 0.018974219854632768"/>
			<geometry>
				<mesh filename="textured_objs/original-36.obj"/>
			</geometry>
		</collision>
	</link>
	<joint name="joint_88" type="prismatic">
		<origin xyz="0.911923877178733 0.05530041397070634 -0.018974219854632768"/>
		<axis xyz="-0.05880441485746992 -0.9696166147022008 -0.2374566513844455"/>
		<child link="link_88"/>
		<parent link="link_0"/>
		<limit lower="0" upper="0.02"/>
	</joint>
	<link name="link_89">
		<visual name="key-201">
			<origin xyz="-0.911923877178733 -0.05530041397070634 0.018974219854632768"/>
			<geometry>
				<mesh filename="textured_objs/original-184.obj"/>
			</geometry>
		</visual>
		<visual name="key-201">
			<origin xyz="-0.911923877178733 -0.05530041397070634 0.018974219854632768"/>
			<geometry>
				<mesh filename="textured_objs/original-43.obj"/>
			</geometry>
		</visual>
		<collision>
			<origin xyz="-0.911923877178733 -0.05530041397070634 0.018974219854632768"/>
			<geometry>
				<mesh filename="textured_objs/original-184.obj"/>
			</geometry>
		</collision>
		<collision>
			<origin xyz="-0.911923877178733 -0.05530041397070634 0.018974219854632768"/>
			<geometry>
				<mesh filename="textured_objs/original-43.obj"/>
			</geometry>
		</collision>
	</link>
	<joint name="joint_89" type="prismatic">
		<origin xyz="0.911923877178733 0.05530041397070634 -0.018974219854632768"/>
		<axis xyz="-0.05880441485746992 -0.9696166147022008 -0.2374566513844455"/>
		<child link="link_89"/>
		<parent link="link_0"/>
		<limit lower="0" upper="0.02"/>
	</joint>
	<link name="link_90">
		<visual name="key-202">
			<origin xyz="-0.911923877178733 -0.05530041397070634 0.018974219854632768"/>
			<geometry>
				<mesh filename="textured_objs/original-181.obj"/>
			</geometry>
		</visual>
		<visual name="key-202">
			<origin xyz="-0.911923877178733 -0.05530041397070634 0.018974219854632768"/>
			<geometry>
				<mesh filename="textured_objs/original-78.obj"/>
			</geometry>
		</visual>
		<collision>
			<origin xyz="-0.911923877178733 -0.05530041397070634 0.018974219854632768"/>
			<geometry>
				<mesh filename="textured_objs/original-181.obj"/>
			</geometry>
		</collision>
		<collision>
			<origin xyz="-0.911923877178733 -0.05530041397070634 0.018974219854632768"/>
			<geometry>
				<mesh filename="textured_objs/original-78.obj"/>
			</geometry>
		</collision>
	</link>
	<joint name="joint_90" type="prismatic">
		<origin xyz="0.911923877178733 0.05530041397070634 -0.018974219854632768"/>
		<axis xyz="-0.05880441485746992 -0.9696166147022008 -0.2374566513844455"/>
		<child link="link_90"/>
		<parent link="link_0"/>
		<limit lower="0" upper="0.02"/>
	</joint>
	<link name="link_91">
		<visual name="key-203">
			<origin xyz="-0.911923877178733 -0.05530041397070634 0.018974219854632768"/>
			<geometry>
				<mesh filename="textured_objs/original-154.obj"/>
			</geometry>
		</visual>
		<visual name="key-203">
			<origin xyz="-0.911923877178733 -0.05530041397070634 0.018974219854632768"/>
			<geometry>
				<mesh filename="textured_objs/original-40.obj"/>
			</geometry>
		</visual>
		<collision>
			<origin xyz="-0.911923877178733 -0.05530041397070634 0.018974219854632768"/>
			<geometry>
				<mesh filename="textured_objs/original-154.obj"/>
			</geometry>
		</collision>
		<collision>
			<origin xyz="-0.911923877178733 -0.05530041397070634 0.018974219854632768"/>
			<geometry>
				<mesh filename="textured_objs/original-40.obj"/>
			</geometry>
		</collision>
	</link>
	<joint name="joint_91" type="prismatic">
		<origin xyz="0.911923877178733 0.05530041397070634 -0.018974219854632768"/>
		<axis xyz="-0.05880441485746992 -0.9696166147022008 -0.2374566513844455"/>
		<child link="link_91"/>
		<parent link="link_0"/>
		<limit lower="0" upper="0.02"/>
	</joint>
	<link name="link_92">
		<visual name="key-204">
			<origin xyz="-0.911923877178733 -0.05530041397070634 0.018974219854632768"/>
			<geometry>
				<mesh filename="textured_objs/original-140.obj"/>
			</geometry>
		</visual>
		<visual name="key-204">
			<origin xyz="-0.911923877178733 -0.05530041397070634 0.018974219854632768"/>
			<geometry>
				<mesh filename="textured_objs/original-112.obj"/>
			</geometry>
		</visual>
		<collision>
			<origin xyz="-0.911923877178733 -0.05530041397070634 0.018974219854632768"/>
			<geometry>
				<mesh filename="textured_objs/original-140.obj"/>
			</geometry>
		</collision>
		<collision>
			<origin xyz="-0.911923877178733 -0.05530041397070634 0.018974219854632768"/>
			<geometry>
				<mesh filename="textured_objs/original-112.obj"/>
			</geometry>
		</collision>
	</link>
	<joint name="joint_92" type="prismatic">
		<origin xyz="0.911923877178733 0.05530041397070634 -0.018974219854632768"/>
		<axis xyz="-0.05880441485746992 -0.9696166147022008 -0.2374566513844455"/>
		<child link="link_92"/>
		<parent link="link_0"/>
		<limit lower="0" upper="0.02"/>
	</joint>
	<link name="link_93">
		<visual name="key-205">
			<origin xyz="-0.911923877178733 -0.05530041397070634 0.018974219854632768"/>
			<geometry>
				<mesh filename="textured_objs/original-174.obj"/>
			</geometry>
		</visual>
		<visual name="key-205">
			<origin xyz="-0.911923877178733 -0.05530041397070634 0.018974219854632768"/>
			<geometry>
				<mesh filename="textured_objs/original-27.obj"/>
			</geometry>
		</visual>
		<collision>
			<origin xyz="-0.911923877178733 -0.05530041397070634 0.018974219854632768"/>
			<geometry>
				<mesh filename="textured_objs/original-174.obj"/>
			</geometry>
		</collision>
		<collision>
			<origin xyz="-0.911923877178733 -0.05530041397070634 0.018974219854632768"/>
			<geometry>
				<mesh filename="textured_objs/original-27.obj"/>
			</geometry>
		</collision>
	</link>
	<joint name="joint_93" type="prismatic">
		<origin xyz="0.911923877178733 0.05530041397070634 -0.018974219854632768"/>
		<axis xyz="-0.05880441485746992 -0.9696166147022008 -0.2374566513844455"/>
		<child link="link_93"/>
		<parent link="link_0"/>
		<limit lower="0" upper="0.02"/>
	</joint>
	<link name="link_94">
		<visual name="key-206">
			<origin xyz="-0.911923877178733 -0.05530041397070634 0.018974219854632768"/>
			<geometry>
				<mesh filename="textured_objs/original-173.obj"/>
			</geometry>
		</visual>
		<visual name="key-206">
			<origin xyz="-0.911923877178733 -0.05530041397070634 0.018974219854632768"/>
			<geometry>
				<mesh filename="textured_objs/original-45.obj"/>
			</geometry>
		</visual>
		<collision>
			<origin xyz="-0.911923877178733 -0.05530041397070634 0.018974219854632768"/>
			<geometry>
				<mesh filename="textured_objs/original-173.obj"/>
			</geometry>
		</collision>
		<collision>
			<origin xyz="-0.911923877178733 -0.05530041397070634 0.018974219854632768"/>
			<geometry>
				<mesh filename="textured_objs/original-45.obj"/>
			</geometry>
		</collision>
	</link>
	<joint name="joint_94" type="prismatic">
		<origin xyz="0.911923877178733 0.05530041397070634 -0.018974219854632768"/>
		<axis xyz="-0.05880441485746992 -0.9696166147022008 -0.2374566513844455"/>
		<child link="link_94"/>
		<parent link="link_0"/>
		<limit lower="0" upper="0.02"/>
	</joint>
	<link name="link_95">
		<visual name="key-207">
			<origin xyz="-0.911923877178733 -0.05530041397070634 0.018974219854632768"/>
			<geometry>
				<mesh filename="textured_objs/original-226.obj"/>
			</geometry>
		</visual>
		<visual name="key-207">
			<origin xyz="-0.911923877178733 -0.05530041397070634 0.018974219854632768"/>
			<geometry>
				<mesh filename="textured_objs/original-111.obj"/>
			</geometry>
		</visual>
		<collision>
			<origin xyz="-0.911923877178733 -0.05530041397070634 0.018974219854632768"/>
			<geometry>
				<mesh filename="textured_objs/original-226.obj"/>
			</geometry>
		</collision>
		<collision>
			<origin xyz="-0.911923877178733 -0.05530041397070634 0.018974219854632768"/>
			<geometry>
				<mesh filename="textured_objs/original-111.obj"/>
			</geometry>
		</collision>
	</link>
	<joint name="joint_95" type="prismatic">
		<origin xyz="0.911923877178733 0.05530041397070634 -0.018974219854632768"/>
		<axis xyz="-0.05880441485746992 -0.9696166147022008 -0.2374566513844455"/>
		<child link="link_95"/>
		<parent link="link_0"/>
		<limit lower="0" upper="0.02"/>
	</joint>
	<link name="link_96">
		<visual name="key-208">
			<origin xyz="-0.911923877178733 -0.05530041397070634 0.018974219854632768"/>
			<geometry>
				<mesh filename="textured_objs/original-74.obj"/>
			</geometry>
		</visual>
		<visual name="key-208">
			<origin xyz="-0.911923877178733 -0.05530041397070634 0.018974219854632768"/>
			<geometry>
				<mesh filename="textured_objs/original-115.obj"/>
			</geometry>
		</visual>
		<collision>
			<origin xyz="-0.911923877178733 -0.05530041397070634 0.018974219854632768"/>
			<geometry>
				<mesh filename="textured_objs/original-74.obj"/>
			</geometry>
		</collision>
		<collision>
			<origin xyz="-0.911923877178733 -0.05530041397070634 0.018974219854632768"/>
			<geometry>
				<mesh filename="textured_objs/original-115.obj"/>
			</geometry>
		</collision>
	</link>
	<joint name="joint_96" type="prismatic">
		<origin xyz="0.911923877178733 0.05530041397070634 -0.018974219854632768"/>
		<axis xyz="-0.05880441485746992 -0.9696166147022008 -0.2374566513844455"/>
		<child link="link_96"/>
		<parent link="link_0"/>
		<limit lower="0" upper="0.02"/>
	</joint>
	<link name="link_97">
		<visual name="key-209">
			<origin xyz="-0.911923877178733 -0.05530041397070634 0.018974219854632768"/>
			<geometry>
				<mesh filename="textured_objs/original-172.obj"/>
			</geometry>
		</visual>
		<visual name="key-209">
			<origin xyz="-0.911923877178733 -0.05530041397070634 0.018974219854632768"/>
			<geometry>
				<mesh filename="textured_objs/original-65.obj"/>
			</geometry>
		</visual>
		<collision>
			<origin xyz="-0.911923877178733 -0.05530041397070634 0.018974219854632768"/>
			<geometry>
				<mesh filename="textured_objs/original-172.obj"/>
			</geometry>
		</collision>
		<collision>
			<origin xyz="-0.911923877178733 -0.05530041397070634 0.018974219854632768"/>
			<geometry>
				<mesh filename="textured_objs/original-65.obj"/>
			</geometry>
		</collision>
	</link>
	<joint name="joint_97" type="prismatic">
		<origin xyz="0.911923877178733 0.05530041397070634 -0.018974219854632768"/>
		<axis xyz="-0.05880441485746992 -0.9696166147022008 -0.2374566513844455"/>
		<child link="link_97"/>
		<parent link="link_0"/>
		<limit lower="0" upper="0.02"/>
	</joint>
	<link name="link_98">
		<visual name="key-210">
			<origin xyz="-0.911923877178733 -0.05530041397070634 0.018974219854632768"/>
			<geometry>
				<mesh filename="textured_objs/original-18.obj"/>
			</geometry>
		</visual>
		<visual name="key-210">
			<origin xyz="-0.911923877178733 -0.05530041397070634 0.018974219854632768"/>
			<geometry>
				<mesh filename="textured_objs/original-134.obj"/>
			</geometry>
		</visual>
		<collision>
			<origin xyz="-0.911923877178733 -0.05530041397070634 0.018974219854632768"/>
			<geometry>
				<mesh filename="textured_objs/original-18.obj"/>
			</geometry>
		</collision>
		<collision>
			<origin xyz="-0.911923877178733 -0.05530041397070634 0.018974219854632768"/>
			<geometry>
				<mesh filename="textured_objs/original-134.obj"/>
			</geometry>
		</collision>
	</link>
	<joint name="joint_98" type="prismatic">
		<origin xyz="0.911923877178733 0.05530041397070634 -0.018974219854632768"/>
		<axis xyz="-0.05880441485746992 -0.9696166147022008 -0.2374566513844455"/>
		<child link="link_98"/>
		<parent link="link_0"/>
		<limit lower="0" upper="0.02"/>
	</joint>
	<link name="link_99">
		<visual name="key-211">
			<origin xyz="-0.911923877178733 -0.05530041397070634 0.018974219854632768"/>
			<geometry>
				<mesh filename="textured_objs/original-139.obj"/>
			</geometry>
		</visual>
		<visual name="key-211">
			<origin xyz="-0.911923877178733 -0.05530041397070634 0.018974219854632768"/>
			<geometry>
				<mesh filename="textured_objs/original-33.obj"/>
			</geometry>
		</visual>
		<collision>
			<origin xyz="-0.911923877178733 -0.05530041397070634 0.018974219854632768"/>
			<geometry>
				<mesh filename="textured_objs/original-139.obj"/>
			</geometry>
		</collision>
		<collision>
			<origin xyz="-0.911923877178733 -0.05530041397070634 0.018974219854632768"/>
			<geometry>
				<mesh filename="textured_objs/original-33.obj"/>
			</geometry>
		</collision>
	</link>
	<joint name="joint_99" type="prismatic">
		<origin xyz="0.911923877178733 0.05530041397070634 -0.018974219854632768"/>
		<axis xyz="-0.05880441485746992 -0.9696166147022008 -0.2374566513844455"/>
		<child link="link_99"/>
		<parent link="link_0"/>
		<limit lower="0" upper="0.02"/>
	</joint>
	<link name="link_100">
		<visual name="key-212">
			<origin xyz="-0.911923877178733 -0.05530041397070634 0.018974219854632768"/>
			<geometry>
				<mesh filename="textured_objs/original-84.obj"/>
			</geometry>
		</visual>
		<visual name="key-212">
			<origin xyz="-0.911923877178733 -0.05530041397070634 0.018974219854632768"/>
			<geometry>
				<mesh filename="textured_objs/original-192.obj"/>
			</geometry>
		</visual>
		<collision>
			<origin xyz="-0.911923877178733 -0.05530041397070634 0.018974219854632768"/>
			<geometry>
				<mesh filename="textured_objs/original-84.obj"/>
			</geometry>
		</collision>
		<collision>
			<origin xyz="-0.911923877178733 -0.05530041397070634 0.018974219854632768"/>
			<geometry>
				<mesh filename="textured_objs/original-192.obj"/>
			</geometry>
		</collision>
	</link>
	<joint name="joint_100" type="prismatic">
		<origin xyz="0.911923877178733 0.05530041397070634 -0.018974219854632768"/>
		<axis xyz="-0.05880441485746992 -0.9696166147022008 -0.2374566513844455"/>
		<child link="link_100"/>
		<parent link="link_0"/>
		<limit lower="0" upper="0.02"/>
	</joint>
	<link name="link_101">
		<visual name="key-213">
			<origin xyz="-0.911923877178733 -0.05530041397070634 0.018974219854632768"/>
			<geometry>
				<mesh filename="textured_objs/original-199.obj"/>
			</geometry>
		</visual>
		<visual name="key-213">
			<origin xyz="-0.911923877178733 -0.05530041397070634 0.018974219854632768"/>
			<geometry>
				<mesh filename="textured_objs/original-93.obj"/>
			</geometry>
		</visual>
		<collision>
			<origin xyz="-0.911923877178733 -0.05530041397070634 0.018974219854632768"/>
			<geometry>
				<mesh filename="textured_objs/original-199.obj"/>
			</geometry>
		</collision>
		<collision>
			<origin xyz="-0.911923877178733 -0.05530041397070634 0.018974219854632768"/>
			<geometry>
				<mesh filename="textured_objs/original-93.obj"/>
			</geometry>
		</collision>
	</link>
	<joint name="joint_101" type="prismatic">
		<origin xyz="0.911923877178733 0.05530041397070634 -0.018974219854632768"/>
		<axis xyz="-0.05880441485746992 -0.9696166147022008 -0.2374566513844455"/>
		<child link="link_101"/>
		<parent link="link_0"/>
		<limit lower="0" upper="0.02"/>
	</joint>
	<link name="link_102">
		<visual name="key-214">
			<origin xyz="-0.911923877178733 -0.05530041397070634 0.018974219854632768"/>
			<geometry>
				<mesh filename="textured_objs/original-89.obj"/>
			</geometry>
		</visual>
		<visual name="key-214">
			<origin xyz="-0.911923877178733 -0.05530041397070634 0.018974219854632768"/>
			<geometry>
				<mesh filename="textured_objs/original-90.obj"/>
			</geometry>
		</visual>
		<visual name="key-214">
			<origin xyz="-0.911923877178733 -0.05530041397070634 0.018974219854632768"/>
			<geometry>
				<mesh filename="textured_objs/original-197.obj"/>
			</geometry>
		</visual>
		<collision>
			<origin xyz="-0.911923877178733 -0.05530041397070634 0.018974219854632768"/>
			<geometry>
				<mesh filename="textured_objs/original-89.obj"/>
			</geometry>
		</collision>
		<collision>
			<origin xyz="-0.911923877178733 -0.05530041397070634 0.018974219854632768"/>
			<geometry>
				<mesh filename="textured_objs/original-90.obj"/>
			</geometry>
		</collision>
		<collision>
			<origin xyz="-0.911923877178733 -0.05530041397070634 0.018974219854632768"/>
			<geometry>
				<mesh filename="textured_objs/original-197.obj"/>
			</geometry>
		</collision>
	</link>
	<joint name="joint_102" type="prismatic">
		<origin xyz="0.911923877178733 0.05530041397070634 -0.018974219854632768"/>
		<axis xyz="-0.05880441485746992 -0.9696166147022008 -0.2374566513844455"/>
		<child link="link_102"/>
		<parent link="link_0"/>
		<limit lower="0" upper="0.02"/>
	</joint>
	<link name="link_103">
		<visual name="key-215">
			<origin xyz="-0.911923877178733 -0.05530041397070634 0.018974219854632768"/>
			<geometry>
				<mesh filename="textured_objs/original-198.obj"/>
			</geometry>
		</visual>
		<visual name="key-215">
			<origin xyz="-0.911923877178733 -0.05530041397070634 0.018974219854632768"/>
			<geometry>
				<mesh filename="textured_objs/original-92.obj"/>
			</geometry>
		</visual>
		<collision>
			<origin xyz="-0.911923877178733 -0.05530041397070634 0.018974219854632768"/>
			<geometry>
				<mesh filename="textured_objs/original-198.obj"/>
			</geometry>
		</collision>
		<collision>
			<origin xyz="-0.911923877178733 -0.05530041397070634 0.018974219854632768"/>
			<geometry>
				<mesh filename="textured_objs/original-92.obj"/>
			</geometry>
		</collision>
	</link>
	<joint name="joint_103" type="prismatic">
		<origin xyz="0.911923877178733 0.05530041397070634 -0.018974219854632768"/>
		<axis xyz="-0.05880441485746992 -0.9696166147022008 -0.2374566513844455"/>
		<child link="link_103"/>
		<parent link="link_0"/>
		<limit lower="0" upper="0.02"/>
	</joint>
	<link name="link_104">
		<visual name="key-216">
			<origin xyz="-0.911923877178733 -0.05530041397070634 0.018974219854632768"/>
			<geometry>
				<mesh filename="textured_objs/original-202.obj"/>
			</geometry>
		</visual>
		<visual name="key-216">
			<origin xyz="-0.911923877178733 -0.05530041397070634 0.018974219854632768"/>
			<geometry>
				<mesh filename="textured_objs/original-96.obj"/>
			</geometry>
		</visual>
		<collision>
			<origin xyz="-0.911923877178733 -0.05530041397070634 0.018974219854632768"/>
			<geometry>
				<mesh filename="textured_objs/original-202.obj"/>
			</geometry>
		</collision>
		<collision>
			<origin xyz="-0.911923877178733 -0.05530041397070634 0.018974219854632768"/>
			<geometry>
				<mesh filename="textured_objs/original-96.obj"/>
			</geometry>
		</collision>
	</link>
	<joint name="joint_104" type="prismatic">
		<origin xyz="0.911923877178733 0.05530041397070634 -0.018974219854632768"/>
		<axis xyz="-0.05880441485746992 -0.9696166147022008 -0.2374566513844455"/>
		<child link="link_104"/>
		<parent link="link_0"/>
		<limit lower="0" upper="0.02"/>
	</joint>
	<link name="link_105">
		<visual name="key-217">
			<origin xyz="-0.911923877178733 -0.05530041397070634 0.018974219854632768"/>
			<geometry>
				<mesh filename="textured_objs/original-191.obj"/>
			</geometry>
		</visual>
		<visual name="key-217">
			<origin xyz="-0.911923877178733 -0.05530041397070634 0.018974219854632768"/>
			<geometry>
				<mesh filename="textured_objs/original-83.obj"/>
			</geometry>
		</visual>
		<collision>
			<origin xyz="-0.911923877178733 -0.05530041397070634 0.018974219854632768"/>
			<geometry>
				<mesh filename="textured_objs/original-191.obj"/>
			</geometry>
		</collision>
		<collision>
			<origin xyz="-0.911923877178733 -0.05530041397070634 0.018974219854632768"/>
			<geometry>
				<mesh filename="textured_objs/original-83.obj"/>
			</geometry>
		</collision>
	</link>
	<joint name="joint_105" type="prismatic">
		<origin xyz="0.911923877178733 0.05530041397070634 -0.018974219854632768"/>
		<axis xyz="-0.05880441485746992 -0.9696166147022008 -0.2374566513844455"/>
		<child link="link_105"/>
		<parent link="link_0"/>
		<limit lower="0" upper="0.02"/>
	</joint>
	<link name="link_106">
		<visual name="key-218">
			<origin xyz="-0.911923877178733 -0.05530041397070634 0.018974219854632768"/>
			<geometry>
				<mesh filename="textured_objs/original-162.obj"/>
			</geometry>
		</visual>
		<visual name="key-218">
			<origin xyz="-0.911923877178733 -0.05530041397070634 0.018974219854632768"/>
			<geometry>
				<mesh filename="textured_objs/original-67.obj"/>
			</geometry>
		</visual>
		<collision>
			<origin xyz="-0.911923877178733 -0.05530041397070634 0.018974219854632768"/>
			<geometry>
				<mesh filename="textured_objs/original-162.obj"/>
			</geometry>
		</collision>
		<collision>
			<origin xyz="-0.911923877178733 -0.05530041397070634 0.018974219854632768"/>
			<geometry>
				<mesh filename="textured_objs/original-67.obj"/>
			</geometry>
		</collision>
	</link>
	<joint name="joint_106" type="prismatic">
		<origin xyz="0.911923877178733 0.05530041397070634 -0.018974219854632768"/>
		<axis xyz="-0.05880441485746992 -0.9696166147022008 -0.2374566513844455"/>
		<child link="link_106"/>
		<parent link="link_0"/>
		<limit lower="0" upper="0.02"/>
	</joint>
	<link name="link_107">
		<visual name="key-219">
			<origin xyz="-0.911923877178733 -0.05530041397070634 0.018974219854632768"/>
			<geometry>
				<mesh filename="textured_objs/original-210.obj"/>
			</geometry>
		</visual>
		<visual name="key-219">
			<origin xyz="-0.911923877178733 -0.05530041397070634 0.018974219854632768"/>
			<geometry>
				<mesh filename="textured_objs/original-103.obj"/>
			</geometry>
		</visual>
		<collision>
			<origin xyz="-0.911923877178733 -0.05530041397070634 0.018974219854632768"/>
			<geometry>
				<mesh filename="textured_objs/original-210.obj"/>
			</geometry>
		</collision>
		<collision>
			<origin xyz="-0.911923877178733 -0.05530041397070634 0.018974219854632768"/>
			<geometry>
				<mesh filename="textured_objs/original-103.obj"/>
			</geometry>
		</collision>
	</link>
	<joint name="joint_107" type="prismatic">
		<origin xyz="0.911923877178733 0.05530041397070634 -0.018974219854632768"/>
		<axis xyz="-0.05880441485746992 -0.9696166147022008 -0.2374566513844455"/>
		<child link="link_107"/>
		<parent link="link_0"/>
		<limit lower="0" upper="0.02"/>
	</joint>
	<link name="link_108">
		<visual name="key-220">
			<origin xyz="-0.911923877178733 -0.05530041397070634 0.018974219854632768"/>
			<geometry>
				<mesh filename="textured_objs/original-194.obj"/>
			</geometry>
		</visual>
		<visual name="key-220">
			<origin xyz="-0.911923877178733 -0.05530041397070634 0.018974219854632768"/>
			<geometry>
				<mesh filename="textured_objs/original-86.obj"/>
			</geometry>
		</visual>
		<collision>
			<origin xyz="-0.911923877178733 -0.05530041397070634 0.018974219854632768"/>
			<geometry>
				<mesh filename="textured_objs/original-194.obj"/>
			</geometry>
		</collision>
		<collision>
			<origin xyz="-0.911923877178733 -0.05530041397070634 0.018974219854632768"/>
			<geometry>
				<mesh filename="textured_objs/original-86.obj"/>
			</geometry>
		</collision>
	</link>
	<joint name="joint_108" type="prismatic">
		<origin xyz="0.911923877178733 0.05530041397070634 -0.018974219854632768"/>
		<axis xyz="-0.05880441485746992 -0.9696166147022008 -0.2374566513844455"/>
		<child link="link_108"/>
		<parent link="link_0"/>
		<limit lower="0" upper="0.02"/>
	</joint>
	<link name="link_109">
		<visual name="key-221">
			<origin xyz="-0.911923877178733 -0.05530041397070634 0.018974219854632768"/>
			<geometry>
				<mesh filename="textured_objs/original-149.obj"/>
			</geometry>
		</visual>
		<visual name="key-221">
			<origin xyz="-0.911923877178733 -0.05530041397070634 0.018974219854632768"/>
			<geometry>
				<mesh filename="textured_objs/original-71.obj"/>
			</geometry>
		</visual>
		<collision>
			<origin xyz="-0.911923877178733 -0.05530041397070634 0.018974219854632768"/>
			<geometry>
				<mesh filename="textured_objs/original-149.obj"/>
			</geometry>
		</collision>
		<collision>
			<origin xyz="-0.911923877178733 -0.05530041397070634 0.018974219854632768"/>
			<geometry>
				<mesh filename="textured_objs/original-71.obj"/>
			</geometry>
		</collision>
	</link>
	<joint name="joint_109" type="prismatic">
		<origin xyz="0.911923877178733 0.05530041397070634 -0.018974219854632768"/>
		<axis xyz="-0.05880441485746992 -0.9696166147022008 -0.2374566513844455"/>
		<child link="link_109"/>
		<parent link="link_0"/>
		<limit lower="0" upper="0.02"/>
	</joint>
	<link name="link_110">
		<visual name="key-222">
			<origin xyz="-0.911923877178733 -0.05530041397070634 0.018974219854632768"/>
			<geometry>
				<mesh filename="textured_objs/original-222.obj"/>
			</geometry>
		</visual>
		<visual name="key-222">
			<origin xyz="-0.911923877178733 -0.05530041397070634 0.018974219854632768"/>
			<geometry>
				<mesh filename="textured_objs/original-59.obj"/>
			</geometry>
		</visual>
		<collision>
			<origin xyz="-0.911923877178733 -0.05530041397070634 0.018974219854632768"/>
			<geometry>
				<mesh filename="textured_objs/original-222.obj"/>
			</geometry>
		</collision>
		<collision>
			<origin xyz="-0.911923877178733 -0.05530041397070634 0.018974219854632768"/>
			<geometry>
				<mesh filename="textured_objs/original-59.obj"/>
			</geometry>
		</collision>
	</link>
	<joint name="joint_110" type="prismatic">
		<origin xyz="0.911923877178733 0.05530041397070634 -0.018974219854632768"/>
		<axis xyz="-0.05880441485746992 -0.9696166147022008 -0.2374566513844455"/>
		<child link="link_110"/>
		<parent link="link_0"/>
		<limit lower="0" upper="0.02"/>
	</joint>
</robot>
