<?xml version="1.0" ?>
<robot name="partnet_1a5494c28b607f699263b5578aef09fa">
	<link name="base"/>
	<link name="link_0">
		<visual name="frame-6">
			<origin xyz="-0.12023099999999998 -0.06139036951659382 0.09590392734686537"/>
			<geometry>
				<mesh filename="textured_objs/new-3.obj"/>
			</geometry>
		</visual>
		<visual name="screen-7">
			<origin xyz="-0.12023099999999998 -0.06139036951659382 0.09590392734686537"/>
			<geometry>
				<mesh filename="textured_objs/new-2.obj"/>
			</geometry>
		</visual>
		<collision>
			<origin xyz="-0.12023099999999998 -0.06139036951659382 0.09590392734686537"/>
			<geometry>
				<mesh filename="textured_objs/new-3.obj"/>
			</geometry>
		</collision>
		<collision>
			<origin xyz="-0.12023099999999998 -0.06139036951659382 0.09590392734686537"/>
			<geometry>
				<mesh filename="textured_objs/new-2.obj"/>
			</geometry>
		</collision>
	</link>
	<joint name="joint_0" type="revolute">
		<origin xyz="0.12023099999999998 0.06139036951659382 -0.09590392734686537"/>
		<axis xyz="-1 0 0"/>
		<child link="link_0"/>
		<parent link="link_1"/>
		<limit lower="-0.48380526865282814" upper="2.029468854219006"/>
	</joint>
	<link name="link_1">
		<visual name="base_support-4">
			<origin xyz="0 0 0"/>
			<geometry>
				<mesh filename="textured_objs/new-1.obj"/>
			</geometry>
		</visual>
		<visual name="surface-5">
			<origin xyz="0 0 0"/>
			<geometry>
				<mesh filename="textured_objs/new-0.obj"/>
			</geometry>
		</visual>
		<collision>
			<origin xyz="0 0 0"/>
			<geometry>
				<mesh filename="textured_objs/new-1.obj"/>
			</geometry>
		</collision>
		<collision>
			<origin xyz="0 0 0"/>
			<geometry>
				<mesh filename="textured_objs/new-0.obj"/>
			</geometry>
		</collision>
	</link>
	<joint name="joint_1" type="fixed">
		<origin rpy="1.570796326794897 0 -1.570796326794897" xyz="0 0 0"/>
		<child link="link_1"/>
		<parent link="base"/>
	</joint>
</robot>
