<?xml version="1.0" ?>
<robot name="partnet_273314626729b1e973222d877df1ecac">
	<link name="base"/>
	<link name="link_0">
		<visual name="lamp_arm_straight_bar-25">
			<origin xyz="0 0.501004011222157 0.421094108130413"/>
			<geometry>
				<mesh filename="textured_objs/original-63.obj"/>
			</geometry>
		</visual>
		<visual name="lamp_arm_straight_bar-25">
			<origin xyz="0 0.501004011222157 0.421094108130413"/>
			<geometry>
				<mesh filename="textured_objs/original-62.obj"/>
			</geometry>
		</visual>
		<visual name="lamp_arm_straight_bar-25">
			<origin xyz="0 0.501004011222157 0.421094108130413"/>
			<geometry>
				<mesh filename="textured_objs/original-50.obj"/>
			</geometry>
		</visual>
		<collision>
			<origin xyz="0 0.501004011222157 0.421094108130413"/>
			<geometry>
				<mesh filename="textured_objs/original-63.obj"/>
			</geometry>
		</collision>
		<collision>
			<origin xyz="0 0.501004011222157 0.421094108130413"/>
			<geometry>
				<mesh filename="textured_objs/original-62.obj"/>
			</geometry>
		</collision>
		<collision>
			<origin xyz="0 0.501004011222157 0.421094108130413"/>
			<geometry>
				<mesh filename="textured_objs/original-50.obj"/>
			</geometry>
		</collision>
	</link>
	<joint name="joint_0" type="revolute">
		<origin xyz="0 -0.501004011222157 -0.421094108130413"/>
		<axis xyz="-1 0 0"/>
		<child link="link_0"/>
		<parent link="link_4"/>
		<limit lower="-0.7853981633974483" upper="0.7853981633974483"/>
	</joint>
	<link name="link_1">
		<visual name="lamp_arm_curved_bar-20">
			<origin xyz="0 -0.5954986511213731 -0.3148151334011385"/>
			<geometry>
				<mesh filename="textured_objs/original-64.obj"/>
			</geometry>
		</visual>
		<visual name="lamp_arm_curved_bar-20">
			<origin xyz="0 -0.5954986511213731 -0.3148151334011385"/>
			<geometry>
				<mesh filename="textured_objs/original-56.obj"/>
			</geometry>
		</visual>
		<collision>
			<origin xyz="0 -0.5954986511213731 -0.3148151334011385"/>
			<geometry>
				<mesh filename="textured_objs/original-64.obj"/>
			</geometry>
		</collision>
		<collision>
			<origin xyz="0 -0.5954986511213731 -0.3148151334011385"/>
			<geometry>
				<mesh filename="textured_objs/original-56.obj"/>
			</geometry>
		</collision>
	</link>
	<joint name="joint_1" type="revolute">
		<origin xyz="0 0.3310264154790775 0.7366252356316002"/>
		<axis xyz="1 0 0"/>
		<child link="link_1"/>
		<parent link="link_3"/>
		<limit lower="-1.0471975511965976" upper="1.0471975511965976"/>
	</joint>
	<link name="link_2">
		<visual name="lamp_cover_holder-6">
			<origin xyz="0.0040496185367449545 -0.4857680416119243 0.1159625071606532"/>
			<geometry>
				<mesh filename="textured_objs/original-69.obj"/>
			</geometry>
		</visual>
		<visual name="lamp_shade-9">
			<origin xyz="0.0040496185367449545 -0.4857680416119243 0.1159625071606532"/>
			<geometry>
				<mesh filename="textured_objs/original-68.obj"/>
			</geometry>
		</visual>
		<visual name="light_bulb-8">
			<origin xyz="0.0040496185367449545 -0.4857680416119243 0.1159625071606532"/>
			<geometry>
				<mesh filename="textured_objs/original-71.obj"/>
			</geometry>
		</visual>
		<visual name="light_bulb-8">
			<origin xyz="0.0040496185367449545 -0.4857680416119243 0.1159625071606532"/>
			<geometry>
				<mesh filename="textured_objs/original-75.obj"/>
			</geometry>
		</visual>
		<collision>
			<origin xyz="0.0040496185367449545 -0.4857680416119243 0.1159625071606532"/>
			<geometry>
				<mesh filename="textured_objs/original-69.obj"/>
			</geometry>
		</collision>
		<collision>
			<origin xyz="0.0040496185367449545 -0.4857680416119243 0.1159625071606532"/>
			<geometry>
				<mesh filename="textured_objs/original-68.obj"/>
			</geometry>
		</collision>
		<collision>
			<origin xyz="0.0040496185367449545 -0.4857680416119243 0.1159625071606532"/>
			<geometry>
				<mesh filename="textured_objs/original-71.obj"/>
			</geometry>
		</collision>
		<collision>
			<origin xyz="0.0040496185367449545 -0.4857680416119243 0.1159625071606532"/>
			<geometry>
				<mesh filename="textured_objs/original-75.obj"/>
			</geometry>
		</collision>
	</link>
	<joint name="joint_2" type="continuous">
		<origin xyz="-0.0040496185367449545 -0.10973060950944885 -0.4307776405617917"/>
		<axis xyz="-5.395163513794664e-05 -0.23219592236892692 -0.9726690345253438"/>
		<child link="link_2"/>
		<parent link="link_1"/>
	</joint>
	<link name="link_3">
		<visual name="lamp_arm_straight_bar-24">
			<origin xyz="0 -0.2644722356422956 0.4218101022304617"/>
			<geometry>
				<mesh filename="textured_objs/original-49.obj"/>
			</geometry>
		</visual>
		<visual name="lamp_arm_straight_bar-24">
			<origin xyz="0 -0.2644722356422956 0.4218101022304617"/>
			<geometry>
				<mesh filename="textured_objs/original-60.obj"/>
			</geometry>
		</visual>
		<visual name="lamp_joint-17">
			<origin xyz="0 -0.2644722356422956 0.4218101022304617"/>
			<geometry>
				<mesh filename="textured_objs/original-61.obj"/>
			</geometry>
		</visual>
		<visual name="lamp_joint-18">
			<origin xyz="0 -0.2644722356422956 0.4218101022304617"/>
			<geometry>
				<mesh filename="textured_objs/original-52.obj"/>
			</geometry>
		</visual>
		<visual name="lamp_joint-18">
			<origin xyz="0 -0.2644722356422956 0.4218101022304617"/>
			<geometry>
				<mesh filename="textured_objs/original-58.obj"/>
			</geometry>
		</visual>
		<visual name="lamp_joint-18">
			<origin xyz="0 -0.2644722356422956 0.4218101022304617"/>
			<geometry>
				<mesh filename="textured_objs/original-51.obj"/>
			</geometry>
		</visual>
		<visual name="lamp_joint-19">
			<origin xyz="0 -0.2644722356422956 0.4218101022304617"/>
			<geometry>
				<mesh filename="textured_objs/original-65.obj"/>
			</geometry>
		</visual>
		<visual name="lamp_arm_straight_bar-21">
			<origin xyz="0 -0.2644722356422956 0.4218101022304617"/>
			<geometry>
				<mesh filename="textured_objs/original-53.obj"/>
			</geometry>
		</visual>
		<visual name="lamp_arm_straight_bar-21">
			<origin xyz="0 -0.2644722356422956 0.4218101022304617"/>
			<geometry>
				<mesh filename="textured_objs/original-59.obj"/>
			</geometry>
		</visual>
		<visual name="lamp_arm_straight_bar-22">
			<origin xyz="0 -0.2644722356422956 0.4218101022304617"/>
			<geometry>
				<mesh filename="textured_objs/original-66.obj"/>
			</geometry>
		</visual>
		<visual name="lamp_arm_straight_bar-23">
			<origin xyz="0 -0.2644722356422956 0.4218101022304617"/>
			<geometry>
				<mesh filename="textured_objs/original-48.obj"/>
			</geometry>
		</visual>
		<collision>
			<origin xyz="0 -0.2644722356422956 0.4218101022304617"/>
			<geometry>
				<mesh filename="textured_objs/original-49.obj"/>
			</geometry>
		</collision>
		<collision>
			<origin xyz="0 -0.2644722356422956 0.4218101022304617"/>
			<geometry>
				<mesh filename="textured_objs/original-60.obj"/>
			</geometry>
		</collision>
		<collision>
			<origin xyz="0 -0.2644722356422956 0.4218101022304617"/>
			<geometry>
				<mesh filename="textured_objs/original-61.obj"/>
			</geometry>
		</collision>
		<collision>
			<origin xyz="0 -0.2644722356422956 0.4218101022304617"/>
			<geometry>
				<mesh filename="textured_objs/original-52.obj"/>
			</geometry>
		</collision>
		<collision>
			<origin xyz="0 -0.2644722356422956 0.4218101022304617"/>
			<geometry>
				<mesh filename="textured_objs/original-58.obj"/>
			</geometry>
		</collision>
		<collision>
			<origin xyz="0 -0.2644722356422956 0.4218101022304617"/>
			<geometry>
				<mesh filename="textured_objs/original-51.obj"/>
			</geometry>
		</collision>
		<collision>
			<origin xyz="0 -0.2644722356422956 0.4218101022304617"/>
			<geometry>
				<mesh filename="textured_objs/original-65.obj"/>
			</geometry>
		</collision>
		<collision>
			<origin xyz="0 -0.2644722356422956 0.4218101022304617"/>
			<geometry>
				<mesh filename="textured_objs/original-53.obj"/>
			</geometry>
		</collision>
		<collision>
			<origin xyz="0 -0.2644722356422956 0.4218101022304617"/>
			<geometry>
				<mesh filename="textured_objs/original-59.obj"/>
			</geometry>
		</collision>
		<collision>
			<origin xyz="0 -0.2644722356422956 0.4218101022304617"/>
			<geometry>
				<mesh filename="textured_objs/original-66.obj"/>
			</geometry>
		</collision>
		<collision>
			<origin xyz="0 -0.2644722356422956 0.4218101022304617"/>
			<geometry>
				<mesh filename="textured_objs/original-48.obj"/>
			</geometry>
		</collision>
	</link>
	<joint name="joint_3" type="revolute">
		<origin xyz="0 0.7654762468644526 -0.0007159941000487446"/>
		<axis xyz="1 0 0"/>
		<child link="link_3"/>
		<parent link="link_0"/>
		<limit lower="-0.7853981633974483" upper="0.7853981633974483"/>
	</joint>
	<link name="link_4">
		<visual name="lamp_joint-16">
			<origin xyz="0 0 0"/>
			<geometry>
				<mesh filename="textured_objs/original-54.obj"/>
			</geometry>
		</visual>
		<visual name="lamp_joint-16">
			<origin xyz="0 0 0"/>
			<geometry>
				<mesh filename="textured_objs/original-57.obj"/>
			</geometry>
		</visual>
		<visual name="lamp_joint-16">
			<origin xyz="0 0 0"/>
			<geometry>
				<mesh filename="textured_objs/original-55.obj"/>
			</geometry>
		</visual>
		<visual name="lamp_base_part-28">
			<origin xyz="0 0 0"/>
			<geometry>
				<mesh filename="textured_objs/new-0.obj"/>
			</geometry>
		</visual>
		<visual name="lamp_arm_straight_bar-26">
			<origin xyz="0 0 0"/>
			<geometry>
				<mesh filename="textured_objs/new-1.obj"/>
			</geometry>
		</visual>
		<collision>
			<origin xyz="0 0 0"/>
			<geometry>
				<mesh filename="textured_objs/original-54.obj"/>
			</geometry>
		</collision>
		<collision>
			<origin xyz="0 0 0"/>
			<geometry>
				<mesh filename="textured_objs/original-57.obj"/>
			</geometry>
		</collision>
		<collision>
			<origin xyz="0 0 0"/>
			<geometry>
				<mesh filename="textured_objs/original-55.obj"/>
			</geometry>
		</collision>
		<collision>
			<origin xyz="0 0 0"/>
			<geometry>
				<mesh filename="textured_objs/new-0.obj"/>
			</geometry>
		</collision>
		<collision>
			<origin xyz="0 0 0"/>
			<geometry>
				<mesh filename="textured_objs/new-1.obj"/>
			</geometry>
		</collision>
	</link>
	<joint name="joint_4" type="fixed">
		<origin rpy="1.570796326794897 0 -1.570796326794897" xyz="0 0 0"/>
		<child link="link_4"/>
		<parent link="base"/>
	</joint>
</robot>
