<?xml version="1.0" ?>
<robot name="partnet_1e9a36b3360f23388962005ce0e986db">
	<link name="base"/>
	<link name="link_0">
		<visual name="lamp_arm_straight_bar-15">
			<origin xyz="0.00012618158852113206 0.5045340047940331 0.2960457332331541"/>
			<geometry>
				<mesh filename="textured_objs/original-7.obj"/>
			</geometry>
		</visual>
		<visual name="lamp_arm_straight_bar-15">
			<origin xyz="0.00012618158852113206 0.5045340047940331 0.2960457332331541"/>
			<geometry>
				<mesh filename="textured_objs/original-6.obj"/>
			</geometry>
		</visual>
		<collision>
			<origin xyz="0.00012618158852113206 0.5045340047940331 0.2960457332331541"/>
			<geometry>
				<mesh filename="textured_objs/original-7.obj"/>
			</geometry>
		</collision>
		<collision>
			<origin xyz="0.00012618158852113206 0.5045340047940331 0.2960457332331541"/>
			<geometry>
				<mesh filename="textured_objs/original-6.obj"/>
			</geometry>
		</collision>
	</link>
	<joint name="joint_0" type="revolute">
		<origin xyz="-0.00012618158852113206 -0.5045340047940331 -0.2960457332331541"/>
		<axis xyz="-0.9999999687261597 0.0002500953410302977 0"/>
		<child link="link_0"/>
		<parent link="link_1"/>
		<limit lower="-0.6974335690969338" upper="0.6974335690969341"/>
	</joint>
	<link name="link_1">
		<visual name="lamp_base_part-18">
			<origin xyz="0 0 0"/>
			<geometry>
				<mesh filename="textured_objs/original-4.obj"/>
			</geometry>
		</visual>
		<visual name="lamp_arm_curved_bar-16">
			<origin xyz="0 0 0"/>
			<geometry>
				<mesh filename="textured_objs/original-8.obj"/>
			</geometry>
		</visual>
		<collision>
			<origin xyz="0 0 0"/>
			<geometry>
				<mesh filename="textured_objs/original-4.obj"/>
			</geometry>
		</collision>
		<collision>
			<origin xyz="0 0 0"/>
			<geometry>
				<mesh filename="textured_objs/original-8.obj"/>
			</geometry>
		</collision>
	</link>
	<joint name="joint_1" type="fixed">
		<origin rpy="1.570796326794897 0 -1.570796326794897" xyz="0 0 0"/>
		<child link="link_1"/>
		<parent link="base"/>
	</joint>
	<link name="link_2">
		<visual name="lamp_shade-9">
			<origin xyz="-0.020858815740286828 -0.5589676681772568 0.5909557968569753"/>
			<geometry>
				<mesh filename="textured_objs/original-3.obj"/>
			</geometry>
		</visual>
		<visual name="lamp_shade-9">
			<origin xyz="-0.020858815740286828 -0.5589676681772568 0.5909557968569753"/>
			<geometry>
				<mesh filename="textured_objs/original-2.obj"/>
			</geometry>
		</visual>
		<visual name="lamp_arm_straight_bar-14">
			<origin xyz="-0.020858815740286828 -0.5589676681772568 0.5909557968569753"/>
			<geometry>
				<mesh filename="textured_objs/original-9.obj"/>
			</geometry>
		</visual>
		<collision>
			<origin xyz="-0.020858815740286828 -0.5589676681772568 0.5909557968569753"/>
			<geometry>
				<mesh filename="textured_objs/original-3.obj"/>
			</geometry>
		</collision>
		<collision>
			<origin xyz="-0.020858815740286828 -0.5589676681772568 0.5909557968569753"/>
			<geometry>
				<mesh filename="textured_objs/original-2.obj"/>
			</geometry>
		</collision>
		<collision>
			<origin xyz="-0.020858815740286828 -0.5589676681772568 0.5909557968569753"/>
			<geometry>
				<mesh filename="textured_objs/original-9.obj"/>
			</geometry>
		</collision>
	</link>
	<joint name="joint_2" type="revolute">
		<origin xyz="0.02098499732880796 1.0635016729712898 -0.2949100636238212"/>
		<axis xyz="0.9999999998687011 1.5923183783891676e-05 -3.008283561350552e-06"/>
		<child link="link_2"/>
		<parent link="link_0"/>
		<limit lower="-1.049291946298991" upper="0.48380526865282814"/>
	</joint>
</robot>
